Workbook

Sheet Executive Summary
B4: =Assumptions!C3&" Executive Summary" -> Brownstone Apartments Executive Summary
B6: Property Summary | E6: Project Capitalization | H6: Financing Assumptions | J6: Refinancing Assumptions
B8: Property Name | C8: =Assumptions!C3 -> Brownstone Apartments | E8: Purchase Price | F8: =Assumptions!C23 -> 3725000 | H8: Loan Amount | I8: ='Loan Summary'!G30 -> 2778100 | J8: Loan Amount | K8: =IF(OR(Assumptions!$AD$3>'Sale Analysis'!$E$3,Assumptions!$AD$3=""),"",ROUND('Loan Summary'!C9,-3)) -> 3740000
B9: Property Address | C9: =Assumptions!C4 -> 9559 Flower St | E9: Closing Costs & Reserves | F9: =ROUND(Assumptions!C24,-3) -> 65000 | H9: Loan Type | I9: =Assumptions!W2 -> Bridge | J9: Interest Rate | K9: =IF(OR(Assumptions!$AD$3>'Sale Analysis'!$E$3,Assumptions!$AD$3>=""),"",'Loan Summary'!C10) -> 0.055
B10: City, State | C10: =Assumptions!C5 -> Bellflower, CA 90706 | E10: Capital Expenditures | F10: =ROUND(Assumptions!C28+Assumptions!C45,-3) -> 484000 | H10: Interest Rate | I10: ='Loan Summary'!C3 -> 0.0585 | J10: Refi Cap Rate | K10: =IF(OR(Assumptions!$AD$3>'Sale Analysis'!$E$3,Assumptions!$AD$3=""),"",Assumptions!AD9) -> 0.0575
B11: Year Built | C11: =Assumptions!C6 -> 1967 | E11: Total Capitalization | F11: =SUM(F8:F10) -> 4274000 | H11: LTC | I11: =G13 -> 0.6499766 | J11: Net Refi Proceeds | K11: =IFERROR(ROUND(Assumptions!AD26,-3),"") -> 943000
B12: Total Units | C12: =Assumptions!C10 -> 17 | E12: Total Equity | F12: =ROUND(Assumptions!C36,-3) -> 1498000 | G12: =F12/F11 -> 0.35049134 | H12: Term* | I12: ='Loan Summary'!C5 -> 60 | J12: % of Equity Returned | K12: =IFERROR(K11/F12,"") -> 0.62950601
B13: Purchase Price/Per Unit | C13: =Assumptions!C23/Assumptions!C10 -> 219117.65 | E13: Total Debt & Pref. Equity | F13: =ROUND(I8,-3) -> 2778000 | G13: =F13/F11 -> 0.6499766 | H13: I/O Period | I13: ='Loan Summary'!C6 -> 60 | J13: Refi Month | K13: =IF(OR(Assumptions!$AD$3>'Sale Analysis'!$E$3,Assumptions!$AD$3=""),"",Assumptions!AD3) -> 35
B14: Purchase Price/Per Sqft. | C14: =Assumptions!C23/C15 -> 313.84278 | J14: TLV Max | K14: =IF(OR(Assumptions!$AD$3>'Sale Analysis'!$E$3,Assumptions!$AD$3=""),"",Assumptions!AD11) -> 0.7
B15: Gross Rentable Square Footage | C15: =Assumptions!C9 -> 11869 | J15: DSCR Max | K15: =IF(OR(Assumptions!$AD$3>'Sale Analysis'!$E$3,Assumptions!$AD$3=""),"",Assumptions!AD16) -> 1.25
B17: Economics | E17: Sale Analysis | H17: Unit Type | I17: # of units | J17: Current Rent | K17: Proforma Rent
B19: Deal Returns | E19: Sale Price | F19: ='Sale Analysis'!E11 -> 5406000 | H19: =IF(H18="TOTAL","",IF('Unit Mix'!B4=0,'Unit Mix'!$B$18,'Unit Mix'!B4)) -> Stu - ADU | I19: =IF('Unit Mix'!C4=0,'Unit Mix'!$C$18,'Unit Mix'!C4) -> 1 | J19: =IF('Unit Mix'!E4=0,'Unit Mix'!$E$18,'Unit Mix'!E4) -> 1340 | K19: =IF('Unit Mix'!H4="",'Unit Mix'!$H$18,'Unit Mix'!H4) -> 1650
B20: Total Investment | C20: =-ROUND('Waterfall Split'!C55,-3) -> 1498000 | E20: Proceeds From Sale | F20: ='Sale Analysis'!E18 -> 1553458.1 | H20: =IF(OR(H19="TOTAL",H19=""),"",IF('Unit Mix'!B5=0,'Unit Mix'!$B$18,'Unit Mix'!B5)) -> 1x1 | I20: =IF(OR(H19="TOTAL",H19=""),"",IF('Unit Mix'!C5=0,'Unit Mix'!$C$18,'Unit Mix'!C5)) -> 9 | J20: =IF(OR(H19="TOTAL",H19=""),"",IF('Unit Mix'!E5=0,'Unit Mix'!$E$18,'Unit Mix'!E5)) -> 1427 | K20: =IF(OR(H19="TOTAL",H19=""),"",IF('Unit Mix'!H5="",'Unit Mix'!$H$18,'Unit Mix'!H5)) -> 1925
B21: Gross Distributions | C21: =ROUND('Waterfall Split'!C56,-3) -> 2965000 | E21: Sale Cap Rate | F21: ='Sale Analysis'!E4 -> 0.0575 | H21: =IF(OR(H20="TOTAL",H20=""),"",IF('Unit Mix'!B6=0,'Unit Mix'!$B$18,'Unit Mix'!B6)) -> 2x1 | I21: =IF(OR(H20="TOTAL",H20=""),"",IF('Unit Mix'!C6=0,'Unit Mix'!$C$18,'Unit Mix'!C6)) -> 7 | J21: =IF(OR(H20="TOTAL",H20=""),"",IF('Unit Mix'!E6=0,'Unit Mix'!$E$18,'Unit Mix'!E6)) -> 1676 | K21: =IF(OR(H20="TOTAL",H20=""),"",IF('Unit Mix'!H6="",'Unit Mix'!$H$18,'Unit Mix'!H6)) -> 2250
B22: Gross Equity Multiple | C22: ='Waterfall Split'!C59 -> 1.9795314 | E22: Sale Month | F22: ='Sale Analysis'!E3 -> 83 | H22: =IF(OR(H21="TOTAL",H21=""),"",IF('Unit Mix'!B7=0,'Unit Mix'!$B$18,'Unit Mix'!B7)) -> TOTAL | I22: =IF(OR(H21="TOTAL",H21=""),"",IF('Unit Mix'!C7=0,'Unit Mix'!$C$18,'Unit Mix'!C7)) -> 17 | J22: =IF(OR(H21="TOTAL",H21=""),"",IF('Unit Mix'!E7=0,'Unit Mix'!$E$18,'Unit Mix'!E7)) -> 1524.4118 | K22: =IF(OR(H21="TOTAL",H21=""),"",IF('Unit Mix'!H7="",'Unit Mix'!$H$18,'Unit Mix'!H7)) -> 2042.6471
B23: Gross IRR | C23: ='Waterfall Split'!C58 -> 0.15240298 | H23: =IF(OR(H22="TOTAL",H22=""),"",IF('Unit Mix'!B8=0,'Unit Mix'!$B$18,'Unit Mix'!B8)) | I23: =IF(OR(H22="TOTAL",H22=""),"",IF('Unit Mix'!C8=0,'Unit Mix'!$C$18,'Unit Mix'!C8)) | J23: =IF(OR(H22="TOTAL",H22=""),"",IF('Unit Mix'!E8=0,'Unit Mix'!$E$18,'Unit Mix'!E8)) | K23: =IF(OR(H22="TOTAL",H22=""),"",IF('Unit Mix'!H8="",'Unit Mix'!$H$18,'Unit Mix'!H8))
B24: Investor Returns | H24: =IF(OR(H23="TOTAL",H23=""),"",IF('Unit Mix'!B9=0,'Unit Mix'!$B$18,'Unit Mix'!B9)) | I24: =IF(OR(H23="TOTAL",H23=""),"",IF('Unit Mix'!C9=0,'Unit Mix'!$C$18,'Unit Mix'!C9)) | J24: =IF(OR(H23="TOTAL",H23=""),"",IF('Unit Mix'!E9=0,'Unit Mix'!$E$18,'Unit Mix'!E9)) | K24: =IF(OR(H23="TOTAL",H23=""),"",IF('Unit Mix'!H9="",'Unit Mix'!$H$18,'Unit Mix'!H9))
B25: Total Investment | C25: =-ROUND('Waterfall Split'!C62,-3) -> 1423000 | H25: =IF(OR(H24="TOTAL",H24=""),"",IF('Unit Mix'!B10=0,'Unit Mix'!$B$18,'Unit Mix'!B10)) | I25: =IF(OR(H24="TOTAL",H24=""),"",IF('Unit Mix'!C10=0,'Unit Mix'!$C$18,'Unit Mix'!C10)) | J25: =IF(OR(H24="TOTAL",H24=""),"",IF('Unit Mix'!E10=0,'Unit Mix'!$E$18,'Unit Mix'!E10)) | K25: =IF(OR(H24="TOTAL",H24=""),"",IF('Unit Mix'!H10="",'Unit Mix'!$H$18,'Unit Mix'!H10))
B26: Gross Distributions | C26: =ROUND('Waterfall Split'!C63,-3) -> 2544000 | E26: CoC Dist. | G26: YoC | H26: =IF(OR(H25="TOTAL",H25=""),"",IF('Unit Mix'!B11=0,'Unit Mix'!$B$18,'Unit Mix'!B11)) | I26: =IF(OR(H25="TOTAL",H25=""),"",IF('Unit Mix'!C11=0,'Unit Mix'!$C$18,'Unit Mix'!C11)) | J26: =IF(OR(H25="TOTAL",H25=""),"",IF('Unit Mix'!E11=0,'Unit Mix'!$E$18,'Unit Mix'!E11)) | K26: =IF(OR(H25="TOTAL",H25=""),"",IF('Unit Mix'!H11="",'Unit Mix'!$H$18,'Unit Mix'!H11))
B27: Net Equity Multiple | C27: ='Waterfall Split'!C66 -> 1.788103 | E27: Year 1 | F27: ='Cash Flow Summary'!D29 -> 0 | G27: ='Cash Flow Summary'!E15 -> 0.065173381 | H27: =IF(OR(H26="TOTAL",H26=""),"",IF('Unit Mix'!B12=0,'Unit Mix'!$B$18,'Unit Mix'!B12)) | I27: =IF(OR(H26="TOTAL",H26=""),"",IF('Unit Mix'!C12=0,'Unit Mix'!$C$18,'Unit Mix'!C12)) | J27: =IF(OR(H26="TOTAL",H26=""),"",IF('Unit Mix'!E12=0,'Unit Mix'!$E$18,'Unit Mix'!E12)) | K27: =IF(OR(H26="TOTAL",H26=""),"",IF('Unit Mix'!H12="",'Unit Mix'!$H$18,'Unit Mix'!H12))
B28: Net IRR | C28: ='Waterfall Split'!C65 -> 0.13274836 | E28: Year 2 | F28: ='Cash Flow Summary'!E29 -> 0.05 | G28: ='Cash Flow Summary'!F15 -> 0.075702648 | H28: =IF(OR(H27="TOTAL",H27=""),"",IF('Unit Mix'!B13=0,'Unit Mix'!$B$18,'Unit Mix'!B13)) | I28: =IF(OR(H27="TOTAL",H27=""),"",IF('Unit Mix'!C13=0,'Unit Mix'!$C$18,'Unit Mix'!C13)) | J28: =IF(OR(H27="TOTAL",H27=""),"",IF('Unit Mix'!E13=0,'Unit Mix'!$E$18,'Unit Mix'!E13)) | K28: =IF(OR(H27="TOTAL",H27=""),"",IF('Unit Mix'!H13="",'Unit Mix'!$H$18,'Unit Mix'!H13))
E29: =IF(F22<24,"","Year 3") -> Year 3 | F29: =IF(F22<24,"",'Cash Flow Summary'!F29) -> 0.075 | G29: =IF(F22<24,"",'Cash Flow Summary'!G15) -> 0.075010153 | H29: =IF(OR(H28="TOTAL",H28=""),"",IF('Unit Mix'!B14=0,'Unit Mix'!$B$18,'Unit Mix'!B14)) | I29: =IF(OR(H28="TOTAL",H28=""),"",IF('Unit Mix'!C14=0,'Unit Mix'!$C$18,'Unit Mix'!C14)) | J29: =IF(OR(H28="TOTAL",H28=""),"",IF('Unit Mix'!E14=0,'Unit Mix'!$E$18,'Unit Mix'!E14)) | K29: =IF(OR(H28="TOTAL",H28=""),"",IF('Unit Mix'!H14="",'Unit Mix'!$H$18,'Unit Mix'!H14))
E30: =IF(F22<36,"","Year 4") -> Year 4 | F30: =IF(F22<36,"",'Cash Flow Summary'!G29) -> 0.12 | G30: =IF(F22<36,"",'Cash Flow Summary'!H15) -> 0.076101844 | H30: =IF(OR(H29="TOTAL",H29=""),"",IF('Unit Mix'!B15=0,'Unit Mix'!$B$18,'Unit Mix'!B15)) | I30: =IF(OR(H29="TOTAL",H29=""),"",IF('Unit Mix'!C15=0,'Unit Mix'!$C$18,'Unit Mix'!C15)) | J30: =IF(OR(H29="TOTAL",H29=""),"",IF('Unit Mix'!E15=0,'Unit Mix'!$E$18,'Unit Mix'!E15)) | K30: =IF(OR(H29="TOTAL",H29=""),"",IF('Unit Mix'!H15="",'Unit Mix'!$H$18,'Unit Mix'!H15))
E31: =IF(F22<48,"","Year 5") -> Year 5 | F31: =IF(F22<48,"",'Cash Flow Summary'!H29) -> 0.13 | G31: =IF(F22<48,"",'Cash Flow Summary'!I15) -> 0.077036158 | H31: =IF(OR(H30="TOTAL",H30=""),"",IF('Unit Mix'!B16=0,'Unit Mix'!$B$18,'Unit Mix'!B16)) | I31: =IF(OR(H30="TOTAL",H30=""),"",IF('Unit Mix'!C16=0,'Unit Mix'!$C$18,'Unit Mix'!C16)) | J31: =IF(OR(H30="TOTAL",H30=""),"",IF('Unit Mix'!E16=0,'Unit Mix'!$E$18,'Unit Mix'!E16)) | K31: =IF(OR(H30="TOTAL",H30=""),"",IF('Unit Mix'!H16="",'Unit Mix'!$H$18,'Unit Mix'!H16))
E32: =IF(F22<60,"","Year 6") -> Year 6 | F32: =IF(F22<60,"",'Cash Flow Summary'!I29) -> 0.14 | G32: =IF(F22<60,"",'Cash Flow Summary'!J15) -> 0.077987488 | I32: =IF(OR(H31="TOTAL",H31=""),"",IF('Unit Mix'!C17=0,'Unit Mix'!$C$18,'Unit Mix'!C17)) | J32: =IF(OR(H31="TOTAL",H31=""),"",IF('Unit Mix'!E17=0,'Unit Mix'!$E$18,'Unit Mix'!E17)) | K32: =IF(OR(H31="TOTAL",H31=""),"",IF('Unit Mix'!H17="",'Unit Mix'!$H$18,'Unit Mix'!H17))
E33: =IF(F22<72,"","Year 7") -> Year 7 | F33: =IF(F22<72,"",'Cash Flow Summary'!J29) -> 0.15 | G33: =IF(F22<72,"",'Cash Flow Summary'!J15) -> 0.077987488

Sheet Sale Matrix
B2: Sale Matrix
B3: Exit Cap Rate | C3: ='Sale Analysis'!C4 -> 0.0525 | D3: ='Sale Analysis'!D4 -> 0.055 | E3: ='Sale Analysis'!E4 -> 0.0575 | F3: ='Sale Analysis'!F4 -> 0.06 | G3: ='Sale Analysis'!G4 -> 0.0625
B4: Total Investment | C4: =ROUND('Sale Analysis'!C20,-3) -> 1498000 | D4: =ROUND('Sale Analysis'!D20,-3) -> 1498000 | E4: =ROUND('Sale Analysis'!E20,-3) -> 1498000 | F4: =ROUND('Sale Analysis'!F20,-3) -> 1498000 | G4: =ROUND('Sale Analysis'!G20,-3) -> 1498000
B5: Gross Distributions | C5: =ROUND('Sale Analysis'!C20+'Sale Analysis'!C21,-3) -> 3369000 | D5: =ROUND('Sale Analysis'!D20+'Sale Analysis'!D21,-3) -> 3160000 | E5: =ROUND('Sale Analysis'!E20+'Sale Analysis'!E21,-3) -> 2965000 | F5: =ROUND('Sale Analysis'!F20+'Sale Analysis'!F21,-3) -> 2783000 | G5: =ROUND('Sale Analysis'!G20+'Sale Analysis'!G21,-3) -> 2614000
B6: Gross Equity Multiple | C6: ='Sale Analysis'!C22 -> 2.249616 | D6: ='Sale Analysis'!D22 -> 2.1097161 | E6: ='Sale Analysis'!E22 -> 1.9795314 | F6: ='Sale Analysis'!F22 -> 1.8584143 | G6: ='Sale Analysis'!G22 -> 1.7457171
B7: Gross IRR | C7: ='Sale Analysis'!C23 -> 0.17656094 | D7: ='Sale Analysis'!D23 -> 0.16449794 | E7: ='Sale Analysis'!E23 -> 0.15240298 | F7: ='Sale Analysis'!F23 -> 0.14025808 | G7: ='Sale Analysis'!G23 -> 0.12803772

Sheet P&L OM
B4: =Assumptions!C3 -> Brownstone Apartments
B5: Proforma Operating Statement
C6: Year 1 | D6: Year 2 | E6: Year 3 | F6: Year 4
B7: Revenue
B8: Gross Potential Rent | C8: ='Monthly Cash Flow'!P10 -> 418953.69 | D8: ='Monthly Cash Flow'!AC10 -> 426544.74 | E8: ='Monthly Cash Flow'!AP10 -> 437208.36 | F8: ='Monthly Cash Flow'!BC10 -> 448138.57
B9: Loss to Lease | C9: ='Monthly Cash Flow'!P11 -> 77858.225 | D9: ='Monthly Cash Flow'!AC11 -> 13584.558 | E9: ='Monthly Cash Flow'!AP11 -> 5410.3301 | F9: ='Monthly Cash Flow'!BC11 -> 8214.1492
B10: Gross Rental Income | C10: ='Monthly Cash Flow'!P12 -> 341095.47 | D10: ='Monthly Cash Flow'!AC12 -> 412960.18 | E10: ='Monthly Cash Flow'!AP12 -> 431798.03 | F10: ='Monthly Cash Flow'!BC12 -> 439924.42
B11: Loss to Vacancy | C11: ='Monthly Cash Flow'!P13+'Monthly Cash Flow'!P14 -> -45882.087 | D11: ='Monthly Cash Flow'!AC13+'Monthly Cash Flow'!AC14 -> -41454.616 | E11: ='Monthly Cash Flow'!AP13+'Monthly Cash Flow'!AP14 -> -12953.941 | F11: ='Monthly Cash Flow'!BC13+'Monthly Cash Flow'!BC14 -> -13197.733
B12: Concessions | C12: ='Monthly Cash Flow'!P16 -> 0 | D12: ='Monthly Cash Flow'!AC16 -> 0 | E12: ='Monthly Cash Flow'!AP16 -> 0 | F12: ='Monthly Cash Flow'!BC16 -> 0
B13: RUBS Income | C13: ='Monthly Cash Flow'!P28 -> 3019.6078 | D13: ='Monthly Cash Flow'!AC28 -> 10298.235 | E13: ='Monthly Cash Flow'!AP28 -> 11767 | F13: ='Monthly Cash Flow'!BC28 -> 12061.175
B14: Other Income | C14: ='Monthly Cash Flow'!P30-C13 -> 8567.1 | D14: ='Monthly Cash Flow'!AC30-D13 -> 11417.1 | E14: ='Monthly Cash Flow'!AP30-E13 -> 11417.1 | F14: ='Monthly Cash Flow'!BC30-F13 -> 11417.1
B15: Total Revenue | C15: =SUM(C10:C14) -> 306800.09 | D15: =SUM(D10:D14) -> 393220.9 | E15: =SUM(E10:E14) -> 442028.19 | F15: =SUM(F10:F14) -> 450204.96
B16: Per Unit | C16: =C15/Assumptions!$C$10 -> 18047.064 | D16: =D15/Assumptions!$C$10 -> 23130.641 | E16: =E15/Assumptions!$C$10 -> 26001.658 | F16: =F15/Assumptions!$C$10 -> 26482.645
B17: Incr % YoY | D17: =(D15/C15)-1 -> 0.28168444 | E17: =(E15/D15)-1 -> 0.1241218 | F17: =(F15/E15)-1 -> 0.018498307
B18: Operating Expenses
B19: Property Taxes | C19: ='Monthly Cash Flow'!P36 -> 45817.5 | D19: ='Monthly Cash Flow'!AC36 -> 46733.85 | E19: ='Monthly Cash Flow'!AP36 -> 47668.527 | F19: ='Monthly Cash Flow'!BC36 -> 48621.898
B20: Insurance | C20: ='Monthly Cash Flow'!P37 -> 14000 | D20: ='Monthly Cash Flow'!AC37 -> 14350 | E20: ='Monthly Cash Flow'!AP37 -> 14708.75 | F20: ='Monthly Cash Flow'!BC37 -> 15076.469
B21: Property Mgmt Fee | C21: ='Monthly Cash Flow'!P38 -> 9204.0027 | D21: ='Monthly Cash Flow'!AC38 -> 11796.627 | E21: ='Monthly Cash Flow'!AP38 -> 13260.846 | F21: ='Monthly Cash Flow'!BC38 -> 13506.149
B22: Utilities | C22: ='Monthly Cash Flow'!P47 -> 14000 | D22: ='Monthly Cash Flow'!AC47 -> 14350 | E22: ='Monthly Cash Flow'!AP47 -> 14708.75 | F22: ='Monthly Cash Flow'!BC47 -> 15076.469
B23: R&M | C23: ='Monthly Cash Flow'!P49 -> 12750 | D23: ='Monthly Cash Flow'!AC49 -> 13068.75 | E23: ='Monthly Cash Flow'!AP49 -> 13395.469 | F23: ='Monthly Cash Flow'!BC49 -> 13730.355
B24: Turnover | C24: ='Monthly Cash Flow'!P50 -> 0 | D24: ='Monthly Cash Flow'!AC50 -> 0 | E24: ='Monthly Cash Flow'!AP50 -> 0 | F24: ='Monthly Cash Flow'!BC50 -> 8500
B25: Grounds/Landscaping | C25: ='Monthly Cash Flow'!P51 -> 3500 | D25: ='Monthly Cash Flow'!AC51 -> 3587.5 | E25: ='Monthly Cash Flow'!AP51 -> 3677.1875 | F25: ='Monthly Cash Flow'!BC51 -> 3769.1172
B26: Advertising | C26: ='Monthly Cash Flow'!P52 -> 1500 | D26: ='Monthly Cash Flow'!AC52 -> 1537.5 | E26: ='Monthly Cash Flow'!AP52 -> 1575.9375 | F26: ='Monthly Cash Flow'!BC52 -> 1615.3359
B27: Administration | C27: ='Monthly Cash Flow'!P53 -> 0 | D27: ='Monthly Cash Flow'!AC53 -> 0 | E27: ='Monthly Cash Flow'!AP53 -> 0 | F27: ='Monthly Cash Flow'!BC53 -> 0
B28: Payroll | C28: ='Monthly Cash Flow'!P54 -> 9000 | D28: ='Monthly Cash Flow'!AC54 -> 9225 | E28: ='Monthly Cash Flow'!AP54 -> 9455.625 | F28: ='Monthly Cash Flow'!BC54 -> 9692.0156
B29: Total operating Expenses | C29: =SUM(C19:C28) -> 109771.5 | D29: =SUM(D19:D28) -> 114649.23 | E29: =SUM(E19:E28) -> 118451.09 | F29: =SUM(F19:F28) -> 129587.81
B30: Per Unit | C30: =C29/Assumptions!$C$10 -> 6457.1472 | D30: =D29/Assumptions!$C$10 -> 6744.0722 | E30: =E29/Assumptions!$C$10 -> 6967.7113 | F30: =F29/Assumptions!$C$10 -> 7622.8122
B31: % of Net Rental Income | C31: =C29/C15 -> 0.35779488 | D31: =D29/D15 -> 0.29156443 | E31: =E29/E15 -> 0.2679718 | F31: =F29/F15 -> 0.2878418
B33: Net Operating Income | C33: =C15-C29 -> 197028.59 | D33: =D15-D29 -> 278571.68 | E33: =E15-E29 -> 323577.1 | F33: =F15-F29 -> 320617.15
B34: Per Unit | C34: =C33/Assumptions!$C$10 -> 11589.917 | D34: =D33/Assumptions!$C$10 -> 16386.569 | E34: =E33/Assumptions!$C$10 -> 19033.947 | F34: =F33/Assumptions!$C$10 -> 18859.833
B35: Operating Margin (%) | C35: =C33/C15 -> 0.64220512 | D35: =D33/D15 -> 0.70843557 | E35: =E33/E15 -> 0.7320282 | F35: =F33/F15 -> 0.7121582
B36: Incr % YoY | D36: =(D33/C33)-1 -> 0.41386425 | E36: =(E33/D33)-1 -> 0.16155778 | F36: =(F33/E33)-1 -> -0.0091475681
B37: F&C Yield on Cost | C37: ='Cash Flow Summary'!D15 -> 0.046095926 | D37: ='Cash Flow Summary'!E15 -> 0.065173381 | E37: ='Cash Flow Summary'!F15 -> 0.075702648 | F37: ='Cash Flow Summary'!G15 -> 0.075010153

Sheet Cash Flow OM
B4: =Assumptions!C3 -> Brownstone Apartments
B5: Proforma Cash Flow Summary
C6: Year 0 | D6: Year 1 | E6: Year 2 | F6: Year 3
B8: Net Operating Income | D8: ='Cash Flow Summary'!D13 -> 197028.59 | E8: ='Cash Flow Summary'!E13 -> 278571.68 | F8: ='Cash Flow Summary'!F13 -> 323577.1
B10: Other Cash Sources (Uses)
B12: Acquisition Cost
B13: Purchase Price | C13: =-Assumptions!C23 -> -3725000
B14: Closing and Formation Costs | C14: =-Assumptions!C24 -> -65030
B16: Financing
B17: Senior Loan Proceeds | C17: =Assumptions!C16 -> 2357500 | D17: =SUM('Loan Summary'!K2:K13) -> 286827.94 | E17: =SUM('Loan Summary'!K14:K25) -> 133772.06 | F17: =SUM('Loan Summary'!K26:K37) -> 0
B18: Refinance Proceeds | D18: =SUM('Cont. Dist.'!D13:O13) -> 0 | E18: =SUM('Cont. Dist.'!P13:AA13) -> 0 | F18: =SUM('Cont. Dist.'!AB13:AM13) -> 943390.35
B19: Debt Service | D19: =-'Cash Flow Summary'!D18-'Cash Flow Summary'!D19 -> -146549.76 | E19: =-'Cash Flow Summary'!E18-'Cash Flow Summary'!E19 -> -159910.29 | F19: =-'Cash Flow Summary'!F18-'Cash Flow Summary'!F19 -> -169717.46
B20: Debt Repayment | D20: =IF(AND('Sale Analysis'!$E$3>0,'Sale Analysis'!$E$3<13),'Sale Analysis'!$E$13,0) -> 0 | E20: =IF(AND('Sale Analysis'!$E$3>12,'Sale Analysis'!$E$3<25),'Sale Analysis'!$E$13,0) -> 0 | F20: =IF(AND('Sale Analysis'!$E$3>24,'Sale Analysis'!$E$3<37),'Sale Analysis'!$E$13,0) -> 0
B22: Renovation Budget
B23: Interior Renovations & Buyouts | D23: =-'Monthly Cash Flow'!P81*(1-'Renovation Budget'!$D$18) -> -181547.79 | E23: =('Monthly Cash Flow'!AC81*(1-'Renovation Budget'!$D$18))*-1 -> -127083.46 | F23: =('Monthly Cash Flow'!AP81*(1-'Renovation Budget'!$D$18))*-1 -> 0
B24: Exterior Renovations | D24: =('Monthly Cash Flow'!P82*(1-'Renovation Budget'!$D$18))*-1 -> -89585 | E24: =('Monthly Cash Flow'!AC82*(1-'Renovation Budget'!$D$18))*-1 -> 0 | F24: =('Monthly Cash Flow'!AP82*(1-'Renovation Budget'!$D$18))*-1 -> 0
B26: Sale Proceeds
B27: Sale Price | D27: =IF(AND('Sale Analysis'!$E$3>0,'Sale Analysis'!$E$3<13),'Sale Analysis'!$E$11,0) -> 0 | E27: =IF(AND('Sale Analysis'!$E$3>12,'Sale Analysis'!$E$3<25),'Sale Analysis'!$E$11,0) -> 0 | F27: =IF(AND('Sale Analysis'!$E$3>24,'Sale Analysis'!$E$3<37),'Sale Analysis'!$E$11,0) -> 0
B28: Selling Expenses | D28: =IF(AND('Sale Analysis'!$E$3>0,'Sale Analysis'!$E$3<13),SUM('Sale Analysis'!$E$14:$E$17,'Sale Analysis'!$E$12),0) -> 0 | E28: =IF(AND('Sale Analysis'!$E$3>12,'Sale Analysis'!$E$3<25),SUM('Sale Analysis'!$E$14:$E$17,'Sale Analysis'!$E$12),0) -> 0 | F28: =IF(AND('Sale Analysis'!$E$3>24,'Sale Analysis'!$E$3<37),SUM('Sale Analysis'!$E$14:$E$17,'Sale Analysis'!$E$12),0) -> 0
B30: Paladin Fees
B31: Acquisition Fee | C31: =-Assumptions!C39 -> -42092.05
B32: Asset Management Fee | D32: =('Monthly Cash Flow'!P66)*-1 -> -22464.626 | E32: =('Monthly Cash Flow'!AC66)*-1 -> -22464.626 | F32: =('Monthly Cash Flow'!AP66)*-1 -> -22464.626
B33: Construction Management Fee | D33: =((D24/0.95)*0.05)+((D23/0.95)*0.05) -> -14270.147 | E33: =((E24/0.95)*0.05)+((E23/0.95)*0.05) -> -6688.6029 | F33: =((F24/0.95)*0.05)+((F23/0.95)*0.05) -> 0
B35: Partnership Expenses & Rep Reserve | D35: =('Monthly Cash Flow'!P62)*-1 -> -20000 | E35: =('Monthly Cash Flow'!AC62)*-1 -> -20500 | F35: =('Monthly Cash Flow'!AP62)*-1 -> -21012.5
B37: Net Cash Flow | C37: =SUM(C8:C35) -> -1474622.1 | D37: =SUM(D8:D35) -> 9439.2058 | E37: =SUM(E8:E35) -> 75696.754 | F37: =SUM(F8:F35) -> 1053772.9
B40: Investor Net Cash Flow | C40: ='Waterfall Split'!H64 -> -1422759.7 | D40: =SUM('Waterfall Split'!I64:T64) -> 0 | E40: =SUM('Waterfall Split'!U64:AF64) -> 71137.983 | F40: =SUM('Waterfall Split'!AG64:AR64) -> 991725.05
B42: Cumulative Total Cost | D42: =Assumptions!$C$16-'Cont. Dist.'!O8 -> 3855141.8 | E42: =Assumptions!$C$16-'Cont. Dist.'!AA8 -> 3855141.8 | F42: =Assumptions!$C$16-'Cont. Dist.'!AM8 -> 3855141.8
B43: Free & Clear Yield | D43: ='Cash Flow Summary'!D15 -> 0.046095926 | E43: ='Cash Flow Summary'!E15 -> 0.065173381 | F43: ='Cash Flow Summary'!F15 -> 0.075702648
B45: Gross Equity Multiple | C45: ='Executive Summary'!C22 -> 1.9795314
B46: Gross IRR | C46: ='Executive Summary'!C23 -> 0.15240298
B48: Net Equity Multiple | C48: ='Executive Summary'!C27 -> 1.788103
B49: Net IRR | C49: ='Executive Summary'!C28 -> 0.13274836

Sheet 3 Pager Graphs
B2: Purchase Snapshot | E2: Planned Improvements | F2: Total | G2: Per Unit | I2: Net Operating Income | J2: Current | K2: Stabilized (Mo. 36) | X2: Sales Comps | Y2: Location | Z2: Property Status | AA2: Cap Rate | AB2: Price/Unit | AC2: Price/Sqft. | AD2: Sale Date | AE2: Year Built | AF2: Notes | AP2: Fee Schedule | AS2: JV Deal Structure
B3: Purchase Price | C3: ='Executive Summary'!F8 -> 3725000 | E3: Exterior Improvements | F3: ='Renovation Budget'!C15 -> 82000 | G3: =F3/$C$4 -> 4823.5294 | I3: Gross Potential Rent | J3: ='Monthly Cash Flow'!D10*12 -> 417045.67 | K3: ='Monthly Cash Flow'!AO10*12 -> 442173.39 | AP3: Asset Management Fee | AQ3: 1% of invested equity | AS3: GP Equity Participation | AT3: 5% of total equity
B4: Number of Units | C4: ='Executive Summary'!C12 -> 17 | E4: Interior Improvements | F4: ='Renovation Budget'!C6 -> 282500 | G4: =F4/$C$4 -> 16617.647 | I4: Less: Loss to Lease | J4: =J5-J3 -> -106065.67 | K4: =K5-K3 -> -5620.1046 | AP4: Construction Management Fee | AQ4: 5% of renovation budget | AS4: Preferred Return | AT4: 8% IRR
B5: Price Per Unit | C5: ='Executive Summary'!C13 -> 219117.65 | E5: Contingency / Other Costs | F5: =ROUND('Renovation Budget'!C17+'Renovation Budget'!C18,-3) -> 55000 | G5: =ROUND(F5/$C$4,-2) -> 3200 | I5: Gross Scheduled Rent | J5: ='Monthly Cash Flow'!C12*12 -> 310980 | K5: ='Monthly Cash Flow'!AO12*12 -> 436553.29 | AP5: Acquisition Fee | AQ5: 1.5% of total capitalization | AS5: Tier 1 LP/GP Split | AT5: 65%/35% up to 17% IRR
B6: Price Per Sqft. | C6: ='Executive Summary'!C14 -> 313.84278 | E6: Total Renovation Budget | F6: =SUM(F3:F5) -> 419500 | G6: =ROUND(F6/$C$4,-2) -> 24700 | I6: Other Income | J6: ='Monthly Cash Flow'!C30*12 -> 3000 | K6: ='Monthly Cash Flow'!AO30*12 -> 23184.1 | AS6: Tier 2 LP/GP Split | AT6: 50%/50% above 17% IRR
B7: Rentable Sqft. | C7: ='Executive Summary'!C15 -> 11869 | E7: Closing / Loan Costs | F7: =ROUND(Assumptions!C42+Assumptions!C35+Assumptions!C34,-3) -> 130000 | G7: =ROUND(F7/$C$4,-2) -> 7600 | I7: Gross Operating Income | J7: =J5+J6 -> 313980 | K7: =K5+K6 -> 459737.39
B8: Year Built | C8: ='Executive Summary'!C11 -> 1967 | E8: Purchase Price | F8: =Assumptions!C23 -> 3725000 | G8: =ROUND(F8/$C$4,-2) -> 219100 | I8: Less: Vacancy (3%) | J8: =-3%*J5 -> -9329.4 | K8: =-3%*K5 -> -13096.599
E9: Total Projected Capitalization | F9: =F6+F7+F8 -> 4274500 | G9: =ROUND(F9/$C$4,-2) -> 251400 | I9: Effective Gross Income | J9: =J7+J8 -> 304650.6 | K9: =K7+K8 -> 446640.79
I10: Less: Operating Expenses | J10: ='Monthly Cash Flow'!C58*12 -> 109520.43 | K10: ='Monthly Cash Flow'!AO58*12 -> 118589.47
I11: Net Operating Income | J11: =J9-J10 -> 195130.17 | K11: =K9-K10 -> 328051.32
I12: Free-and-clear Yield on Cost | J12: =J11/(F8+F7) -> 0.050617424 | K12: =K11/F9 -> 0.076746127
M15: Sale Analysis
M16: Sale Month | N16: ='Sale Analysis'!C3 -> 83 | O16: ='Sale Analysis'!D3 -> 83 | P16: ='Sale Analysis'!E3 -> 83 | Q16: ='Sale Analysis'!F3 -> 83 | R16: ='Sale Analysis'!G3 -> 83
M17: Cap Rate | N17: ='Sale Analysis'!C4 -> 0.0525 | O17: ='Sale Analysis'!D4 -> 0.055 | P17: ='Sale Analysis'!E4 -> 0.0575 | Q17: ='Sale Analysis'!F4 -> 0.06 | R17: ='Sale Analysis'!G4 -> 0.0625
M18: Revenue | N18: ='Sale Analysis'!C5 -> 464200.75 | O18: ='Sale Analysis'!D5 -> 464200.75 | P18: ='Sale Analysis'!E5 -> 464200.75 | Q18: ='Sale Analysis'!F5 -> 464200.75 | R18: ='Sale Analysis'!G5 -> 464200.75
M19: Expenses | N19: ='Sale Analysis'!C6 -> 86850.573 | O19: ='Sale Analysis'!D6 -> 86850.573 | P19: ='Sale Analysis'!E6 -> 86850.573 | Q19: ='Sale Analysis'!F6 -> 86850.573 | R19: ='Sale Analysis'!G6 -> 86850.573
M20: Tax Adjustment | N20: ='Sale Analysis'!C7 -> 71622.9 | O20: ='Sale Analysis'!D7 -> 68966.1 | P20: ='Sale Analysis'!E7 -> 66493.8 | Q20: ='Sale Analysis'!F7 -> 64193.7 | R20: ='Sale Analysis'!G7 -> 62053.5
M21: NOI | N21: ='Sale Analysis'!C8 -> 305727.28 | O21: ='Sale Analysis'!D8 -> 308384.08 | P21: ='Sale Analysis'!E8 -> 310856.38 | Q21: ='Sale Analysis'!F8 -> 313156.48 | R21: ='Sale Analysis'!G8 -> 315296.68
M23: Sale Price (Per Unit) | N23: ='Sale Analysis'!C10 -> 342529.41 | O23: ='Sale Analysis'!D10 -> 329823.53 | P23: ='Sale Analysis'!E10 -> 318000 | Q23: ='Sale Analysis'!F10 -> 307000 | R23: ='Sale Analysis'!G10 -> 296764.71
M24: Sale Price | N24: ='Sale Analysis'!C11 -> 5823000 | O24: ='Sale Analysis'!D11 -> 5607000 | P24: ='Sale Analysis'!E11 -> 5406000 | Q24: ='Sale Analysis'!F11 -> 5219000 | R24: ='Sale Analysis'!G11 -> 5045000
M25: Plus: Working Capital Dist. | N25: ='Sale Analysis'!C12 -> 49829.382 | O25: ='Sale Analysis'!D12 -> 49829.382 | P25: ='Sale Analysis'!E12 -> 49829.382 | Q25: ='Sale Analysis'!F12 -> 49829.382 | R25: ='Sale Analysis'!G12 -> 49829.382
M26: Less: Loan | N26: ='Sale Analysis'!C13 -> -3740191.3 | O26: ='Sale Analysis'!D13 -> -3740191.3 | P26: ='Sale Analysis'!E13 -> -3740191.3 | Q26: ='Sale Analysis'!F13 -> -3740191.3 | R26: ='Sale Analysis'!G13 -> -3740191.3
M27: Less: Broker Fee | N27: ='Sale Analysis'!#REF! -> #REF! | O27: ='Sale Analysis'!D15 -> -56070 | P27: ='Sale Analysis'!E15 -> -54060 | Q27: ='Sale Analysis'!F15 -> -52190 | R27: ='Sale Analysis'!G15 -> -50450
M28: Less: Closing Costs (1.25%) | N28: ='Sale Analysis'!C14 -> -116460 | O28: ='Sale Analysis'!D14+O27 -> -168210 | P28: ='Sale Analysis'!E14+P27 -> -162180 | Q28: ='Sale Analysis'!F14+Q27 -> -156570 | R28: ='Sale Analysis'!G14+R27 -> -151350
M31: Total Distributions | N31: ='Sale Analysis'!C17 -> 0 | O31: ='Sale Analysis'!D18 -> 1748428.1 | P31: ='Sale Analysis'!E18 -> 1553458.1 | Q31: ='Sale Analysis'!F18 -> 1372068.1 | R31: ='Sale Analysis'!G18 -> 1203288.1
M33: Equity Contribution | N33: ='Sale Analysis'!C19 -> 0 | O33: ='Sale Analysis'!C20 -> 1497641.8 | P33: ='Sale Analysis'!D20 -> 1497641.8 | Q33: ='Sale Analysis'!E20 -> 1497641.8 | R33: ='Sale Analysis'!F20 -> 1497641.8
M34: Equity Gains | N34: ='Sale Analysis'!C20 -> 1497641.8 | O34: ='Sale Analysis'!D21 -> 1661957.1 | P34: ='Sale Analysis'!E21 -> 1466987.1 | Q34: ='Sale Analysis'!F21 -> 1285597.1 | R34: ='Sale Analysis'!G21 -> 1116817.1
M35: Equity Multiple | N35: ='Sale Analysis'!C21 -> 1871477.1 | O35: ='Sale Analysis'!D22 -> 2.1097161 | P35: ='Sale Analysis'!E22 -> 1.9795314 | Q35: ='Sale Analysis'!F22 -> 1.8584143 | R35: ='Sale Analysis'!G22 -> 1.7457171
M36: IRR | N36: ='Sale Analysis'!C22 -> 2.249616 | O36: ='Sale Analysis'!D23 -> 0.16449794 | P36: ='Sale Analysis'!E23 -> 0.15240298 | Q36: ='Sale Analysis'!F23 -> 0.14025808 | R36: ='Sale Analysis'!G23 -> 0.12803772
T39: Deal Returns
T40: Total Investment | U40: ='Executive Summary'!C20 -> 1498000
T41: Gross Distributions | U41: ='Executive Summary'!C21 -> 2965000
T42: Gross Equity Multiple | U42: ='Executive Summary'!C22 -> 1.9795314
T43: Gross IRR | U43: ='Executive Summary'!C23 -> 0.15240298
T44: Stabilized Yield on Cost | U44: =K12 -> 0.076746127
AH50: Competitive Properties
AH52: Unit Type | AI52: SUBJECT PROPERTY (In Place) | AJ52: SUBJECT PROPERTY (Pro Forma)
AH54: ='Executive Summary'!H19 -> Stu - ADU
AH55: ='Executive Summary'!H20 -> 1x1
AH56: ='Executive Summary'!H21 -> 2x1
...

Sheet Rent Comps
B2: Competitive Properties
B3: Unit Type | C3: 1 Bed | D3: 2 Bed | E3: 2 Bed TH | F3: Proximity | G3: Notes
K20: Fees
K21: Acquisition Fee | L21: =Assumptions!C39 -> 42092.05 | M21: 1% of Capitalization
K22: Closing Costs | L22: 105000 | M22: Legal, DD, and Escrow
K23: Buyer Broker Fee | L23: =Assumptions!C23*1% -> 37250 | M23: 1% of Purchase Price
K24: Equity Brokerage Fee | L24: =Assumptions!C41-L25 -> -118218 | M24: Tiered Fee
K25: Debt Brokerage Fee | L25: 145998 | M25: 1% of Loan Sizing
K26: Total Fees & Formation Costs | L26: =SUM(L21:L25) -> 212122.05

Sheet Assumptions
AF1: REFI OUT BRIDGE CALC
B2: Property Information | F2: Market | G2: Yr0 | H2: Yr1 | I2: Yr2 | J2: Yr3 | K2: Yr4 | L2: Yr5 | M2: Yr6 | N2: Yr7 | R2: Acquisition Loan | W2: Bridge | Y2: Refinance Loan | AD2: =IF(AND(AD3>12,AD3<25),2,IF(AND(AD3>24,AD3<37),3,IF(AND(AD3>36,AD3<49),4,IF(AND(AD3>48,AD3<61),5,IF(AND(AD3>60,AD3<73),6,IF(AND(AD3>72,AD3<85),7,1)))))) -> 3 | AF2: Refinance Loan | AK2: =IF(AND(AK3>12,AK3<25),2,IF(AND(AK3>24,AK3<37),3,IF(AND(AK3>36,AK3<49),4,IF(AND(AK3>48,AK3<61),5,IF(AND(AK3>60,AK3<73),6,IF(AND(AK3>72,AK3<85),7,1)))))) -> 3
B3: Property Name | C3: Brownstone Apartments | F3: Market Rent Growth | H3: 0.01 | I3: 0.025 | J3: 0.025 | K3: 0.025 | L3: 0.02 | M3: 0.02 | N3: 0.02 | Y3: Refinance Month | AD3: 35 | AF3: Refinance Month | AK3: =W21 -> 26
B4: Address | C4: 9559 Flower St | F4: Effective Rent Growth | H4: =H3+(G8-H8) -> 0.01 | I4: =I3+(H8-I8) -> 0.025 | J4: =J3+(I8-J8) -> 0.025 | K4: =K3+(J8-K8) -> 0.025 | L4: =L3+(K8-L8) -> 0.02 | M4: =M3+(L8-M8) -> 0.02 | N4: =N3+(M8-N8) -> 0.02 | R4: Amortization Period | W4: 30 | Y4: Amortization Period (Years) | AD4: 30 | AF4: Amortization Period (Years) | AK4: 30
B5: City/State | C5: Bellflower, CA 90706 | F5: Vacancy | H5: 0.02 | I5: 0.02 | J5: 0.03 | K5: 0.03 | L5: 0.03 | M5: 0.03 | N5: 0.03 | R5: Annual Interest Rate | W5: 0.0585 | Y5: Annual Interest Rate | AD5: 0.055 | AF5: Annual Interest Rate | AK5: =W24 -> 0.0535
B6: Year of Construction | C6: 1967 | F6: Collections Loss
B7: Acquisition Date | C7: 46204 | F7: Concessions (# Mo. Free) | R7: Loan-to-Value Test | Y7: Loan-to-Value Test | AF7: Loan-to-Value Test
B8: Total Square Footage | C8: 18737 | F8: Concessions % | G8: =(G7/12)*G9 -> 0 | H8: =(H7/12)*H9 -> 0 | I8: =(I7/12)*I9 -> 0 | J8: =(J7/12)*J9 -> 0 | K8: =(K7/12)*K9 -> 0 | L8: =(L7/12)*L9 -> 0 | M8: =(M7/12)*M9 -> 0 | N8: =(N7/12)*N9 -> 0 | R8: In-Place NOI | W8: ='Monthly Cash Flow'!C60*12 -> 188910.57 | Y8: NOI at Point of Refinance | AD8: ='Sale Analysis'!T7 -> 318545.92 | AF8: NOI at Point of Refinance | AK8: ='Sale Analysis'!Q7 -> 326725.61
B9: Gross Rentable SF | C9: 11869 | F9: Retention | R9: Capitalization Rate at Point of Purchase | W9: =C12 -> 0.050714247 | Y9: Capitalization Rate at Point of Refinance | AD9: 0.0575 | AF9: Capitalization Rate at Point of Refinance | AK9: =W25 -> 0.05
B10: Units | C10: 17 | R10: Valuation at Point of Purchase | W10: =W8/W9 -> 3725000 | Y10: Valuation at Point of Refinance | AD10: =AD8/AD9 -> 5539929.1 | AF10: Total Cost | AK10: ='Executive Summary'!F11 -> 4274000
B11: Asking Price | C11: 3850000 | F11: Other Income | G11: Yr0 | H11: Yr1 | I11: Yr2 | J11: Yr3 | K11: Yr4 | L11: Yr5 | M11: Yr6 | N11: Yr7 | R11: Maximum LTV | W11: 0.65 | Y11: Maximum LTV | AD11: 0.7 | AF11: Maximum LTV | AK11: =W23 -> 0.65
B12: Current Cap Rate | C12: ='Monthly Cash Flow'!A60/Assumptions!C23 -> 0.050714247 | R12: Maximum Loan Proceeds | W12: =W10*W11 -> 2421250 | Y12: Maximum Loan Proceeds | AD12: =AD10*AD11 -> 3877950.4 | AF12: Maximum Loan Proceeds | AK12: =AK10*AK11 -> 2778100
F13: Credit Check Fees
B14: Capitalization & Project Costs | F14: Late Fees | H14: =75*0.33*$C$10 -> 420.75 | I14: =75*0.33*$C$10 -> 420.75 | J14: =75*0.33*$C$10 -> 420.75 | K14: =75*0.33*$C$10 -> 420.75 | L14: =75*0.33*$C$10 -> 420.75 | M14: =75*0.33*$C$10 -> 420.75 | N14: =75*0.33*$C$10 -> 420.75 | R14: Debt Service Coverage Ratio Test | Y14: Debt Service Coverage Ratio Test | AF14: Debt Service Coverage Ratio Test
B15: Sources | F15: NSF Fees | H15: =35*0.33*$C$10 -> 196.35 | I15: =35*0.33*$C$10 -> 196.35 | J15: =35*0.33*$C$10 -> 196.35 | K15: =35*0.33*$C$10 -> 196.35 | L15: =35*0.33*$C$10 -> 196.35 | M15: =35*0.33*$C$10 -> 196.35 | N15: =35*0.33*$C$10 -> 196.35 | R15: =R8 -> In-Place NOI | W15: =W8 -> 188910.57 | Y15: =Y8 -> NOI at Point of Refinance | AD15: =AD8 -> 318545.92 | AF15: =AF8 -> NOI at Point of Refinance | AK15: =AK8 -> 326725.61
B16: Senior Debt | C16: =W32 -> 2357500 | F16: Early Termination Fees | R16: Required Minimum Debt Service Coverage Ratio | W16: 1.15 | Y16: Required Minimum Debt Service Coverage Ratio | AD16: 1.25 | AF16: Required Minimum Debt Service Coverage Ratio | AK16: =W22 -> 1.25
B17: Loan Draws | C17: =C26+C25 -> 419175 | F17: Laundry & Valet Trash Income | G17: =2400 -> 2400 | H17: =300*$C$10 -> 5100 | I17: =300*$C$10 -> 5100 | J17: =300*$C$10 -> 5100 | K17: =300*$C$10 -> 5100 | L17: =300*$C$10 -> 5100 | M17: =300*$C$10 -> 5100 | N17: =300*$C$10 -> 5100 | R17: Maximum Allowable Debt Service | W17: =W15/W16 -> 164270.06 | Y17: Maximum Allowable Debt Service | AD17: =AD15/AD16 -> 254836.74 | AF17: Maximum Allowable Debt Service | AK17: =AK15/AK16 -> 261380.49
B18: Equity | C18: =C36 -> 1497641.8 | F18: Pet Rent | R18: Maximum Loan Proceeds | W18: =-PV(W5/12,W4*12,W17/12) -> 2320430.9 | Y18: Maximum Loan Proceeds | AD18: =-PV(AD5/12,AD4*12,AD17/12) -> 3740191.3 | AF18: Maximum Loan Proceeds | AK18: =-PV(AK5/12,AK4*12,AK17/12) -> 3900639.9
B19: Reinvested Operating CF | F19: Application Fees
B20: Total Capitalization | C20: =SUM(C16:C19) -> 4274316.8 | F20: Parking | G20: =50*12 -> 600 | H20: =(((100*4)+(25*3))*12)/2 -> 2850 | I20: =(((100*4)+(25*3))*12) -> 5700 | J20: =(((100*4)+(25*3))*12) -> 5700 | K20: =(((100*4)+(25*3))*12) -> 5700 | L20: =(((100*4)+(25*3))*12) -> 5700 | M20: =(((100*4)+(25*3))*12) -> 5700 | N20: =(((100*4)+(25*3))*12) -> 5700 | R20: Future Refi DSCR Test - For Bridge
F21: RUBs | R21: DSCR Test Month | W21: 26 | Y21: Lesser of the three values above (Loan Size) | AD21: =MIN(AD12,AD18) -> 3740191.3 | AF21: Lesser of the three values above (Loan Size) | AK21: =MIN(AK12,AK18)-SUM('Loan Summary'!K2:K361) -> 2357500
B22: Uses | R22: Required Minimum Debt Service Coverage Ratio | W22: 1.25 | Y22: Less: Senior Debt | AD22: =-VLOOKUP($AD$3-1,'Loan Summary'!$F$2:$L$361,7,FALSE) -> -2778100
B23: Purchase Price | C23: 3725000 | F23: Expenses | G23: Yr0 | H23: Yr1 | I23: Yr2 | J23: Yr3 | K23: Yr4 | L23: Yr5 | M23: Yr6 | N23: Yr7 | R23: Maximum Loan To Cost | W23: 0.65 | Y23: Less: Refi Fee | AD23: =-'Loan Summary'!C15 -> -18700.957 | AF23: Mortgage Constant Calculation
B24: Closing & Formation Costs | C24: =C40+C41 -> 65030 | F24: Property Taxes | G24: =H24 -> 45817.5 | H24: =C23*P24 -> 45817.5 | I24: =H24*1.02 -> 46733.85 | J24: =I24*1.02 -> 47668.527 | K24: =J24*1.02 -> 48621.898 | L24: =K24*1.02 -> 49594.335 | M24: =L24*1.02 -> 50586.222 | N24: =M24*1.02 -> 51597.947 | O24: mill rate | P24: 0.0123 | R24: New Loan Interest Rate | W24: 0.0535 | Y24: Less: Loan Buydown | AD24: =-'Loan Summary'!C14 -> 0 | AF24: Annual Interest Rate | AK24: =AK5 -> 0.0535
B25: Buyouts | C25: ='Renovation Budget'!C4+('Renovation Budget'!C4*'Renovation Budget'!D17)+('Renovation Budget'!C4*'Renovation Budget'!D18) -> 48875 | F25: Insurance | G25: 14000 | H25: =G25 -> 14000 | I25: =H25*(1+$G$40) -> 14350 | J25: =I25*(1+$G$40) -> 14708.75 | K25: =J25*(1+$G$40) -> 15076.469 | L25: =K25*(1+$G$40) -> 15453.38 | M25: =L25*(1+$G$40) -> 15839.715 | N25: =M25*(1+$G$40) -> 16235.708 | R25: Capitalization Rate at Date of Refinance | W25: 0.05 | Y25: Less: Preferred Equity | AF25: Monthly Interest Rate | AK25: =AK24/12 -> 0.0044583333
B26: Renovation Budget | C26: =C45-C25 -> 370300 | F26: Management Fee | G26: % of Revenue | I26: 0.03 | K26: If Fixed: Increase/Year? | R26: Maximum Loan Proceeds | W26: =AK21 -> 2357500 | Y26: Distributions from Refinance | AD26: =SUM(AD21:AD25) -> 943390.35 | AE26: =AD26/C36 -> 0.62991723 | AF26: Months of Amortization | AK26: =AK4*12 -> 360
B27: Total Cost | C27: =SUM(C23:C26) -> 4209205 | E27: =G27/$C$10 -> 823.52941 | F27: Electric | G27: 14000 | H27: =G27 -> 14000 | I27: =H27*(1+$G$40) -> 14350 | J27: =I27*(1+$G$40) -> 14708.75 | K27: =J27*(1+$G$40) -> 15076.469 | L27: =K27*(1+$G$40) -> 15453.38 | M27: =L27*(1+$G$40) -> 15839.715 | N27: =M27*(1+$G$40) -> 16235.708 | R27: Interest Reserve? | W27: Yes | AF27: Monthly Mortgage Constant | AK27: =AK25/(1-(1/(1+AK25)^AK26)) -> 0.0055841369
B28: Plus: Acq Fee /Working Capital/Reserves | C28: =C39+C35+C34 -> 65111.752 | E28: =G28/$C$10 -> 0 | F28: Gas | I28: =H28*(1+$G$40) -> 0 | J28: =I28*(1+$G$40) -> 0 | K28: =J28*(1+$G$40) -> 0 | L28: =K28*(1+$G$40) -> 0 | M28: =L28*(1+$G$40) -> 0 | N28: =M28*(1+$G$40) -> 0 | R28: Lender Draw for Capital? | W28: Yes | Y28: Mortgage Constant Calculation | AF28: Annual Mortgage Constant | AK28: =AK27*12 -> 0.067009643
B29: Total Uses | C29: =SUM(C27:C28) -> 4274316.8 | E29: =G29/$C$10 -> 0 | F29: Water/Sewer | I29: =H29*(1+$G$40) -> 0 | J29: =I29*(1+$G$40) -> 0 | K29: =J29*(1+$G$40) -> 0 | L29: =K29*(1+$G$40) -> 0 | M29: =L29*(1+$G$40) -> 0 | N29: =M29*(1+$G$40) -> 0 | Y29: Annual Interest Rate | AD29: =AD5 -> 0.055 | AF29: Check on Cap Rate Calculation by Sizing Loan | AK29: =AK17/AK28 -> 3900639.9
E30: =G30/$C$10 -> 0 | F30: Trash (Inc Valet Trash) | I30: =H30*(1+$G$40) -> 0 | J30: =I30*(1+$G$40) -> 0 | K30: =J30*(1+$G$40) -> 0 | L30: =K30*(1+$G$40) -> 0 | M30: =L30*(1+$G$40) -> 0 | N30: =M30*(1+$G$40) -> 0 | Y30: Monthly Interest Rate | AD30: =AD29/12 -> 0.0045833333
B31: Total Equity | E31: =G31/$C$10 -> 750 | F31: R&M | G31: =750*C10 -> 12750 | H31: =G31 -> 12750 | I31: =H31*(1+$G$40) -> 13068.75 | J31: =I31*(1+$G$40) -> 13395.469 | K31: =J31*(1+$G$40) -> 13730.355 | L31: =K31*(1+$G$40) -> 14073.614 | M31: =L31*(1+$G$40) -> 14425.455 | N31: =M31*(1+$G$40) -> 14786.091 | R31: ASSUMED OVERRIDE | Y31: Months of Amortization | AD31: =AD4*12 -> 360
B32: Closing Equity | C32: =C23-C16+C42 -> 1474622.1 | E32: =G32/$C$10 -> 0 | F32: Turnover | I32: =H32*(1+$G$40) -> 0 | J32: =I32*(1+$G$40) -> 0 | K32: =500*C10 -> 8500 | L32: =K32*(1+$G$40) -> 8712.5 | M32: =L32*(1+$G$40) -> 8930.3125 | N32: =M32*(1+$G$40) -> 9153.5703 | R32: Lesser of the three values above (Loan Size) | W32: =IF(W2="Assumed",$W$31,IF(W2="Bridge",W26,MIN(W12,W18))) -> 2357500 | Y32: Monthly Mortgage Constant | AD32: =AD30/(1-(1/(1+AD30)^AD31)) -> 0.00567789
B33: Renovation Equity | C33: =IF('Monthly Cash Flow'!C88="Lender Draw",0,C45) -> 0 | E33: =G33/$C$10 -> 205.88235 | F33: Grounds/Landscaping | G33: 3500 | H33: =G33 -> 3500 | I33: =H33*(1+$G$40) -> 3587.5 | J33: =I33*(1+$G$40) -> 3677.1875 | K33: =J33*(1+$G$40) -> 3769.1172 | L33: =K33*(1+$G$40) -> 3863.3451 | M33: =L33*(1+$G$40) -> 3959.9287 | N33: =M33*(1+$G$40) -> 4058.927 | Y33: Annual Mortgage Constant | AD33: =AD32*12 -> 0.06813468
B34: Lender Reserves | C34: =-IF(AND(W2="Bridge",W27="Yes"),'Monthly Cash Flow'!B77,0) -> 23019.702 | D34: =D36-C36 -> 0 | E34: =G34/$C$10 -> 88.235294 | F34: Advertising | G34: 1500 | H34: =G34 -> 1500 | I34: =H34*(1+$G$40) -> 1537.5 | J34: =I34*(1+$G$40) -> 1575.9375 | K34: =J34*(1+$G$40) -> 1615.3359 | L34: =K34*(1+$G$40) -> 1655.7193 | M34: =L34*(1+$G$40) -> 1697.1123 | N34: =M34*(1+$G$40) -> 1739.5401 | R34: Mortgage Constant Calculation | Y34: Check on Cap Rate Calculation by Sizing Loan | AD34: =AD17/AD33 -> 3740191.3
B35: Additional Paid In Capital | D35: check | E35: =G35/$C$10 -> 0 | F35: Administration | I35: =H35*(1+$G$40) -> 0 | J35: =I35*(1+$G$40) -> 0 | K35: =J35*(1+$G$40) -> 0 | L35: =K35*(1+$G$40) -> 0 | M35: =L35*(1+$G$40) -> 0 | N35: =M35*(1+$G$40) -> 0 | R35: Annual Interest Rate | W35: =W5 -> 0.0585
B36: TOTAL EQUITY | C36: =C32+C33+C34+C35 -> 1497641.8 | D36: =-'Cont. Dist.'!CI8 -> 1497641.8 | E36: =G36/$C$10 -> 529.41176 | F36: Payroll | G36: 9000 | H36: =G36 -> 9000 | I36: =H36*(1+$G$40) -> 9225 | J36: =I36*(1+$G$40) -> 9455.625 | K36: =J36*(1+$G$40) -> 9692.0156 | L36: =K36*(1+$G$40) -> 9934.316 | M36: =L36*(1+$G$40) -> 10182.674 | N36: =M36*(1+$G$40) -> 10437.241 | R36: Monthly Interest Rate | W36: =W35/12 -> 0.004875
E37: =G37/$C$10 -> 1176.4706 | F37: Capital Rsrv & Partnership | G37: 20000 | H37: =G37 -> 20000 | I37: =H37*(1+$G$40) -> 20500 | J37: =I37*(1+$G$40) -> 21012.5 | K37: =J37*(1+$G$40) -> 21537.812 | L37: =K37*(1+$G$40) -> 22076.258 | M37: =L37*(1+$G$40) -> 22628.164 | N37: =M37*(1+$G$40) -> 23193.868 | R37: Months of Amortization | W37: =W4*12 -> 360
B38: Fees | F38: Asset Mgmt. Fee | G38: 0.015 | R38: Monthly Mortgage Constant | W38: =W36/(1-(1/(1+W36)^W37)) -> 0.0058994093
B39: Acquisition Fee | C39: =C27*D39 -> 42092.05 | D39: 0.01 | R39: Annual Mortgage Constant | W39: =W38*12 -> 0.070792912
B40: Closing Costs | C40: =(C23*D40) -> 37250 | D40: 0.01 | F40: Yearly Expense % Increase | G40: 0.025 | R40: Check on Cap Rate Calculation by Sizing Loan | W40: =W17/W39 -> 2320430.9
...

Sheet Unit Mix
B2: Unit Mix | E2: Rents
B3: Unit Type | C3: # of Units | D3: Sqft. | E3: Current RR | F3: Current Market | G3: Post Reno Rent Increase | H3: Post Reno Rents | I3: Total Monthly Rent
B4: Stu - ADU | C4: 1 | D4: 499 | E4: 1340 | F4: 1650 | H4: =IF(F4+G4=0,"",F4+G4) -> 1650 | I4: =IF(C4="","",C4*H4) -> 1650
B5: 1x1 | C5: 9 | D5: 648 | E5: 1427 | F5: 1925 | H5: =IF(F5+G5=0,"",F5+G5) -> 1925 | I5: =IF(C5="","",C5*H5) -> 17325
B6: 2x1 | C6: 7 | D6: 840 | E6: 1676 | F6: 2250 | H6: =IF(F6+G6=0,"",F6+G6) -> 2250 | I6: =IF(C6="","",C6*H6) -> 15750
H7: =IF(F7+G7=0,"",F7+G7) | I7: =IF(C7="","",C7*H7)
H8: =IF(F8+G8=0,"",F8+G8) | I8: =IF(C8="","",C8*H8)
H9: =IF(F9+G9=0,"",F9+G9) | I9: =IF(C9="","",C9*H9)
H10: =IF(F10+G10=0,"",F10+G10) | I10: =IF(C10="","",C10*H10)
H11: =IF(F11+G11=0,"",F11+G11) | I11: =IF(C11="","",C11*H11)
H12: =IF(F12+G12=0,"",F12+G12) | I12: =IF(C12="","",C12*H12)
H13: =IF(F13+G13=0,"",F13+G13) | I13: =IF(C13="","",C13*H13)
H14: =IF(F14+G14=0,"",F14+G14) | I14: =IF(C14="","",C14*H14)
H15: =IF(F15+G15=0,"",F15+G15) | I15: =IF(C15="","",C15*H15)
H16: =IF(F16+G16=0,"",F16+G16) | I16: =IF(C16="","",C16*H16)
H17: =IF(F17+G17=0,"",F17+G17) | I17: =IF(C17="","",C17*H17)
B18: TOTAL | C18: =SUM(C3:C17) -> 17 | D18: =IFERROR(AVERAGE(D4:D17),"") -> 662.33333 | E18: =IFERROR(SUMPRODUCT(E4:E17,C4:C17)/SUM(C4:C17),"") -> 1524.4118 | F18: =IFERROR(AVERAGE(F4:F17),"") -> 1941.6667 | G18: =IFERROR(AVERAGE(G4:G17),"") | H18: =IFERROR(SUMPRODUCT(H4:H17,C4:C17)/SUM(C4:C17),"") -> 2042.6471
D19: Current GR | E19: =SUMPRODUCT(C4:C17,E4:E17) -> 25915 | G19: Post Reno Market Rent | I19: =SUM(I4:I17) -> 34725 | K19: =(I19/E19)-1 -> 0.33995755
B29: Rent Comps

Sheet Renovation Budget
B2: Interiors & Buyouts | D2: Notes | E2: Interiors & Buyouts
B3: Interior Renovations | C3: =F3*Assumptions!C53 -> 240000 | E3: Interior Renovations | F3: =L3 -> 14117.647 | J3: 15000 | K3: =J3/17 -> 882.35294 | L3: =K3*16 -> 14117.647
B4: Buyouts | C4: =Assumptions!C53*'Renovation Budget'!F4*'Renovation Budget'!F5 -> 42500 | E4: Buyouts | F4: 5000
E5: % of Turns as Buyouts | F5: 0.5
B6: TOTAL INTERIOR RENOVATIONS | C6: =SUM(C3:C5) -> 282500
B8: Exterior Renovations | D8: Notes
B9: Gate repair/paint | C9: 25000
B10: Paint | C10: 25000
B11: New Doors | C11: 17000
B12: Landscape | C12: 5000
B13: Garage Door | C13: 10000
B15: TOTAL EXTERIOR RENOVATIONS | C15: =SUM(C9:C14) -> 82000
B17: Contingency | C17: =(C15+C6)*D17 -> 36450 | D17: 0.1
B18: Construction Mgmt. Fee | C18: =(C6+C15)*D18 -> 18225 | D18: 0.05
B20: TOTAL RENOVATION CAPITAL | C20: =C6+C15+C17+C18 -> 419175

Sheet Loan Summary
B1: ACQUISITION LOAN SUMMARY | F1: Month | G1: Beginning | H1: Payment | I1: Interest | J1: Principal | K1: Draw | L1: Ending Balance | O1: MEMBER LOAN SUMMARY | R1: Month | S1: Beginning | T1: Accrued Return | U1: Pay | V1: Refi Paydown | W1: Ending Balance
B2: Principal Balance | C2: =Assumptions!W32 -> 2357500 | F2: 1 | G2: =IF(F2<$C$16,$C$2,$C$9) -> 2357500 | H2: =IF(F2<$C$16,IF(F2>$C$6,-PMT(($C$3/12),$C$4,$C$2),I2),-PMT($C$10/12,$C$11,$C$9)) -> 11492.812 | I2: =IF(F2<$C$16,G2*($C$3/12),G2*($C$10/12)) -> 11492.812 | J2: =IF(F2<$C$16,IF(F2<=$C$6,0,H2-I2),IF(F2<=$C$16+$C$13,0,H2-I2)) -> 0 | K2: =IF('Monthly Cash Flow'!$C$88="Lender Draw",HLOOKUP(F2,'Monthly Cash Flow'!$D$79:$CP$88,10),0) -> 25000 | L2: =G2-J2+K2 -> 2382500 | O2: Principal Balance | P2: =Assumptions!C17 -> 419175 | R2: 1 | S2: =P2 -> 419175 | T2: =(S2*$P$3)/12 -> 4191.75 | U2: =-IF('Cash Flow Summary'!$D$24="No",0,IF(AND('Cash Flow Summary'!$D$24="Yes",HLOOKUP($R2,'Monthly Cash Flow'!$D$6:$CP$68,61,FALSE)>0),HLOOKUP($R2,'Monthly Cash Flow'!$D$6:$CP$68,61,FALSE),IF('Cash Flow Summary'!$D$24="Current Pay",('Loan Summary'!S2*'Loan Summary'!$P$3)/12,0))) -> 0 | V2: =IF('Loan Summary'!R2=Assumptions!$AD$3,Assumptions!$AD$25,0) -> 0 | W2: =S2+T2+U2+V2 -> 423366.75
B3: Interest Rate | C3: =Assumptions!W5 -> 0.0585 | F3: 2 | G3: =IF(F3<$C$16,L2,IF(F3=$C$16,$C$9,L2)) -> 2382500 | H3: =IF(F3<$C$16,IF(F3>$C$6,-PMT(($C$3/12),$C$4,$C$2),I3),-PMT($C$10/12,$C$11,$C$9)) -> 11614.688 | I3: =IF(F3<$C$16,G3*($C$3/12),G3*($C$10/12)) -> 11614.688 | J3: =IF(F3<$C$16,IF(F3<=$C$6,0,H3-I3),IF(F3<=$C$16+$C$13,0,H3-I3)) -> 0 | K3: =IF('Monthly Cash Flow'!$C$88="Lender Draw",HLOOKUP(F3,'Monthly Cash Flow'!$D$79:$CP$88,10),0) -> 23575 | L3: =G3-J3+K3 -> 2406075 | O3: Pref Rate | P3: 0.12 | R3: 2 | S3: =W2 -> 423366.75 | T3: =(S3*$P$3)/12 -> 4233.6675 | U3: =-IF('Cash Flow Summary'!$D$24="No",0,IF(AND('Cash Flow Summary'!$D$24="Yes",HLOOKUP($R3,'Monthly Cash Flow'!$D$6:$CP$68,61,FALSE)>0),HLOOKUP($R3,'Monthly Cash Flow'!$D$6:$CP$68,61,FALSE),IF('Cash Flow Summary'!$D$24="Current Pay",('Loan Summary'!S3*'Loan Summary'!$P$3)/12,0))) -> 0 | V3: =IF('Loan Summary'!R3=Assumptions!$AD$3,Assumptions!$AD$25,0) -> 0 | W3: =S3+T3+U3+V3 -> 427600.42
B4: Amortization Schd | C4: 360 | D4: Months | F4: 3 | G4: =IF(F4<$C$16,L3,IF(F4=$C$16,$C$9,L3)) -> 2406075 | H4: =IF(F4<$C$16,IF(F4>$C$6,-PMT(($C$3/12),$C$4,$C$2),I4),-PMT($C$10/12,$C$11,$C$9)) -> 11729.616 | I4: =IF(F4<$C$16,G4*($C$3/12),G4*($C$10/12)) -> 11729.616 | J4: =IF(F4<$C$16,IF(F4<=$C$6,0,H4-I4),IF(F4<=$C$16+$C$13,0,H4-I4)) -> 0 | K4: =IF('Monthly Cash Flow'!$C$88="Lender Draw",HLOOKUP(F4,'Monthly Cash Flow'!$D$79:$CP$88,10),0) -> 42685.294 | L4: =G4-J4+K4 -> 2448760.3 | O4: Compounding Periods/Yr | P4: 12 | R4: 3 | S4: =W3 -> 427600.42 | T4: =(S4*$P$3)/12 -> 4276.0042 | U4: =-IF('Cash Flow Summary'!$D$24="No",0,IF(AND('Cash Flow Summary'!$D$24="Yes",HLOOKUP($R4,'Monthly Cash Flow'!$D$6:$CP$68,61,FALSE)>0),HLOOKUP($R4,'Monthly Cash Flow'!$D$6:$CP$68,61,FALSE),IF('Cash Flow Summary'!$D$24="Current Pay",('Loan Summary'!S4*'Loan Summary'!$P$3)/12,0))) -> 0 | V4: =IF('Loan Summary'!R4=Assumptions!$AD$3,Assumptions!$AD$25,0) -> 0 | W4: =S4+T4+U4+V4 -> 431876.42
B5: Term | C5: 60 | D5: Months | F5: 4 | G5: =IF(F5<$C$16,L4,IF(F5=$C$16,$C$9,L4)) -> 2448760.3 | H5: =IF(F5<$C$16,IF(F5>$C$6,-PMT(($C$3/12),$C$4,$C$2),I5),-PMT($C$10/12,$C$11,$C$9)) -> 11937.706 | I5: =IF(F5<$C$16,G5*($C$3/12),G5*($C$10/12)) -> 11937.706 | J5: =IF(F5<$C$16,IF(F5<=$C$6,0,H5-I5),IF(F5<=$C$16+$C$13,0,H5-I5)) -> 0 | K5: =IF('Monthly Cash Flow'!$C$88="Lender Draw",HLOOKUP(F5,'Monthly Cash Flow'!$D$79:$CP$88,10),0) -> 42685.294 | L5: =G5-J5+K5 -> 2491445.6 | O5: Paydown through CF? | P5: No | R5: 4 | S5: =W4 -> 431876.42 | T5: =(S5*$P$3)/12 -> 4318.7642 | U5: =-IF('Cash Flow Summary'!$D$24="No",0,IF(AND('Cash Flow Summary'!$D$24="Yes",HLOOKUP($R5,'Monthly Cash Flow'!$D$6:$CP$68,61,FALSE)>0),HLOOKUP($R5,'Monthly Cash Flow'!$D$6:$CP$68,61,FALSE),IF('Cash Flow Summary'!$D$24="Current Pay",('Loan Summary'!S5*'Loan Summary'!$P$3)/12,0))) -> 0 | V5: =IF('Loan Summary'!R5=Assumptions!$AD$3,Assumptions!$AD$25,0) -> 0 | W5: =S5+T5+U5+V5 -> 436195.19
B6: Interest Only | C6: 60 | D6: Months | F6: 5 | G6: =IF(F6<$C$16,L5,IF(F6=$C$16,$C$9,L5)) -> 2491445.6 | H6: =IF(F6<$C$16,IF(F6>$C$6,-PMT(($C$3/12),$C$4,$C$2),I6),-PMT($C$10/12,$C$11,$C$9)) -> 12145.797 | I6: =IF(F6<$C$16,G6*($C$3/12),G6*($C$10/12)) -> 12145.797 | J6: =IF(F6<$C$16,IF(F6<=$C$6,0,H6-I6),IF(F6<=$C$16+$C$13,0,H6-I6)) -> 0 | K6: =IF('Monthly Cash Flow'!$C$88="Lender Draw",HLOOKUP(F6,'Monthly Cash Flow'!$D$79:$CP$88,10),0) -> 19110.294 | L6: =G6-J6+K6 -> 2510555.9 | R6: 5 | S6: =W5 -> 436195.19 | T6: =(S6*$P$3)/12 -> 4361.9519 | U6: =-IF('Cash Flow Summary'!$D$24="No",0,IF(AND('Cash Flow Summary'!$D$24="Yes",HLOOKUP($R6,'Monthly Cash Flow'!$D$6:$CP$68,61,FALSE)>0),HLOOKUP($R6,'Monthly Cash Flow'!$D$6:$CP$68,61,FALSE),IF('Cash Flow Summary'!$D$24="Current Pay",('Loan Summary'!S6*'Loan Summary'!$P$3)/12,0))) -> 0 | V6: =IF('Loan Summary'!R6=Assumptions!$AD$3,Assumptions!$AD$25,0) -> 0 | W6: =S6+T6+U6+V6 -> 440557.14
F7: 6 | G7: =IF(F7<$C$16,L6,IF(F7=$C$16,$C$9,L6)) -> 2510555.9 | H7: =IF(F7<$C$16,IF(F7>$C$6,-PMT(($C$3/12),$C$4,$C$2),I7),-PMT($C$10/12,$C$11,$C$9)) -> 12238.96 | I7: =IF(F7<$C$16,G7*($C$3/12),G7*($C$10/12)) -> 12238.96 | J7: =IF(F7<$C$16,IF(F7<=$C$6,0,H7-I7),IF(F7<=$C$16+$C$13,0,H7-I7)) -> 0 | K7: =IF('Monthly Cash Flow'!$C$88="Lender Draw",HLOOKUP(F7,'Monthly Cash Flow'!$D$79:$CP$88,10),0) -> 19110.294 | L7: =G7-J7+K7 -> 2529666.2 | R7: 6 | S7: =W6 -> 440557.14 | T7: =(S7*$P$3)/12 -> 4405.5714 | U7: =-IF('Cash Flow Summary'!$D$24="No",0,IF(AND('Cash Flow Summary'!$D$24="Yes",HLOOKUP($R7,'Monthly Cash Flow'!$D$6:$CP$68,61,FALSE)>0),HLOOKUP($R7,'Monthly Cash Flow'!$D$6:$CP$68,61,FALSE),IF('Cash Flow Summary'!$D$24="Current Pay",('Loan Summary'!S7*'Loan Summary'!$P$3)/12,0))) -> 0 | V7: =IF('Loan Summary'!R7=Assumptions!$AD$3,Assumptions!$AD$25,0) -> 0 | W7: =S7+T7+U7+V7 -> 444962.71
B8: REFINANCE LOAN SUMMARY | F8: 7 | G8: =IF(F8<$C$16,L7,IF(F8=$C$16,$C$9,L7)) -> 2529666.2 | H8: =IF(F8<$C$16,IF(F8>$C$6,-PMT(($C$3/12),$C$4,$C$2),I8),-PMT($C$10/12,$C$11,$C$9)) -> 12332.123 | I8: =IF(F8<$C$16,G8*($C$3/12),G8*($C$10/12)) -> 12332.123 | J8: =IF(F8<$C$16,IF(F8<=$C$6,0,H8-I8),IF(F8<=$C$16+$C$13,0,H8-I8)) -> 0 | K8: =IF('Monthly Cash Flow'!$C$88="Lender Draw",HLOOKUP(F8,'Monthly Cash Flow'!$D$79:$CP$88,10),0) -> 19110.294 | L8: =G8-J8+K8 -> 2548776.5 | R8: 7 | S8: =W7 -> 444962.71 | T8: =(S8*$P$3)/12 -> 4449.6271 | U8: =-IF('Cash Flow Summary'!$D$24="No",0,IF(AND('Cash Flow Summary'!$D$24="Yes",HLOOKUP($R8,'Monthly Cash Flow'!$D$6:$CP$68,61,FALSE)>0),HLOOKUP($R8,'Monthly Cash Flow'!$D$6:$CP$68,61,FALSE),IF('Cash Flow Summary'!$D$24="Current Pay",('Loan Summary'!S8*'Loan Summary'!$P$3)/12,0))) -> 0 | V8: =IF('Loan Summary'!R8=Assumptions!$AD$3,Assumptions!$AD$25,0) -> 0 | W8: =S8+T8+U8+V8 -> 449412.34
B9: Principal Balance | C9: =Assumptions!AD21 -> 3740191.3 | F9: 8 | G9: =IF(F9<$C$16,L8,IF(F9=$C$16,$C$9,L8)) -> 2548776.5 | H9: =IF(F9<$C$16,IF(F9>$C$6,-PMT(($C$3/12),$C$4,$C$2),I9),-PMT($C$10/12,$C$11,$C$9)) -> 12425.285 | I9: =IF(F9<$C$16,G9*($C$3/12),G9*($C$10/12)) -> 12425.285 | J9: =IF(F9<$C$16,IF(F9<=$C$6,0,H9-I9),IF(F9<=$C$16+$C$13,0,H9-I9)) -> 0 | K9: =IF('Monthly Cash Flow'!$C$88="Lender Draw",HLOOKUP(F9,'Monthly Cash Flow'!$D$79:$CP$88,10),0) -> 19110.294 | L9: =G9-J9+K9 -> 2567886.8 | R9: 8 | S9: =W8 -> 449412.34 | T9: =(S9*$P$3)/12 -> 4494.1234 | U9: =-IF('Cash Flow Summary'!$D$24="No",0,IF(AND('Cash Flow Summary'!$D$24="Yes",HLOOKUP($R9,'Monthly Cash Flow'!$D$6:$CP$68,61,FALSE)>0),HLOOKUP($R9,'Monthly Cash Flow'!$D$6:$CP$68,61,FALSE),IF('Cash Flow Summary'!$D$24="Current Pay",('Loan Summary'!S9*'Loan Summary'!$P$3)/12,0))) -> 0 | V9: =IF('Loan Summary'!R9=Assumptions!$AD$3,Assumptions!$AD$25,0) -> 0 | W9: =S9+T9+U9+V9 -> 453906.46
B10: Interest Rate | C10: =Assumptions!AD5 -> 0.055 | F10: 9 | G10: =IF(F10<$C$16,L9,IF(F10=$C$16,$C$9,L9)) -> 2567886.8 | H10: =IF(F10<$C$16,IF(F10>$C$6,-PMT(($C$3/12),$C$4,$C$2),I10),-PMT($C$10/12,$C$11,$C$9)) -> 12518.448 | I10: =IF(F10<$C$16,G10*($C$3/12),G10*($C$10/12)) -> 12518.448 | J10: =IF(F10<$C$16,IF(F10<=$C$6,0,H10-I10),IF(F10<=$C$16+$C$13,0,H10-I10)) -> 0 | K10: =IF('Monthly Cash Flow'!$C$88="Lender Draw",HLOOKUP(F10,'Monthly Cash Flow'!$D$79:$CP$88,10),0) -> 19110.294 | L10: =G10-J10+K10 -> 2586997.1 | R10: 9 | S10: =W9 -> 453906.46 | T10: =(S10*$P$3)/12 -> 4539.0646 | U10: =-IF('Cash Flow Summary'!$D$24="No",0,IF(AND('Cash Flow Summary'!$D$24="Yes",HLOOKUP($R10,'Monthly Cash Flow'!$D$6:$CP$68,61,FALSE)>0),HLOOKUP($R10,'Monthly Cash Flow'!$D$6:$CP$68,61,FALSE),IF('Cash Flow Summary'!$D$24="Current Pay",('Loan Summary'!S10*'Loan Summary'!$P$3)/12,0))) -> 0 | V10: =IF('Loan Summary'!R10=Assumptions!$AD$3,Assumptions!$AD$25,0) -> 0 | W10: =S10+T10+U10+V10 -> 458445.52
B11: Amortization Schd | C11: =Assumptions!AD4*12 -> 360 | D11: Months | F11: 10 | G11: =IF(F11<$C$16,L10,IF(F11=$C$16,$C$9,L10)) -> 2586997.1 | H11: =IF(F11<$C$16,IF(F11>$C$6,-PMT(($C$3/12),$C$4,$C$2),I11),-PMT($C$10/12,$C$11,$C$9)) -> 12611.611 | I11: =IF(F11<$C$16,G11*($C$3/12),G11*($C$10/12)) -> 12611.611 | J11: =IF(F11<$C$16,IF(F11<=$C$6,0,H11-I11),IF(F11<=$C$16+$C$13,0,H11-I11)) -> 0 | K11: =IF('Monthly Cash Flow'!$C$88="Lender Draw",HLOOKUP(F11,'Monthly Cash Flow'!$D$79:$CP$88,10),0) -> 19110.294 | L11: =G11-J11+K11 -> 2606107.4 | R11: 10 | S11: =W10 -> 458445.52 | T11: =(S11*$P$3)/12 -> 4584.4552 | U11: =-IF('Cash Flow Summary'!$D$24="No",0,IF(AND('Cash Flow Summary'!$D$24="Yes",HLOOKUP($R11,'Monthly Cash Flow'!$D$6:$CP$68,61,FALSE)>0),HLOOKUP($R11,'Monthly Cash Flow'!$D$6:$CP$68,61,FALSE),IF('Cash Flow Summary'!$D$24="Current Pay",('Loan Summary'!S11*'Loan Summary'!$P$3)/12,0))) -> 0 | V11: =IF('Loan Summary'!R11=Assumptions!$AD$3,Assumptions!$AD$25,0) -> 0 | W11: =S11+T11+U11+V11 -> 463029.98
B12: Term | C12: 120 | D12: Months | F12: 11 | G12: =IF(F12<$C$16,L11,IF(F12=$C$16,$C$9,L11)) -> 2606107.4 | H12: =IF(F12<$C$16,IF(F12>$C$6,-PMT(($C$3/12),$C$4,$C$2),I12),-PMT($C$10/12,$C$11,$C$9)) -> 12704.773 | I12: =IF(F12<$C$16,G12*($C$3/12),G12*($C$10/12)) -> 12704.773 | J12: =IF(F12<$C$16,IF(F12<=$C$6,0,H12-I12),IF(F12<=$C$16+$C$13,0,H12-I12)) -> 0 | K12: =IF('Monthly Cash Flow'!$C$88="Lender Draw",HLOOKUP(F12,'Monthly Cash Flow'!$D$79:$CP$88,10),0) -> 19110.294 | L12: =G12-J12+K12 -> 2625217.6 | R12: 11 | S12: =W11 -> 463029.98 | T12: =(S12*$P$3)/12 -> 4630.2998 | U12: =-IF('Cash Flow Summary'!$D$24="No",0,IF(AND('Cash Flow Summary'!$D$24="Yes",HLOOKUP($R12,'Monthly Cash Flow'!$D$6:$CP$68,61,FALSE)>0),HLOOKUP($R12,'Monthly Cash Flow'!$D$6:$CP$68,61,FALSE),IF('Cash Flow Summary'!$D$24="Current Pay",('Loan Summary'!S12*'Loan Summary'!$P$3)/12,0))) -> 0 | V12: =IF('Loan Summary'!R12=Assumptions!$AD$3,Assumptions!$AD$25,0) -> 0 | W12: =S12+T12+U12+V12 -> 467660.28
B13: Interest Only | C13: 120 | D13: Months | F13: 12 | G13: =IF(F13<$C$16,L12,IF(F13=$C$16,$C$9,L12)) -> 2625217.6 | H13: =IF(F13<$C$16,IF(F13>$C$6,-PMT(($C$3/12),$C$4,$C$2),I13),-PMT($C$10/12,$C$11,$C$9)) -> 12797.936 | I13: =IF(F13<$C$16,G13*($C$3/12),G13*($C$10/12)) -> 12797.936 | J13: =IF(F13<$C$16,IF(F13<=$C$6,0,H13-I13),IF(F13<=$C$16+$C$13,0,H13-I13)) -> 0 | K13: =IF('Monthly Cash Flow'!$C$88="Lender Draw",HLOOKUP(F13,'Monthly Cash Flow'!$D$79:$CP$88,10),0) -> 19110.294 | L13: =G13-J13+K13 -> 2644327.9 | R13: 12 | S13: =W12 -> 467660.28 | T13: =(S13*$P$3)/12 -> 4676.6028 | U13: =-IF('Cash Flow Summary'!$D$24="No",0,IF(AND('Cash Flow Summary'!$D$24="Yes",HLOOKUP($R13,'Monthly Cash Flow'!$D$6:$CP$68,61,FALSE)>0),HLOOKUP($R13,'Monthly Cash Flow'!$D$6:$CP$68,61,FALSE),IF('Cash Flow Summary'!$D$24="Current Pay",('Loan Summary'!S13*'Loan Summary'!$P$3)/12,0))) -> 0 | V13: =IF('Loan Summary'!R13=Assumptions!$AD$3,Assumptions!$AD$25,0) -> 0 | W13: =S13+T13+U13+V13 -> 472336.88
B14: Rate Buydown | F14: 13 | G14: =IF(F14<$C$16,L13,IF(F14=$C$16,$C$9,L13)) -> 2644327.9 | H14: =IF(F14<$C$16,IF(F14>$C$6,-PMT(($C$3/12),$C$4,$C$2),I14),-PMT($C$10/12,$C$11,$C$9)) -> 12891.099 | I14: =IF(F14<$C$16,G14*($C$3/12),G14*($C$10/12)) -> 12891.099 | J14: =IF(F14<$C$16,IF(F14<=$C$6,0,H14-I14),IF(F14<=$C$16+$C$13,0,H14-I14)) -> 0 | K14: =IF('Monthly Cash Flow'!$C$88="Lender Draw",HLOOKUP(F14,'Monthly Cash Flow'!$D$79:$CP$88,10),0) -> 19110.294 | L14: =G14-J14+K14 -> 2663438.2 | R14: 13 | S14: =W13 -> 472336.88 | T14: =(S14*$P$3)/12 -> 4723.3688 | U14: =-IF('Cash Flow Summary'!$E$24="No",0,IF(AND('Cash Flow Summary'!$D$24="Yes",HLOOKUP($R14,'Monthly Cash Flow'!$D$6:$CP$68,61,FALSE)>0),HLOOKUP($R14,'Monthly Cash Flow'!$D$6:$CP$68,61,FALSE),IF('Cash Flow Summary'!$E$24="Current Pay",('Loan Summary'!S14*'Loan Summary'!$P$3)/12,0))) -> 0 | V14: =IF('Loan Summary'!R14=Assumptions!$AD$3,Assumptions!$AD$25,0) -> 0 | W14: =S14+T14+U14+V14 -> 477060.25
B15: Refi Fee | C15: =D15*C9 -> 18700.957 | D15: 0.005 | F15: 14 | G15: =IF(F15<$C$16,L14,IF(F15=$C$16,$C$9,L14)) -> 2663438.2 | H15: =IF(F15<$C$16,IF(F15>$C$6,-PMT(($C$3/12),$C$4,$C$2),I15),-PMT($C$10/12,$C$11,$C$9)) -> 12984.261 | I15: =IF(F15<$C$16,G15*($C$3/12),G15*($C$10/12)) -> 12984.261 | J15: =IF(F15<$C$16,IF(F15<=$C$6,0,H15-I15),IF(F15<=$C$16+$C$13,0,H15-I15)) -> 0 | K15: =IF('Monthly Cash Flow'!$C$88="Lender Draw",HLOOKUP(F15,'Monthly Cash Flow'!$D$79:$CP$88,10),0) -> 19110.294 | L15: =G15-J15+K15 -> 2682548.5 | R15: 14 | S15: =W14 -> 477060.25 | T15: =(S15*$P$3)/12 -> 4770.6025 | U15: =-IF('Cash Flow Summary'!$E$24="No",0,IF(AND('Cash Flow Summary'!$D$24="Yes",HLOOKUP($R15,'Monthly Cash Flow'!$D$6:$CP$68,61,FALSE)>0),HLOOKUP($R15,'Monthly Cash Flow'!$D$6:$CP$68,61,FALSE),IF('Cash Flow Summary'!$E$24="Current Pay",('Loan Summary'!S15*'Loan Summary'!$P$3)/12,0))) -> 0 | V15: =IF('Loan Summary'!R15=Assumptions!$AD$3,Assumptions!$AD$25,0) -> 0 | W15: =S15+T15+U15+V15 -> 481830.85
B16: Refi Month | C16: =IF(Assumptions!AD3="","",Assumptions!AD3) -> 35 | F16: 15 | G16: =IF(F16<$C$16,L15,IF(F16=$C$16,$C$9,L15)) -> 2682548.5 | H16: =IF(F16<$C$16,IF(F16>$C$6,-PMT(($C$3/12),$C$4,$C$2),I16),-PMT($C$10/12,$C$11,$C$9)) -> 13077.424 | I16: =IF(F16<$C$16,G16*($C$3/12),G16*($C$10/12)) -> 13077.424 | J16: =IF(F16<$C$16,IF(F16<=$C$6,0,H16-I16),IF(F16<=$C$16+$C$13,0,H16-I16)) -> 0 | K16: =IF('Monthly Cash Flow'!$C$88="Lender Draw",HLOOKUP(F16,'Monthly Cash Flow'!$D$79:$CP$88,10),0) -> 19110.294 | L16: =G16-J16+K16 -> 2701658.8 | R16: 15 | S16: =W15 -> 481830.85 | T16: =(S16*$P$3)/12 -> 4818.3085 | U16: =-IF('Cash Flow Summary'!$E$24="No",0,IF(AND('Cash Flow Summary'!$D$24="Yes",HLOOKUP($R16,'Monthly Cash Flow'!$D$6:$CP$68,61,FALSE)>0),HLOOKUP($R16,'Monthly Cash Flow'!$D$6:$CP$68,61,FALSE),IF('Cash Flow Summary'!$E$24="Current Pay",('Loan Summary'!S16*'Loan Summary'!$P$3)/12,0))) -> 0 | V16: =IF('Loan Summary'!R16=Assumptions!$AD$3,Assumptions!$AD$25,0) -> 0 | W16: =S16+T16+U16+V16 -> 486649.16
F17: 16 | G17: =IF(F17<$C$16,L16,IF(F17=$C$16,$C$9,L16)) -> 2701658.8 | H17: =IF(F17<$C$16,IF(F17>$C$6,-PMT(($C$3/12),$C$4,$C$2),I17),-PMT($C$10/12,$C$11,$C$9)) -> 13170.587 | I17: =IF(F17<$C$16,G17*($C$3/12),G17*($C$10/12)) -> 13170.587 | J17: =IF(F17<$C$16,IF(F17<=$C$6,0,H17-I17),IF(F17<=$C$16+$C$13,0,H17-I17)) -> 0 | K17: =IF('Monthly Cash Flow'!$C$88="Lender Draw",HLOOKUP(F17,'Monthly Cash Flow'!$D$79:$CP$88,10),0) -> 19110.294 | L17: =G17-J17+K17 -> 2720769.1 | R17: 16 | S17: =W16 -> 486649.16 | T17: =(S17*$P$3)/12 -> 4866.4916 | U17: =-IF('Cash Flow Summary'!$E$24="No",0,IF(AND('Cash Flow Summary'!$D$24="Yes",HLOOKUP($R17,'Monthly Cash Flow'!$D$6:$CP$68,61,FALSE)>0),HLOOKUP($R17,'Monthly Cash Flow'!$D$6:$CP$68,61,FALSE),IF('Cash Flow Summary'!$E$24="Current Pay",('Loan Summary'!S17*'Loan Summary'!$P$3)/12,0))) -> 0 | V17: =IF('Loan Summary'!R17=Assumptions!$AD$3,Assumptions!$AD$25,0) -> 0 | W17: =S17+T17+U17+V17 -> 491515.65
F18: 17 | G18: =IF(F18<$C$16,L17,IF(F18=$C$16,$C$9,L17)) -> 2720769.1 | H18: =IF(F18<$C$16,IF(F18>$C$6,-PMT(($C$3/12),$C$4,$C$2),I18),-PMT($C$10/12,$C$11,$C$9)) -> 13263.749 | I18: =IF(F18<$C$16,G18*($C$3/12),G18*($C$10/12)) -> 13263.749 | J18: =IF(F18<$C$16,IF(F18<=$C$6,0,H18-I18),IF(F18<=$C$16+$C$13,0,H18-I18)) -> 0 | K18: =IF('Monthly Cash Flow'!$C$88="Lender Draw",HLOOKUP(F18,'Monthly Cash Flow'!$D$79:$CP$88,10),0) -> 19110.294 | L18: =G18-J18+K18 -> 2739879.4 | R18: 17 | S18: =W17 -> 491515.65 | T18: =(S18*$P$3)/12 -> 4915.1565 | U18: =-IF('Cash Flow Summary'!$E$24="No",0,IF(AND('Cash Flow Summary'!$D$24="Yes",HLOOKUP($R18,'Monthly Cash Flow'!$D$6:$CP$68,61,FALSE)>0),HLOOKUP($R18,'Monthly Cash Flow'!$D$6:$CP$68,61,FALSE),IF('Cash Flow Summary'!$E$24="Current Pay",('Loan Summary'!S18*'Loan Summary'!$P$3)/12,0))) -> 0 | V18: =IF('Loan Summary'!R18=Assumptions!$AD$3,Assumptions!$AD$25,0) -> 0 | W18: =S18+T18+U18+V18 -> 496430.81
