Workbook
Name _off3: [10]Marina!#REF!
Name _off4: [10]Marina!#REF!
Name _off5: [10]Marina!#REF!
Name _off6: [10]Marina!#REF!
Name _ret1: #REF!
Name _ret2: #REF!
Name _ret3: #REF!
Name _ret4: #REF!
Name _ret5: #REF!
Name _ret6: #REF!
Name _sa1: #REF!
Name _sa2: #REF!
Name _sa3: #REF!
Name _sa4: #REF!
Name _sa5: #REF!
Name _sa6: #REF!
Name ArgusInput: [12]ArgusRaw.Primary!$A$1:$EZ$100
Name ArgusInput.New: [12]ArgusRaw.Secondary!$A$1:$EZ$100
Name Budget.AnalystReport.Rows: #REF!
Name Budget.BudgetPeriods.Columns: #REF!
Name Budget.ColumnHeadings.Row: #REF!
Name Budget.HideColumns.Row: #REF!
Name Budget.HideRows.Column: #REF!
Name Budget.RowOrderBy.Column: #REF!
Name Budget.RowOrderByDescription.Column: #REF!
Name Budget.Total.Column: #REF!
Name Budget.WBCol.Column: #REF!
Name Budget.WBStatus.Column: #REF!
Name Case_A: '[14]PRO FORMA'!#REF!
Name CAT_Com: '[15]PF Base 5 yr'!$B$93:$E$97
Name Choices_Wrapper: #N/A
Name Choices_Wrapper5: #N/A
Name cnsld2: [10]consolsum!#REF!
Name cnsld3: [10]consolsum!#REF!
Name cnsld4: [10]consolsum!#REF!
Name cost1: #REF!
Name CostInflation: [12]Assumptions!$F$15
Name Cur_QTD_Total_Revenue: #REF!
Name Date_Acquisition: [12]Assumptions!$C$20
Name Date_AmortStart1: [12]Assumptions!$C$38
Name Date_AmortStart2: [12]Assumptions!$D$38
Name Date_CostsPricing: [12]Assumptions!$F$13
Name Date_PreDevEnd: [12]Assumptions!$C$21
Name Date_Refi: [12]Assumptions!$C$25
Name Date_Sale: [12]Assumptions!$C$26
Name Date_SaleParcel: [12]Assumptions!$C$27
Name Date_Stabilization: [12]Assumptions!$C$23
Name Description: #REF!
Name DevFeeTarget: '[12]Dev Costs'!$G$109
Name EntryCapRt: [12]Assumptions!$C$13
Name ExitCapRt: [12]Assumptions!$C$14
Name FileVersion: [12]Assumptions!$C$9
Name FinFeeTarget: '[12]Dev Costs'!$G$118
Name Hello: #N/A
Name Hello5: #N/A
Name hotl1: #REF!
Name hotl2: #REF!
Name hotl3: #REF!
Name hotl4: #REF!
Name hotl5: #REF!

Sheet Assumptions
B1: CLARENDON - LAND+HOME, AMENITY+HOTEL DEVELOPMENT - ASSUMPTIONS
B2: OVERALL ASSUMPTIONS
B4: General | E4: Debt Financing | F4: LAND + HOME | G4: AMENITY + HOTEL | I4: Sub-Debt/ Equity Financing | K4: LAND + HOME | L4: AMENITY + HOTEL | N4: Land & Infrastructure
B5: Development Start Date (Yr 0) | C5: 45658 | E5: Origination Year | F5: 2024 | G5: 2026 | I5: Pref Accrual Rate | K5: 0.1 | L5: 0.1 | P5: Acres | Q5: Value
B6: Development Start Year | C6: =YEAR(C5) -> 2025 | E6: Original Term (Years) | F6: 3 | G6: 3 | I6: EB-5 Interest Rate (Debt+1/5) | K6: =F8+0.015 -> 0.135 | L6: =G8+0.015 -> 0.135 | N6: Total Land | P6: =P7+P8 -> 319 | Q6: =Q7+Q8 -> 22000000
B7: Fiscal Year Start Month | C7: =MONTH(C5) -> 1 | E7: Underwritten LTC | F7: 0.6 | G7: 0.77 | I7: EB-5 Origination Fee | K7: 0.01 | L7: =K7 -> 0.01 | N7: RESI | P7: 240 | Q7: 15000000
B8: Repayment Waterfall | E8: Interest Rate | F8: 0.12 | G8: =F8 -> 0.12 | I8: EB-5 Exit Fee | K8: 0.01 | L8: =K8 -> 0.01 | N8: AMENITY + HOTEL | P8: 79 | Q8: 7000000
B9: Loan | E9: Debt Placement & Origination Fee | F9: 0.035 | G9: =F9 -> 0.035 | I9: Bridge Loan Placement Fee | K9: 0.02 | L9: N/A | N9: Infrastructure Cost | Q9: 15000000
B10: Preferred Return | E10: 1 Year Extension Fee | F10: =0.005*4 -> 0.02 | I10: Bridge Loan Interest Rate | K10: 0.15 | L10: N/A
B11: Capital Return | E11: Financing Cost Gross-up | F11: 0.242 | G11: 0.26317942 | I11: JV GP Promote Split | K11: 0.4 | L11: 0.4
F12: ='Proforma L+H'!V156-'Proforma L+H'!U156 -> -3436770.5 | G12: ='Proforma A+H'!W189-'Proforma A+H'!X189 -> -600699.11
B14: LAND + HOME ASSUMPTIONS
B16: Build / Sale Cost | E16: Unit Mix | J16: Unit Sales
B17: Vertical Construction Cost psft | C17: =850*C18 -> 850 | F17: Avg Size | G17: PPSF | H17: Escalation | J17: Sales Price Scalar | M17: 1
B18: Vertical Construction Costs Scalar | C18: 1 | E18: Homesites | F18: 3500 | G18: 1750 | H18: 0.1 | J18: Net Profit % | M18: 0.2
B19: Cost of Sale - RE Fees | C19: 0.045 | E19: Village | F19: 4500 | G19: 1650 | H19: 0.075 | J19: Phantom Tax Rate | M19: 0.3
B20: Real Estate Taxes (Annual) / mils | C20: =10000/39 -> 256.41026 | E20: Cottages | F20: 2500 | G20: 1850 | H20: 0.075
B23: AMENITY + HOTEL ASSUMPTIONS
B25: Hotel Details | E25: Hotel Guest Rooms | K25: Build Cost
B26: Start Date | C26: 46053 | F26: Lodge Rooms | G26: Villa/Cabin | H26: Cottages | I26: Auton. Tents | K26: Vertical Construction Costs Scalar | N26: ='Returns A+H'!L14 -> 1
B27: Member Dues / year / unit | C27: 15000 | E27: Guest Rooms | F27: 20 | G27: 24 | H27: 24 | I27: 12 | K27: Real Estate Taxes (Annual) / mils | N27: ='Proforma Resi'!C269 -> 256
B28: Loan Interest Rate | C28: 0.03 | E28: SQFT | F28: 500 | G28: 750 | H28: 1250 | I28: 625
B29: Loan Origination Fees | C29: 0 | E29: Sales Price / SF | F29: 0 | G29: 2500 | H29: 2250 | I29: 0
B30: Disposition Year | C30: 7 | E30: Average Daily Rate | F30: 1175 | G30: 1800 | H30: 3125 | I30: 850
B31: Terminal Cap Rate | C31: 0.065 | E31: Average Sales Price | F31: =F28*F29 -> 0 | G31: =G28*G29 -> 1875000 | H31: =H28*H29 -> 2812500 | I31: =I28*I29 -> 0
B32: Selling Costs | C32: 0.05 | E32: Sales Price Escalation | F32: 0.05 | G32: 0.1 | H32: 0.1 | I32: 0.05
B33: Hold Period | C33: 132 | E33: % Rooms for Sale | F33: 0 | G33: =5/6 -> 0.83333333 | H33: 1 | I33: 0
B34: Hotel Room Rent Growth Rate | C34: 0.03
B35: Hotel Days | C35: 365
B36: Hotel Rooms Operating Cost | C36: =35%-F33*15% -> 0.35
B37: Condo Owner Revenue Split | C37: 0.5
F38: 1 | G38: 2 | H38: 3 | I38: 4 | J38: 5 | K38: 6 | L38: 7 | M38: 8 | N38: 9 | O38: 10 | P38: 11 | Q38: 12
B39: Bar Details | F39: 44562 | G39: =F39+31 -> 44593 | H39: =G39+31 -> 44624 | I39: =H39+31 -> 44655 | J39: =I39+31 -> 44686 | K39: =J39+31 -> 44717 | L39: =K39+31 -> 44748 | M39: =L39+31 -> 44779 | N39: =M39+31 -> 44810 | ... Q39: =P39+31 -> 44903 | R39: Avg
B40: Start Date | C40: 46753 | E40: Seasonal Occupancy - Hotel | F40: 0.75 | G40: 0.75 | H40: 0.65 | I40: 0.3 | J40: 0.3 | K40: 0.55 | L40: 0.65 | M40: 0.55 | N40: 0.5 | O40: 0.3 | P40: 0.2 | Q40: 0.55 | R40: =AVERAGE(F40:Q40) -> 0.50416667
B41: Available room/nights | C41: =(F27+G27)*C35 -> 16060 | E41: Conference Center Occupancy | F41: 0.25 | G41: 0.25 | H41: 0.25 | I41: 0.5 | J41: 0.75 | K41: 1 | L41: 1 | M41: 1 | N41: 0.75 | O41: 0.5 | P41: 0.25 | Q41: 0.25 | R41: =AVERAGE(F41:Q41) -> 0.5625
B42: Paid Room Nights | C42: =C41*R40 -> 8096.9167 | E42: Adj. Conf Center Occupancy | F42: =IF(OR(F38<MONTH($C$63),F38>$C$64),0,F41) -> 0.25 | G42: =IF(OR(G38<MONTH($C$63),G38>$C$64),0,G41) -> 0.25 | H42: =IF(OR(H38<MONTH($C$63),H38>$C$64),0,H41) -> 0.25 | I42: =IF(OR(I38<MONTH($C$63),I38>$C$64),0,I41) -> 0.5 | J42: =IF(OR(J38<MONTH($C$63),J38>$C$64),0,J41) -> 0.75 | K42: =IF(OR(K38<MONTH($C$63),K38>$C$64),0,K41) -> 1 | L42: =IF(OR(L38<MONTH($C$63),L38>$C$64),0,L41) -> 1 | M42: =IF(OR(M38<MONTH($C$63),M38>$C$64),0,M41) -> 1 | ... Q42: =IF(OR(Q38<MONTH($C$63),Q38>$C$64),0,Q41) -> 0.25 | R42: =AVERAGE(F42:Q42) -> 0.5625
B43: Bar Revenue (% of Room Rev) | C43: 0.2
B44: Bar COS (% of Bar Rev) | C44: 0.75 | F44: 1 | G44: =F44+1 -> 2 | H44: =G44+1 -> 3 | I44: =H44+1 -> 4 | J44: =I44+1 -> 5 | K44: =J44+1 -> 6 | L44: =K44+1 -> 7 | M44: =L44+1 -> 8 | N44: =M44+1 -> 9 | O44: =N44+1 -> 10
F45: =EDATE(C5,12) -> 46023 | G45: =EDATE(F45,12) -> 46388 | H45: =EDATE(G45,12) -> 46753 | I45: =EDATE(H45,12) -> 47119 | J45: =EDATE(I45,12) -> 47484 | K45: =EDATE(J45,12) -> 47849 | L45: =EDATE(K45,12) -> 48214 | M45: =EDATE(L45,12) -> 48580 | N45: =EDATE(M45,12) -> 48945 | O45: =EDATE(N45,12) -> 49310 | P45: Total Rooms | Q45: Condos
B46: Spa / Wellness Center Details | E46: Conf Center Rental Rates | F46: =Assumptions!$C$60 -> 50000 | G46: =F46*(1+$C$61) -> 51500 | H46: =G46*(1+$C$61) -> 53045 | I46: =H46*(1+$C$61) -> 54636.35 | J46: =I46*(1+$C$61) -> 56275.44 | K46: =J46*(1+$C$61) -> 57963.704 | L46: =K46*(1+$C$61) -> 59702.615 | M46: =L46*(1+$C$61) -> 61493.693 | N46: =M46*(1+$C$61) -> 63338.504 | O46: =N46*(1+$C$61) -> 65238.659
...

Sheet Exhibits
B4: CLARENDON - OVERALL DEVELOPMENT: PROFORMA | H4: =B4 -> CLARENDON - OVERALL DEVELOPMENT: PROFORMA | N4: CLARENDON - OVERALL DEVELOPMENT: PROFORMA
B5: PROFORMA - SOURCES & USES SUMMARY | H5: PROFORMA - SOURCES & USES PRE-REVENUE | N5: PROFORMA - BUSINESS CASE ANALYSIS
B6: SOURCES | C6: $ | D6: $/SF | E6: Per Home | F6: % Total | H6: =B6 -> SOURCES | I6: Pre-EB5 | J6: Post EB-5 Closing | L6: % Total | O6: $ | P6: % Total
B7: =B41 -> MTN ORIGINS - PURSUIT CAPITAL | C7: =C41+C74 -> 1500000 | F7: =C7/$C$18 -> 0.0016951519 | H7: =B7 -> MTN ORIGINS - PURSUIT CAPITAL | I7: =C7 -> 1500000 | J7: =C7 -> 1500000 | L7: =SUM(J7:K7)/$J$18 -> 0.0065615802 | N7: =B13 -> LAND SALE TO AMENITY | O7: =O40 -> 15000000 | P7: =O7/$O$12 -> 0.022856343
B8: =B42 -> JV - EQUITY CAPITAL | C8: =C42+C75 -> 10000000 | F8: =C8/$C$18 -> 0.011301013 | H8: =B8 -> JV - EQUITY CAPITAL | I8: =C8 -> 10000000 | J8: =C8 -> 10000000 | L8: =SUM(J8:K8)/$J$18 -> 0.043743868 | N8: =B14 -> PRESALE REVENUES | O8: =O41 -> 81794306 | P8: =O8/$O$12 -> 0.12463458
B9: =B43 -> JV BRIDGE LOAN | C9: =C43 -> 15000000 | F9: =C9/$C$18 -> 0.016951519 | H9: =B9 -> JV BRIDGE LOAN | I9: =C9 -> 15000000 | L9: =SUM(J9:K9)/$J$18 -> 0 | N9: =B15 -> UNIT SALES | O9: =O42+O73 -> 4.0967444e+08 | P9: =O9/$O$12 -> 0.62424396
B10: =B44 -> SELLER FINANCE | C10: =C44 -> 0 | F10: =C10/$C$18 -> 0 | H10: =B10 -> SELLER FINANCE | I10: =C10 -> 0 | L10: =SUM(J10:K10)/$J$18 -> 0 | N10: =B16 -> TOTAL NET OPERATING INCOME (NOI) | O10: =O72 -> 30073583 | P10: =O10/$O$12 -> 0.045824809
B11: =B45 -> EB5 - MEZZ DEBT | C11: =C45+C76 -> 49600000 | F11: =C11/$C$18 -> 0.056053023 | H11: =B11 -> EB5 - MEZZ DEBT | J11: =C11 -> 49600000 | L11: =SUM(J11:K11)/$J$18 -> 0.21696958 | N11: =B17 -> HOTEL SALE PROCEEDS / DISPOSITION | O11: =O74 -> 1.1973065e+08 | P11: =O11/$O$12 -> 0.18244031
B12: =B46 -> DEV LOAN | C12: =C46+C77 -> 1.5250347e+08 | F12: =C12/$C$18 -> 0.17234437 | H12: =B12 -> DEV LOAN | J12: =C12 -> 1.5250347e+08 | L12: =SUM(J12:K12)/$J$18 -> 0.66710917 | N12: TOTAL REVENUE | O12: =SUM(O7:O11) -> 6.5627297e+08 | P12: =O12/$O$12 -> 1
B13: =B47 -> LAND SALE TO AMENITY | C13: =C47 -> 15000000 | F13: =C13/$C$18 -> 0.016951519 | H13: =B13 -> LAND SALE TO AMENITY | J13: =C13 -> 15000000 | L13: =SUM(J13:K13)/$J$18 -> 0.065615802
B14: =B48 -> PRESALE REVENUES | C14: =C48 -> 81794306 | F14: =C14/$C$18 -> 0.09243585 | N14: =B21 -> LAND & PROJECT ACQUISITION | O14: =C21 -> 33977750 | P14: =O14/$O$25 -> 0.070704279
B15: =B49 -> UNIT SALES | C15: =C49+C79 -> 4.0967444e+08 | F15: =C15/$C$18 -> 0.46297361 | N15: =B22 -> HARD COSTS - SITE, RESTORATION & INFRASTRUCTURE | O15: =C22 -> 20734437 | P15: =O15/$O$25 -> 0.043146277
B16: =B78 -> TOTAL NET OPERATING INCOME (NOI) | C16: =C78 -> 30073583 | F16: =C16/$C$18 -> 0.033986195 | N16: =B23 -> TOTAL VERTICAL CONSTRUCTION COSTS | O16: =C23 -> 2.7232005e+08 | P16: =O16/$O$25 -> 0.56667062
B17: =B80 -> HOTEL SALE PROCEEDS / DISPOSITION | C17: =C80 -> 1.1973065e+08 | F17: =C17/$C$18 -> 0.13530776 | N17: =B24 -> SOFT COSTS PROFESSIONALS - FINAL ENTITLEMENTS & SITE INFRA. | O17: =C24 -> 13754560 | P17: =O17/$O$25 -> 0.028621856
B18: TOTAL SOURCES | C18: =SUM(C7:C17) -> 8.8487644e+08 | F18: =C18/$C$18 -> 1 | H18: =B18 -> TOTAL SOURCES | I18: =SUM(I7:I17) -> 26500000 | J18: =SUM(J7:J17) -> 2.2860347e+08 | L18: =I18/$I$18 -> 1 | N18: =B25 -> SOFT COSTS PROFESSIONALS - HOMES | O18: =C25 -> 6141551.6 | P18: =O18/$O$25 -> 0.012779951
N19: =B26 -> SOFT COSTS - SALES | O19: =C26-O24 -> 1050000 | P19: =O19/$O$25 -> 0.0021849443
B20: USES | C20: $ | D20: $/SF | E20: Per Home | F20: % Total | H20: =B20 -> USES | I20: $ | L20: % Total | N20: =B27 -> SOFT COSTS - TAXES AND INSURANCE | O20: =C27 -> 1694303.5 | P20: =O20/$O$25 -> 0.003525675
B21: =B53 -> LAND & PROJECT ACQUISITION | C21: =C53+C84 -> 33977750 | F21: =C21/$C$33 -> 0.038398299 | H21: =B21 -> LAND & PROJECT ACQUISITION | I21: =I53+I84 -> 33977750 | L21: =I21/$I$33 -> 0.14863182 | N21: =B28 -> SOFT COSTS - MUNICIPALITY FEES | O21: =C28 -> 2334431.8 | P21: =O21/$O$25 -> 0.0048577177
B22: =B54 -> HARD COSTS - SITE, RESTORATION & INFRASTRUCTURE | C22: =C54+C86 -> 20734437 | F22: =C22/$C$33 -> 0.023432014 | H22: =B22 -> HARD COSTS - SITE, RESTORATION & INFRASTRUCTURE | I22: =I54+I86 -> 13660311 | L22: =I22/$I$33 -> 0.059755485 | N22: =B29 -> DEVELOPMENT FEES | O22: =C29 -> 13294099 | P22: =O22/$O$25 -> 0.027663683
B23: =B85 -> TOTAL VERTICAL CONSTRUCTION COSTS | C23: =C55+C85 -> 2.7232005e+08 | F23: =C23/$C$33 -> 0.30774924 | H23: =B23 -> TOTAL VERTICAL CONSTRUCTION COSTS | I23: =I55+I85 -> 1.0096407e+08 | L23: =I23/$I$33 -> 0.4416559 | N23: FINANCING COSTS | O23: =O54+O85 -> 87157632 | P23: =O23/$O$25 -> 0.18136626
B24: =B56 -> SOFT COSTS PROFESSIONALS - FINAL ENTITLEMENTS & SITE INFRA. | C24: =C56+C87 -> 13754560 | F24: =C24/$C$33 -> 0.015544046 | H24: =B24 -> SOFT COSTS PROFESSIONALS - FINAL ENTITLEMENTS & SITE INFRA. | I24: =I56+I87 -> 11260236 | L24: =I24/$I$33 -> 0.049256626 | N24: POST SALE COSTS | O24: =O55+O86 -> 28102626 | P24: =O24/$O$25 -> 0.058478736
B25: =B57 -> SOFT COSTS PROFESSIONALS - HOMES | C25: =C57 -> 6141551.6 | F25: =C25/$C$33 -> 0.0069405753 | H25: =B25 -> SOFT COSTS PROFESSIONALS - HOMES | I25: =I57 -> 1162353.1 | L25: =I25/$I$33 -> 0.0050845822 | N25: TOTAL COSTS | O25: =SUM(O14:O24) -> 4.8056144e+08 | P25: =O25/$O$25 -> 1
B26: =B58 -> SOFT COSTS - SALES | C26: =C58+C88 -> 29152626 | F26: =C26/$C$33 -> 0.03294542 | H26: =B26 -> SOFT COSTS - SALES | I26: =I58+I88 -> 1375506.2 | L26: =I26/$I$33 -> 0.0060169964
B27: =B59 -> SOFT COSTS - TAXES AND INSURANCE | C27: =C59+C89 -> 1694303.5 | F27: =C27/$C$33 -> 0.0019147345 | H27: =B27 -> SOFT COSTS - TAXES AND INSURANCE | I27: =I59+I89 -> 686279.03 | L27: =I27/$I$33 -> 0.0030020499 | N27: NET PROFIT | O27: =O12-O25 -> 1.7571153e+08 | P27: =O27/O12 -> 0.26774153
B28: =B60 -> SOFT COSTS - MUNICIPALITY FEES | C28: =C60+C90 -> 2334431.8 | F28: =C28/$C$33 -> 0.0026381444 | H28: =B28 -> SOFT COSTS - MUNICIPALITY FEES | I28: =I60+I90 -> 473003.67 | L28: =I28/$I$33 -> 0.002069101
B29: =B61 -> DEVELOPMENT FEES | C29: =C61+C91 -> 13294099 | F29: =C29/$C$33 -> 0.015023679 | H29: =B29 -> DEVELOPMENT FEES | I29: =I61+I91 -> 6049088.5 | L29: =I29/$I$33 -> 0.026461053
B30: =B62 -> FINANCING COSTS & REPAYMENT | C30: =C62+C92 -> 2.6017864e+08 | F30: =C30/$C$33 -> 0.29402821 | H30: =B30 -> FINANCING COSTS & REPAYMENT | I30: =I62+I92 -> 49683122 | L30: =I30/$I$33 -> 0.21733319
B31: EB-5 SINKING FUND | C31: =C63+C93 -> 49600000 | F31: =C31/$C$33 -> 0.056053023 | L31: =I31/$I$33 -> 0
B32: =B64 -> DISTRIBUTIONS | C32: =C64+C94 -> 1.81694e+08 | F32: =C32/$C$33 -> 0.20533262 | H32: WORKING CAPITAL | I32: =I33-SUM(I21:I30) -> 9311749 | L32: =I32/$I$33 -> 0.040733192
B33: TOTAL USES | C33: =SUM(C21:C32) -> 8.8487644e+08 | F33: =C33/$C$33 -> 1 | H33: =B33 -> TOTAL USES | I33: =J18 -> 2.2860347e+08 | L33: =I33/$I$33 -> 1
F34: =C34/$C$33 -> 0
N36: CLARENDON - RESI DEVELOPMENT: PROFORMA
N37: PROFORMA - BUSINESS CASE ANALYSIS
B38: CLARENDON - RESI DEVELOPMENT: PROFORMA | H38: =B38 -> CLARENDON - RESI DEVELOPMENT: PROFORMA | O38: $ | P38: % Total
B39: PROFORMA - SOURCES & USES SUMMARY | D39: ='Proforma L+H'!$D$17 -> 158750 | E39: ='Proforma L+H'!$R$16 -> 45 | H39: PROFORMA - SOURCES & USES PRE-REVENUE (Year 0-1)
B40: SOURCES | C40: $ | D40: $/SF | E40: Per Home | F40: % Total | H40: =B40 -> SOURCES | I40: $ | J40: $/SF | K40: Per Home | L40: % Total | N40: =B47 -> LAND SALE TO AMENITY | O40: =C47 -> 15000000 | P40: =O40/$O$43 -> 0.040316553
B41: ='Proforma L+H'!B229 -> MTN ORIGINS - PURSUIT CAPITAL | C41: ='Proforma L+H'!R229 -> 1500000 | D41: =C41/'Proforma L+H'!$D$17 -> 9.4488189 | E41: =C41/'Proforma L+H'!$R$16 -> 33333.333 | F41: =C41/$C$50 -> 0.0032024503 | H41: =B41 -> MTN ORIGINS - PURSUIT CAPITAL | I41: =C41 -> 1500000 | J41: =I41/$D$39 -> 9.4488189 | K41: =I41/$E$39 -> 33333.333 | L41: =I41/$I$50 -> 0.013472764 | N41: =B48 -> PRESALE REVENUES | O41: =C48 -> 81794306 | P41: =O41/$O$43 -> 0.2198443
B42: ='Proforma L+H'!B230 -> JV - EQUITY CAPITAL | C42: ='Proforma L+H'!R230 -> 10000000 | D42: =C42/'Proforma L+H'!$D$17 -> 62.992126 | E42: =C42/'Proforma L+H'!$R$16 -> 222222.22 | F42: =C42/$C$50 -> 0.021349668 | H42: =B42 -> JV - EQUITY CAPITAL | I42: =C42 -> 10000000 | J42: =I42/$D$39 -> 62.992126 | K42: =I42/$E$39 -> 222222.22 | L42: =I42/$I$50 -> 0.089818426 | N42: =B49 -> UNIT SALES | O42: =C49 -> 2.7526131e+08 | P42: =O42/$O$43 -> 0.73983915
B43: ='Proforma L+H'!B231 -> JV BRIDGE LOAN | C43: ='Proforma L+H'!R231 -> 15000000 | D43: =C43/'Proforma L+H'!$D$17 -> 94.488189 | E43: =C43/'Proforma L+H'!$R$16 -> 333333.33 | F43: =C43/$C$50 -> 0.032024503 | H43: =B43 -> JV BRIDGE LOAN | I43: =C43 -> 15000000 | J43: =I43/$D$39 -> 94.488189 | K43: =I43/$E$39 -> 333333.33 | L43: =I43/$I$50 -> 0.13472764 | N43: TOTAL REVENUE | O43: =SUM(O40:O42) -> 3.7205562e+08 | P43: =O43/$O$43 -> 1
B44: ='Proforma L+H'!B232 -> SELLER FINANCE | C44: ='Proforma L+H'!R232 -> 0 | D44: =C44/'Proforma L+H'!$D$17 -> 0 | E44: =C44/'Proforma L+H'!$R$16 -> 0 | F44: =C44/$C$50 -> 0 | H44: =B44 -> SELLER FINANCE | I44: =C44 -> 0 | J44: =I44/$D$39 -> 0 | K44: =I44/$E$39 -> 0 | L44: =I44/$I$50 -> 0
...

Sheet COMB CASH FLOWS
B4: COMBINED MONTHLY CASH FLOWS - UNDER DEVELOPMENT

Sheet Combined Returns
B1: CLARENDON - LAND, HOME, AMENITY DEVELOPMENT
B2: Returns Analysis
B4: PROJECT FINANCING ANALYSIS | F4: BUSINESS CASE ANALYSIS
B5: TOTAL PROJECT CAPITAL NEEDS: | D5: ='Returns L+H'!D5 -> 96335729 | F5: TOTAL PROJECT REVENUE (less brokers fees): | H5: ='Returns L+H'!H5 -> 3.7205562e+08
B6: TOTAL PROJECT VALUE (PV of FINAL BUILD OUT): | D6: ='Returns L+H'!D6 -> 287850000 | F6: - TOTAL PROJECT COST: | H6: ='Returns L+H'!H6 -> 2.7367968e+08
B7: STARTING SPEC DEVELOPMENT VALUE: | D7: ='Returns L+H'!D7 -> 0 | F7: = NET PROFIT | H7: ='Returns L+H'!H7 -> 98375940
B8: EQUITY to SPEC DEV VALUE (ETV): | D8: ='Returns L+H'!D8 -> #DIV/0! | F8: NET PROFIT %: | H8: ='Returns L+H'!H8 -> 0.26441192
B9: LOAN to COST (LTC): | D9: ='Returns L+H'!D9 -> 0.88062581 | F9: RETURN on EQUITY/CAPTIAL (ROE): | H9: ='Returns L+H'!H9 -> 8.5544296
B10: LOAN to VALUE (LTV): | D10: ='Returns L+H'!D10 -> 0.055454059
B12: PROJECT RETURNS ANALYSIS
B13: PROJECT NET CASH FLOWS: | D13: ='Returns L+H'!D13 -> 98320252
B14: EQUITY MULTIPLE: | D14: ='Returns L+H'!D14 -> 9.5495871
B15: MODELED ROI: | D15: ='Returns L+H'!D15 -> 8.5495871
B16: PROJECT IRR : | D16: ='Returns L+H'!D16 -> 0.64360042
F18: ='Proforma L+H'!E3 -> 0 | G18: ='Proforma L+H'!F3 -> 1 | H18: ='Proforma L+H'!G3 -> 2 | I18: ='Proforma L+H'!H3 -> 3 | J18: ='Proforma L+H'!I3 -> 4 | K18: ='Proforma L+H'!J3 -> 5 | L18: ='Proforma L+H'!K3 -> 6 | M18: ='Proforma L+H'!L3 -> 7 | ... R18: ='Proforma L+H'!Q3 -> 12
B19: SUMMARY OF RETURNS | F19: ='Proforma L+H'!E4 -> 45658 | G19: ='Proforma L+H'!F4 -> 46023 | H19: ='Proforma L+H'!G4 -> 46388 | I19: ='Proforma L+H'!H4 -> 46753 | J19: ='Proforma L+H'!I4 -> 47119 | K19: ='Proforma L+H'!J4 -> 47484 | L19: ='Proforma L+H'!K4 -> 47849 | M19: ='Proforma L+H'!L4 -> 48214 | ... R19: ='Proforma L+H'!Q4 -> 50041
B20: JV LP Returns
B21: Capital Return | D21: =SUM(F21:R21) -> 14641000 | F21: ='Returns L+H'!F21+'Returns A+H'!F21 -> 0 | G21: ='Returns L+H'!G21+'Returns A+H'!G21 -> 0 | H21: ='Returns L+H'!H21+'Returns A+H'!H21 -> 0 | I21: ='Returns L+H'!I21+'Returns A+H'!I21 -> 0 | J21: ='Returns L+H'!J21+'Returns A+H'!J21 -> 14641000 | K21: ='Returns L+H'!K21+'Returns A+H'!K21 -> 0 | L21: ='Returns L+H'!L21+'Returns A+H'!L21 -> 0 | M21: ='Returns L+H'!M21+'Returns A+H'!M21 -> 0 | ... R21: ='Returns L+H'!R21+'Returns A+H'!R21 -> 0
B22: Profit Split | D22: =SUM(F22:R22) -> 14953795 | F22: ='Returns L+H'!F22+'Returns A+H'!F22 -> 0 | G22: ='Returns L+H'!G22+'Returns A+H'!G22 -> 0 | H22: ='Returns L+H'!H22+'Returns A+H'!H22 -> 0 | I22: ='Returns L+H'!I22+'Returns A+H'!I22 -> 0 | J22: ='Returns L+H'!J22+'Returns A+H'!J22 -> 14953795 | K22: ='Returns L+H'!K22+'Returns A+H'!K22 -> 0 | L22: ='Returns L+H'!L22+'Returns A+H'!L22 -> 4.535136e-09 | M22: ='Returns L+H'!M22+'Returns A+H'!M22 -> 0 | ... R22: ='Returns L+H'!R22+'Returns A+H'!R22 -> 0
B23: Total Distributions | D23: =SUM(F23:R23) -> 29594795 | F23: =F21+F22 -> 0 | G23: =G21+G22 -> 0 | H23: =H21+H22 -> 0 | I23: =I21+I22 -> 0 | J23: =J21+J22 -> 29594795 | K23: =K21+K22 -> 0 | L23: =L21+L22 -> 4.535136e-09 | M23: =M21+M22 -> 0 | ... R23: =R21+R22 -> 0
B24: Total Contributions | D24: =SUM(F24:R24) -> 10000000 | F24: ='Returns L+H'!F24+'Returns A+H'!F24 -> 10000000 | G24: ='Returns L+H'!G24+'Returns A+H'!G24 -> 0 | H24: ='Returns L+H'!H24+'Returns A+H'!H24 -> 0
B25: Net Profit / Cash Flows | D25: =SUM(F25:R25) -> 19594795 | F25: =F23-F24 -> -10000000 | G25: =G23-G24 -> 0 | H25: =H23-H24 -> 0 | I25: =I23-I24 -> 0 | J25: =J23-J24 -> 29594795 | K25: =K23-K24 -> 0 | L25: =L23-L24 -> 4.535136e-09 | M25: =M23-M24 -> 0 | ... R25: =R23-R24 -> 0
B26: IRR | F26: =IRR(F25:R25) -> 0.31160732
B27: Equity Multiple | F27: =SUMIF(F25:R25,">0")/-SUMIF(F25:R25,"<0") -> 2.9594795
B28: Cumulative (Equity) Cash Position | F28: =F25+E28 -> -10000000 | G28: =G25+F28 -> -10000000 | H28: =H25+G28 -> -10000000 | I28: =I25+H28 -> -10000000 | J28: =J25+I28 -> 19594795 | K28: =K25+J28 -> 19594795 | L28: =L25+K28 -> 19594795 | M28: =M25+L28 -> 19594795 | ... R28: =R25+Q28 -> 19594795
B30: MO LP Returns
B31: Capital Return + Pref | D31: =SUM(F31:R31) -> 2196150 | F31: ='Returns L+H'!F31+'Returns A+H'!F31 -> 0 | G31: ='Returns L+H'!G31+'Returns A+H'!G31 -> 0 | H31: ='Returns L+H'!H31+'Returns A+H'!H31 -> 0 | I31: ='Returns L+H'!I31+'Returns A+H'!I31 -> 0 | J31: ='Returns L+H'!J31+'Returns A+H'!J31 -> 2196150 | K31: ='Returns L+H'!K31+'Returns A+H'!K31 -> 0 | L31: ='Returns L+H'!L31+'Returns A+H'!L31 -> 0 | M31: ='Returns L+H'!M31+'Returns A+H'!M31 -> 0 | ... R31: ='Returns L+H'!R31+'Returns A+H'!R31 -> 0
B32: Profit Split | D32: =SUM(F32:R32) -> 2243069.2 | F32: ='Returns L+H'!F32+'Returns A+H'!F32 -> 0 | G32: ='Returns L+H'!G32+'Returns A+H'!G32 -> 0 | H32: ='Returns L+H'!H32+'Returns A+H'!H32 -> 0 | I32: ='Returns L+H'!I32+'Returns A+H'!I32 -> 0 | J32: ='Returns L+H'!J32+'Returns A+H'!J32 -> 2243069.2 | K32: ='Returns L+H'!K32+'Returns A+H'!K32 -> 0 | L32: ='Returns L+H'!L32+'Returns A+H'!L32 -> 6.802704e-10 | M32: ='Returns L+H'!M32+'Returns A+H'!M32 -> 0 | ... R32: ='Returns L+H'!R32+'Returns A+H'!R32 -> 0
B33: Total Distributions | D33: =SUM(F33:R33) -> 4439219.2 | F33: =SUM(F31:F32) -> 0 | G33: =SUM(G31:G32) -> 0 | H33: =SUM(H31:H32) -> 0 | I33: =SUM(I31:I32) -> 0 | J33: =SUM(J31:J32) -> 4439219.2 | K33: =SUM(K31:K32) -> 0 | L33: =SUM(L31:L32) -> 6.802704e-10 | M33: =SUM(M31:M32) -> 0 | ... R33: =SUM(R31:R32) -> 0
B34: Total Contributions | D34: =SUM(F34:R34) -> 1500000 | F34: ='Returns L+H'!F34+'Returns A+H'!F34 -> 1500000 | G34: ='Returns L+H'!G34+'Returns A+H'!G34 -> 0 | H34: ='Returns L+H'!H34+'Returns A+H'!H34 -> 0 | I34: ='Returns L+H'!I34+'Returns A+H'!I34 -> 0 | J34: ='Returns L+H'!J34+'Returns A+H'!J34 -> 0 | K34: ='Returns L+H'!K34+'Returns A+H'!K34 -> 0 | L34: ='Returns L+H'!L34+'Returns A+H'!L34 -> 0 | M34: ='Returns L+H'!M34+'Returns A+H'!M34 -> 0 | N34: ='Returns L+H'!N34+'Returns A+H'!N34 -> 0
B35: Net Profit / Cash Flows | D35: =SUM(F35:R35) -> 2939219.2 | F35: =F33-F34 -> -1500000 | G35: =G33-G34 -> 0 | H35: =H33-H34 -> 0 | I35: =I33-I34 -> 0 | J35: =J33-J34 -> 4439219.2 | K35: =K33-K34 -> 0 | L35: =L33-L34 -> 6.802704e-10 | M35: =M33-M34 -> 0 | ... R35: =R33-R34 -> 0
B36: IRR | F36: =IRR(F35:R35) -> 0.31160732
B37: Equity Multiple | F37: =SUMIF(F35:R35,">0")/-SUMIF(F35:R35,"<0") -> 2.9594795
B38: Cumulative (Equity) Cash Position | F38: =F35+E38 -> -1500000 | G38: =G35+F38 -> -1500000 | H38: =H35+G38 -> -1500000 | I38: =I35+H38 -> -1500000 | J38: =J35+I38 -> 2939219.2 | K38: =K35+J38 -> 2939219.2 | L38: =L35+K38 -> 2939219.2 | M38: =M35+L38 -> 2939219.2 | ... R38: =R35+Q38 -> 2939219.2
B40: MO/JV JV GP Returns
B41: Total Distributions | D41: =SUM(F41:R41) -> 1.4765999e+08 | F41: ='Returns L+H'!F41+'Returns A+H'!F41 -> 0 | G41: ='Returns L+H'!G41+'Returns A+H'!G41 -> 7262.0859 | H41: ='Returns L+H'!H41+'Returns A+H'!H41 -> 0 | I41: ='Returns L+H'!I41+'Returns A+H'!I41 -> 0 | J41: ='Returns L+H'!J41+'Returns A+H'!J41 -> 9943752.6 | K41: ='Returns L+H'!K41+'Returns A+H'!K41 -> 98981767 | L41: ='Returns L+H'!L41+'Returns A+H'!L41 -> 2.2351742e-09 | M41: ='Returns L+H'!M41+'Returns A+H'!M41 -> 38727204 | ... R41: ='Returns L+H'!R41+'Returns A+H'!R41 -> 0
B42: Net Profit / Cash Flows | D42: =SUM(F42:R42) -> 1.4765999e+08 | F42: =SUM(F41:F41) -> 0 | G42: =SUM(G41:G41) -> 7262.0859 | H42: =SUM(H41:H41) -> 0 | I42: =SUM(I41:I41) -> 0 | J42: =SUM(J41:J41) -> 9943752.6 | K42: =SUM(K41:K41) -> 98981767 | L42: =SUM(L41:L41) -> 2.2351742e-09 | M42: =SUM(M41:M41) -> 38727204 | ... R42: =SUM(R41:R41) -> 0
B43: JV Portion | C43: =Assumptions!K11 -> 0.4 | D43: =SUM(F43:R43) -> 59063994 | F43: =F42*$C$43 -> 0 | G43: =G42*$C$43 -> 2904.8344 | H43: =H42*$C$43 -> 0 | I43: =I42*$C$43 -> 0 | J43: =J42*$C$43 -> 3977501 | K43: =K42*$C$43 -> 39592707 | L43: =L42*$C$43 -> 8.9406967e-10 | M43: =M42*$C$43 -> 15490881 | ... R43: =R42*$C$43 -> 0
B44: MO Portion | C44: =1-C43 -> 0.6 | D44: =SUM(F44:R44) -> 88595991 | F44: =F42*$C$44 -> 0 | G44: =G42*$C$44 -> 4357.2516 | H44: =H42*$C$44 -> 0 | I44: =I42*$C$44 -> 0 | J44: =J42*$C$44 -> 5966251.6 | K44: =K42*$C$44 -> 59389060 | L44: =L42*$C$44 -> 1.3411045e-09 | M44: =M42*$C$44 -> 23236322 | ... R44: =R42*$C$44 -> 0
B46: Net Cash Flow For Distributions - TOTAL PROJECT RETURNS
...

Sheet Proforma Resi
B1: BRUNDAGE - RESI DEVELOPMENT: PROFORMA | AB1: AMU Fee | AC1: =+IF(AC2<0,-$C$193*AC2,0) -> 0 | AD1: =+IF(AD2<0,-$C$193*AD2,0) -> #REF! | AE1: =+IF(AE2<0,-$C$193*AE2,0) -> #REF! | AF1: =+IF(AF2<0,-$C$193*AF2,0) -> #REF! | AG1: =+IF(AG2<0,-$C$193*AG2,0) -> #REF! | AH1: =+IF(AH2<0,-$C$193*AH2,0) -> #REF! | AI1: =+IF(AI2<0,-$C$193*AI2,0) -> #REF! | AJ1: =+IF(AJ2<0,-$C$193*AJ2,0) -> #REF!
B2: Build & Sales Proforma | AB2: Cumulative PM (Equity) Cash Position | AC2: =+'Returns Resi'!F30 -> 0 | AD2: =+'Returns Resi'!G40 -> #REF! | AE2: =+'Returns Resi'!H40 -> #REF! | AF2: =+'Returns Resi'!I40 -> #REF! | AG2: =+'Returns Resi'!J40 -> #REF! | AH2: =+'Returns Resi'!K40 -> #REF! | AI2: =+'Returns Resi'!L40 -> #REF! | AJ2: =+'Returns Resi'!M40 -> #REF!
E3: 0 | F3: =E3+1 -> 1 | G3: =F3+1 -> 2 | H3: =G3+1 -> 3 | I3: =H3+1 -> 4 | J3: =I3+1 -> 5 | K3: =J3+1 -> 6 | L3: =K3+1 -> 7 | M3: =L3+1 -> 8 | ... Q3: =P3+1 -> 12 | AC3: Year 0 | AD3: Year 1 | AE3: Year 2 | AF3: Year 3 | AG3: Year 4 | AH3: Year 5 | AI3: Year 6 | AJ3: Year 7
E4: =Assumptions!C6 -> 2025 | F4: =E4+1 -> 2026 | G4: =F4+1 -> 2027 | H4: =G4+1 -> 2028 | I4: =H4+1 -> 2029 | J4: =I4+1 -> 2030 | K4: =J4+1 -> 2031 | L4: =K4+1 -> 2032 | M4: =L4+1 -> 2033 | ... Q4: =P4+1 -> 2037 | R4: TOTALS
C5: Average. Sqft of Lots | D5: Average Unit Size (sf) | E5: 44927 | F5: =E5+365 -> 45292 | G5: =F5+366 -> 45658 | H5: =G5+365 -> 46023 | I5: =H5+365 -> 46388 | J5: =I5+365 -> 46753 | K5: =J5+366 -> 47119 | L5: =K5+365 -> 47484 | M5: =L5+365 -> 47849 | N5: =M5+365 -> 48214 | O5: =N5+365 -> 48579 | P5: =O5+366 -> 48945 | Q5: =P5+365 -> 49310 | S5: Basis per Lot+Unit
A6: Map | B6: Buildout schedule | D6: Unit Size
B7: ='Proforma Resi'!E265 -> Phase 1: Downhill SFR | C7: 10000 | D7: ='Proforma Resi'!G265 -> 2650 | F7: 1 | G7: 1 | H7: 5 | I7: 3 | R7: =SUM(F7:Q7) -> 10 | S7: =D7*F23 -> 3776250 | T7: =R7*S7 -> 37762500 | V7: =SUMPRODUCT(D7,R7) -> 26500
B8: ='Proforma Resi'!E266 -> Phase 1: Uphill SFR | C8: 10000 | D8: ='Proforma Resi'!G266 -> 2405 | F8: 1 | G8: 2 | R8: =SUM(F8:Q8) -> 3 | S8: =D8*F24 -> 3487250 | T8: =R8*S8 -> 10461750 | V8: =SUMPRODUCT(D8,R8) -> 7215
B9: ='Proforma Resi'!E267 -> Phase 1: Uphill/Downhill Duplex | C9: 5000 | D9: ='Proforma Resi'!G267 -> 1783 | F9: 2 | G9: 8 | H9: 4 | I9: 8 | R9: =SUM(F9:Q9) -> 22 | S9: =D9*F25 -> 2451625 | T9: =R9*S9 -> 53935750 | V9: =SUMPRODUCT(D9,R9) -> 39226
B10: ='Proforma Resi'!E268 -> Phase 1: Multi-unit | C10: 5000 | D10: ='Proforma Resi'!G268 -> 1350 | G10: 4 | H10: 4 | R10: =SUM(F10:Q10) -> 8 | S10: =D10*F26 -> 1957500 | T10: =R10*S10 -> 15660000 | V10: =SUMPRODUCT(D10,R10) -> 10800
B11: Total starts | F11: =SUM(F7:F10) -> 4 | G11: =SUM(G7:G10) -> 15 | H11: =SUM(H7:H10) -> 13 | I11: =SUM(I7:I10) -> 11 | J11: =SUM(J7:J10) -> 0 | K11: =SUM(K7:K10) -> 0 | L11: =SUM(L7:L10) -> 0 | M11: =SUM(M7:M10) -> 0 | ... R11: =SUM(R7:R10) -> 43 | S11: TOTAL HOMES | T11: =SUM(T7:T10) -> 117820000 | V11: =SUMPRODUCT(D7:D10,R7:R10) -> 83741 | W11: /sf | X11: =SUM(T7:T10)/V11 -> 1406.9572 | Y11: /sf | Z11: /sf
B12: Total Sellable SQFT | C12: =SUMPRODUCT(C7:C10,R7:R10) -> 280000 | D12: =SUMPRODUCT(D7:D10,R7:R10) -> 83741 | T12: =T11/R11 -> 2740000 | U12: Average
B13: Total Sellable ACRES | C13: =C12/43560 -> 6.4279155
B15: Sales Schedule
B16: =B7 -> Phase 1: Downhill SFR | C16: =R7 -> 10 | F16: 0 | G16: =F7 -> 1 | H16: =G7 -> 1 | I16: =H7 -> 5 | J16: =I7 -> 3 | K16: =J7 -> 0 | L16: =K7 -> 0 | M16: =L7 -> 0 | N16: =M7 -> 0 | ... Q16: =P7 -> 0 | R16: =SUM(F16:Q16) -> 10 | AC16: =+_xlfn.XLOOKUP($T16,$D$23:$D$26,O$23:O$26) -> 2541.4559 | AD16: =+_xlfn.XLOOKUP($T16,$D$23:$D$26,P$23:P$26) -> 2732.0651 | AE16: =+_xlfn.XLOOKUP($T16,$D$23:$D$26,Q$23:Q$26) -> 2936.97
B17: =B8 -> Phase 1: Uphill SFR | C17: =R8 -> 3 | F17: 0 | G17: =F8 -> 1 | H17: =G8 -> 2 | I17: =H8 -> 0 | J17: =I8 -> 0 | K17: =J8 -> 0 | L17: =K8 -> 0 | M17: =L8 -> 0 | N17: =M8 -> 0 | ... Q17: =P8 -> 0 | R17: =SUM(F17:Q17) -> 3 | AC17: =+AC16 -> 2541.4559 | AD17: =+AD16 -> 2732.0651 | AE17: =+AE16 -> 2936.97
B18: =B9 -> Phase 1: Uphill/Downhill Duplex | C18: =R9 -> 22 | F18: 0 | G18: =F9 -> 2 | H18: =G9 -> 8 | I18: =H9 -> 4 | J18: =I9 -> 8 | K18: =J9 -> 0 | L18: =K9 -> 0 | M18: =L9 -> 0 | N18: =M9 -> 0 | ... Q18: =P9 -> 0 | R18: =SUM(F18:Q18) -> 22 | AC18: =+_xlfn.XLOOKUP($T18,$D$23:$D$26,O$23:O$26) -> 2541.4559 | AD18: =+_xlfn.XLOOKUP($T18,$D$23:$D$26,P$23:P$26) -> 2732.0651 | AE18: =+_xlfn.XLOOKUP($T18,$D$23:$D$26,Q$23:Q$26) -> 2936.97
B19: =B10 -> Phase 1: Multi-unit | C19: =R10 -> 8 | F19: 0 | G19: =F10 -> 0 | H19: =G10 -> 4 | I19: =H10 -> 4 | J19: =I10 -> 0 | K19: =J10 -> 0 | L19: =K10 -> 0 | M19: =L10 -> 0 | N19: =M10 -> 0 | ... Q19: =P10 -> 0 | R19: =SUM(F19:Q19) -> 8 | AC19: =+AC18 -> 2541.4559 | AD19: =+AD18 -> 2732.0651 | AE19: =+AE18 -> 2936.97
B20: Total sales | C20: =SUM(C16:C19) -> 43 | F20: =SUM(F16:F19) -> 0 | G20: =SUM(G16:G19) -> 4 | H20: =SUM(H16:H19) -> 15 | I20: =SUM(I16:I19) -> 13 | J20: =SUM(J16:J19) -> 11 | K20: =SUM(K16:K19) -> 0 | L20: =SUM(L16:L19) -> 0 | M20: =SUM(M16:M19) -> 0 | ... R20: =SUM(R16:R19) -> 43
B22: Sales Price Escalation
B23: Phase 1: Large SFR | C23: 0.075 | F23: ='Proforma Resi'!H265 -> 1425 | G23: ='Proforma Resi'!H265 -> 1425 | H23: =G23*(1+$C23) -> 1531.875 | I23: =H23*(1+$C23) -> 1646.7656 | J23: =I23*(1+$C23) -> 1770.273 | K23: =J23*(1+$C23) -> 1903.0435 | L23: =K23*(1+$C23) -> 2045.7718 | M23: =L23*(1+$C23) -> 2199.2047 | N23: =M23*(1+$C$23) -> 2364.145 | O23: =N23*(1+$C$23) -> 2541.4559 | P23: =O23*(1+$C$23) -> 2732.0651 | Q23: =P23*(1+$C$23) -> 2936.97
B24: Phase 1: Small SFR | C24: 0.075 | F24: ='Proforma Resi'!H266 -> 1450 | G24: 1450 | H24: =G24*(1+$C24) -> 1558.75 | I24: =H24*(1+$C24) -> 1675.6562 | J24: =I24*(1+$C24) -> 1801.3305 | K24: =J24*(1+$C24) -> 1936.4303 | L24: =K24*(1+$C24) -> 2081.6625 | M24: =L24*(1+$C24) -> 2237.7872 | N24: =M24*(1+$C$24) -> 2405.6213 | O24: =N24*(1+$C$24) -> 2586.0428 | P24: =O24*(1+$C$24) -> 2779.9961 | Q24: =P24*(1+$C$24) -> 2988.4958
B25: Phase 1: Small Duplex | C25: 0.075 | F25: ='Proforma Resi'!H267 -> 1375 | G25: 1375 | H25: =G25*(1+$C25) -> 1478.125 | I25: =H25*(1+$C25) -> 1588.9844 | J25: =I25*(1+$C25) -> 1708.1582 | K25: =J25*(1+$C25) -> 1836.2701 | L25: =K25*(1+$C25) -> 1973.9903 | M25: =L25*(1+$C25) -> 2122.0396 | N25: =M25*(1+$C$25) -> 2281.1926 | O25: =N25*(1+$C$25) -> 2452.282 | P25: =O25*(1+$C$25) -> 2636.2032 | Q25: =P25*(1+$C$25) -> 2833.9184
B26: Phase 1: Multi-unit | C26: 0.075 | F26: ='Proforma Resi'!H268 -> 1450 | G26: ='Proforma Resi'!H268 -> 1450 | H26: ='Proforma Resi'!H268 -> 1450 | I26: ='Proforma Resi'!H268 -> 1450 | J26: =I26*(1+$C26) -> 1558.75 | K26: =J26*(1+$C26) -> 1675.6562 | L26: =K26*(1+$C26) -> 1801.3305 | M26: =L26*(1+$C26) -> 1936.4303 | N26: =M26*(1+$C$26) -> 2081.6625 | O26: =N26*(1+$C$26) -> 2237.7872 | P26: =O26*(1+$C$26) -> 2405.6213 | Q26: =P26*(1+$C$26) -> 2586.0428
B27: Average Sales $ per Unit | G27: =IFERROR(SUM(F42+G44)/G20,"") -> 3041687.5 | H27: =IFERROR(SUM(G42+H44)/H20,"") -> 2698068.8 | I27: =IFERROR(SUM(H42+I44)/I20,"") -> 3152483.2 | J27: =IFERROR(SUM(I42+J44)/J20,"") -> 3494439.9 | K27: =IFERROR(SUM(J42+K44)/K20,"") | L27: =IFERROR(SUM(K42+L44)/L20,"") | M27: =IFERROR(SUM(L42+M44)/M20,"") | N27: =IFERROR(SUM(M42+N44)/N20,"") | ... Q27: =IFERROR(SUM(P42+Q44)/Q20,"")
B28: SOURCES | T28: Loan / Equity Financing | W28: Project Financing Metrics
B29: CM - PURSUIT CAPITAL | E29: 75000 | L29: 0 | R29: =SUM(E29:Q29) -> 75000 | T29: Year 0-2 Dev Cost | U29: =SUM(E197:G197) -> #REF! | V29: Actual | W29: VALUE OF SPEC DEV | Y29: =SUMPRODUCT(D7:D10,F7:F10,F23:F26) -> 12166750
B30: PM1 - EQUITY CONTRIBUTION (LAND) | F30: $11.7M in LAND CONTRIBUTION SHOWN ON BALANCE SHEET OF DEV LLC | T30: Financing Cost Gross-Up | U30: =U29*(1+Assumptions!#REF!) -> #REF! | V30: =U29+SUMIF(E3:Q3,"<="&Assumptions!G6,'Proforma Resi'!E201:Q201)+R202 -> #REF! | W30: ETV | Y30: =(R32)/Y29 -> #REF!
B31: PM2 - EQUITY (CASH) | F31: =U34-SUM(E29:F29) -> #REF! | L31: 0 | R31: =SUM(E31:Q31) -> #REF! | T31: Year 0-2 Unit Sales | U31: =SUM(E44:G44) -> 12166750 | W31: LTV | Y31: =R35/(Y29+R64+F72+G72) -> #REF!
B32: EQUITY / PROJECT ACQUISITION + ENTITLEMENT | E32: =SUM(E29:E31) -> 75000 | F32: =SUM(F29:F31) -> #REF! | G32: =SUM(G29:G31) -> 0 | H32: =SUM(H29:H31) -> 0 | I32: =SUM(I29:I31) -> 0 | J32: =SUM(J29:J31) -> 0 | K32: =SUM(K29:K31) -> 0 | L32: =SUM(L29:L31) -> 0 | ... R32: =SUM(R29:R31) -> #REF! | T32: LTC | U32: =Assumptions!F7 -> 0.6 | W32: LTC Total (INCL LAND VALUE) | Y32: =(R35/(R58+R32+R35)) -> #REF!
T33: Loan Amount | U33: =U30*U32 -> #REF! | V33: Actual
B34: Development Loan | C34: =U33 -> #REF! | E34: 0 | F34: =MAX(F197-F32-F44-E230,0) -> #REF! | G34: =MAX(G197-G32-G44-F230,0) -> #REF! | H34: =MAX(H197-H32-H44-G230,0) -> #REF! | I34: =MAX(I197-I32-I44-H230,0) -> #REF! | J34: =MAX(J197-J32-J44-I230,0) -> #REF! | K34: =MAX(K197-K32-K44-J230,0) -> #REF! | L34: =MAX(L197-L32-L44-K230,0) -> #REF! | M34: =MAX(M197-M32-M44-L230,0) -> #REF! | O34: =MAX(O197-O32-O44-N230,0) -> #REF! | P34: =MAX(P197-P32-P44-O230,0) -> #REF! | Q34: =MAX(Q197-Q32-Q44-P230,0) -> #REF! | R34: =SUM(E34:Q34) -> #REF! | T34: Initial Equity | U34: =U30-U33-C56*0.89 -> #REF! | V34: =U34+C56 -> #REF!
B35: DEBT | E35: =SUM(E34:E34) -> 0 | F35: =SUM(F34:F34) -> #REF! | G35: =SUM(G34:G34) -> #REF! | H35: =SUM(H34:H34) -> #REF! | I35: =SUM(I34:I34) -> #REF! | J35: =SUM(J34:J34) -> #REF! | K35: =SUM(K34:K34) -> #REF! | L35: =SUM(L34:L34) -> #REF! | ... Q35: =SUM(Q34:Q34) -> #REF! | R35: =SUM(E35:Q35) -> #REF!
B37: Construction Start Draw
B38: Foundation Complete Draw
B39: Structure Complete Draw
B40: MEP 4-way Draw
B41: Finishes Start Draw
B42: PRESALE REVENUES | C42: =SUM(C37:C41) -> 0 | E42: =SUM(E37:E41) -> 0 | F42: =SUM(F37:F41) -> 0 | G42: =SUM(G37:G41) -> 0 | H42: =SUM(H37:H41) -> 0 | I42: =SUM(I37:I41) -> 0 | J42: =SUM(J37:J41) -> 0 | K42: =SUM(K37:K41) -> 0 | L42: =SUM(L37:L41) -> 0 | ... P42: =SUM(P37:P41) -> 0 | R42: =SUM(E42:Q42) -> 0 | T42: TOTAL HOME SALES
B43: INFRASTRUCTURE REPAYMENT FROM HOTEL PROFORMA | H43: ='Proforma A+H'!#REF! -> #REF!
...

Sheet Returns Resi
B1: BRUNDAGE - Resi DEVELOPMENT: RETURNS
B2: Returns Analysis
B4: PROJECT FINANCING ANALYSIS | F4: PROJECT RETURNS ANALYSIS | J4: SENSITIVITY ANALYSIS - PROJECT-LEVEL RETURNS, LEVERED
B5: TOTAL PROJECT CAPITAL NEEDS | D5: =SUM('Proforma Resi'!R32,'Proforma Resi'!R35) -> #REF! | F5: TOTAL RETURN | H5: =D54 -> #REF!
B6: TOTAL PROJECT VALUE (PV of FINAL BUILD OUT) | D6: ='Proforma Resi'!T11 -> 117820000 | F6: INVESTED CAPITAL | H6: =D55 -> #REF! | J6: Metric: | K6: IRR | L6: Sales Price Scalar
B7: STARTING SPEC DEVELOPMENT VALUE | D7: ='Proforma Resi'!G44+'Proforma Resi'!F42 -> 12166750 | F7: NET PROFIT | H7: =D56 -> #REF! | J7: Vertical Const. Costs Scalar | K7: =SUMIF(F5:F10,K6,H5:H10) -> #REF! | L7: =M7-10% -> 0.8 | M7: =N7-10% -> 0.9 | N7: 1 | O7: =N7+10% -> 1.1 | P7: =O7+10% -> 1.2
B8: EQUITY to SPEC DEV VALUE (ETV) | D8: ='Proforma Resi'!Y30 -> #REF! | F8: EQUITY MULTIPLE | H8: =H5/H6 -> #REF! | K8: =K9-10% -> 0.8 | L8: #REF! | M8: #REF! | N8: #REF! | O8: #REF! | P8: #REF!
B9: LOAN to COST (LTC) | D9: ='Proforma Resi'!Y32 -> #REF! | F9: ROI | H9: =H7/H6 -> #REF! | K9: =K10-10% -> 0.9 | L9: #REF! | M9: #REF! | N9: #REF! | O9: #REF! | P9: #REF!
B10: LOAN to VALUE (LTV) | D10: ='Proforma Resi'!Y31 -> #REF! | F10: IRR | H10: =XIRR(F56:N56,F20:N20) -> #REF! | K10: 1 | L10: #REF! | M10: #REF! | N10: #REF! | O10: #REF! | P10: #REF!
K11: =K10+10% -> 1.1 | L11: #REF! | M11: #REF! | N11: #REF! | O11: #REF! | P11: #REF!
B12: BUSINESS CASE ANALYSIS | K12: =K11+10% -> 1.2 | L12: #REF! | M12: #REF! | N12: #REF! | O12: #REF! | P12: #REF!
B13: TOTAL PROJECT REVENUE (less brokers fees): | D13: =('Proforma Resi'!R44+'Proforma Resi'!R42)-'Proforma Resi'!R172 -> 1.2545596e+08 | J13: Current Assumptions
B14: - TOTAL PROJECT COST | D14: ='Proforma Resi'!R197-'Proforma Resi'!R172+'Proforma Resi'!R202+'Proforma Resi'!R201 -> #REF! | J14: Vertical Const. Costs Scalar | L14: 1
B15: = NET PROFIT | D15: =D13-D14 -> #REF! | J15: Sales Price Scalar | L15: 1
B16: NET PROFIT %: | D16: =D15/D13 -> #REF!
B17: RETURN on EQUITY/CAPTIAL (ROE): | D17: =D15/H6 -> #REF!
F18: ='Proforma Resi'!E3 -> 0 | G18: ='Proforma Resi'!F3 -> 1 | H18: ='Proforma Resi'!G3 -> 2 | I18: ='Proforma Resi'!H3 -> 3 | J18: ='Proforma Resi'!I3 -> 4 | K18: ='Proforma Resi'!J3 -> 5 | L18: ='Proforma Resi'!K3 -> 6 | M18: ='Proforma Resi'!L3 -> 7 | ... R18: ='Proforma Resi'!Q3 -> 12
F19: =Assumptions!C6 -> 2025 | G19: =F19+1 -> 2026 | H19: =G19+1 -> 2027 | I19: =H19+1 -> 2028 | J19: =I19+1 -> 2029 | K19: =J19+1 -> 2030 | L19: =K19+1 -> 2031 | M19: =L19+1 -> 2032 | N19: =M19+1 -> 2033 | ... R19: =Q19+1 -> 2037
B20: SUMMARY OF RETURNS | F20: =DATE(F19,12,31) -> 46022 | G20: =EDATE(F20,12) -> 46387 | H20: =EDATE(G20,12) -> 46752 | I20: =EDATE(H20,12) -> 47118 | J20: =EDATE(I20,12) -> 47483 | K20: =EDATE(J20,12) -> 47848 | L20: =EDATE(K20,12) -> 48213 | M20: =EDATE(L20,12) -> 48579 | N20: =EDATE(M20,12) -> 48944 | ... R20: =EDATE(Q20,12) -> 50405
B21: Preferred Members 1 (PM1) Returns
B22: Land Repayment | D22: =SUM(F22:R22) -> 15000000 | F22: ='Proforma Resi'!E50+'Proforma Resi'!E54 -> 0 | G22: ='Proforma Resi'!F50+'Proforma Resi'!F54 -> 3000000 | H22: ='Proforma Resi'!G50+'Proforma Resi'!G54 -> 1703345 | I22: ='Proforma Resi'!H50+'Proforma Resi'!H54 -> 5665944.4 | J22: ='Proforma Resi'!I50+'Proforma Resi'!I54 -> 4630710.6 | K22: ='Proforma Resi'!J50+'Proforma Resi'!J54 -> 0 | L22: ='Proforma Resi'!K50+'Proforma Resi'!K54 -> 0 | M22: ='Proforma Resi'!L50+'Proforma Resi'!L54 -> 0 | ... R22: ='Proforma Resi'!Q50+'Proforma Resi'!Q54 -> 0
B23: Interest | D23: =SUM(F23:R23) -> #REF! | F23: ='Proforma Resi'!E57 -> 0 | G23: ='Proforma Resi'!F57 -> #REF! | H23: ='Proforma Resi'!G57 -> #REF! | I23: ='Proforma Resi'!H57 -> #REF! | J23: ='Proforma Resi'!I57 -> #REF! | K23: ='Proforma Resi'!J57 -> #REF! | L23: ='Proforma Resi'!K57 -> #REF! | M23: ='Proforma Resi'!L57 -> #REF! | ... R23: ='Proforma Resi'!Q57 -> #REF!
B24: ="Additional Profit Split ("&TEXT(Assumptions!#REF!,"0%")&")" -> #REF! | D24: =SUM(F24:R24) -> #REF! | F24: ='Proforma Resi'!E223 -> 0 | G24: ='Proforma Resi'!F223 -> #REF! | H24: ='Proforma Resi'!G223 -> #REF! | I24: ='Proforma Resi'!H223 -> #REF! | J24: ='Proforma Resi'!I223 -> #REF! | K24: ='Proforma Resi'!J223 -> #REF! | L24: ='Proforma Resi'!K223 -> #REF! | M24: ='Proforma Resi'!L223 -> #REF! | ... R24: ='Proforma Resi'!Q223 -> #REF!
B25: Total PM Distributions | D25: =SUM(F25:R25) -> #REF! | F25: =SUM(F22:F24) -> 0 | G25: =SUM(G22:G24) -> #REF! | H25: =SUM(H22:H24) -> #REF! | I25: =SUM(I22:I24) -> #REF! | J25: =SUM(J22:J24) -> #REF! | K25: =SUM(K22:K24) -> #REF! | L25: =SUM(L22:L24) -> #REF! | M25: =SUM(M22:M24) -> #REF! | ... R25: =SUM(R22:R24) -> #REF!
B26: Total PM Contributions | D26: =SUM(F26:R26) -> 15000000 | G26: ='Proforma Resi'!C56 -> 15000000 | H26: 0 | I26: 0 | J26: 0 | K26: 0 | L26: 0 | M26: 0 | N26: 0 | O26: 0 | P26: 0 | Q26: 0 | R26: 0
B27: PM Net Profit / Cash Flows | D27: =SUM(F27:R27) -> #REF! | F27: =F25-F26 -> 0 | G27: =G25-G26 -> #REF! | H27: =H25-H26 -> #REF! | I27: =I25-I26 -> #REF! | J27: =J25-J26 -> #REF! | K27: =K25-K26 -> #REF! | L27: =L25-L26 -> #REF! | M27: =M25-M26 -> #REF! | ... R27: =R25-R26 -> #REF!
B28: PM IRR | F28: =XIRR(G27:R27,G20:R20) -> #REF!
B29: PM Equity Multiple | F29: =SUMIF(F27:R27,">0")/-SUMIF(F27:R27,"<0") -> #DIV/0!
B30: Cumulative PM (Equity) Cash Position | F30: =F27+E30 -> 0 | G30: =G27+F30 -> #REF! | H30: =H27+G30 -> #REF! | I30: =I27+H30 -> #REF! | J30: =J27+I30 -> #REF! | K30: =K27+J30 -> #REF! | L30: =L27+K30 -> #REF! | M30: =M27+L30 -> #REF! | ... R30: =R27+Q30 -> #REF!
B32: Preferred Members 2 (PM2) Returns
B33: Preferred Returns | D33: =SUM(F33:R33) -> 0 | F33: ='Proforma Resi'!E221 -> 0 | G33: ='Proforma Resi'!F221 -> 0 | H33: ='Proforma Resi'!G221 -> 0 | I33: ='Proforma Resi'!H221 -> 0 | J33: ='Proforma Resi'!I221 -> 0 | K33: ='Proforma Resi'!J221 -> 0 | L33: ='Proforma Resi'!K221 -> 0 | M33: ='Proforma Resi'!L221 -> 0 | ... R33: ='Proforma Resi'!Q221 -> 0
B34: ="Additional Profit Split ("&TEXT(Assumptions!#REF!,"0%")&")" -> #REF! | D34: =SUM(F34:R34) -> #REF! | F34: ='Proforma Resi'!E224 -> 0 | G34: ='Proforma Resi'!F224 -> #REF! | H34: ='Proforma Resi'!G224 -> #REF! | I34: ='Proforma Resi'!H224 -> #REF! | J34: ='Proforma Resi'!I224 -> #REF! | K34: ='Proforma Resi'!J224 -> #REF! | L34: ='Proforma Resi'!K224 -> #REF! | M34: ='Proforma Resi'!L224 -> #REF! | ... R34: ='Proforma Resi'!Q224 -> #REF!
B35: Total PM Distributions | D35: =SUM(F35:R35) -> #REF! | F35: =SUM(F33:F34) -> 0 | G35: =SUM(G33:G34) -> #REF! | H35: =SUM(H33:H34) -> #REF! | I35: =SUM(I33:I34) -> #REF! | J35: =SUM(J33:J34) -> #REF! | K35: =SUM(K33:K34) -> #REF! | L35: =SUM(L33:L34) -> #REF! | M35: =SUM(M33:M34) -> #REF! | ... R35: =SUM(R33:R34) -> #REF!
B36: Total PM Contributions | D36: =SUM(F36:R36) -> #REF! | F36: ='Proforma Resi'!E31 -> 0 | G36: ='Proforma Resi'!F31 -> #REF! | H36: ='Proforma Resi'!G31 -> 0 | I36: ='Proforma Resi'!H31 -> 0 | J36: ='Proforma Resi'!I31 -> 0 | K36: ='Proforma Resi'!J31 -> 0 | L36: ='Proforma Resi'!K31 -> 0 | M36: ='Proforma Resi'!L31 -> 0 | ... R36: ='Proforma Resi'!Q31 -> 0
B37: PM Net Profit / Cash Flows | D37: =SUM(F37:R37) -> #REF! | F37: =F35-F36 -> 0 | G37: =G35-G36 -> #REF! | H37: =H35-H36 -> #REF! | I37: =I35-I36 -> #REF! | J37: =J35-J36 -> #REF! | K37: =K35-K36 -> #REF! | L37: =L35-L36 -> #REF! | M37: =M35-M36 -> #REF! | ... R37: =R35-R36 -> #REF!
B38: PM IRR | F38: =XIRR(G37:R37,G20:R20) -> #REF!
B39: PM Equity Multiple | F39: =SUMIF(F37:R37,">0")/-SUMIF(F37:R37,"<0") -> #DIV/0!
B40: Cumulative PM (Equity) Cash Position | F40: =F37+E40 -> 0 | G40: =G37+F40 -> #REF! | H40: =H37+G40 -> #REF! | I40: =I37+H40 -> #REF! | J40: =J37+I40 -> #REF! | K40: =K37+J40 -> #REF! | L40: =L37+K40 -> #REF! | M40: =M37+L40 -> #REF! | ... R40: =R37+Q40 -> #REF!
B42: Common Members (CM) Returns
B43: ="CM Profit Split ("&TEXT(Assumptions!#REF!,"0%")&")" -> #REF! | D43: =SUM(F43:R43) -> #REF! | F43: ='Proforma Resi'!E225 -> 0 | G43: ='Proforma Resi'!F225 -> #REF! | H43: ='Proforma Resi'!G225 -> #REF! | I43: ='Proforma Resi'!H225 -> #REF! | J43: ='Proforma Resi'!I225 -> #REF! | K43: ='Proforma Resi'!J225 -> #REF! | L43: ='Proforma Resi'!K225 -> #REF! | M43: ='Proforma Resi'!L225 -> #REF! | ... R43: ='Proforma Resi'!Q225 -> #REF!
...

Sheet Proforma L+H
B1: CLARENDON - LAND & HOME DEVELOPMENT | AC1: Year 0 | AD1: Year 1 | AE1: Year 2 | AF1: Year 3 | AG1: Year 4 | AH1: Year 5 | AI1: Year 6 | AJ1: Year 7
B2: Build & Sales Proforma
E3: 0 | F3: =E3+1 -> 1 | G3: =F3+1 -> 2 | H3: =G3+1 -> 3 | I3: =H3+1 -> 4 | J3: =I3+1 -> 5 | K3: =J3+1 -> 6 | L3: =K3+1 -> 7 | M3: =L3+1 -> 8 | ... Q3: =P3+1 -> 12 | Z3: Checks | AA3: =SUM(AA4:AA223) -> #REF!
D4: Year Beginning | E4: =Assumptions!C5 -> 45658 | F4: =EDATE(E4,12) -> 46023 | G4: =EDATE(F4,12) -> 46388 | H4: =EDATE(G4,12) -> 46753 | I4: =EDATE(H4,12) -> 47119 | J4: =EDATE(I4,12) -> 47484 | K4: =EDATE(J4,12) -> 47849 | L4: =EDATE(K4,12) -> 48214 | M4: =EDATE(L4,12) -> 48580 | ... Q4: =EDATE(P4,12) -> 50041 | S4: Basis per Lot+Unit
A5: Map | B5: Buildout schedule | D5: Avg Unit Size
A6: A- | B6: Pondside Cabins @ Event Barn (13ea) | D6: 1500 | R6: =SUM(F6:Q6) -> 0 | S6: =D6*$E$33 -> 2850000 | T6: =R6*S6 -> 0 | V6: =#REF!*#REF! -> #REF!
A7: B- | B7: Village Cabins (13ea) | D7: 2000 | R7: =SUM(F7:Q7) -> 0 | S7: =D7*$E$33 -> 3800000 | T7: =R7*S7 -> 0
A8: C- | B8: Village Cottages (13ea) | D8: 2500 | R8: =SUM(F8:Q8) -> 0 | S8: =D8*$E$33 -> 4750000 | T8: =R8*S8 -> 0
A9: D- | B9: Guest Cabins @ Fitness Spa (13ea) | D9: 2500 | R9: =SUM(F9:Q9) -> 0 | S9: =D9*$E$33 -> 4750000 | T9: =R9*S9 -> 0
A10: F- | B10: Jimmy Creek Homes (4ea) | D10: 3500 | F10: 4 | R10: =SUM(E10:Q10) -> 4 | S10: =D10*$E$31 -> 6300000 | T10: =R10*S10 -> 25200000
A11: G- | B11: Bench Homesites (15ea) | D11: 3250 | G11: 10 | H11: 5 | R11: =SUM(E11:Q11) -> 15 | S11: =D11*$E$31 -> 5850000 | T11: =R11*S11 -> 87750000
A12: H- | B12: Forest Homesites (10ea) | D12: 3750 | H12: 10 | R12: =SUM(E12:Q12) -> 10 | S12: =D12*$E$31 -> 6750000 | T12: =R12*S12 -> 67500000 | U12: Improved Value Before Escalation
A13: J- | B13: Hillside Homesites (10ea) | D13: 3750 | I13: 10 | R13: =SUM(E13:Q13) -> 10 | S13: =D13*$E$31 -> 6750000 | T13: =R13*S13 -> 67500000
A14: E- | B14: Village Homesites (6ea) | D14: 4500 | R14: =SUM(E14:Q14) -> 0 | S14: =D14*$E$32 -> 7425000 | T14: =R14*S14 -> 0
A15: K- | B15: Deer Creek Homesites (5ea + 1 lot used for Clubhouse) | D15: 3500 | F15: 1 | I15: 5 | R15: =SUM(E15:Q15) -> 6 | S15: =D15*$E$33 -> 6650000 | T15: =R15*S15 -> 39900000
B16: Total starts | E16: =SUM(E6:E15) -> 0 | F16: =SUM(F6:F15) -> 5 | G16: =SUM(G6:G15) -> 10 | H16: =SUM(H6:H15) -> 15 | I16: =SUM(I6:I15) -> 15 | J16: =SUM(J6:J15) -> 0 | K16: =SUM(K6:K15) -> 0 | L16: =SUM(L6:L15) -> 0 | ... R16: =SUM(R6:R15) -> 45 | S16: TOTAL HOMES | T16: =SUM(T6:T15) -> 287850000 | V16: =SUMPRODUCT(D6:D15,R6:R15) -> 158750 | W16: sf | X16: =SUM(T6:T15)/V16 -> 1813.2283 | Y16: /sf | Z16: /sf
B17: Total Sellable SQFT | D17: =SUMPRODUCT(D6:D15,R6:R15) -> 158750 | T17: =T16/R16 -> 6396666.7 | U17: Average | V17: =D17/R16 -> 3527.7778
B19: Sales Schedule | U19: Year 1 | V19: Year 2 | W19: Year 3 | X19: Year 4 | Y19: Year 5 | Z19: Year 6 | AA19: Year 7
B20: =B6 -> Pondside Cabins @ Event Barn (13ea) | C20: =R6 -> 0 | D20: =T20 -> Cottages | G20: =F6 -> 0 | H20: =G6 -> 0 | I20: =H6 -> 0 | J20: =I6 -> 0 | K20: =J6 -> 0 | L20: =K6 -> 0 | M20: =L6 -> 0 | N20: =M6 -> 0 | ... Q20: =P6 -> 0 | R20: =SUM(F20:Q20) -> 0 | T20: Cottages | U20: =+F33 -> 1900 | V20: =+G33 -> 1900 | W20: =+H33 -> 2090 | X20: =+I33 -> 2299 | Y20: =+J33 -> 2528.9 | Z20: =+K33 -> 2781.79 | AA20: {=+L33:P33} -> 3059.969 | AB20: 3365.9659 | AC20: 3702.5625 | AD20: 4072.8187 | AE20: 4480.1006
B21: =B7 -> Village Cabins (13ea) | C21: =R7 -> 0 | D21: =T21 -> Cottages | G21: =F7 -> 0 | H21: =G7 -> 0 | I21: =H7 -> 0 | J21: =I7 -> 0 | K21: =J7 -> 0 | L21: =K7 -> 0 | M21: =L7 -> 0 | N21: =M7 -> 0 | ... Q21: =P7 -> 0 | R21: =SUM(F21:Q21) -> 0 | T21: Cottages | U21: =+U20 -> 1900 | V21: =+V20 -> 1900 | W21: =+W20 -> 2090 | X21: =+X20 -> 2299 | Y21: =+Y20 -> 2528.9 | Z21: =+Z20 -> 2781.79 | AA21: =+AA20 -> 3059.969
B22: =B8 -> Village Cottages (13ea) | C22: =R8 -> 0 | D22: =T22 -> Cottages | G22: =F8 -> 0 | H22: =G8 -> 0 | I22: =H8 -> 0 | J22: =I8 -> 0 | K22: =J8 -> 0 | L22: =K8 -> 0 | M22: =L8 -> 0 | N22: =M8 -> 0 | ... Q22: =P8 -> 0 | R22: =SUM(F22:Q22) -> 0 | T22: Cottages | U22: =+U21 -> 1900 | V22: =+V21 -> 1900 | W22: =+W21 -> 2090 | X22: =+X21 -> 2299 | Y22: =+Y21 -> 2528.9 | Z22: =+Z21 -> 2781.79 | AA22: =+AA21 -> 3059.969
B23: =B9 -> Guest Cabins @ Fitness Spa (13ea) | C23: =R9 -> 0 | D23: =T23 -> Cottages | G23: =F9 -> 0 | H23: =G9 -> 0 | I23: =H9 -> 0 | J23: =I9 -> 0 | K23: =J9 -> 0 | L23: =K9 -> 0 | M23: =L9 -> 0 | N23: =M9 -> 0 | ... Q23: =P9 -> 0 | R23: =SUM(F23:Q23) -> 0 | T23: Cottages | U23: =+U22 -> 1900 | V23: =+V22 -> 1900 | W23: =+W22 -> 2090 | X23: =+X22 -> 2299 | Y23: =+Y22 -> 2528.9 | Z23: =+Z22 -> 2781.79 | AA23: =+AA22 -> 3059.969
B24: =B10 -> Jimmy Creek Homes (4ea) | C24: =R10 -> 4 | D24: =T24 -> Village | F24: =E10 -> 0 | G24: =F10 -> 4 | H24: =G10 -> 0 | I24: =H10 -> 0 | J24: =I10 -> 0 | K24: =J10 -> 0 | L24: =K10 -> 0 | M24: =L14 -> 0 | N24: =M14 -> 0 | O24: =N14 -> 0 | P24: =O14 -> 0 | Q24: =P14 -> 0 | R24: =SUM(F24:Q24) -> 4 | T24: Village | U24: =+F31 -> 1800 | V24: =+G32 -> 1773.75 | W24: =+H32 -> 1906.7812 | X24: =+I32 -> 2049.7898 | Y24: =+J32 -> 2203.5241 | Z24: =+K32 -> 2368.7884 | AA24: =+L32 -> 2546.4475
B25: =B11 -> Bench Homesites (15ea) | C25: =R11 -> 15 | D25: =T25 -> Homesites | F25: =E11 -> 0 | G25: =F11 -> 0 | H25: =G11 -> 10 | I25: =H11 -> 5 | J25: =I11 -> 0 | K25: =J11 -> 0 | L25: =K11 -> 0 | M25: =L10 -> 0 | N25: =M10 -> 0 | O25: =N10 -> 0 | P25: =O10 -> 0 | Q25: =P10 -> 0 | R25: =SUM(F25:Q25) -> 15 | T25: Homesites | U25: =+F31 -> 1800 | V25: =+G31 -> 1800 | W25: =+H31 -> 1980 | X25: =+I31 -> 2178 | Y25: =+J31 -> 2395.8 | Z25: =+K31 -> 2635.38 | AA25: =+L31 -> 2898.918
B26: =B12 -> Forest Homesites (10ea) | C26: =R12 -> 10 | D26: =T26 -> Homesites | F26: =E12 -> 0 | G26: =F12 -> 0 | H26: =G12 -> 0 | I26: =H12 -> 10 | J26: =I12 -> 0 | K26: =J12 -> 0 | L26: =K12 -> 0 | M26: =L11 -> 0 | N26: =M11 -> 0 | O26: =N11 -> 0 | P26: =O11 -> 0 | Q26: =P11 -> 0 | R26: =SUM(F26:Q26) -> 10 | T26: Homesites | U26: =+U25 -> 1800 | V26: =+V25 -> 1800 | W26: =+W25 -> 1980 | X26: =+X25 -> 2178 | Y26: =+Y25 -> 2395.8 | Z26: =+Z25 -> 2635.38 | AA26: =+AA25 -> 2898.918
B27: =B13 -> Hillside Homesites (10ea) | C27: =R13 -> 10 | D27: =T27 -> Homesites | F27: =E13 -> 0 | G27: =F13 -> 0 | H27: =G13 -> 0 | I27: =H13 -> 0 | J27: =I13 -> 10 | K27: =J13 -> 0 | L27: =K13 -> 0 | M27: =L13 -> 0 | ... P27: =O13 -> 0 | Q27: =P12 -> 0 | R27: =SUM(F27:Q27) -> 10 | T27: Homesites | U27: =+U26 -> 1800 | V27: =+V26 -> 1800 | W27: =+W26 -> 1980 | X27: =+X26 -> 2178 | Y27: =+Y26 -> 2395.8 | Z27: =+Z26 -> 2635.38 | AA27: =+AA26 -> 2898.918
B28: =B14 -> Village Homesites (6ea) | C28: =R14 -> 0 | D28: =T28 -> Homesites | F28: =E14 -> 0 | G28: =F14 -> 0 | H28: =G14 -> 0 | I28: =H14 -> 0 | J28: =I14 -> 0 | K28: =J14 -> 0 | L28: =K14 -> 0 | M28: =L13 -> 0 | N28: =M13 -> 0 | O28: =N13 -> 0 | P28: =O13 -> 0 | Q28: =P13 -> 0 | R28: =SUM(F28:Q28) -> 0 | T28: Homesites | U28: =+U27 -> 1800 | V28: =+V27 -> 1800 | W28: =+W27 -> 1980 | X28: =+X27 -> 2178 | Y28: =+Y27 -> 2395.8 | Z28: =+Z27 -> 2635.38 | AA28: =+AA27 -> 2898.918
B29: =B15 -> Deer Creek Homesites (5ea + 1 lot used for Clubhouse) | C29: =R15 -> 6 | D29: =T29 -> Cottages | F29: =E15 -> 0 | G29: =F15 -> 1 | H29: =G15 -> 0 | I29: =H15 -> 0 | J29: =I15 -> 5 | K29: =J15 -> 0 | L29: =K15 -> 0 | M29: =L15 -> 0 | ... Q29: =P15 -> 0 | R29: =SUM(F29:Q29) -> 6 | T29: Cottages | U29: =+U23 -> 1900 | V29: =+V23 -> 1900 | W29: =+W23 -> 2090 | X29: =+X23 -> 2299 | Y29: =+Y23 -> 2528.9 | Z29: =+Z23 -> 2781.79 | AA29: =+AA23 -> 3059.969
B30: Total sales | C30: =SUM(C20:C29) -> 45 | F30: =SUM(F20:F29) -> 0 | G30: =SUM(G20:G29) -> 5 | H30: =SUM(H20:H29) -> 10 | I30: =SUM(I20:I29) -> 15 | J30: =SUM(J20:J29) -> 15 | K30: =SUM(K20:K29) -> 0 | L30: =SUM(L20:L29) -> 0 | M30: =SUM(M20:M29) -> 0 | ... R30: =SUM(R20:R29) -> 45 | Z30: Check on Sales & Build out | AA30: =+R16-R30 -> 0
B31: Sales Price Escalation / Residential Sales Sqft Price | C31: =Assumptions!H18 -> 0.1 | D31: Homesites | E31: 1800 | F31: =E31 -> 1800 | G31: =F31 -> 1800 | H31: =G31*(1+$C$31) -> 1980 | I31: =H31*(1+$C$31) -> 2178 | J31: =I31*(1+$C$31) -> 2395.8 | K31: =J31*(1+$C$31) -> 2635.38 | L31: =K31*(1+$C$31) -> 2898.918 | M31: =L31*(1+$C$31) -> 3188.8098 | N31: =M31*(1+$C$31) -> 3507.6908 | O31: =N31*(1+$C$31) -> 3858.4599 | ... Q31: =P31*(1+$C$31) -> 4668.7364
B32: Sales Price Escalation / Residential Sales Sqft Price | C32: =Assumptions!H19 -> 0.075 | D32: Village | E32: =Assumptions!G19 -> 1650 | F32: =E32 -> 1650 | G32: =F32*(1+$C$32) -> 1773.75 | H32: =G32*(1+$C$32) -> 1906.7812 | I32: =H32*(1+$C$32) -> 2049.7898 | J32: =I32*(1+$C$32) -> 2203.5241 | K32: =J32*(1+$C$32) -> 2368.7884 | L32: =K32*(1+$C$32) -> 2546.4475 | M32: =L32*(1+$C$32) -> 2737.4311 | N32: =M32*(1+$C$32) -> 2942.7384 | ... Q32: =P32*(1+$C$32) -> 3655.7547
B33: Sales Price Escalation / Residential Sales Sqft Price | C33: 0.1 | D33: Cottages | E33: 1900 | F33: =E33 -> 1900 | G33: =F33 -> 1900 | H33: =G33*(1+$C$33) -> 2090 | I33: =H33*(1+$C$33) -> 2299 | J33: =I33*(1+$C$33) -> 2528.9 | K33: =J33*(1+$C$33) -> 2781.79 | L33: =K33*(1+$C$33) -> 3059.969 | M33: =L33*(1+$C$33) -> 3365.9659 | N33: =M33*(1+$C$33) -> 3702.5625 | O33: =N33*(1+$C$33) -> 4072.8187 | ... Q33: =P33*(1+$C$33) -> 4928.1107 | U33: Average Res Unit Sales Price
F34: Average Sales $ per Unit | H34: =SUM(G56+H57)/H30 -> 6435000 | I34: =SUM(H56+I57)/I30 -> 7804500 | J34: =SUM(I56+J57)/J30 -> 8939883.3 | R34: TOTALS | T34: =(R56+R57)/R16 -> 7934569.3 | W34: =T34/T17 -> 1.2404225
B35: SOURCES
L36: 0 | R36: =SUM(E36:Q36) -> 0
B37: EQUITY INVESTMENT | L37: 0 | R37: =SUM(E37:Q37) -> 0 | T37: {=SUMPRODUCT(E10:E15*S10:S15)} -> 0 | U37: VALUE OF SPEC DEV
B38: MTN ORIGINS - PURSUIT CAPITAL | E38: 1500000 | R38: =SUM(E38:Q38) -> 1500000
B39: JV - EQUITY CAPITAL | E39: 10000000 | R39: =SUM(E39:Q39) -> 10000000
B40: EQUITY INVESTMENT | E40: =SUM(E38:E39) -> 11500000 | F40: =SUM(F38:F39) -> 0 | G40: =SUM(G38:G39) -> 0 | H40: =SUM(H38:H39) -> 0 | I40: =SUM(I38:I39) -> 0 | J40: =SUM(J38:J39) -> 0 | K40: =SUM(K38:K39) -> 0 | L40: =SUM(L38:L39) -> 0 | R40: =SUM(E40:Q40) -> 11500000 | T40: =(C184+E40)/T37 -> #DIV/0! | U40: ETV | V40: =25000000-E40 -> 13500000 | W40: =25000000-F40 -> 25000000 | Z40: Force to 40mm for total | AA40: =ROUND(40000000-R40,0) -> 28500000
B42: DEBT | C42: =U158 -> 49035729 | T42: =(E48+F48)/(E40+F40+E48+F48) -> 0.83846603 | U42: LTC Year 0+1
...

Sheet L+H Monthly CF
B1: CLARENDON - LAND & HOME DEVELOPMENT
B2: Build & Sales Proforma
E3: 0 | F3: 0 | G3: 0 | H3: 0 | I3: 0 | J3: 0 | K3: 0 | L3: 0 | M3: 0 | N3: 0 | O3: 0 | P3: 0 | Q3: =E3+1 -> 1 | R3: =F3+1 -> 1 | S3: =G3+1 -> 1 | T3: =H3+1 -> 1 | U3: =I3+1 -> 1 | V3: =J3+1 -> 1 | W3: =K3+1 -> 1 | X3: =L3+1 -> 1 | ... AZ3: =AN3+1 -> 3 | BA3: 48mo Total | BB3: Check
D4: Month Beginning | E4: =Assumptions!C5 -> 45658 | F4: =EDATE(E4,1) -> 45689 | G4: =EDATE(F4,1) -> 45717 | H4: =EDATE(G4,1) -> 45748 | I4: =EDATE(H4,1) -> 45778 | J4: =EDATE(I4,1) -> 45809 | K4: =EDATE(J4,1) -> 45839 | L4: =EDATE(K4,1) -> 45870 | M4: =EDATE(L4,1) -> 45901 | ... AZ4: =EDATE(AY4,1) -> 47088
F5: Average Sales $ per Unit
B6: SOURCES
B8: ='Proforma L+H'!B37 -> EQUITY INVESTMENT
B9: ='Proforma L+H'!B38 -> MTN ORIGINS - PURSUIT CAPITAL | E9: ='Proforma L+H'!E38 -> 1500000 | Q9: ='Proforma L+H'!F38 -> 0 | AC9: ='Proforma L+H'!G38 -> 0 | AO9: ='Proforma L+H'!H38 -> 0 | BA9: =SUM(E9:AZ9) -> 1500000 | BB9: =SUM('Proforma L+H'!E38:H38)-BA9 -> 0
B10: ='Proforma L+H'!B39 -> JV - EQUITY CAPITAL | E10: ='Proforma L+H'!E39 -> 10000000 | Q10: ='Proforma L+H'!F39 -> 0 | AC10: ='Proforma L+H'!G39 -> 0 | AO10: ='Proforma L+H'!H39 -> 0 | BA10: =SUM(E10:AZ10) -> 10000000 | BB10: =SUM('Proforma L+H'!E39:H39)-BA10 -> 0
B11: ='Proforma L+H'!B40 -> EQUITY INVESTMENT | E11: ='Proforma L+H'!E40 -> 11500000 | Q11: ='Proforma L+H'!F40 -> 0 | AC11: ='Proforma L+H'!G40 -> 0 | AO11: ='Proforma L+H'!H40 -> 0 | BA11: =SUM(E11:AZ11) -> 11500000 | BB11: =SUM('Proforma L+H'!E40:H40)-BA11 -> 0
B13: ='Proforma L+H'!B42 -> DEBT | C13: =U259 -> 0
B14: ='Proforma L+H'!B43 -> JV BRIDGE LOAN | E14: ='Proforma L+H'!E43 -> 15000000 | Q14: ='Proforma L+H'!F43 -> 0 | AC14: ='Proforma L+H'!G43 -> 0 | AO14: ='Proforma L+H'!H43 -> 0 | BA14: =SUM(E14:AZ14) -> 15000000 | BB14: =SUM('Proforma L+H'!E43:H43)-BA14 -> 0
B15: ='Proforma L+H'!B44 -> SELLER FINANCE | E15: ='Proforma L+H'!E44 -> 0 | Q15: ='Proforma L+H'!F44 -> 0 | AC15: ='Proforma L+H'!G44 -> 0 | AO15: ='Proforma L+H'!H44 -> 0 | BA15: =SUM(E15:AZ15) -> 0 | BB15: =SUM('Proforma L+H'!E44:H44)-BA15 -> 0
B16: ='Proforma L+H'!B45 -> EB5 - MEZZ DEBT | E16: ='Proforma L+H'!E45 -> 0 | Q16: ='Proforma L+H'!F45 -> 20800000 | AC16: ='Proforma L+H'!G45 -> 0 | AO16: ='Proforma L+H'!H45 -> 0 | BA16: =SUM(E16:AZ16) -> 20800000 | BB16: =SUM('Proforma L+H'!E45:H45)-BA16 -> 0
B17: ='Proforma L+H'!B46 -> DEV LOAN - DEV COSTS | C17: =U258 -> 0 | E17: ='Proforma L+H'!E46 -> 0 | Q17: ='Proforma L+H'!F46 -> 19800183 | AC17: ='Proforma L+H'!G46 -> 0 | AO17: ='Proforma L+H'!H46 -> 0 | BA17: =SUM(E17:AZ17) -> 19800183 | BB17: =SUM('Proforma L+H'!E46:H46)-BA17 -> 0
B18: ='Proforma L+H'!B47 -> DEV LOAN - FINANCING / RESERVE | E18: ='Proforma L+H'!E47 -> 0 | Q18: ='Proforma L+H'!F47 -> 4092272.5 | AC18: ='Proforma L+H'!G47 -> 2867094.7 | AO18: ='Proforma L+H'!H47 -> 3746337.1 | BA18: =SUM(E18:AZ18) -> 10705704 | BB18: =SUM('Proforma L+H'!E47:H47)-BA18 -> 0
B19: ='Proforma L+H'!B48 -> DEBT | E19: ='Proforma L+H'!E48 -> 15000000 | Q19: ='Proforma L+H'!F48 -> 44692456 | AC19: ='Proforma L+H'!G48 -> 2867094.7 | AO19: ='Proforma L+H'!H48 -> 3746337.1 | BA19: =SUM(E19:AZ19) -> 66305888 | BB19: =SUM('Proforma L+H'!E48:H48)-BA19 -> 0
B21: ='Proforma L+H'!B50 -> VALUE CREATED POST PUD of 80 ACRES | E21: ='Proforma L+H'!E50 -> 0 | Q21: ='Proforma L+H'!F50 -> 0 | AC21: ='Proforma L+H'!G50 -> 15000000 | AO21: ='Proforma L+H'!H50 -> 0 | BA21: =SUM(E21:AZ21) -> 15000000 | BB21: =SUM('Proforma L+H'!E50:H50)-BA21 -> 0
B22: ='Proforma L+H'!B51 -> LAND SALE TO AMENITY | E22: ='Proforma L+H'!E51 -> 0 | Q22: ='Proforma L+H'!F51 -> 0 | AC22: ='Proforma L+H'!G51 -> 0 | AO22: ='Proforma L+H'!H51 -> 0 | BA22: =SUM(E22:AZ22) -> 0 | BB22: =SUM('Proforma L+H'!E51:H51)-BA22 -> 0
B27: ='Proforma L+H'!B56 -> PRESALE REVENUES | C27: =SUM(#REF!) -> #REF! | E27: ='Proforma L+H'!E56 -> 0 | F27: =OFFSET('Proforma L+H'!$E56,0,'L+H Monthly CF'!F$3)/12 -> 0 | G27: =OFFSET('Proforma L+H'!$E56,0,'L+H Monthly CF'!G$3)/12 -> 0 | H27: =OFFSET('Proforma L+H'!$E56,0,'L+H Monthly CF'!H$3)/12 -> 0 | I27: =OFFSET('Proforma L+H'!$E56,0,'L+H Monthly CF'!I$3)/12 -> 0 | J27: =OFFSET('Proforma L+H'!$E56,0,'L+H Monthly CF'!J$3)/12 -> 0 | K27: =OFFSET('Proforma L+H'!$E56,0,'L+H Monthly CF'!K$3)/12 -> 0 | L27: =OFFSET('Proforma L+H'!$E56,0,'L+H Monthly CF'!L$3)/12 -> 0 | M27: =OFFSET('Proforma L+H'!$E56,0,'L+H Monthly CF'!M$3)/12 -> 0 | ... AZ27: =OFFSET('Proforma L+H'!$E56,0,'L+H Monthly CF'!AZ$3)/12 -> 1954218.8 | BA27: =SUM(E27:AZ27) -> 41623062 | BB27: =SUM('Proforma L+H'!E56:H56)-BA27 -> 0
B28: ='Proforma L+H'!B57 -> UNIT SALES | E28: ='Proforma L+H'!E57 -> 0 | F28: =OFFSET('Proforma L+H'!$E57,0,'L+H Monthly CF'!F$3)/12 -> 0 | G28: =OFFSET('Proforma L+H'!$E57,0,'L+H Monthly CF'!G$3)/12 -> 0 | H28: =OFFSET('Proforma L+H'!$E57,0,'L+H Monthly CF'!H$3)/12 -> 0 | I28: =OFFSET('Proforma L+H'!$E57,0,'L+H Monthly CF'!I$3)/12 -> 0 | J28: =OFFSET('Proforma L+H'!$E57,0,'L+H Monthly CF'!J$3)/12 -> 0 | K28: =OFFSET('Proforma L+H'!$E57,0,'L+H Monthly CF'!K$3)/12 -> 0 | L28: =OFFSET('Proforma L+H'!$E57,0,'L+H Monthly CF'!L$3)/12 -> 0 | M28: =OFFSET('Proforma L+H'!$E57,0,'L+H Monthly CF'!M$3)/12 -> 0 | ... AZ28: =OFFSET('Proforma L+H'!$E57,0,'L+H Monthly CF'!AZ$3)/12 -> 4312609.4 | BA28: =SUM(E28:AZ28) -> 77660062 | BB28: =SUM('Proforma L+H'!E57:H57)-BA28 -> 0
