Workbook
Name _off3: #REF!
Name _off4: #REF!
Name _off5: #REF!
Name _off6: #REF!
Name _ret1: #REF!
Name _ret2: #REF!
Name _ret3: #REF!
Name _ret4: #REF!
Name _ret5: #REF!
Name _ret6: #REF!
Name _sa1: #REF!
Name _sa2: #REF!
Name _sa3: #REF!
Name _sa4: #REF!
Name _sa5: #REF!
Name _sa6: #REF!
Name ArgusInput: #REF!
Name ArgusInput.New: #REF!
Name Budget.AnalystReport.Rows: #REF!
Name Budget.BudgetPeriods.Columns: #REF!
Name Budget.ColumnHeadings.Row: #REF!
Name Budget.HideColumns.Row: #REF!
Name Budget.HideRows.Column: #REF!
Name Budget.RowOrderBy.Column: #REF!
Name Budget.RowOrderByDescription.Column: #REF!
Name Budget.Total.Column: #REF!
Name Budget.WBCol.Column: #REF!
Name Budget.WBStatus.Column: #REF!
Name Case_A: #REF!
Name CAT_Com: #REF!
Name Choices_Wrapper: #N/A
Name Choices_Wrapper5: #N/A
Name cnsld2: #REF!
Name cnsld3: #REF!
Name cnsld4: #REF!
Name cost1: #REF!
Name CostInflation: #REF!
Name Cur_QTD_Total_Revenue: #REF!
Name Date_Acquisition: #REF!
Name Date_AmortStart1: #REF!
Name Date_AmortStart2: #REF!
Name Date_CostsPricing: #REF!
Name Date_PreDevEnd: #REF!
Name Date_Refi: #REF!
Name Date_Sale: #REF!
Name Date_SaleParcel: #REF!
Name Date_Stabilization: #REF!
Name Description: #REF!
Name DevFeeTarget: #REF!
Name EntryCapRt: #REF!
Name ExitCapRt: #REF!
Name FileVersion: #REF!
Name FinFeeTarget: #REF!
Name Hello: #N/A
Name Hello5: #N/A
Name hotl1: #REF!
Name hotl2: #REF!
Name hotl3: #REF!
Name hotl4: #REF!
Name hotl5: #REF!

Sheet Assumptions
B1: CLARENDON - LAND+HOME, AMENITY+HOTEL DEVELOPMENT - ASSUMPTIONS
B2: OVERALL ASSUMPTIONS
B4: General | E4: Debt Financing | F4: LAND + HOME | G4: AMENITY + HOTEL | I4: Sub-Debt/ Equity Financing | K4: LAND + HOME | L4: AMENITY + HOTEL | N4: Land & Infrastructure
B5: Development Start Date | C5: 45473 | E5: Origination Year | F5: 2024 | G5: 2026 | I5: Pref Accrual Rate | K5: 0.1 | L5: 0.1 | P5: Acres | Q5: Value
B6: Development Start Year | C6: 2024 | E6: Original Term (Years) | F6: 2 | G6: 3 | I6: EB-5 Interest Rate | K6: 0.11 | L6: 0.11 | N6: Total Land | P6: =P7+P8 -> 319 | Q6: =Q7+Q8 -> 22000000
E7: Underwritten LTC | F7: 0.8118774 | G7: 0.75 | I7: EB-5 Origination Fee | K7: 0.01 | L7: =K7 -> 0.01 | N7: RESI | P7: 240 | Q7: 15000000
B8: Repayment Waterfall | E8: Interest Rate | F8: 0.12 | G8: =F8 -> 0.12 | I8: EB-5 Exit Fee | K8: 0.01 | L8: =K8 -> 0.01 | N8: AMENITY + HOTEL | P8: 79 | Q8: 7000000
B9: Loan | E9: Debt Placement & Origination Fee | F9: =0.0294+0.005+0.0056 -> 0.04 | G9: =F9 -> 0.04 | I9: Bridge Loan Placement Fee | K9: 0.02 | L9: N/A | N9: Infrastructure Cost | Q9: 15000000
B10: Preferred Return | E10: 1 Year Extension Fee | F10: =0.005*4 -> 0.02 | I10: Bridge Loan Interest Rate | K10: 0.15 | L10: N/A
B11: Capital Return | E11: Financing Cost Gross-up | F11: 0.2 | G11: 0.275 | I11: GP Promote Split | K11: 0 | L11: 0
F12: ='Proforma Land+Home'!V148-'Proforma Land+Home'!U148 -> -3349077.3 | G12: =IFERROR('Proforma A+H'!W188-'Proforma A+H'!X188,"")
B14: LAND + HOME ASSUMPTIONS
B16: Build / Sale Cost | E16: Unit Mix | J16: Unit Sales
B17: Vertical Construction Cost psft | C17: =850*C18 -> 850 | F17: Avg Size | G17: PPSF | H17: Escalation | J17: Sales Price Scalar | M17: 1
B18: Vertical Construction Costs Scalar | C18: 1 | E18: Homesites | F18: 3500 | G18: 1750 | H18: 0.1 | J18: Net Profit % | M18: 0.2
B19: Cost of Sale - RE Fees | C19: 0.045 | E19: Village | F19: 4500 | G19: 1650 | H19: 0.075 | J19: Phantom Tax Rate | M19: 0.3
B20: Real Estate Taxes (Annual) / mils | C20: =10000/39 -> 256.41026 | E20: Cottages | F20: 2500 | G20: 1850 | H20: 0.075
B23: AMENITY + HOTEL ASSUMPTIONS
B25: Hotel Details | E25: Hotel Guest Rooms | K25: Build Cost
B26: Start Date | C26: 46053 | F26: Lodge Rooms | G26: Villa/Cabin | H26: Cottages | I26: Auton. Tents | K26: Vertical Construction Costs Scalar | N26: ='Returns A+H'!L14 -> 1
B27: Member Dues / year / unit | C27: 15000 | E27: Guest Rooms | F27: 20 | G27: 24 | H27: 24 | I27: 12 | K27: Real Estate Taxes (Annual) / mils | N27: ='Proforma Resi'!C269 -> 256
B28: Loan Interest Rate | C28: 0.03 | E28: SQFT | F28: 500 | G28: 750 | H28: 1250 | I28: 625
B29: Loan Origination Fees | C29: 0 | E29: Sales Price / SF | F29: 0 | G29: 2250 | H29: 2000 | I29: 0
B30: Disposition Year | C30: ='Returns A+H'!L15 -> 7 | E30: Average Daily Rate | F30: 1100 | G30: 1300 | H30: 3000 | I30: 750
B31: Terminal Cap Rate | C31: 0.065 | E31: Average Sales Price | F31: =F28*F29 -> 0 | G31: =G28*G29 -> 1687500 | H31: =H28*H29 -> 2500000 | I31: =I28*I29 -> 0
B32: Selling Costs | C32: 0.05 | E32: Sales Price Escalation | F32: 0.05 | G32: 0.05 | H32: 0.05 | I32: 0.05
B33: Hold Period | C33: 132 | E33: % Rooms for Sale | F33: 0 | G33: 0.5 | H33: 1 | I33: 0
B34: Hotel Room Rent Growth Rate | C34: 0.03
B35: Hotel Days | C35: 365
B36: Hotel Rooms Operating Cost | C36: =35%-F33*15% -> 0.35
B37: Condo Owner Revenue Split | C37: 0.5
F38: 1 | G38: 2 | H38: 3 | I38: 4 | J38: 5 | K38: 6 | L38: 7 | M38: 8 | N38: 9 | O38: 10 | P38: 11 | Q38: 12
B39: Bar Details | F39: 44562 | G39: =F39+31 -> 44593 | H39: =G39+31 -> 44624 | I39: =H39+31 -> 44655 | J39: =I39+31 -> 44686 | K39: =J39+31 -> 44717 | L39: =K39+31 -> 44748 | M39: =L39+31 -> 44779 | N39: =M39+31 -> 44810 | ... Q39: =P39+31 -> 44903 | R39: Avg
B40: Start Date | C40: 46753 | E40: Seasonal Occupancy - Hotel | F40: 0.75 | G40: 0.75 | H40: 0.65 | I40: 0.25 | J40: 0.15 | K40: 0.45 | L40: 0.65 | M40: 0.55 | N40: 0.45 | O40: 0.1 | P40: 0.1 | Q40: 0.55 | R40: =AVERAGE(F40:Q40) -> 0.45
B41: Available room/nights | C41: =(F27+G27)*C35 -> 16060 | E41: Conference Center Occupancy | F41: 0.25 | G41: 0.25 | H41: 0.25 | I41: 0.5 | J41: 0.75 | K41: 1 | L41: 1 | M41: 1 | N41: 0.75 | O41: 0.5 | P41: 0.25 | Q41: 0.25 | R41: =AVERAGE(F41:Q41) -> 0.5625
B42: Paid Room Nights | C42: =C41*R40 -> 7227 | E42: Adj. Conf Center Occupancy | F42: =IF(OR(F38<MONTH($C$63),F38>$C$64),0,F41) -> 0.25 | G42: =IF(OR(G38<MONTH($C$63),G38>$C$64),0,G41) -> 0.25 | H42: =IF(OR(H38<MONTH($C$63),H38>$C$64),0,H41) -> 0.25 | I42: =IF(OR(I38<MONTH($C$63),I38>$C$64),0,I41) -> 0.5 | J42: =IF(OR(J38<MONTH($C$63),J38>$C$64),0,J41) -> 0.75 | K42: =IF(OR(K38<MONTH($C$63),K38>$C$64),0,K41) -> 1 | L42: =IF(OR(L38<MONTH($C$63),L38>$C$64),0,L41) -> 1 | M42: =IF(OR(M38<MONTH($C$63),M38>$C$64),0,M41) -> 1 | ... Q42: =IF(OR(Q38<MONTH($C$63),Q38>$C$64),0,Q41) -> 0.25 | R42: =AVERAGE(F42:Q42) -> 0.5625
B43: Bar Revenue (% of Room Rev) | C43: 0.2
B44: Bar COS (% of Bar Rev) | C44: 0.75 | F44: 0 | G44: =F44+1 -> 1 | H44: =G44+1 -> 2 | I44: =H44+1 -> 3 | J44: =I44+1 -> 4 | K44: =J44+1 -> 5 | L44: =K44+1 -> 6 | M44: =L44+1 -> 7 | N44: =M44+1 -> 8 | O44: =N44+1 -> 9
F45: =YEAR(C5)+1 -> 2025 | G45: =F45+1 -> 2026 | H45: =G45+1 -> 2027 | I45: =H45+1 -> 2028 | J45: =I45+1 -> 2029 | K45: =J45+1 -> 2030 | L45: =K45+1 -> 2031 | M45: =L45+1 -> 2032 | N45: =M45+1 -> 2033 | O45: =N45+1 -> 2034 | P45: Total Rooms | Q45: Condos
B46: Spa / Wellness Center Details | E46: Conf Center Rental Rates | F46: =Assumptions!$C$60 -> 25000 | G46: =F46*(1+$C$61) -> 25750 | H46: =G46*(1+$C$61) -> 26522.5 | I46: =H46*(1+$C$61) -> 27318.175 | J46: =I46*(1+$C$61) -> 28137.72 | K46: =J46*(1+$C$61) -> 28981.852 | L46: =K46*(1+$C$61) -> 29851.307 | M46: =L46*(1+$C$61) -> 30746.847 | N46: =M46*(1+$C$61) -> 31669.252 | O46: =N46*(1+$C$61) -> 32619.33
...

Sheet Exhibits
B4: CLARENDON - OVERALL DEVELOPMENT: PROFORMA | H4: =B4 -> CLARENDON - OVERALL DEVELOPMENT: PROFORMA
B5: PROFORMA - SOURCES & USES SUMMARY | H5: PROFORMA - SOURCES & USES PRE-REVENUE
B6: SOURCES | C6: $ | D6: $/SF | E6: Per Home | F6: % Total | H6: =B6 -> SOURCES | I6: $ | J6: $/SF | K6: Per Home | L6: % Total
B7: =B39 -> SPONSOR - EQUITY CAPITAL | C7: =C39+C70 -> 400000 | F7: =C7/$C$17 -> #VALUE! | H7: =B7 -> SPONSOR - EQUITY CAPITAL | I7: =C7 -> 400000 | L7: =I7/$I$17 -> #VALUE!
B8: =B40 -> LP - EQUITY CAPITAL | C8: =C40+C71 -> 15000000 | F8: =C8/$C$17 -> #VALUE! | H8: =B8 -> LP - EQUITY CAPITAL | I8: =C8 -> 15000000 | L8: =I8/$I$17 -> #VALUE!
B9: =B41 -> SELLER CARRYBACK | C9: =C41+C71 -> 0 | F9: =C9/$C$17 -> #VALUE! | H9: =B9 -> SELLER CARRYBACK | I9: =C9 -> 0 | L9: =I9/$I$17 -> #VALUE!
B10: =B42 -> EB5 - MEZZ DEBT | C10: =C42+C72 -> #VALUE! | F10: =C10/$C$17 -> #VALUE! | H10: =B10 -> EB5 - MEZZ DEBT | I10: =C10 -> #VALUE! | L10: =I10/$I$17 -> #VALUE!
B11: =B43 -> DEV LOAN | C11: =C43+C73 -> #VALUE! | F11: =C11/$C$17 -> #VALUE! | H11: =B11 -> DEV LOAN | I11: ='Proforma Land+Home'!E220+'Proforma Land+Home'!F220 -> 50115929 | L11: =I11/$I$17 -> #VALUE!
B12: =B44 -> LAND SALE TO AMENITY | C12: =C44 -> 0 | F12: =C12/$C$17 -> #VALUE! | H12: =B12 -> LAND SALE TO AMENITY | I12: =C12 -> 0 | L12: =I12/$I$17 -> #VALUE!
B13: =B45 -> PRESALE REVENUES | C13: =C45 -> 67709709 | F13: =C13/$C$17 -> #VALUE! | L13: =I13/$I$17 -> #VALUE!
B14: =B46 -> UNIT SALES | C14: =C46+C75 -> 3.7390114e+08 | F14: =C14/$C$17 -> #VALUE! | L14: =I14/$I$17 -> #VALUE!
B15: =B74 -> TOTAL NET OPERATING INCOME (NOI) | C15: =C74 -> 28604665 | F15: =C15/$C$17 -> #VALUE! | L15: =I15/$I$17 -> #VALUE!
B16: =B76 -> HOTEL SALE PROCEEDS / DISPOSITION | C16: =C76 -> 1.4914314e+08 | F16: =C16/$C$17 -> #VALUE! | L16: =I16/$I$17 -> #VALUE!
B17: TOTAL SOURCES | C17: =SUM(C7:C16) -> #VALUE! | F17: =C17/$C$17 -> #VALUE! | H17: =B17 -> TOTAL SOURCES | I17: =SUM(I7:I16) -> #VALUE! | L17: =I17/$I$17 -> #VALUE!
B19: USES | C19: $ | D19: $/SF | E19: Per Home | F19: % Total | H19: =B19 -> USES | I19: $ | J19: $/SF | K19: Per Home | L19: % Total
B20: =B50 -> LAND & PROJECT ACQUISITION | C20: =C50+C80 -> #VALUE! | F20: =C20/$C$31 -> #VALUE! | H20: =B20 -> LAND & PROJECT ACQUISITION | I20: =I50+I80 -> #VALUE! | L20: =I20/$I$31 -> #VALUE!
B21: =B51 -> HARD COSTS - SITE, RESTORATION & INFRASTRUCTURE | C21: =C51+C82 -> 20739104 | F21: =C21/$C$31 -> #VALUE! | H21: =B21 -> HARD COSTS - SITE, RESTORATION & INFRASTRUCTURE | I21: =I51+I82 -> 13964533 | L21: =I21/$I$31 -> #VALUE!
B22: =B81 -> TOTAL VERTICAL CONSTRUCTION COSTS | C22: =C52+C81 -> 2.5321538e+08 | F22: =C22/$C$31 -> #VALUE! | H22: =B22 -> TOTAL VERTICAL CONSTRUCTION COSTS | I22: =I52+I81 -> 1.1676776e+08 | L22: =I22/$I$31 -> #VALUE!
B23: =B53 -> SOFT COSTS PROFESSIONALS - FINAL ENTITLEMENTS & SITE INFRA. | C23: =C53+C83 -> 12354530 | F23: =C23/$C$31 -> #VALUE! | H23: =B23 -> SOFT COSTS PROFESSIONALS - FINAL ENTITLEMENTS & SITE INFRA. | I23: =I53+I83 -> 9906180.6 | L23: =I23/$I$31 -> #VALUE!
B24: =B54 -> SOFT COSTS PROFESSIONALS - HOMES | C24: =C54 -> 6121864.1 | F24: =C24/$C$31 -> #VALUE! | H24: =B24 -> SOFT COSTS PROFESSIONALS - HOMES | I24: =I54 -> 2091708.1 | L24: =I24/$I$31 -> #VALUE!
B25: =B55 -> SOFT COSTS - SALES | C25: =C55+C84 -> 14113850 | F25: =C25/$C$31 -> #VALUE! | H25: =B25 -> SOFT COSTS - SALES | I25: =I55+I84 -> 1577500 | L25: =I25/$I$31 -> #VALUE!
B26: =B56 -> SOFT COSTS - TAXES AND INSURANCE | C26: =C56+C85 -> 1584893.3 | F26: =C26/$C$31 -> #VALUE! | H26: =B26 -> SOFT COSTS - TAXES AND INSURANCE | I26: =I56+I85 -> 767702.48 | L26: =I26/$I$31 -> #VALUE!
B27: =B57 -> SOFT COSTS - MUNICIPALITY FEES | C27: =C57+C86 -> 2286123.4 | F27: =C27/$C$31 -> #VALUE! | H27: =B27 -> SOFT COSTS - MUNICIPALITY FEES | I27: =I57+I86 -> 806661.07 | L27: =I27/$I$31 -> #VALUE!
B28: =B58 -> DEVELOPMENT FEES | C28: =C58+C87 -> 18496362 | F28: =C28/$C$31 -> #VALUE! | H28: =B28 -> DEVELOPMENT FEES | I28: =I58+I87 -> 5150109.4 | L28: =I28/$I$31 -> #VALUE!
B29: =B59 -> FINANCING COSTS & REPAYMENT | C29: =C59+C88 -> #VALUE! | F29: =C29/$C$31 -> #VALUE! | H29: =B29 -> FINANCING COSTS & REPAYMENT | I29: =I59+I88 -> #VALUE! | L29: =I29/$I$31 -> #VALUE!
B30: =B60 -> DISTRIBUTIONS | C30: =C60+C89 -> #VALUE! | F30: =C30/$C$31 -> #VALUE! | H30: WORKING CAPITAL | I30: =I31-SUM(I20:I29) -> #VALUE! | L30: =I30/$I$31 -> #VALUE!
B31: TOTAL USES | C31: =SUM(C20:C30) -> #VALUE! | F31: =C31/$C$31 -> #VALUE! | H31: =B31 -> TOTAL USES | I31: =I17 -> #VALUE! | L31: =I31/$I$31 -> #VALUE!
F32: =C32/$C$31 -> #VALUE!
B36: CLARENDON - RESI DEVELOPMENT: PROFORMA | H36: =B36 -> CLARENDON - RESI DEVELOPMENT: PROFORMA
B37: PROFORMA - SOURCES & USES SUMMARY | D37: ='Proforma Land+Home'!$D$18 -> 158750 | E37: ='Proforma Land+Home'!$R$17 -> 45 | H37: PROFORMA - SOURCES & USES PRE-REVENUE (Year 0-1)
B38: SOURCES | C38: $ | D38: $/SF | E38: Per Home | F38: % Total | H38: =B38 -> SOURCES | I38: $ | J38: $/SF | K38: Per Home | L38: % Total
B39: ='Proforma Land+Home'!B216 -> SPONSOR - EQUITY CAPITAL | C39: ='Proforma Land+Home'!R216 -> 400000 | D39: =C39/'Proforma Land+Home'!$D$18 -> 2.519685 | E39: =C39/'Proforma Land+Home'!$R$17 -> 8888.8889 | F39: =C39/$C$47 -> 0.00091959703 | H39: =B39 -> SPONSOR - EQUITY CAPITAL | I39: =C39 -> 400000 | J39: =I39/$D$37 -> 2.519685 | K39: =I39/$E$37 -> 8888.8889 | L39: =I39/$I$47 -> 0.0048154039
B40: ='Proforma Land+Home'!B217 -> LP - EQUITY CAPITAL | C40: ='Proforma Land+Home'!R217 -> 15000000 | D40: =C40/'Proforma Land+Home'!$D$18 -> 94.488189 | E40: =C40/'Proforma Land+Home'!$R$17 -> 333333.33 | F40: =C40/$C$47 -> 0.034484889 | H40: =B40 -> LP - EQUITY CAPITAL | I40: =C40 -> 15000000 | J40: =I40/$D$37 -> 94.488189 | K40: =I40/$E$37 -> 333333.33 | L40: =I40/$I$47 -> 0.18057765
B41: ='Proforma Land+Home'!B218 -> SELLER CARRYBACK | C41: ='Proforma Land+Home'!R218 -> 0 | D41: =C41/'Proforma Land+Home'!$D$18 -> 0 | E41: =C41/'Proforma Land+Home'!$R$17 -> 0 | F41: =C41/$C$47 -> 0 | H41: =B41 -> SELLER CARRYBACK | I41: =C41 -> 0 | J41: =I41/$D$37 -> 0 | K41: =I41/$E$37 -> 0 | L41: =I41/$I$47 -> 0
B42: ='Proforma Land+Home'!B219 -> EB5 - MEZZ DEBT | C42: ='Proforma Land+Home'!R219 -> 0 | D42: =C42/'Proforma Land+Home'!$D$18 -> 0 | E42: =C42/'Proforma Land+Home'!$R$17 -> 0 | F42: =C42/$C$47 -> 0 | H42: =B42 -> EB5 - MEZZ DEBT | I42: =SUM('Proforma Land+Home'!E219:F219) -> 0 | J42: =I42/$D$37 -> 0 | K42: =I42/$E$37 -> 0 | L42: =I42/$I$47 -> 0
B43: ='Proforma Land+Home'!B220 -> DEV LOAN | C43: ='Proforma Land+Home'!R220 -> 67666761 | D43: =C43/'Proforma Land+Home'!$D$18 -> 426.24731 | E43: =C43/'Proforma Land+Home'!$R$17 -> 1503705.8 | F43: =C43/$C$47 -> 0.15556538 | H43: =B43 -> DEV LOAN | I43: =C43 -> 67666761 | J43: =I43/$D$37 -> 426.24731 | K43: =I43/$E$37 -> 1503705.8 | L43: =I43/$I$47 -> 0.81460695
B44: ='Proforma Land+Home'!B221 -> LAND SALE TO AMENITY | C44: ='Proforma Land+Home'!R221 -> 0 | D44: =C44/'Proforma Land+Home'!$D$18 -> 0 | E44: =C44/'Proforma Land+Home'!$R$17 -> 0 | F44: =C44/$C$47 -> 0 | H44: =B44 -> LAND SALE TO AMENITY | I44: =C44 -> 0 | J44: =I44/$D$37 -> 0 | K44: =I44/$E$37 -> 0 | L44: =I44/$I$47 -> 0
B45: ='Proforma Land+Home'!B222 -> PRESALE REVENUES | C45: ='Proforma Land+Home'!R222 -> 67709709 | D45: =C45/'Proforma Land+Home'!$D$18 -> 426.51785 | E45: =C45/'Proforma Land+Home'!$R$17 -> 1504660.2 | F45: =C45/$C$47 -> 0.15566412
B46: ='Proforma Land+Home'!B223 -> UNIT SALES | C46: ='Proforma Land+Home'!R223 -> 2.8419666e+08 | D46: =C46/'Proforma Land+Home'!$D$18 -> 1790.2152 | E46: =C46/'Proforma Land+Home'!$R$17 -> 6315481.4 | F46: =C46/$C$47 -> 0.65336601
B47: ='Proforma Land+Home'!B224 -> TOTAL SOURCES | C47: ='Proforma Land+Home'!R224 -> 4.3497313e+08 | D47: =C47/'Proforma Land+Home'!$D$18 -> 2739.9882 | E47: =C47/'Proforma Land+Home'!$R$17 -> 9666069.6 | F47: =E47/$E$47 -> 1 | H47: =B47 -> TOTAL SOURCES | I47: =SUM(I39:I46) -> 83066761 | J47: =I47/$D$37 -> 523.25518 | K47: =I47/$E$37 -> 1845928 | L47: =I47/$I$47 -> 1
...

Sheet COMB CASH FLOWS
B4: COMBINED MONTHLY CASH FLOWS - UNDER DEVELOPMENT

Sheet Combined Returns
B1: CLARENDON - LAND, HOME, AMENITY DEVELOPMENT
B2: Returns Analysis
B4: PROJECT FINANCING ANALYSIS | F4: BUSINESS CASE ANALYSIS
B5: TOTAL PROJECT CAPITAL NEEDS: | D5: ='Returns Land+Home'!D5 -> 83066761 | F5: TOTAL PROJECT REVENUE (less brokers fees): | H5: ='Returns Land+Home'!H5 -> 3.3911752e+08
B6: TOTAL PROJECT VALUE (PV of FINAL BUILD OUT): | D6: ='Returns Land+Home'!D6 -> 279912500 | F6: - TOTAL PROJECT COST: | H6: ='Returns Land+Home'!H6 -> 2.5078657e+08
B7: STARTING SPEC DEVELOPMENT VALUE: | D7: ='Returns Land+Home'!D7 -> 30975000 | F7: = NET PROFIT | H7: ='Returns Land+Home'!H7 -> 88330954
B8: EQUITY to SPEC DEV VALUE (ETV): | D8: ='Returns Land+Home'!D8 -> 0.49717514 | F8: NET PROFIT %: | H8: ='Returns Land+Home'!H8 -> 0.26047299
B9: LOAN to COST (LTC): | D9: ='Returns Land+Home'!D9 -> 0.81460695 | F9: RETURN on EQUITY/CAPTIAL (ROE): | H9: ='Returns Land+Home'!H9 -> 5.7357762
B10: LOAN to VALUE (LTV): | D10: ='Returns Land+Home'!D10 -> 0.11019829
B12: PROJECT RETURNS ANALYSIS
B13: PROJECT NET CASH FLOWS: | D13: ='Returns Land+Home'!D13 -> 88855954
B14: EQUITY MULTIPLE: | D14: ='Returns Land+Home'!D14 -> 6.7698671
B15: MODELED ROI: | D15: ='Returns Land+Home'!D15 -> 5.7698671
B16: PROJECT IRR : | D16: ='Returns Land+Home'!D16 -> 0.53538527
F18: ='Proforma Land+Home'!E3 -> Year 0 | G18: ='Proforma Land+Home'!F3 -> Year 1 | H18: ='Proforma Land+Home'!G3 -> Year 2 | I18: ='Proforma Land+Home'!H3 -> Year 3 | J18: ='Proforma Land+Home'!I3 -> Year 4 | K18: ='Proforma Land+Home'!J3 -> Year 5 | L18: ='Proforma Land+Home'!K3 -> Year 6 | M18: ='Proforma Land+Home'!L3 -> Year 7 | ... R18: ='Proforma Land+Home'!Q3 -> Year 12
F19: ='Proforma Land+Home'!E4 -> 2025 | G19: ='Proforma Land+Home'!F4 -> 2026 | H19: ='Proforma Land+Home'!G4 -> 2027 | I19: ='Proforma Land+Home'!H4 -> 2028 | J19: ='Proforma Land+Home'!I4 -> 2029 | K19: ='Proforma Land+Home'!J4 -> 2030 | L19: ='Proforma Land+Home'!K4 -> 2031 | M19: ='Proforma Land+Home'!L4 -> 2032 | ... R19: ='Proforma Land+Home'!Q4 -> 2037
B20: SUMMARY OF RETURNS | F20: ='Proforma Land+Home'!E5 -> 45658 | G20: ='Proforma Land+Home'!F5 -> 46023 | H20: ='Proforma Land+Home'!G5 -> 46388 | I20: ='Proforma Land+Home'!H5 -> 46753 | J20: ='Proforma Land+Home'!I5 -> 47119 | K20: ='Proforma Land+Home'!J5 -> 47484 | L20: ='Proforma Land+Home'!K5 -> 47849 | M20: ='Proforma Land+Home'!L5 -> 48214 | ... R20: ='Proforma Land+Home'!Q5 -> 50040
B21: Wondership LP Returns
B22: Capital Return | D22: =SUM(F22:R22) -> 20940638 | F22: ='Returns Land+Home'!F22+'Returns A+H'!F22 -> 0 | G22: ='Returns Land+Home'!G22+'Returns A+H'!G22 -> 0 | H22: ='Returns Land+Home'!H22+'Returns A+H'!H22 -> 1968762.1 | I22: ='Returns Land+Home'!I22+'Returns A+H'!I22 -> 6074217.7 | J22: ='Returns Land+Home'!J22+'Returns A+H'!J22 -> 12897658 | K22: ='Returns Land+Home'!K22+'Returns A+H'!K22 -> 0 | L22: ='Returns Land+Home'!L22+'Returns A+H'!L22 -> 0 | M22: ='Returns Land+Home'!M22+'Returns A+H'!M22 -> 0 | ... R22: ='Returns Land+Home'!R22+'Returns A+H'!R22 -> 0
B23: Profit Split | D23: =SUM(F23:R23) -> #VALUE! | F23: ='Returns Land+Home'!F23+'Returns A+H'!F23 -> 0 | G23: ='Returns Land+Home'!G23+'Returns A+H'!G23 -> 0 | H23: ='Returns Land+Home'!H23+'Returns A+H'!H23 -> 0 | I23: ='Returns Land+Home'!I23+'Returns A+H'!I23 -> 0 | J23: ='Returns Land+Home'!J23+'Returns A+H'!J23 -> 22249737 | K23: ='Returns Land+Home'!K23+'Returns A+H'!K23 -> 2681101.7 | L23: ='Returns Land+Home'!L23+'Returns A+H'!L23 -> 19243076 | M23: ='Returns Land+Home'!M23+'Returns A+H'!M23 -> #VALUE! | ... R23: ='Returns Land+Home'!R23+'Returns A+H'!R23 -> 0
B24: Total Distributions | D24: =SUM(F24:R24) -> #VALUE! | F24: =F22+F23 -> 0 | G24: =G22+G23 -> 0 | H24: =H22+H23 -> 1968762.1 | I24: =I22+I23 -> 6074217.7 | J24: =J22+J23 -> 35147395 | K24: =K22+K23 -> 2681101.7 | L24: =L22+L23 -> 19243076 | M24: =M22+M23 -> #VALUE! | ... R24: =R22+R23 -> 0
B25: Total Contributions | D25: =SUM(F25:R25) -> 15000000 | F25: ='Returns Land+Home'!F25+'Returns A+H'!F25 -> 15000000 | G25: ='Returns Land+Home'!G25+'Returns A+H'!G25 -> 0 | H25: ='Returns Land+Home'!H25+'Returns A+H'!H25 -> 0
B26: Net Profit / Cash Flows | D26: =SUM(F26:R26) -> #VALUE! | F26: =F24-F25 -> -15000000 | G26: =G24-G25 -> 0 | H26: =H24-H25 -> 1968762.1 | I26: =I24-I25 -> 6074217.7 | J26: =J24-J25 -> 35147395 | K26: =K24-K25 -> 2681101.7 | L26: =L24-L25 -> 19243076 | M26: =M24-M25 -> #VALUE! | ... R26: =R24-R25 -> 0
B27: IRR | F27: =XIRR(G26:R26,G20:R20) -> #VALUE!
B28: Equity Multiple | F28: =SUMIF(F26:R26,">0")/-SUMIF(F26:R26,"<0") -> 4.3409702
B29: Cumulative (Equity) Cash Position | F29: =F26+E29 -> -15000000 | G29: =G26+F29 -> -15000000 | H29: =H26+G29 -> -13031238 | I29: =I26+H29 -> -6957020.3 | J29: =J26+I29 -> 28190375 | K29: =K26+J29 -> 30871476 | L29: =L26+K29 -> 50114552 | M29: =M26+L29 -> #VALUE! | ... R29: =R26+Q29 -> #VALUE!
B31: MO LP Returns
B32: Capital Return + Pref | F32: ='Returns Land+Home'!F32+'Returns A+H'!F32 -> 0 | G32: ='Returns Land+Home'!G32+'Returns A+H'!G32 -> 0 | H32: ='Returns Land+Home'!H32+'Returns A+H'!H32 -> 52500.322 | I32: ='Returns Land+Home'!I32+'Returns A+H'!I32 -> 161979.14 | J32: ='Returns Land+Home'!J32+'Returns A+H'!J32 -> #VALUE! | K32: ='Returns Land+Home'!K32+'Returns A+H'!K32 -> #VALUE! | L32: ='Returns Land+Home'!L32+'Returns A+H'!L32 -> #VALUE! | M32: ='Returns Land+Home'!M32+'Returns A+H'!M32 -> #VALUE! | ... R32: ='Returns Land+Home'!R32+'Returns A+H'!R32 -> 0
B33: Profit Split | F33: ='Returns Land+Home'!F33+'Returns A+H'!F33 -> 0 | G33: ='Returns Land+Home'!G33+'Returns A+H'!G33 -> 0 | H33: ='Returns Land+Home'!H33+'Returns A+H'!H33 -> 0 | I33: ='Returns Land+Home'!I33+'Returns A+H'!I33 -> 0 | J33: ='Returns Land+Home'!J33+'Returns A+H'!J33 -> #VALUE! | K33: ='Returns Land+Home'!K33+'Returns A+H'!K33 -> #VALUE! | L33: ='Returns Land+Home'!L33+'Returns A+H'!L33 -> #VALUE! | M33: ='Returns Land+Home'!M33+'Returns A+H'!M33 -> #VALUE! | ... R33: ='Returns Land+Home'!R33+'Returns A+H'!R33 -> 0
B34: Total Distributions | D34: =SUM(F34:R34) -> #VALUE! | F34: =SUM(F32:F33) -> 0 | G34: =SUM(G32:G33) -> 0 | H34: =SUM(H32:H33) -> 52500.322 | I34: =SUM(I32:I33) -> 161979.14 | J34: =SUM(J32:J33) -> #VALUE! | K34: =SUM(K32:K33) -> #VALUE! | L34: =SUM(L32:L33) -> #VALUE! | M34: =SUM(M32:M33) -> #VALUE! | ... R34: =SUM(R32:R33) -> 0
B35: Total Contributions | D35: =SUM(F35:R35) -> 400000 | F35: ='Returns Land+Home'!F35+'Returns A+H'!F35 -> 400000 | G35: ='Returns Land+Home'!G35+'Returns A+H'!G35 -> 0 | H35: ='Returns Land+Home'!H35+'Returns A+H'!H35 -> 0
B36: Net Profit / Cash Flows | D36: =SUM(F36:R36) -> #VALUE! | F36: =F34-F35 -> -400000 | G36: =G34-G35 -> 0 | H36: =H34-H35 -> 52500.322 | I36: =I34-I35 -> 161979.14 | J36: =J34-J35 -> #VALUE! | K36: =K34-K35 -> #VALUE! | L36: =L34-L35 -> #VALUE! | M36: =M34-M35 -> #VALUE! | ... R36: =R34-R35 -> 0
B37: IRR | F37: =XIRR(F36:R36,F20:R20) -> #VALUE!
B38: Equity Multiple | F38: =SUMIF(F36:R36,">0")/-SUMIF(F36:R36,"<0") -> 0.53619865
B39: Cumulative (Equity) Cash Position | F39: =F36+E39 -> -400000 | G39: =G36+F39 -> -400000 | H39: =H36+G39 -> -347499.68 | I39: =I36+H39 -> -185520.54 | J39: =J36+I39 -> #VALUE! | K39: =K36+J39 -> #VALUE! | L39: =L36+K39 -> #VALUE! | M39: =M36+L39 -> #VALUE! | ... R39: =R36+Q39 -> #VALUE!
B41: MO/Wondership JV GP Returns
B42: Total Distributions | D42: =SUM(F42:R42) -> #VALUE! | F42: ='Returns Land+Home'!F42+'Returns A+H'!F42 -> 0 | G42: ='Returns Land+Home'!G42+'Returns A+H'!G42 -> 0 | H42: ='Returns Land+Home'!H42+'Returns A+H'!H42 -> 0 | I42: ='Returns Land+Home'!I42+'Returns A+H'!I42 -> 0 | J42: ='Returns Land+Home'!J42+'Returns A+H'!J42 -> 14896191 | K42: ='Returns Land+Home'!K42+'Returns A+H'!K42 -> 2752597.8 | L42: ='Returns Land+Home'!L42+'Returns A+H'!L42 -> 19756225 | M42: ='Returns Land+Home'!M42+'Returns A+H'!M42 -> #VALUE! | ... R42: ='Returns Land+Home'!R42+'Returns A+H'!R42 -> 0
B43: ='Proforma Land+Home'!B138 -> Developer Overhead | D43: =SUM(F43:R43) -> #REF! | F43: ='Returns Land+Home'!#REF!+'Returns A+H'!F43 -> #REF! | G43: ='Returns Land+Home'!#REF!+'Returns A+H'!G43 -> #REF! | H43: ='Returns Land+Home'!#REF!+'Returns A+H'!H43 -> #REF! | I43: ='Returns Land+Home'!#REF!+'Returns A+H'!I43 -> #REF! | J43: ='Returns Land+Home'!#REF!+'Returns A+H'!J43 -> #REF! | K43: ='Returns Land+Home'!#REF!+'Returns A+H'!K43 -> #REF! | L43: ='Returns Land+Home'!#REF!+'Returns A+H'!L43 -> #REF! | M43: ='Returns Land+Home'!#REF!+'Returns A+H'!M43 -> #REF! | ... R43: ='Returns Land+Home'!#REF!+'Returns A+H'!R43 -> #REF!
B44: ='Proforma Land+Home'!B139 -> Disposition Fees | D44: =SUM(F44:R44) -> #REF! | F44: ='Returns Land+Home'!#REF! -> #REF! | G44: ='Returns Land+Home'!#REF! -> #REF! | H44: ='Returns Land+Home'!#REF! -> #REF! | I44: ='Returns Land+Home'!#REF! -> #REF! | J44: ='Returns Land+Home'!#REF! -> #REF! | K44: ='Returns Land+Home'!#REF! -> #REF! | L44: ='Returns Land+Home'!#REF! -> #REF! | M44: ='Returns Land+Home'!#REF! -> #REF! | ... R44: ='Returns Land+Home'!#REF! -> #REF!
B45: Net Profit / Cash Flows | D45: =SUM(F45:R45) -> #REF! | F45: =SUM(F42:F44) -> #REF! | G45: =SUM(G42:G44) -> #REF! | H45: =SUM(H42:H44) -> #REF! | I45: =SUM(I42:I44) -> #REF! | J45: =SUM(J42:J44) -> #REF! | K45: =SUM(K42:K44) -> #REF! | L45: =SUM(L42:L44) -> #REF! | M45: =SUM(M42:M44) -> #VALUE! | ... R45: =SUM(R42:R44) -> #REF!
...

Sheet Proforma Resi
B1: BRUNDAGE - RESI DEVELOPMENT: PROFORMA | AB1: AMU Fee | AC1: =+IF(AC2<0,-$C$193*AC2,0) -> 0 | AD1: =+IF(AD2<0,-$C$193*AD2,0) -> #REF! | AE1: =+IF(AE2<0,-$C$193*AE2,0) -> #REF! | AF1: =+IF(AF2<0,-$C$193*AF2,0) -> #REF! | AG1: =+IF(AG2<0,-$C$193*AG2,0) -> #REF! | AH1: =+IF(AH2<0,-$C$193*AH2,0) -> #REF! | AI1: =+IF(AI2<0,-$C$193*AI2,0) -> #REF! | AJ1: =+IF(AJ2<0,-$C$193*AJ2,0) -> #REF!
B2: Build & Sales Proforma | AB2: Cumulative PM (Equity) Cash Position | AC2: =+'Returns Resi'!F30 -> 0 | AD2: =+'Returns Resi'!G40 -> #REF! | AE2: =+'Returns Resi'!H40 -> #REF! | AF2: =+'Returns Resi'!I40 -> #REF! | AG2: =+'Returns Resi'!J40 -> #REF! | AH2: =+'Returns Resi'!K40 -> #REF! | AI2: =+'Returns Resi'!L40 -> #REF! | AJ2: =+'Returns Resi'!M40 -> #REF!
E3: 0 | F3: =E3+1 -> 1 | G3: =F3+1 -> 2 | H3: =G3+1 -> 3 | I3: =H3+1 -> 4 | J3: =I3+1 -> 5 | K3: =J3+1 -> 6 | L3: =K3+1 -> 7 | M3: =L3+1 -> 8 | ... Q3: =P3+1 -> 12 | AC3: Year 0 | AD3: Year 1 | AE3: Year 2 | AF3: Year 3 | AG3: Year 4 | AH3: Year 5 | AI3: Year 6 | AJ3: Year 7
E4: =Assumptions!C6 -> 2024 | F4: =E4+1 -> 2025 | G4: =F4+1 -> 2026 | H4: =G4+1 -> 2027 | I4: =H4+1 -> 2028 | J4: =I4+1 -> 2029 | K4: =J4+1 -> 2030 | L4: =K4+1 -> 2031 | M4: =L4+1 -> 2032 | ... Q4: =P4+1 -> 2036 | R4: TOTALS
C5: Average. Sqft of Lots | D5: Average Unit Size (sf) | E5: 44927 | F5: =E5+365 -> 45292 | G5: =F5+366 -> 45658 | H5: =G5+365 -> 46023 | I5: =H5+365 -> 46388 | J5: =I5+365 -> 46753 | K5: =J5+366 -> 47119 | L5: =K5+365 -> 47484 | M5: =L5+365 -> 47849 | N5: =M5+365 -> 48214 | O5: =N5+365 -> 48579 | P5: =O5+366 -> 48945 | Q5: =P5+365 -> 49310 | S5: Basis per Lot+Unit
A6: Map | B6: Buildout schedule | D6: Unit Size
B7: ='Proforma Resi'!E265 -> Phase 1: Downhill SFR | C7: 10000 | D7: ='Proforma Resi'!G265 -> 2650 | F7: 1 | G7: 1 | H7: 5 | I7: 3 | R7: =SUM(F7:Q7) -> 10 | S7: =D7*F23 -> 3776250 | T7: =R7*S7 -> 37762500 | V7: =SUMPRODUCT(D7,R7) -> 26500
B8: ='Proforma Resi'!E266 -> Phase 1: Uphill SFR | C8: 10000 | D8: ='Proforma Resi'!G266 -> 2405 | F8: 1 | G8: 2 | R8: =SUM(F8:Q8) -> 3 | S8: =D8*F24 -> 3487250 | T8: =R8*S8 -> 10461750 | V8: =SUMPRODUCT(D8,R8) -> 7215
B9: ='Proforma Resi'!E267 -> Phase 1: Uphill/Downhill Duplex | C9: 5000 | D9: ='Proforma Resi'!G267 -> 1783 | F9: 2 | G9: 8 | H9: 4 | I9: 8 | R9: =SUM(F9:Q9) -> 22 | S9: =D9*F25 -> 2451625 | T9: =R9*S9 -> 53935750 | V9: =SUMPRODUCT(D9,R9) -> 39226
B10: ='Proforma Resi'!E268 -> Phase 1: Multi-unit | C10: 5000 | D10: ='Proforma Resi'!G268 -> 1350 | G10: 4 | H10: 4 | R10: =SUM(F10:Q10) -> 8 | S10: =D10*F26 -> 1957500 | T10: =R10*S10 -> 15660000 | V10: =SUMPRODUCT(D10,R10) -> 10800
B11: Total starts | F11: =SUM(F7:F10) -> 4 | G11: =SUM(G7:G10) -> 15 | H11: =SUM(H7:H10) -> 13 | I11: =SUM(I7:I10) -> 11 | J11: =SUM(J7:J10) -> 0 | K11: =SUM(K7:K10) -> 0 | L11: =SUM(L7:L10) -> 0 | M11: =SUM(M7:M10) -> 0 | ... R11: =SUM(R7:R10) -> 43 | S11: TOTAL HOMES | T11: =SUM(T7:T10) -> 117820000 | V11: =SUMPRODUCT(D7:D10,R7:R10) -> 83741 | W11: /sf | X11: =SUM(T7:T10)/V11 -> 1406.9572 | Y11: /sf | Z11: /sf
B12: Total Sellable SQFT | C12: =SUMPRODUCT(C7:C10,R7:R10) -> 280000 | D12: =SUMPRODUCT(D7:D10,R7:R10) -> 83741 | T12: =T11/R11 -> 2740000 | U12: Average
B13: Total Sellable ACRES | C13: =C12/43560 -> 6.4279155
B15: Sales Schedule
B16: =B7 -> Phase 1: Downhill SFR | C16: =R7 -> 10 | F16: 0 | G16: =F7 -> 1 | H16: =G7 -> 1 | I16: =H7 -> 5 | J16: =I7 -> 3 | K16: =J7 -> 0 | L16: =K7 -> 0 | M16: =L7 -> 0 | N16: =M7 -> 0 | ... Q16: =P7 -> 0 | R16: =SUM(F16:Q16) -> 10 | AC16: =+_xlfn.XLOOKUP($T16,$D$23:$D$26,O$23:O$26) -> 2541.4559 | AD16: =+_xlfn.XLOOKUP($T16,$D$23:$D$26,P$23:P$26) -> 2732.0651 | AE16: =+_xlfn.XLOOKUP($T16,$D$23:$D$26,Q$23:Q$26) -> 2936.97
B17: =B8 -> Phase 1: Uphill SFR | C17: =R8 -> 3 | F17: 0 | G17: =F8 -> 1 | H17: =G8 -> 2 | I17: =H8 -> 0 | J17: =I8 -> 0 | K17: =J8 -> 0 | L17: =K8 -> 0 | M17: =L8 -> 0 | N17: =M8 -> 0 | ... Q17: =P8 -> 0 | R17: =SUM(F17:Q17) -> 3 | AC17: =+AC16 -> 2541.4559 | AD17: =+AD16 -> 2732.0651 | AE17: =+AE16 -> 2936.97
B18: =B9 -> Phase 1: Uphill/Downhill Duplex | C18: =R9 -> 22 | F18: 0 | G18: =F9 -> 2 | H18: =G9 -> 8 | I18: =H9 -> 4 | J18: =I9 -> 8 | K18: =J9 -> 0 | L18: =K9 -> 0 | M18: =L9 -> 0 | N18: =M9 -> 0 | ... Q18: =P9 -> 0 | R18: =SUM(F18:Q18) -> 22 | AC18: =+_xlfn.XLOOKUP($T18,$D$23:$D$26,O$23:O$26) -> 2541.4559 | AD18: =+_xlfn.XLOOKUP($T18,$D$23:$D$26,P$23:P$26) -> 2732.0651 | AE18: =+_xlfn.XLOOKUP($T18,$D$23:$D$26,Q$23:Q$26) -> 2936.97
B19: =B10 -> Phase 1: Multi-unit | C19: =R10 -> 8 | F19: 0 | G19: =F10 -> 0 | H19: =G10 -> 4 | I19: =H10 -> 4 | J19: =I10 -> 0 | K19: =J10 -> 0 | L19: =K10 -> 0 | M19: =L10 -> 0 | N19: =M10 -> 0 | ... Q19: =P10 -> 0 | R19: =SUM(F19:Q19) -> 8 | AC19: =+AC18 -> 2541.4559 | AD19: =+AD18 -> 2732.0651 | AE19: =+AE18 -> 2936.97
B20: Total sales | C20: =SUM(C16:C19) -> 43 | F20: =SUM(F16:F19) -> 0 | G20: =SUM(G16:G19) -> 4 | H20: =SUM(H16:H19) -> 15 | I20: =SUM(I16:I19) -> 13 | J20: =SUM(J16:J19) -> 11 | K20: =SUM(K16:K19) -> 0 | L20: =SUM(L16:L19) -> 0 | M20: =SUM(M16:M19) -> 0 | ... R20: =SUM(R16:R19) -> 43
B22: Sales Price Escalation
B23: Phase 1: Large SFR | C23: 0.075 | F23: ='Proforma Resi'!H265 -> 1425 | G23: ='Proforma Resi'!H265 -> 1425 | H23: =G23*(1+$C23) -> 1531.875 | I23: =H23*(1+$C23) -> 1646.7656 | J23: =I23*(1+$C23) -> 1770.273 | K23: =J23*(1+$C23) -> 1903.0435 | L23: =K23*(1+$C23) -> 2045.7718 | M23: =L23*(1+$C23) -> 2199.2047 | N23: =M23*(1+$C$23) -> 2364.145 | O23: =N23*(1+$C$23) -> 2541.4559 | P23: =O23*(1+$C$23) -> 2732.0651 | Q23: =P23*(1+$C$23) -> 2936.97
B24: Phase 1: Small SFR | C24: 0.075 | F24: ='Proforma Resi'!H266 -> 1450 | G24: 1450 | H24: =G24*(1+$C24) -> 1558.75 | I24: =H24*(1+$C24) -> 1675.6562 | J24: =I24*(1+$C24) -> 1801.3305 | K24: =J24*(1+$C24) -> 1936.4303 | L24: =K24*(1+$C24) -> 2081.6625 | M24: =L24*(1+$C24) -> 2237.7872 | N24: =M24*(1+$C$24) -> 2405.6213 | O24: =N24*(1+$C$24) -> 2586.0428 | P24: =O24*(1+$C$24) -> 2779.9961 | Q24: =P24*(1+$C$24) -> 2988.4958
B25: Phase 1: Small Duplex | C25: 0.075 | F25: ='Proforma Resi'!H267 -> 1375 | G25: 1375 | H25: =G25*(1+$C25) -> 1478.125 | I25: =H25*(1+$C25) -> 1588.9844 | J25: =I25*(1+$C25) -> 1708.1582 | K25: =J25*(1+$C25) -> 1836.2701 | L25: =K25*(1+$C25) -> 1973.9903 | M25: =L25*(1+$C25) -> 2122.0396 | N25: =M25*(1+$C$25) -> 2281.1926 | O25: =N25*(1+$C$25) -> 2452.282 | P25: =O25*(1+$C$25) -> 2636.2032 | Q25: =P25*(1+$C$25) -> 2833.9184
B26: Phase 1: Multi-unit | C26: 0.075 | F26: ='Proforma Resi'!H268 -> 1450 | G26: ='Proforma Resi'!H268 -> 1450 | H26: ='Proforma Resi'!H268 -> 1450 | I26: ='Proforma Resi'!H268 -> 1450 | J26: =I26*(1+$C26) -> 1558.75 | K26: =J26*(1+$C26) -> 1675.6562 | L26: =K26*(1+$C26) -> 1801.3305 | M26: =L26*(1+$C26) -> 1936.4303 | N26: =M26*(1+$C$26) -> 2081.6625 | O26: =N26*(1+$C$26) -> 2237.7872 | P26: =O26*(1+$C$26) -> 2405.6213 | Q26: =P26*(1+$C$26) -> 2586.0428
B27: Average Sales $ per Unit | G27: =IFERROR(SUM(F42+G44)/G20,"") -> 3041687.5 | H27: =IFERROR(SUM(G42+H44)/H20,"") -> 2698068.8 | I27: =IFERROR(SUM(H42+I44)/I20,"") -> 3152483.2 | J27: =IFERROR(SUM(I42+J44)/J20,"") -> 3494439.9 | K27: =IFERROR(SUM(J42+K44)/K20,"") | L27: =IFERROR(SUM(K42+L44)/L20,"") | M27: =IFERROR(SUM(L42+M44)/M20,"") | N27: =IFERROR(SUM(M42+N44)/N20,"") | ... Q27: =IFERROR(SUM(P42+Q44)/Q20,"")
B28: SOURCES | T28: Loan / Equity Financing | W28: Project Financing Metrics
B29: CM - PURSUIT CAPITAL | E29: 75000 | L29: 0 | R29: =SUM(E29:Q29) -> 75000 | T29: Year 0-2 Dev Cost | U29: =SUM(E197:G197) -> #REF! | V29: Actual | W29: VALUE OF SPEC DEV | Y29: =SUMPRODUCT(D7:D10,F7:F10,F23:F26) -> 12166750
B30: PM1 - EQUITY CONTRIBUTION (LAND) | F30: $11.7M in LAND CONTRIBUTION SHOWN ON BALANCE SHEET OF DEV LLC | T30: Financing Cost Gross-Up | U30: =U29*(1+Assumptions!#REF!) -> #REF! | V30: =U29+SUMIF(E3:Q3,"<="&Assumptions!G6,'Proforma Resi'!E201:Q201)+R202 -> #REF! | W30: ETV | Y30: =(R32)/Y29 -> #REF!
B31: PM2 - EQUITY (CASH) | F31: =U34-SUM(E29:F29) -> #REF! | L31: 0 | R31: =SUM(E31:Q31) -> #REF! | T31: Year 0-2 Unit Sales | U31: =SUM(E44:G44) -> 12166750 | W31: LTV | Y31: =R35/(Y29+R64+F72+G72) -> #REF!
B32: EQUITY / PROJECT ACQUISITION + ENTITLEMENT | E32: =SUM(E29:E31) -> 75000 | F32: =SUM(F29:F31) -> #REF! | G32: =SUM(G29:G31) -> 0 | H32: =SUM(H29:H31) -> 0 | I32: =SUM(I29:I31) -> 0 | J32: =SUM(J29:J31) -> 0 | K32: =SUM(K29:K31) -> 0 | L32: =SUM(L29:L31) -> 0 | ... R32: =SUM(R29:R31) -> #REF! | T32: LTC | U32: =Assumptions!F7 -> 0.8118774 | W32: LTC Total (INCL LAND VALUE) | Y32: =(R35/(R58+R32+R35)) -> #REF!
T33: Loan Amount | U33: =U30*U32 -> #REF! | V33: Actual
B34: Development Loan | C34: =U33 -> #REF! | E34: 0 | F34: =MAX(F197-F32-F44-E230,0) -> #REF! | G34: =MAX(G197-G32-G44-F230,0) -> #REF! | H34: =MAX(H197-H32-H44-G230,0) -> #REF! | I34: =MAX(I197-I32-I44-H230,0) -> #REF! | J34: =MAX(J197-J32-J44-I230,0) -> #REF! | K34: =MAX(K197-K32-K44-J230,0) -> #REF! | L34: =MAX(L197-L32-L44-K230,0) -> #REF! | M34: =MAX(M197-M32-M44-L230,0) -> #REF! | O34: =MAX(O197-O32-O44-N230,0) -> #REF! | P34: =MAX(P197-P32-P44-O230,0) -> #REF! | Q34: =MAX(Q197-Q32-Q44-P230,0) -> #REF! | R34: =SUM(E34:Q34) -> #REF! | T34: Initial Equity | U34: =U30-U33-C56*0.89 -> #REF! | V34: =U34+C56 -> #REF!
B35: DEBT | E35: =SUM(E34:E34) -> 0 | F35: =SUM(F34:F34) -> #REF! | G35: =SUM(G34:G34) -> #REF! | H35: =SUM(H34:H34) -> #REF! | I35: =SUM(I34:I34) -> #REF! | J35: =SUM(J34:J34) -> #REF! | K35: =SUM(K34:K34) -> #REF! | L35: =SUM(L34:L34) -> #REF! | ... Q35: =SUM(Q34:Q34) -> #REF! | R35: =SUM(E35:Q35) -> #REF!
B37: Construction Start Draw
B38: Foundation Complete Draw
B39: Structure Complete Draw
B40: MEP 4-way Draw
B41: Finishes Start Draw
B42: PRESALE REVENUES | C42: =SUM(C37:C41) -> 0 | E42: =SUM(E37:E41) -> 0 | F42: =SUM(F37:F41) -> 0 | G42: =SUM(G37:G41) -> 0 | H42: =SUM(H37:H41) -> 0 | I42: =SUM(I37:I41) -> 0 | J42: =SUM(J37:J41) -> 0 | K42: =SUM(K37:K41) -> 0 | L42: =SUM(L37:L41) -> 0 | ... P42: =SUM(P37:P41) -> 0 | R42: =SUM(E42:Q42) -> 0 | T42: TOTAL HOME SALES
B43: INFRASTRUCTURE REPAYMENT FROM HOTEL PROFORMA | H43: ='Proforma A+H'!#REF! -> #REF!
...

Sheet Returns Resi
B1: BRUNDAGE - Resi DEVELOPMENT: RETURNS
B2: Returns Analysis
B4: PROJECT FINANCING ANALYSIS | F4: PROJECT RETURNS ANALYSIS
B5: TOTAL PROJECT CAPITAL NEEDS | D5: =SUM('Proforma Resi'!R32,'Proforma Resi'!R35) -> #REF! | F5: TOTAL RETURN | H5: =D54 -> #REF!
B6: TOTAL PROJECT VALUE (PV of FINAL BUILD OUT) | D6: ='Proforma Resi'!T11 -> 117820000 | F6: INVESTED CAPITAL | H6: =D55 -> #REF!
B7: STARTING SPEC DEVELOPMENT VALUE | D7: ='Proforma Resi'!G44+'Proforma Resi'!F42 -> 12166750 | F7: NET PROFIT | H7: =D56 -> #REF!
B8: EQUITY to SPEC DEV VALUE (ETV) | D8: ='Proforma Resi'!Y30 -> #REF! | F8: EQUITY MULTIPLE | H8: =H5/H6 -> #REF!
B9: LOAN to COST (LTC) | D9: ='Proforma Resi'!Y32 -> #REF! | F9: ROI | H9: =H7/H6 -> #REF!
B10: LOAN to VALUE (LTV) | D10: ='Proforma Resi'!Y31 -> #REF! | F10: IRR | H10: =XIRR(F56:N56,F20:N20) -> #REF!
B12: BUSINESS CASE ANALYSIS
B13: TOTAL PROJECT REVENUE (less brokers fees): | D13: =('Proforma Resi'!R44+'Proforma Resi'!R42)-'Proforma Resi'!R172 -> 1.2545596e+08 | J13: Current Assumptions
B14: - TOTAL PROJECT COST | D14: ='Proforma Resi'!R197-'Proforma Resi'!R172+'Proforma Resi'!R202+'Proforma Resi'!R201 -> #REF! | J14: Vertical Const. Costs Scalar | L14: 1
B15: = NET PROFIT | D15: =D13-D14 -> #REF! | J15: Sales Price Scalar | L15: 1
B16: NET PROFIT %: | D16: =D15/D13 -> #REF!
B17: RETURN on EQUITY/CAPTIAL (ROE): | D17: =D15/H6 -> #REF!
F18: ='Proforma Resi'!E3 -> 0 | G18: ='Proforma Resi'!F3 -> 1 | H18: ='Proforma Resi'!G3 -> 2 | I18: ='Proforma Resi'!H3 -> 3 | J18: ='Proforma Resi'!I3 -> 4 | K18: ='Proforma Resi'!J3 -> 5 | L18: ='Proforma Resi'!K3 -> 6 | M18: ='Proforma Resi'!L3 -> 7 | ... R18: ='Proforma Resi'!Q3 -> 12
F19: =Assumptions!C6 -> 2024 | G19: =F19+1 -> 2025 | H19: =G19+1 -> 2026 | I19: =H19+1 -> 2027 | J19: =I19+1 -> 2028 | K19: =J19+1 -> 2029 | L19: =K19+1 -> 2030 | M19: =L19+1 -> 2031 | N19: =M19+1 -> 2032 | ... R19: =Q19+1 -> 2036
B20: SUMMARY OF RETURNS | F20: =DATE(F19,12,31) -> 45657 | G20: =EDATE(F20,12) -> 46022 | H20: =EDATE(G20,12) -> 46387 | I20: =EDATE(H20,12) -> 46752 | J20: =EDATE(I20,12) -> 47118 | K20: =EDATE(J20,12) -> 47483 | L20: =EDATE(K20,12) -> 47848 | M20: =EDATE(L20,12) -> 48213 | N20: =EDATE(M20,12) -> 48579 | ... R20: =EDATE(Q20,12) -> 50040
B21: Preferred Members 1 (PM1) Returns
B22: Land Repayment | D22: =SUM(F22:R22) -> 15000000 | F22: ='Proforma Resi'!E50+'Proforma Resi'!E54 -> 0 | G22: ='Proforma Resi'!F50+'Proforma Resi'!F54 -> 3000000 | H22: ='Proforma Resi'!G50+'Proforma Resi'!G54 -> 1703345 | I22: ='Proforma Resi'!H50+'Proforma Resi'!H54 -> 5665944.4 | J22: ='Proforma Resi'!I50+'Proforma Resi'!I54 -> 4630710.6 | K22: ='Proforma Resi'!J50+'Proforma Resi'!J54 -> 0 | L22: ='Proforma Resi'!K50+'Proforma Resi'!K54 -> 0 | M22: ='Proforma Resi'!L50+'Proforma Resi'!L54 -> 0 | ... R22: ='Proforma Resi'!Q50+'Proforma Resi'!Q54 -> 0
B23: Interest | D23: =SUM(F23:R23) -> #REF! | F23: ='Proforma Resi'!E57 -> 0 | G23: ='Proforma Resi'!F57 -> #REF! | H23: ='Proforma Resi'!G57 -> #REF! | I23: ='Proforma Resi'!H57 -> #REF! | J23: ='Proforma Resi'!I57 -> #REF! | K23: ='Proforma Resi'!J57 -> #REF! | L23: ='Proforma Resi'!K57 -> #REF! | M23: ='Proforma Resi'!L57 -> #REF! | ... R23: ='Proforma Resi'!Q57 -> #REF!
B24: ="Additional Profit Split ("&TEXT(Assumptions!#REF!,"0%")&")" -> #REF! | D24: =SUM(F24:R24) -> #REF! | F24: ='Proforma Resi'!E223 -> 0 | G24: ='Proforma Resi'!F223 -> #REF! | H24: ='Proforma Resi'!G223 -> #REF! | I24: ='Proforma Resi'!H223 -> #REF! | J24: ='Proforma Resi'!I223 -> #REF! | K24: ='Proforma Resi'!J223 -> #REF! | L24: ='Proforma Resi'!K223 -> #REF! | M24: ='Proforma Resi'!L223 -> #REF! | ... R24: ='Proforma Resi'!Q223 -> #REF!
B25: Total PM Distributions | D25: =SUM(F25:R25) -> #REF! | F25: =SUM(F22:F24) -> 0 | G25: =SUM(G22:G24) -> #REF! | H25: =SUM(H22:H24) -> #REF! | I25: =SUM(I22:I24) -> #REF! | J25: =SUM(J22:J24) -> #REF! | K25: =SUM(K22:K24) -> #REF! | L25: =SUM(L22:L24) -> #REF! | M25: =SUM(M22:M24) -> #REF! | ... R25: =SUM(R22:R24) -> #REF!
B26: Total PM Contributions | D26: =SUM(F26:R26) -> 15000000 | G26: ='Proforma Resi'!C56 -> 15000000 | H26: 0 | I26: 0 | J26: 0 | K26: 0 | L26: 0 | M26: 0 | N26: 0 | O26: 0 | P26: 0 | Q26: 0 | R26: 0
B27: PM Net Profit / Cash Flows | D27: =SUM(F27:R27) -> #REF! | F27: =F25-F26 -> 0 | G27: =G25-G26 -> #REF! | H27: =H25-H26 -> #REF! | I27: =I25-I26 -> #REF! | J27: =J25-J26 -> #REF! | K27: =K25-K26 -> #REF! | L27: =L25-L26 -> #REF! | M27: =M25-M26 -> #REF! | ... R27: =R25-R26 -> #REF!
B28: PM IRR | F28: =XIRR(G27:R27,G20:R20) -> #REF!
B29: PM Equity Multiple | F29: =SUMIF(F27:R27,">0")/-SUMIF(F27:R27,"<0") -> #DIV/0!
B30: Cumulative PM (Equity) Cash Position | F30: =F27+E30 -> 0 | G30: =G27+F30 -> #REF! | H30: =H27+G30 -> #REF! | I30: =I27+H30 -> #REF! | J30: =J27+I30 -> #REF! | K30: =K27+J30 -> #REF! | L30: =L27+K30 -> #REF! | M30: =M27+L30 -> #REF! | ... R30: =R27+Q30 -> #REF!
B32: Preferred Members 2 (PM2) Returns
B33: Preferred Returns | D33: =SUM(F33:R33) -> 0 | F33: ='Proforma Resi'!E221 -> 0 | G33: ='Proforma Resi'!F221 -> 0 | H33: ='Proforma Resi'!G221 -> 0 | I33: ='Proforma Resi'!H221 -> 0 | J33: ='Proforma Resi'!I221 -> 0 | K33: ='Proforma Resi'!J221 -> 0 | L33: ='Proforma Resi'!K221 -> 0 | M33: ='Proforma Resi'!L221 -> 0 | ... R33: ='Proforma Resi'!Q221 -> 0
B34: ="Additional Profit Split ("&TEXT(Assumptions!#REF!,"0%")&")" -> #REF! | D34: =SUM(F34:R34) -> #REF! | F34: ='Proforma Resi'!E224 -> 0 | G34: ='Proforma Resi'!F224 -> #REF! | H34: ='Proforma Resi'!G224 -> #REF! | I34: ='Proforma Resi'!H224 -> #REF! | J34: ='Proforma Resi'!I224 -> #REF! | K34: ='Proforma Resi'!J224 -> #REF! | L34: ='Proforma Resi'!K224 -> #REF! | M34: ='Proforma Resi'!L224 -> #REF! | ... R34: ='Proforma Resi'!Q224 -> #REF!
B35: Total PM Distributions | D35: =SUM(F35:R35) -> #REF! | F35: =SUM(F33:F34) -> 0 | G35: =SUM(G33:G34) -> #REF! | H35: =SUM(H33:H34) -> #REF! | I35: =SUM(I33:I34) -> #REF! | J35: =SUM(J33:J34) -> #REF! | K35: =SUM(K33:K34) -> #REF! | L35: =SUM(L33:L34) -> #REF! | M35: =SUM(M33:M34) -> #REF! | ... R35: =SUM(R33:R34) -> #REF!
B36: Total PM Contributions | D36: =SUM(F36:R36) -> #REF! | F36: ='Proforma Resi'!E31 -> 0 | G36: ='Proforma Resi'!F31 -> #REF! | H36: ='Proforma Resi'!G31 -> 0 | I36: ='Proforma Resi'!H31 -> 0 | J36: ='Proforma Resi'!I31 -> 0 | K36: ='Proforma Resi'!J31 -> 0 | L36: ='Proforma Resi'!K31 -> 0 | M36: ='Proforma Resi'!L31 -> 0 | ... R36: ='Proforma Resi'!Q31 -> 0
B37: PM Net Profit / Cash Flows | D37: =SUM(F37:R37) -> #REF! | F37: =F35-F36 -> 0 | G37: =G35-G36 -> #REF! | H37: =H35-H36 -> #REF! | I37: =I35-I36 -> #REF! | J37: =J35-J36 -> #REF! | K37: =K35-K36 -> #REF! | L37: =L35-L36 -> #REF! | M37: =M35-M36 -> #REF! | ... R37: =R35-R36 -> #REF!
B38: PM IRR | F38: =XIRR(G37:R37,G20:R20) -> #REF!
B39: PM Equity Multiple | F39: =SUMIF(F37:R37,">0")/-SUMIF(F37:R37,"<0") -> #DIV/0!
B40: Cumulative PM (Equity) Cash Position | F40: =F37+E40 -> 0 | G40: =G37+F40 -> #REF! | H40: =H37+G40 -> #REF! | I40: =I37+H40 -> #REF! | J40: =J37+I40 -> #REF! | K40: =K37+J40 -> #REF! | L40: =L37+K40 -> #REF! | M40: =M37+L40 -> #REF! | ... R40: =R37+Q40 -> #REF!
B42: Common Members (CM) Returns
B43: ="CM Profit Split ("&TEXT(Assumptions!#REF!,"0%")&")" -> #REF! | D43: =SUM(F43:R43) -> #REF! | F43: ='Proforma Resi'!E225 -> 0 | G43: ='Proforma Resi'!F225 -> #REF! | H43: ='Proforma Resi'!G225 -> #REF! | I43: ='Proforma Resi'!H225 -> #REF! | J43: ='Proforma Resi'!I225 -> #REF! | K43: ='Proforma Resi'!J225 -> #REF! | L43: ='Proforma Resi'!K225 -> #REF! | M43: ='Proforma Resi'!L225 -> #REF! | ... R43: ='Proforma Resi'!Q225 -> #REF!
B44: Total CM Contributions | D44: =SUM(F44:R44) -> 75000 | F44: ='Proforma Resi'!E29 -> 75000 | G44: ='Proforma Resi'!F29 -> 0 | H44: ='Proforma Resi'!G29 -> 0 | I44: ='Proforma Resi'!H29 -> 0 | J44: ='Proforma Resi'!I29 -> 0 | K44: ='Proforma Resi'!J29 -> 0 | L44: ='Proforma Resi'!K29 -> 0 | M44: ='Proforma Resi'!L29 -> 0 | ... R44: ='Proforma Resi'!Q29 -> 0
...

Sheet Proforma Land+Home
B1: CLARENDON - LAND & HOME DEVELOPMENT | AC1: Year 0 | AD1: Year 1 | AE1: Year 2 | AF1: Year 3 | AG1: Year 4 | AH1: Year 5 | AI1: Year 6 | AJ1: Year 7
B2: Build & Sales Proforma
E3: Year 0 | F3: Year 1 | G3: Year 2 | H3: Year 3 | I3: Year 4 | J3: Year 5 | K3: Year 6 | L3: Year 7 | M3: Year 8 | N3: Year 9 | O3: Year 10 | P3: Year 11 | Q3: Year 12 | Z3: Checks | AA3: =SUM(AA4:AA210) -> #REF!
D4: FY | E4: 2025 | F4: =E4+1 -> 2026 | G4: =F4+1 -> 2027 | H4: =G4+1 -> 2028 | I4: =H4+1 -> 2029 | J4: =I4+1 -> 2030 | K4: =J4+1 -> 2031 | L4: =K4+1 -> 2032 | M4: =L4+1 -> 2033 | ... Q4: =P4+1 -> 2037 | R4: TOTALS
E5: 45658 | F5: =E5+365 -> 46023 | G5: =F5+365 -> 46388 | H5: =G5+365 -> 46753 | I5: =H5+366 -> 47119 | J5: =I5+365 -> 47484 | K5: =J5+365 -> 47849 | L5: =K5+365 -> 48214 | M5: =L5+365 -> 48579 | N5: =M5+365 -> 48944 | O5: =N5+365 -> 49309 | P5: =O5+366 -> 49675 | Q5: =P5+365 -> 50040 | S5: Basis per Lot+Unit
A6: Map | B6: Buildout schedule | D6: Avg Unit Size
A7: A- | B7: Pondside Cabins @ Event Barn (13ea) | D7: 1500 | R7: =SUM(F7:Q7) -> 0 | S7: =D7*$E$34 -> 2775000 | T7: =R7*S7 -> 0 | V7: =#REF!*#REF! -> #REF!
A8: B- | B8: Village Cabins (13ea) | D8: 2000 | R8: =SUM(F8:Q8) -> 0 | S8: =D8*$E$34 -> 3700000 | T8: =R8*S8 -> 0
A9: C- | B9: Village Cottages (13ea) | D9: 2500 | R9: =SUM(F9:Q9) -> 0 | S9: =D9*$E$34 -> 4625000 | T9: =R9*S9 -> 0
A10: D- | B10: Guest Cabins @ Fitness Spa (13ea) | D10: 2500 | R10: =SUM(F10:Q10) -> 0 | S10: =D10*$E$34 -> 4625000 | T10: =R10*S10 -> 0
A11: F- | B11: Jimmy Creek Homes (4ea) | D11: 3500 | E11: 4 | R11: =SUM(E11:Q11) -> 4 | S11: =D11*$E$32 -> 6125000 | T11: =R11*S11 -> 24500000
A12: G- | B12: Bench Homesites (15ea) | D12: 3250 | F12: 8 | G12: 7 | R12: =SUM(E12:Q12) -> 15 | S12: =D12*$E$32 -> 5687500 | T12: =R12*S12 -> 85312500
A13: H- | B13: Forest Homesites (10ea) | D13: 3750 | G13: 5 | H13: 5 | R13: =SUM(E13:Q13) -> 10 | S13: =D13*$E$32 -> 6562500 | T13: =R13*S13 -> 65625000 | U13: Improved Value Before Escalation
A14: J- | B14: Hillside Homesites (10ea) | D14: 3750 | H14: 7 | I14: 3 | R14: =SUM(E14:Q14) -> 10 | S14: =D14*$E$32 -> 6562500 | T14: =R14*S14 -> 65625000
A15: E- | B15: Village Homesites (6ea) | D15: 4500 | R15: =SUM(E15:Q15) -> 0 | S15: =D15*$E$33 -> 7875000 | T15: =R15*S15 -> 0
A16: K- | B16: Deer Creek Homesites (5ea + 1 lot used for Clubhouse) | D16: 3500 | E16: 1 | J16: 5 | R16: =SUM(E16:Q16) -> 6 | S16: =D16*$E$34 -> 6475000 | T16: =R16*S16 -> 38850000
B17: Total starts | E17: =SUM(E7:E16) -> 5 | F17: =SUM(F7:F16) -> 8 | G17: =SUM(G7:G16) -> 12 | H17: =SUM(H7:H16) -> 12 | I17: =SUM(I7:I16) -> 3 | J17: =SUM(J7:J16) -> 5 | K17: =SUM(K7:K16) -> 0 | L17: =SUM(L7:L16) -> 0 | ... R17: =SUM(R7:R16) -> 45 | S17: TOTAL HOMES | T17: =SUM(T7:T16) -> 279912500 | V17: =SUMPRODUCT(D7:D16,R7:R16) -> 158750 | W17: sf | X17: =SUM(T7:T16)/V17 -> 1763.2283 | Y17: /sf | Z17: /sf
B18: Total Sellable SQFT | D18: =SUMPRODUCT(D7:D16,R7:R16) -> 158750 | T18: =T17/R17 -> 6220277.8 | U18: Average | V18: =D18/R17 -> 3527.7778
B20: Sales Schedule | U20: Year 1 | V20: Year 2 | W20: Year 3 | X20: Year 4 | Y20: Year 5 | Z20: Year 6 | AA20: Year 7
B21: =B7 -> Pondside Cabins @ Event Barn (13ea) | C21: =R7 -> 0 | D21: =T21 -> Cottages | G21: =F7 -> 0 | H21: =G7 -> 0 | I21: =H7 -> 0 | J21: =I7 -> 0 | K21: =J7 -> 0 | L21: =K7 -> 0 | M21: =L7 -> 0 | N21: =M7 -> 0 | ... Q21: =P7 -> 0 | R21: =SUM(F21:Q21) -> 0 | T21: Cottages | U21: =+F34 -> 1850 | V21: =+G34 -> 2035 | W21: =+H34 -> 2238.5 | X21: =+I34 -> 2462.35 | Y21: =+J34 -> 2708.585 | Z21: =+K34 -> 2979.4435 | AA21: {=+L34:P34} -> 3277.3879 | AB21: 3605.1266 | AC21: 3965.6393 | AD21: 4362.2032 | AE21: 4798.4236
B22: =B8 -> Village Cabins (13ea) | C22: =R8 -> 0 | D22: =T22 -> Cottages | G22: =F8 -> 0 | H22: =G8 -> 0 | I22: =H8 -> 0 | J22: =I8 -> 0 | K22: =J8 -> 0 | L22: =K8 -> 0 | M22: =L8 -> 0 | N22: =M8 -> 0 | ... Q22: =P8 -> 0 | R22: =SUM(F22:Q22) -> 0 | T22: Cottages | U22: =+U21 -> 1850 | V22: =+V21 -> 2035 | W22: =+W21 -> 2238.5 | X22: =+X21 -> 2462.35 | Y22: =+Y21 -> 2708.585 | Z22: =+Z21 -> 2979.4435 | AA22: =+AA21 -> 3277.3879
B23: =B9 -> Village Cottages (13ea) | C23: =R9 -> 0 | D23: =T23 -> Cottages | G23: =F9 -> 0 | H23: =G9 -> 0 | I23: =H9 -> 0 | J23: =I9 -> 0 | K23: =J9 -> 0 | L23: =K9 -> 0 | M23: =L9 -> 0 | N23: =M9 -> 0 | ... Q23: =P9 -> 0 | R23: =SUM(F23:Q23) -> 0 | T23: Cottages | U23: =+U22 -> 1850 | V23: =+V22 -> 2035 | W23: =+W22 -> 2238.5 | X23: =+X22 -> 2462.35 | Y23: =+Y22 -> 2708.585 | Z23: =+Z22 -> 2979.4435 | AA23: =+AA22 -> 3277.3879
B24: =B10 -> Guest Cabins @ Fitness Spa (13ea) | C24: =R10 -> 0 | D24: =T24 -> Cottages | G24: =F10 -> 0 | H24: =G10 -> 0 | I24: =H10 -> 0 | J24: =I10 -> 0 | K24: =J10 -> 0 | L24: =K10 -> 0 | M24: =L10 -> 0 | N24: =M10 -> 0 | ... Q24: =P10 -> 0 | R24: =SUM(F24:Q24) -> 0 | T24: Cottages | U24: =+U23 -> 1850 | V24: =+V23 -> 2035 | W24: =+W23 -> 2238.5 | X24: =+X23 -> 2462.35 | Y24: =+Y23 -> 2708.585 | Z24: =+Z23 -> 2979.4435 | AA24: =+AA23 -> 3277.3879
B25: =B11 -> Jimmy Creek Homes (4ea) | C25: =R11 -> 4 | D25: =T25 -> Village | F25: =E11 -> 4 | G25: =F11 -> 0 | H25: =G11 -> 0 | I25: =H11 -> 0 | J25: =I11 -> 0 | K25: =J11 -> 0 | L25: =K11 -> 0 | M25: =L15 -> 0 | N25: =M15 -> 0 | O25: =N15 -> 0 | P25: =O15 -> 0 | Q25: =P15 -> 0 | R25: =SUM(F25:Q25) -> 4 | T25: Village | U25: =+F32 -> 1750 | V25: =+G33 -> 1881.25 | W25: =+H33 -> 2022.3438 | X25: =+I33 -> 2174.0195 | Y25: =+J33 -> 2337.071 | Z25: =+K33 -> 2512.3513 | AA25: =+L33 -> 2700.7777
B26: =B12 -> Bench Homesites (15ea) | C26: =R12 -> 15 | D26: =T26 -> Homesites | F26: =E12 -> 0 | G26: =F12 -> 8 | H26: =G12 -> 7 | I26: =H12 -> 0 | J26: =I12 -> 0 | K26: =J12 -> 0 | L26: =K12 -> 0 | M26: =L11 -> 0 | N26: =M11 -> 0 | O26: =N11 -> 0 | P26: =O11 -> 0 | Q26: =P11 -> 0 | R26: =SUM(F26:Q26) -> 15 | T26: Homesites | U26: =+F32 -> 1750 | V26: =+G32 -> 1925 | W26: =+H32 -> 2117.5 | X26: =+I32 -> 2329.25 | Y26: =+J32 -> 2562.175 | Z26: =+K32 -> 2818.3925 | AA26: =+L32 -> 3100.2318
B27: =B13 -> Forest Homesites (10ea) | C27: =R13 -> 10 | D27: =T27 -> Homesites | F27: =E13 -> 0 | G27: =F13 -> 0 | H27: =G13 -> 5 | I27: =H13 -> 5 | J27: =I13 -> 0 | K27: =J13 -> 0 | L27: =K13 -> 0 | M27: =L12 -> 0 | N27: =M12 -> 0 | O27: =N12 -> 0 | P27: =O12 -> 0 | Q27: =P12 -> 0 | R27: =SUM(F27:Q27) -> 10 | T27: Homesites | U27: =+U26 -> 1750 | V27: =+V26 -> 1925 | W27: =+W26 -> 2117.5 | X27: =+X26 -> 2329.25 | Y27: =+Y26 -> 2562.175 | Z27: =+Z26 -> 2818.3925 | AA27: =+AA26 -> 3100.2318
B28: =B14 -> Hillside Homesites (10ea) | C28: =R14 -> 10 | D28: =T28 -> Homesites | F28: =E14 -> 0 | G28: =F14 -> 0 | H28: =G14 -> 0 | I28: =H14 -> 7 | J28: =I14 -> 3 | K28: =J14 -> 0 | L28: =K14 -> 0 | M28: =L14 -> 0 | ... P28: =O14 -> 0 | Q28: =P13 -> 0 | R28: =SUM(F28:Q28) -> 10 | T28: Homesites | U28: =+U27 -> 1750 | V28: =+V27 -> 1925 | W28: =+W27 -> 2117.5 | X28: =+X27 -> 2329.25 | Y28: =+Y27 -> 2562.175 | Z28: =+Z27 -> 2818.3925 | AA28: =+AA27 -> 3100.2318
B29: =B15 -> Village Homesites (6ea) | C29: =R15 -> 0 | D29: =T29 -> Homesites | F29: =E15 -> 0 | G29: =F15 -> 0 | H29: =G15 -> 0 | I29: =H15 -> 0 | J29: =I15 -> 0 | K29: =J15 -> 0 | L29: =K15 -> 0 | M29: =L14 -> 0 | N29: =M14 -> 0 | O29: =N14 -> 0 | P29: =O14 -> 0 | Q29: =P14 -> 0 | R29: =SUM(F29:Q29) -> 0 | T29: Homesites | U29: =+U28 -> 1750 | V29: =+V28 -> 1925 | W29: =+W28 -> 2117.5 | X29: =+X28 -> 2329.25 | Y29: =+Y28 -> 2562.175 | Z29: =+Z28 -> 2818.3925 | AA29: =+AA28 -> 3100.2318
B30: =B16 -> Deer Creek Homesites (5ea + 1 lot used for Clubhouse) | C30: =R16 -> 6 | D30: =T30 -> Cottages | F30: =E16 -> 1 | G30: =F16 -> 0 | H30: =G16 -> 0 | I30: =H16 -> 0 | J30: =I16 -> 0 | K30: =J16 -> 5 | L30: =K16 -> 0 | M30: =L16 -> 0 | ... Q30: =P16 -> 0 | R30: =SUM(F30:Q30) -> 6 | T30: Cottages | U30: =+U24 -> 1850 | V30: =+V24 -> 2035 | W30: =+W24 -> 2238.5 | X30: =+X24 -> 2462.35 | Y30: =+Y24 -> 2708.585 | Z30: =+Z24 -> 2979.4435 | AA30: =+AA24 -> 3277.3879
B31: Total sales | C31: =SUM(C21:C30) -> 45 | F31: =SUM(F21:F30) -> 5 | G31: =SUM(G21:G30) -> 8 | H31: =SUM(H21:H30) -> 12 | I31: =SUM(I21:I30) -> 12 | J31: =SUM(J21:J30) -> 3 | K31: =SUM(K21:K30) -> 5 | L31: =SUM(L21:L30) -> 0 | M31: =SUM(M21:M30) -> 0 | ... R31: =SUM(R21:R30) -> 45 | Z31: Check on Sales & Build out | AA31: =+R17-R31 -> 0
B32: Sales Price Escalation / Residential Sales Sqft Price | C32: =Assumptions!H18 -> 0.1 | D32: Homesites | E32: =Assumptions!G18 -> 1750 | F32: =E32 -> 1750 | G32: =F32*(1+$C$32) -> 1925 | H32: =G32*(1+$C$32) -> 2117.5 | I32: =H32*(1+$C$32) -> 2329.25 | J32: =I32*(1+$C$32) -> 2562.175 | K32: =J32*(1+$C$32) -> 2818.3925 | L32: =K32*(1+$C$32) -> 3100.2318 | M32: =L32*(1+$C$32) -> 3410.2549 | N32: =M32*(1+$C$32) -> 3751.2804 | ... Q32: =P32*(1+$C$32) -> 4992.9542
B33: Sales Price Escalation / Residential Sales Sqft Price | C33: =Assumptions!H19 -> 0.075 | D33: Village | E33: 1750 | F33: =E33 -> 1750 | G33: =F33*(1+$C$33) -> 1881.25 | H33: =G33*(1+$C$33) -> 2022.3438 | I33: =H33*(1+$C$33) -> 2174.0195 | J33: =I33*(1+$C$33) -> 2337.071 | K33: =J33*(1+$C$33) -> 2512.3513 | L33: =K33*(1+$C$33) -> 2700.7777 | M33: =L33*(1+$C$33) -> 2903.336 | N33: =M33*(1+$C$33) -> 3121.0862 | ... Q33: =P33*(1+$C$33) -> 3877.3156
B34: Sales Price Escalation / Residential Sales Sqft Price | C34: 0.1 | D34: Cottages | E34: =Assumptions!G20 -> 1850 | F34: =E34 -> 1850 | G34: =F34*(1+$C$34) -> 2035 | H34: =G34*(1+$C$34) -> 2238.5 | I34: =H34*(1+$C$34) -> 2462.35 | J34: =I34*(1+$C$34) -> 2708.585 | K34: =J34*(1+$C$34) -> 2979.4435 | L34: =K34*(1+$C$34) -> 3277.3879 | M34: =L34*(1+$C$34) -> 3605.1266 | N34: =M34*(1+$C$34) -> 3965.6393 | ... Q34: =P34*(1+$C$34) -> 5278.2659 | U34: Average Res Unit Sales Price
F35: Average Sales $ per Unit | H35: =SUM(G56+H57)/H31 -> 7323020.8 | I35: =SUM(H56+I57)/I31 -> 8734687.5 | J35: =SUM(I56+J57)/J31 -> 9608156.3 | K35: =SUM(J56+K57)/K31 -> 10428052 | T35: =(R56+R57)/R17 -> 7820141.6 | W35: =T35/T18 -> 1.2572013
B36: SOURCES
L37: 0 | R37: =SUM(E37:Q37) -> 0
B38: EQUITY INVESTMENT | L38: 0 | R38: =SUM(E38:Q38) -> 0 | T38: {=SUMPRODUCT(E11:E16*S11:S16)} -> 30975000 | U38: VALUE OF SPEC DEV
B39: SPONSOR - EQUITY CAPITAL | E39: 400000 | R39: =SUM(E39:Q39) -> 400000 | T39: =S39/S41 -> #DIV/0!
B40: LP - EQUITY CAPITAL | E40: 15000000 | R40: =SUM(E40:Q40) -> 15000000 | T40: =S40/S41 -> #DIV/0!
B41: EQUITY INVESTMENT | E41: =SUM(E39:E40) -> 15400000 | F41: =SUM(F39:F40) -> 0 | G41: =SUM(G39:G40) -> 0 | H41: =SUM(H39:H40) -> 0 | I41: =SUM(I39:I40) -> 0 | J41: =SUM(J39:J40) -> 0 | K41: =SUM(K39:K40) -> 0 | L41: =SUM(L39:L40) -> 0 | R41: =SUM(E41:Q41) -> 15400000 | S41: =S39+S40 -> 0 | T41: =(C176+E41)/T38 -> 0.49717514 | U41: ETV | V41: =25000000-E41 -> 9600000 | W41: =25000000-F41 -> 25000000 | Z41: Force to 40mm for total | AA41: =ROUND(40000000-R41,0) -> 24600000
...

Sheet Returns Land+Home
B1: ='Proforma Land+Home'!B1 -> CLARENDON - LAND & HOME DEVELOPMENT
B2: Returns Analysis
B4: PROJECT FINANCING ANALYSIS | F4: BUSINESS CASE ANALYSIS
B5: TOTAL PROJECT CAPITAL NEEDS: | D5: ='Proforma Land+Home'!R41+'Proforma Land+Home'!R48 -> 83066761 | F5: TOTAL PROJECT REVENUE (less brokers fees): | H5: =('Proforma Land+Home'!R51+'Proforma Land+Home'!R57+'Proforma Land+Home'!R56)-'Proforma Land+Home'!R121 -> 3.3911752e+08
B6: TOTAL PROJECT VALUE (PV of FINAL BUILD OUT): | D6: ='Proforma Land+Home'!T17 -> 279912500 | F6: - TOTAL PROJECT COST: | H6: ='Proforma Land+Home'!R143-'Proforma Land+Home'!R121+'Proforma Land+Home'!R148+'Proforma Land+Home'!R149+'Proforma Land+Home'!R159+'Proforma Land+Home'!R160+'Proforma Land+Home'!R165 -> 2.5078657e+08
B7: STARTING SPEC DEVELOPMENT VALUE: | D7: ='Proforma Land+Home'!T38 -> 30975000 | F7: = NET PROFIT | H7: =H5-H6 -> 88330954
B8: EQUITY to SPEC DEV VALUE (ETV): | D8: ='Proforma Land+Home'!T41 -> 0.49717514 | F8: NET PROFIT %: | H8: =H7/H5 -> 0.26047299
B9: LOAN to COST (LTC): | D9: ='Proforma Land+Home'!T46 -> 0.81460695 | F9: RETURN on EQUITY/CAPTIAL (ROE): | H9: =H7/'Proforma Land+Home'!E41 -> 5.7357762
B10: LOAN to VALUE (LTV): | D10: ='Proforma Land+Home'!T48 -> 0.11019829
B12: PROJECT RETURNS ANALYSIS
B13: PROJECT NET CASH FLOWS: | D13: =SUM('Proforma Land+Home'!E210:Q210) -> 88855954
B14: EQUITY MULTIPLE: | D14: ='Proforma Land+Home'!R204/-F48 -> 6.7698671
B15: MODELED ROI: | D15: =D13/-F48 -> 5.7698671
B16: PROJECT IRR : | D16: =XIRR('Proforma Land+Home'!E210:Q210,'Proforma Land+Home'!E5:Q5) -> 0.53538527
F18: ='Proforma Land+Home'!E3 -> Year 0 | G18: ='Proforma Land+Home'!F3 -> Year 1 | H18: ='Proforma Land+Home'!G3 -> Year 2 | I18: ='Proforma Land+Home'!H3 -> Year 3 | J18: ='Proforma Land+Home'!I3 -> Year 4 | K18: ='Proforma Land+Home'!J3 -> Year 5 | L18: ='Proforma Land+Home'!K3 -> Year 6 | M18: ='Proforma Land+Home'!L3 -> Year 7 | ... R18: ='Proforma Land+Home'!Q3 -> Year 12
F19: ='Proforma Land+Home'!E4 -> 2025 | G19: ='Proforma Land+Home'!F4 -> 2026 | H19: ='Proforma Land+Home'!G4 -> 2027 | I19: ='Proforma Land+Home'!H4 -> 2028 | J19: ='Proforma Land+Home'!I4 -> 2029 | K19: ='Proforma Land+Home'!J4 -> 2030 | L19: ='Proforma Land+Home'!K4 -> 2031 | M19: ='Proforma Land+Home'!L4 -> 2032 | ... R19: ='Proforma Land+Home'!Q4 -> 2037
B20: SUMMARY OF RETURNS | F20: ='Proforma Land+Home'!E5 -> 45658 | G20: ='Proforma Land+Home'!F5 -> 46023 | H20: ='Proforma Land+Home'!G5 -> 46388 | I20: ='Proforma Land+Home'!H5 -> 46753 | J20: ='Proforma Land+Home'!I5 -> 47119 | K20: ='Proforma Land+Home'!J5 -> 47484 | L20: ='Proforma Land+Home'!K5 -> 47849 | M20: ='Proforma Land+Home'!L5 -> 48214 | ... R20: ='Proforma Land+Home'!Q5 -> 50040
B21: Equity LP Returns
B22: Capital Return | D22: =SUM(F22:R22) -> 20940638 | F22: ='Proforma Land+Home'!E175 -> 0 | G22: ='Proforma Land+Home'!F175 -> 0 | H22: ='Proforma Land+Home'!G175 -> 1968762.1 | I22: ='Proforma Land+Home'!H175 -> 6074217.7 | J22: ='Proforma Land+Home'!I175 -> 12897658 | K22: ='Proforma Land+Home'!J175 -> 0 | L22: ='Proforma Land+Home'!K175 -> 0 | M22: ='Proforma Land+Home'!L175 -> 0 | ... R22: ='Proforma Land+Home'!Q175 -> 0
B23: Profit Split | D23: =SUM(F23:R23) -> 44173914 | F23: ='Proforma Land+Home'!E201-F22 -> 0 | G23: ='Proforma Land+Home'!F201-G22 -> 0 | H23: ='Proforma Land+Home'!G201-H22 -> 0 | I23: ='Proforma Land+Home'!H201-I22 -> 0 | J23: ='Proforma Land+Home'!I201-J22 -> 22249737 | K23: ='Proforma Land+Home'!J201-K22 -> 2681101.7 | L23: ='Proforma Land+Home'!K201-L22 -> 19243076 | M23: ='Proforma Land+Home'!L201-M22 -> 0 | ... R23: ='Proforma Land+Home'!Q201-R22 -> 0
B24: Total Distributions | D24: =SUM(F24:R24) -> 65114552 | F24: =F22+F23 -> 0 | G24: =G22+G23 -> 0 | H24: =H22+H23 -> 1968762.1 | I24: =I22+I23 -> 6074217.7 | J24: =J22+J23 -> 35147395 | K24: =K22+K23 -> 2681101.7 | L24: =L22+L23 -> 19243076 | M24: =M22+M23 -> 0 | ... R24: =R22+R23 -> 0
B25: Total Contributions | D25: =SUM(F25:R25) -> 15000000 | F25: =-'Proforma Land+Home'!E177 -> 15000000 | G25: =-'Proforma Land+Home'!F177 -> 0
B26: Net Profit / Cash Flows | D26: =SUM(F26:R26) -> 50114552 | F26: =F24-F25 -> -15000000 | G26: =G24-G25 -> 0 | H26: =H24-H25 -> 1968762.1 | I26: =I24-I25 -> 6074217.7 | J26: =J24-J25 -> 35147395 | K26: =K24-K25 -> 2681101.7 | L26: =L24-L25 -> 19243076 | M26: =M24-M25 -> 0 | ... R26: =R24-R25 -> 0
B27: IRR | F27: =XIRR(F26:R26,F20:R20) -> 0.40926964
B28: Equity Multiple | F28: =SUMIF(F26:R26,">0")/-SUMIF(F26:R26,"<0") -> 4.3409702
B29: Cumulative (Equity) Cash Position | F29: =F26+E29 -> -15000000 | G29: =G26+F29 -> -15000000 | H29: =H26+G29 -> -13031238 | I29: =I26+H29 -> -6957020.3 | J29: =J26+I29 -> 28190375 | K29: =K26+J29 -> 30871476 | L29: =L26+K29 -> 50114552 | M29: =M26+L29 -> 50114552 | ... R29: =R26+Q29 -> 50114552
B31: MO LP Returns
B32: Capital Return + Pref | F32: ='Proforma Land+Home'!E181 -> 0 | G32: ='Proforma Land+Home'!F181 -> 0 | H32: ='Proforma Land+Home'!G181 -> 52500.322 | I32: ='Proforma Land+Home'!H181 -> 161979.14 | J32: ='Proforma Land+Home'!I181 -> 343937.56 | K32: ='Proforma Land+Home'!J181 -> 0 | L32: ='Proforma Land+Home'!K181 -> 0 | M32: ='Proforma Land+Home'!L181 -> 0 | ... R32: ='Proforma Land+Home'!Q181 -> 0
B33: Profit Split | F33: ='Proforma Land+Home'!E202-F32 -> 0 | G33: ='Proforma Land+Home'!F202-G32 -> 0 | H33: ='Proforma Land+Home'!G202-H32 -> 0 | I33: ='Proforma Land+Home'!H202-I32 -> 0 | J33: ='Proforma Land+Home'!I202-J32 -> 593326.31 | K33: ='Proforma Land+Home'!J202-K32 -> 71496.046 | L33: ='Proforma Land+Home'!K202-L32 -> 513148.69 | M33: ='Proforma Land+Home'!L202-M32 -> 0 | ... R33: ='Proforma Land+Home'!Q202-R32 -> 0
B34: Total Distributions | D34: =SUM(F34:R34) -> 1736388.1 | F34: =SUM(F32:F33) -> 0 | G34: =SUM(G32:G33) -> 0 | H34: =SUM(H32:H33) -> 52500.322 | I34: =SUM(I32:I33) -> 161979.14 | J34: =SUM(J32:J33) -> 937263.87 | K34: =SUM(K32:K33) -> 71496.046 | L34: =SUM(L32:L33) -> 513148.69 | M34: =SUM(M32:M33) -> 0 | ... R34: =SUM(R32:R33) -> 0
B35: Total Contributions | D35: =SUM(F35:R35) -> 400000 | F35: =-'Proforma Land+Home'!E183 -> 400000
B36: Net Profit / Cash Flows | D36: =SUM(F36:R36) -> 1336388.1 | F36: =F34-F35 -> -400000 | G36: =G34-G35 -> 0 | H36: =H34-H35 -> 52500.322 | I36: =I34-I35 -> 161979.14 | J36: =J34-J35 -> 937263.87 | K36: =K34-K35 -> 71496.046 | L36: =L34-L35 -> 513148.69 | M36: =M34-M35 -> 0 | ... R36: =R34-R35 -> 0
