Workbook
Name c_AcresTotal.Res: SUM(#REF!)
Name c_AcresTotal.Res: SUM(tbl_Parcels[Acres])
Name c_UnitTotal.Res: SUM(#REF!)
Name c_UnitTotal.Res: SUM(tbl_Parcels[Low])
Name cv_CFD.CumeDebtSrvc.Annual: mCFD!$BD$373:$BD$402
Name dvl_DevCostCat: DATA!$AR$10:$AZ$10
Name dvl_Rates.Conting: _xlfn.UNIQUE(_xlfn._xlws.FILTER(iGeneral!$F$41:$F$45,iGeneral!$F$41:$F$45<>0))
Name i_CFD.AV.Inflation: i.Finance!$O$26
Name i_CFD.CommeAssesRatio: i.Finance!$O$25
Name i_CFD.FullCashRatio: i.Finance!$O$23
Name i_CFD.LimValRatio: i.Finance!$O$22
Name i_CFD.ObliRate: i.Finance!$O$61
Name i_CFD.ResiAssesRatio: i.Finance!$O$24
Name i_CFD.SA.COI: i.Finance!$O$54
Name i_CFD.SA.IntRate: i.Finance!$O$51
Name i_CFD.SA.Max: i.Finance!$O$49
Name i_CFD.SA.ResFund: i.Finance!$O$53
Name i_CFD.SA.TermYrs: i.Finance!$O$50
Name i_CFD.SA.UnderFee: i.Finance!$O$55
Name i_CFD.SA.YrsCapInt: i.Finance!$O$52
Name i_CFD.TaxRoll1: i.Finance!$O$17
Name i_CFD.TaxRoll2: i.Finance!$O$18
Name i_CFD.TaxRoll3: i.Finance!$O$19
Name i_Cost.Closing: iGeneral!$F$33
Name i_Cost.Commissions: iGeneral!$F$35
Name i_Cost.Legal: iGeneral!$F$36
Name i_Cost.Other: iGeneral!$F$37
Name i_Cost.Subd: iGeneral!$F$51
Name i_Date.Start: iGeneral!$F$13
Name i_Fee.Dispo: iGeneral!$F$34
Name i_HomeSale.MonthsOffset: i.Finance!$O$12
Name i_HousePrice: iGeneral!$F$50
Name i_HousePrice.Start: i.Finance!$O$11
Name i_Name.Project: iGeneral!$F$10
Name i_Price.FinLot: iGeneral!$F$52
Name i_rate.Hurdle1.MO: (1+i_Rate.Hurdle1)^(1/12)-1
Name i_rate.Hurdle2.MO: (1+i_Rate.Hurdle2)^(1/12)-1
Name i_rate.Hurdle3.MO: (1+i_Rate.Hurdle3)^(1/12)-1
Name i_rate.Pref.MO: (1+i_Rate.Pref)^(1/12)-1
Name i_Velocity.HomeSales: i.Finance!$O$13
Name lst_LotProducts: Table4[Product]
Name lst_LotProducts: Table4[Product]
Name lst_LUcodes: Dashboard!#REF!
Name lst_LUcodes: iMPC!$D$10:$D$14
Name lst_ProductDUA: Table4[DUA]
Name lst_ProductDUA: Table4[DUA]

Sheet Dashboard
C3: Project Name | G3: =iGeneral!F10 -> Villages at Tortolita
N4: Navigation here?
C8: Start Date | I8: =i_Date.Start -> 44562
C9: Project Acres: Gross | I9: =SUM(tbl_Parcels[Acres]) -> 1320
C11: Project Economics
D13: Land Acqusition Price: | I13: =iGeneral!#REF! -> #REF!
D14: Project Entitlements:

Sheet iGeneral
C3: =i_Name.Project -> Villages at Tortolita
D4: =F11 -> Marana, AZ Northeast of Marana Road and I-10
C8: Project Identification
C9: ID | D9: Name
C10: 1 | D10: Project Name | F10: Villages at Tortolita
C11: 2 | D11: Location | F11: Marana, AZ Northeast of Marana Road and I-10
C13: Analysis Start Date | F13: 44562 | H13: Growth rates can start at different times
C15: Land Planning Heirarchy - Largest to Smallest
C16: ID | D16: Type | F16: Code | H16: Notes
C17: 1 | D17: Plan Area | F17: PA
C18: 2 | D18: Development Phase | F18: DP | H18: Each PA has at lease 1 DP
C19: 3 | D19: Sale Phase | F19: SP | H19: Each DP has at least 1 SP
C20: 4 | D20: Parcel | F20: P | H20: Each SP has at least 1 P
C21: 5
C23: Growth Rates
C24: ID | D24: Name | E24: Rate | F24: Starts | H24: Notes
C25: 1 | D25: Price | E25: 0.02 | F25: 1 | H25: Growth rates can start at different times
C26: 2 | D26: Cost | E26: 0.01 | F26: 2
C27: 3
C28: 4
C29: 5
C31: Transaction Costs
C32: ID | D32: Transaction Costs | F32: Factor | G32: % of | H32: Notes
C33: 1 | D33: Closing Costs | F33: 0.005 | G33: Residual
C34: 2 | D34: Disposition Fee | F34: 0.03 | G34: Gross
C35: 3 | D35: Commissions | F35: 0.025 | G35: Residual
C36: 4 | D36: Legal / Transaction | F36: 0.005 | G36: Residual
C37: 5 | D37: Other | F37: 0.005 | G37: Residual
C39: Misc Factors
C40: ID | D40: Type | F40: Factor | H40: Notes
C41: 1 | D41: Contingency - Low | F41: 0.05 | H41: Factors are global
C42: 2 | D42: Contingency - Mid | F42: 0.1
C43: 3 | D43: Contingency - Hi | F43: 0.2
C44: 4 | D44: Maximum DUs | F44: 5000
C45: 5
C48: Starting Market Pricing / Costs
C49: ID | D49: Item | F49: Amount | G49: Unit
C50: 1 | D50: Starting House Price | F50: 300000 | G50: $ / Unit
C51: 2 | D51: Subdivision Development Cost | F51: 1300 | G51: $ / FF
C52: 3 | D52: Finished Residential Lot Price | F52: 2000 | G52: $ / FF
...

Sheet iLandAcquisition
D7: Land Acquisition
O8: =IF(P10>0,#REF!+1,"")
K9: Price
D10: ID | E10: Seller | F10: Installments | H10: Land Conveyed | I10: Date | J10: Payment | K10: $/Acre | L10: $/SF | M10: Notes | Q10: Year | R10: Acres | S10: Price | T10: $/Ac | U10: $/SF
D11: 1 | E11: Joe Shmoe | F11: 1 | G11: 3 | H11: 150 | I11: 44896 | J11: 2500000 | K11: =IFERROR(J11/H11,0) -> 16666.667 | L11: =K11/43560 -> 0.38261402 | Q11: 2022 | R11: 150 | S11: 1000000 | T11: 6666.6667 | U11: 0.15304561
D12: 2 | F12: 2 | G12: 3 | H12: 500 | I12: 45291 | J12: 5000000 | K12: =IFERROR(J12/H12,0) -> 10000 | L12: =K12/43560 -> 0.22956841 | Q12: 2023 | R12: 500 | S12: 5000000 | T12: 10000 | U12: 0.22956841
D13: 3 | F13: 3 | G13: 3 | H13: 750 | I13: 45657 | J13: 6000000 | K13: =IFERROR(J13/H13,0) -> 8000 | L13: =K13/43560 -> 0.18365473 | Q13: 2024 | R13: 750 | S13: 750000 | T13: 1000 | U13: 0.022956841
D14: 4 | K14: =IFERROR(J14/H14,0) -> 0 | L14: =K14/43560 -> 0 | Q14: 2025 | R14: 250 | S14: 2500000 | T14: 10000 | U14: 0.22956841
D15: 5 | E15: Dave Smith | F15: 1 | G15: 1 | H15: 250 | I15: 46146 | J15: 2500000 | K15: =IFERROR(J15/H15,0) -> 10000 | L15: =K15/43560 -> 0.22956841 | Q15: Grand Total | R15: 1650 | S15: 9250000 | T15: 5606.0606 | U15: 0.12869744
D16: 6 | K16: =IFERROR(J16/H16,0) -> 0 | L16: =K16/43560 -> 0
D17: 7 | K17: =IFERROR(J17/H17,0) -> 0 | L17: =K17/43560 -> 0
D18: 8 | K18: =IFERROR(J18/H18,0) -> 0 | L18: =K18/43560 -> 0
D19: 9 | K19: =IFERROR(J19/H19,0) -> 0 | L19: =K19/43560 -> 0
D20: 10 | K20: =IFERROR(J20/H20,0) -> 0 | L20: =K20/43560 -> 0
E21: Total | H21: =SUM(H11:H20) -> 1650 | J21: =SUM(J11:J20) -> 16000000 | K21: =J21/H21 -> 9696.9697 | L21: =K21/43560 -> 0.22261179

Sheet iMPC
C7: Land Use Definitions | L7: Parcel Table - Village 1 | U7: Plan Area and Parcel Summary
H8: Density Range (DUA) | Q8: Potential DUs | X8: Potential DUs | AA8: Acres by Land Use
C9: ID | D9: Code | E9: Use | H9: From | I9: To | L9: ID | M9: Village | N9: Parcel | O9: Acres | P9: Use | Q9: Low | R9: High | U9: Plan Areas | V9: Parcels | W9: Acres | X9: Low | Y9: Hi | AA9: {=TRANSPOSE(lst_LUcodes)} -> MLDR | AB9: MDR | AC9: MHDR | AD9: MU | AE9: 0
C10: 1 | D10: MLDR | E10: Medium Low Residential | H10: 1 | I10: 2.9 | L10: 1 | M10: 1 | N10: =CONCATENATE(tbl_Parcels[[#This Row],[Village]],".",L10) -> 1.1 | O10: 31.73 | P10: MLDR | Q10: =INT(tbl_Parcels[[#This Row],[Acres]]*_xlfn.XLOOKUP(tbl_Parcels[[#This Row],[Use]],lst_LUcodes,$H$10:$H$14)) -> 31 | R10: =INT(tbl_Parcels[[#This Row],[Acres]]*_xlfn.XLOOKUP(tbl_Parcels[[#This Row],[Use]],lst_LUcodes,$I$10:$I$14)) -> 92 | U10: {=_xlfn.UNIQUE(tbl_Parcels[Village])} -> 1 | V10: =COUNTIF(tbl_Parcels[Village],U10) -> 15 | W10: =SUMIF(tbl_Parcels[Village],$U10,tbl_Parcels[Acres]) -> 379.51 | X10: =SUMIFS(tbl_Parcels[Low],tbl_Parcels[Village],$U10) -> 856 | Y10: =SUMIF(tbl_Parcels[Village],$U10,tbl_Parcels[High]) -> 1825 | AA10: =SUMIFS(tbl_Parcels[Acres],tbl_Parcels[Use],AA$9,tbl_Parcels[Village],$U10) -> 136.74 | AB10: =SUMIFS(tbl_Parcels[Acres],tbl_Parcels[Use],AB$9,tbl_Parcels[Village],$U10) -> 242.77 | AC10: =SUMIFS(tbl_Parcels[Acres],tbl_Parcels[Use],AC$9,tbl_Parcels[Village],$U10) -> 0 | AD10: =SUMIFS(tbl_Parcels[Acres],tbl_Parcels[Use],AD$9,tbl_Parcels[Village],$U10) -> 0 | AE10: =SUMIFS(tbl_Parcels[Acres],tbl_Parcels[Use],AE$9,tbl_Parcels[Village],$U10) -> 0
C11: 2 | D11: MDR | E11: Medium Density Residential | H11: 3 | I11: 5.9 | L11: 2 | M11: 1 | N11: =CONCATENATE(tbl_Parcels[[#This Row],[Village]],".",L11) -> 1.2 | O11: 20.83 | P11: MLDR | Q11: =INT(tbl_Parcels[[#This Row],[Acres]]*_xlfn.XLOOKUP(tbl_Parcels[[#This Row],[Use]],lst_LUcodes,$H$10:$H$14)) -> 20 | R11: =INT(tbl_Parcels[[#This Row],[Acres]]*_xlfn.XLOOKUP(tbl_Parcels[[#This Row],[Use]],lst_LUcodes,$I$10:$I$14)) -> 60 | U11: 2 | V11: =COUNTIF(tbl_Parcels[Village],U11) -> 7 | W11: =SUMIF(tbl_Parcels[Village],$U11,tbl_Parcels[Acres]) -> 223.3 | X11: =SUMIFS(tbl_Parcels[Low],tbl_Parcels[Village],$U11) -> 356 | Y11: =SUMIF(tbl_Parcels[Village],$U11,tbl_Parcels[High]) -> 712 | AA11: =SUMIFS(tbl_Parcels[Acres],tbl_Parcels[Use],AA$9,tbl_Parcels[Village],$U11) -> 0 | AB11: =SUMIFS(tbl_Parcels[Acres],tbl_Parcels[Use],AB$9,tbl_Parcels[Village],$U11) -> 0 | AC11: =SUMIFS(tbl_Parcels[Acres],tbl_Parcels[Use],AC$9,tbl_Parcels[Village],$U11) -> 59.41 | AD11: =SUMIFS(tbl_Parcels[Acres],tbl_Parcels[Use],AD$9,tbl_Parcels[Village],$U11) -> 163.89 | AE11: =SUMIFS(tbl_Parcels[Acres],tbl_Parcels[Use],AE$9,tbl_Parcels[Village],$U11) -> 0
C12: 3 | D12: MHDR | E12: Medium Hi Residential | H12: 6 | I12: 12 | L12: 3 | M12: 1 | N12: =CONCATENATE(tbl_Parcels[[#This Row],[Village]],".",L12) -> 1.3 | O12: 18.85 | P12: MDR | Q12: =INT(tbl_Parcels[[#This Row],[Acres]]*_xlfn.XLOOKUP(tbl_Parcels[[#This Row],[Use]],lst_LUcodes,$H$10:$H$14)) -> 56 | R12: =INT(tbl_Parcels[[#This Row],[Acres]]*_xlfn.XLOOKUP(tbl_Parcels[[#This Row],[Use]],lst_LUcodes,$I$10:$I$14)) -> 111 | U12: 3 | V12: =COUNTIF(tbl_Parcels[Village],U12) -> 12 | W12: =SUMIF(tbl_Parcels[Village],$U12,tbl_Parcels[Acres]) -> 328.16 | X12: =SUMIFS(tbl_Parcels[Low],tbl_Parcels[Village],$U12) -> 677 | Y12: =SUMIF(tbl_Parcels[Village],$U12,tbl_Parcels[High]) -> 1477 | AA12: =SUMIFS(tbl_Parcels[Acres],tbl_Parcels[Use],AA$9,tbl_Parcels[Village],$U12) -> 150.63 | AB12: =SUMIFS(tbl_Parcels[Acres],tbl_Parcels[Use],AB$9,tbl_Parcels[Village],$U12) -> 177.53 | AC12: =SUMIFS(tbl_Parcels[Acres],tbl_Parcels[Use],AC$9,tbl_Parcels[Village],$U12) -> 0 | AD12: =SUMIFS(tbl_Parcels[Acres],tbl_Parcels[Use],AD$9,tbl_Parcels[Village],$U12) -> 0 | AE12: =SUMIFS(tbl_Parcels[Acres],tbl_Parcels[Use],AE$9,tbl_Parcels[Village],$U12) -> 0
C13: 4 | D13: MU | E13: Mixed Use | L13: 4 | M13: 1 | N13: =CONCATENATE(tbl_Parcels[[#This Row],[Village]],".",L13) -> 1.4 | O13: 27.82 | P13: MDR | Q13: =INT(tbl_Parcels[[#This Row],[Acres]]*_xlfn.XLOOKUP(tbl_Parcels[[#This Row],[Use]],lst_LUcodes,$H$10:$H$14)) -> 83 | R13: =INT(tbl_Parcels[[#This Row],[Acres]]*_xlfn.XLOOKUP(tbl_Parcels[[#This Row],[Use]],lst_LUcodes,$I$10:$I$14)) -> 164 | U13: 4 | V13: =COUNTIF(tbl_Parcels[Village],U13) -> 14 | W13: =SUMIF(tbl_Parcels[Village],$U13,tbl_Parcels[Acres]) -> 389.03 | X13: =SUMIFS(tbl_Parcels[Low],tbl_Parcels[Village],$U13) -> 794 | Y13: =SUMIF(tbl_Parcels[Village],$U13,tbl_Parcels[High]) -> 1638 | AA13: =SUMIFS(tbl_Parcels[Acres],tbl_Parcels[Use],AA$9,tbl_Parcels[Village],$U13) -> 75.64 | AB13: =SUMIFS(tbl_Parcels[Acres],tbl_Parcels[Use],AB$9,tbl_Parcels[Village],$U13) -> 241.44 | AC13: =SUMIFS(tbl_Parcels[Acres],tbl_Parcels[Use],AC$9,tbl_Parcels[Village],$U13) -> 0 | AD13: =SUMIFS(tbl_Parcels[Acres],tbl_Parcels[Use],AD$9,tbl_Parcels[Village],$U13) -> 71.95 | AE13: =SUMIFS(tbl_Parcels[Acres],tbl_Parcels[Use],AE$9,tbl_Parcels[Village],$U13) -> 0
C14: 5 | L14: 5 | M14: 1 | N14: =CONCATENATE(tbl_Parcels[[#This Row],[Village]],".",L14) -> 1.5 | O14: 27.77 | P14: MLDR | Q14: =INT(tbl_Parcels[[#This Row],[Acres]]*_xlfn.XLOOKUP(tbl_Parcels[[#This Row],[Use]],lst_LUcodes,$H$10:$H$14)) -> 27 | R14: =INT(tbl_Parcels[[#This Row],[Acres]]*_xlfn.XLOOKUP(tbl_Parcels[[#This Row],[Use]],lst_LUcodes,$I$10:$I$14)) -> 80 | U14: Total | V14: =SUM(V10:V13) -> 48 | W14: =SUM(W10:W13) -> 1320 | X14: =SUM(X10:X13) -> 2683 | Y14: =SUM(Y10:Y13) -> 5652 | AA14: =SUM(AA10:AA13) -> 363.01 | AB14: =SUM(AB10:AB13) -> 661.74 | AC14: =SUM(AC10:AC13) -> 59.41 | AD14: =SUM(AD10:AD13) -> 235.84 | AE14: =SUM(AE10:AE13) -> 0
C15: 6 | L15: 6 | M15: 1 | N15: =CONCATENATE(tbl_Parcels[[#This Row],[Village]],".",L15) -> 1.6 | O15: 25.8 | P15: MDR | Q15: =INT(tbl_Parcels[[#This Row],[Acres]]*_xlfn.XLOOKUP(tbl_Parcels[[#This Row],[Use]],lst_LUcodes,$H$10:$H$14)) -> 77 | R15: =INT(tbl_Parcels[[#This Row],[Acres]]*_xlfn.XLOOKUP(tbl_Parcels[[#This Row],[Use]],lst_LUcodes,$I$10:$I$14)) -> 152
A16: =IF(tbl_Parcels[[#This Row],[Village]]=#REF!,A15+1,1) -> #REF! | C16: 7 | L16: 7 | M16: 1 | N16: =CONCATENATE(tbl_Parcels[[#This Row],[Village]],".",L16) -> 1.7 | O16: 19.53 | P16: MDR | Q16: =INT(tbl_Parcels[[#This Row],[Acres]]*_xlfn.XLOOKUP(tbl_Parcels[[#This Row],[Use]],lst_LUcodes,$H$10:$H$14)) -> 58 | R16: =INT(tbl_Parcels[[#This Row],[Acres]]*_xlfn.XLOOKUP(tbl_Parcels[[#This Row],[Use]],lst_LUcodes,$I$10:$I$14)) -> 115
A17: =IF(tbl_Parcels[[#This Row],[Village]]=#REF!,A16+1,1) -> #REF! | C17: 8 | L17: 8 | M17: 1 | N17: =CONCATENATE(tbl_Parcels[[#This Row],[Village]],".",L17) -> 1.8 | O17: 30.58 | P17: MDR | Q17: =INT(tbl_Parcels[[#This Row],[Acres]]*_xlfn.XLOOKUP(tbl_Parcels[[#This Row],[Use]],lst_LUcodes,$H$10:$H$14)) -> 91 | R17: =INT(tbl_Parcels[[#This Row],[Acres]]*_xlfn.XLOOKUP(tbl_Parcels[[#This Row],[Use]],lst_LUcodes,$I$10:$I$14)) -> 180
C18: 9 | L18: 9 | M18: 1 | N18: =CONCATENATE(tbl_Parcels[[#This Row],[Village]],".",L18) -> 1.9 | O18: 21.71 | P18: MDR | Q18: =INT(tbl_Parcels[[#This Row],[Acres]]*_xlfn.XLOOKUP(tbl_Parcels[[#This Row],[Use]],lst_LUcodes,$H$10:$H$14)) -> 65 | R18: =INT(tbl_Parcels[[#This Row],[Acres]]*_xlfn.XLOOKUP(tbl_Parcels[[#This Row],[Use]],lst_LUcodes,$I$10:$I$14)) -> 128
A19: =IF(tbl_Parcels[[#This Row],[Village]]=#REF!,#REF!+1,1) -> #REF! | C19: 10 | L19: 10 | M19: 1 | N19: =CONCATENATE(tbl_Parcels[[#This Row],[Village]],".",L19) -> 1.10 | O19: 22.39 | P19: MDR | Q19: =INT(tbl_Parcels[[#This Row],[Acres]]*_xlfn.XLOOKUP(tbl_Parcels[[#This Row],[Use]],lst_LUcodes,$H$10:$H$14)) -> 67 | R19: =INT(tbl_Parcels[[#This Row],[Acres]]*_xlfn.XLOOKUP(tbl_Parcels[[#This Row],[Use]],lst_LUcodes,$I$10:$I$14)) -> 132
A20: =IF(tbl_Parcels[[#This Row],[Village]]=M9,A19+1,1) -> 1 | L20: 11 | M20: 1 | N20: =CONCATENATE(tbl_Parcels[[#This Row],[Village]],".",L20) -> 1.11 | O20: 29.51 | P20: MLDR | Q20: =INT(tbl_Parcels[[#This Row],[Acres]]*_xlfn.XLOOKUP(tbl_Parcels[[#This Row],[Use]],lst_LUcodes,$H$10:$H$14)) -> 29 | R20: =INT(tbl_Parcels[[#This Row],[Acres]]*_xlfn.XLOOKUP(tbl_Parcels[[#This Row],[Use]],lst_LUcodes,$I$10:$I$14)) -> 85
A21: =IF(tbl_Parcels[[#This Row],[Village]]=M10,A20+1,1) -> 2 | L21: 12 | M21: 1 | N21: =CONCATENATE(tbl_Parcels[[#This Row],[Village]],".",L21) -> 1.12 | O21: 26.9 | P21: MLDR | Q21: =INT(tbl_Parcels[[#This Row],[Acres]]*_xlfn.XLOOKUP(tbl_Parcels[[#This Row],[Use]],lst_LUcodes,$H$10:$H$14)) -> 26 | R21: =INT(tbl_Parcels[[#This Row],[Acres]]*_xlfn.XLOOKUP(tbl_Parcels[[#This Row],[Use]],lst_LUcodes,$I$10:$I$14)) -> 78
A22: =IF(tbl_Parcels[[#This Row],[Village]]=M11,A21+1,1) -> 3 | L22: 13 | M22: 1 | N22: =CONCATENATE(tbl_Parcels[[#This Row],[Village]],".",L22) -> 1.13 | O22: 20.29 | P22: MDR | Q22: =INT(tbl_Parcels[[#This Row],[Acres]]*_xlfn.XLOOKUP(tbl_Parcels[[#This Row],[Use]],lst_LUcodes,$H$10:$H$14)) -> 60 | R22: =INT(tbl_Parcels[[#This Row],[Acres]]*_xlfn.XLOOKUP(tbl_Parcels[[#This Row],[Use]],lst_LUcodes,$I$10:$I$14)) -> 119
A23: =IF(tbl_Parcels[[#This Row],[Village]]=M12,A22+1,1) -> 4 | L23: 14 | M23: 1 | N23: =CONCATENATE(tbl_Parcels[[#This Row],[Village]],".",L23) -> 1.14 | O23: 21.53 | P23: MDR | Q23: =INT(tbl_Parcels[[#This Row],[Acres]]*_xlfn.XLOOKUP(tbl_Parcels[[#This Row],[Use]],lst_LUcodes,$H$10:$H$14)) -> 64 | R23: =INT(tbl_Parcels[[#This Row],[Acres]]*_xlfn.XLOOKUP(tbl_Parcels[[#This Row],[Use]],lst_LUcodes,$I$10:$I$14)) -> 127
A24: =IF(tbl_Parcels[[#This Row],[Village]]=M13,A23+1,1) -> 5 | L24: 15 | M24: 1 | N24: =CONCATENATE(tbl_Parcels[[#This Row],[Village]],".",L24) -> 1.15 | O24: 34.27 | P24: MDR | Q24: =INT(tbl_Parcels[[#This Row],[Acres]]*_xlfn.XLOOKUP(tbl_Parcels[[#This Row],[Use]],lst_LUcodes,$H$10:$H$14)) -> 102 | R24: =INT(tbl_Parcels[[#This Row],[Acres]]*_xlfn.XLOOKUP(tbl_Parcels[[#This Row],[Use]],lst_LUcodes,$I$10:$I$14)) -> 202
A25: =IF(tbl_Parcels[[#This Row],[Village]]=M14,A24+1,1) -> 1 | L25: 16 | M25: 2 | N25: =CONCATENATE(tbl_Parcels[[#This Row],[Village]],".",L25) -> 2.16 | O25: 31.85 | P25: MHDR | Q25: =INT(tbl_Parcels[[#This Row],[Acres]]*_xlfn.XLOOKUP(tbl_Parcels[[#This Row],[Use]],lst_LUcodes,$H$10:$H$14)) -> 191 | R25: =INT(tbl_Parcels[[#This Row],[Acres]]*_xlfn.XLOOKUP(tbl_Parcels[[#This Row],[Use]],lst_LUcodes,$I$10:$I$14)) -> 382
A26: =IF(tbl_Parcels[[#This Row],[Village]]=M15,A25+1,1) -> 1 | L26: 17 | M26: 2 | N26: =CONCATENATE(tbl_Parcels[[#This Row],[Village]],".",L26) -> 2.17 | O26: 31.04 | P26: MU | Q26: =INT(tbl_Parcels[[#This Row],[Acres]]*_xlfn.XLOOKUP(tbl_Parcels[[#This Row],[Use]],lst_LUcodes,$H$10:$H$14)) -> 0 | R26: =INT(tbl_Parcels[[#This Row],[Acres]]*_xlfn.XLOOKUP(tbl_Parcels[[#This Row],[Use]],lst_LUcodes,$I$10:$I$14)) -> 0
A27: =IF(tbl_Parcels[[#This Row],[Village]]=M16,A26+1,1) -> 1 | L27: 18 | M27: 2 | N27: =CONCATENATE(tbl_Parcels[[#This Row],[Village]],".",L27) -> 2.18 | O27: 27.56 | P27: MHDR | Q27: =INT(tbl_Parcels[[#This Row],[Acres]]*_xlfn.XLOOKUP(tbl_Parcels[[#This Row],[Use]],lst_LUcodes,$H$10:$H$14)) -> 165 | R27: =INT(tbl_Parcels[[#This Row],[Acres]]*_xlfn.XLOOKUP(tbl_Parcels[[#This Row],[Use]],lst_LUcodes,$I$10:$I$14)) -> 330
A28: =IF(tbl_Parcels[[#This Row],[Village]]=M17,A27+1,1) -> 1 | L28: 19 | M28: 2 | N28: =CONCATENATE(tbl_Parcels[[#This Row],[Village]],".",L28) -> 2.19 | O28: 21.86 | P28: MU | Q28: =INT(tbl_Parcels[[#This Row],[Acres]]*_xlfn.XLOOKUP(tbl_Parcels[[#This Row],[Use]],lst_LUcodes,$H$10:$H$14)) -> 0 | R28: =INT(tbl_Parcels[[#This Row],[Acres]]*_xlfn.XLOOKUP(tbl_Parcels[[#This Row],[Use]],lst_LUcodes,$I$10:$I$14)) -> 0
A29: =IF(tbl_Parcels[[#This Row],[Village]]=M18,A28+1,1) -> 1 | L29: 20 | M29: 2 | N29: =CONCATENATE(tbl_Parcels[[#This Row],[Village]],".",L29) -> 2.20 | O29: 35.51 | P29: MU | Q29: =INT(tbl_Parcels[[#This Row],[Acres]]*_xlfn.XLOOKUP(tbl_Parcels[[#This Row],[Use]],lst_LUcodes,$H$10:$H$14)) -> 0 | R29: =INT(tbl_Parcels[[#This Row],[Acres]]*_xlfn.XLOOKUP(tbl_Parcels[[#This Row],[Use]],lst_LUcodes,$I$10:$I$14)) -> 0
A30: =IF(tbl_Parcels[[#This Row],[Village]]=M19,A29+1,1) -> 1 | L30: 21 | M30: 2 | N30: =CONCATENATE(tbl_Parcels[[#This Row],[Village]],".",L30) -> 2.21 | O30: 43.89 | P30: MU | Q30: =INT(tbl_Parcels[[#This Row],[Acres]]*_xlfn.XLOOKUP(tbl_Parcels[[#This Row],[Use]],lst_LUcodes,$H$10:$H$14)) -> 0 | R30: =INT(tbl_Parcels[[#This Row],[Acres]]*_xlfn.XLOOKUP(tbl_Parcels[[#This Row],[Use]],lst_LUcodes,$I$10:$I$14)) -> 0
A31: =IF(tbl_Parcels[[#This Row],[Village]]=M20,A30+1,1) -> 1 | L31: 22 | M31: 2 | N31: =CONCATENATE(tbl_Parcels[[#This Row],[Village]],".",L31) -> 2.22 | O31: 31.59 | P31: MU | Q31: =INT(tbl_Parcels[[#This Row],[Acres]]*_xlfn.XLOOKUP(tbl_Parcels[[#This Row],[Use]],lst_LUcodes,$H$10:$H$14)) -> 0 | R31: =INT(tbl_Parcels[[#This Row],[Acres]]*_xlfn.XLOOKUP(tbl_Parcels[[#This Row],[Use]],lst_LUcodes,$I$10:$I$14)) -> 0
... A57: =IF(tbl_Parcels[[#This Row],[Village]]=M46,A56+1,1) -> 4 | L57: 48 | M57: 4 | N57: =CONCATENATE(tbl_Parcels[[#This Row],[Village]],".",L57) -> 4.48 | O57: 14.47 | P57: MU | Q57: =INT(tbl_Parcels[[#This Row],[Acres]]*_xlfn.XLOOKUP(tbl_Parcels[[#This Row],[Use]],lst_LUcodes,$H$10:$H$14)) -> 0 | R57: =INT(tbl_Parcels[[#This Row],[Acres]]*_xlfn.XLOOKUP(tbl_Parcels[[#This Row],[Use]],lst_LUcodes,$I$10:$I$14)) -> 0
A58: =IF(tbl_Parcels[[#This Row],[Village]]=M47,A57+1,1) -> #VALUE!
A59: =IF(tbl_Parcels[[#This Row],[Village]]=M48,A58+1,1) -> #VALUE!
A60: =IF(tbl_Parcels[[#This Row],[Village]]=M49,A59+1,1) -> #VALUE!
A61: =IF(tbl_Parcels[[#This Row],[Village]]=M50,A60+1,1) -> #VALUE!
A62: =IF(tbl_Parcels[[#This Row],[Village]]=M51,A61+1,1) -> #VALUE!
A63: =IF(tbl_Parcels[[#This Row],[Village]]=M52,A62+1,1) -> #VALUE!
A64: =IF(tbl_Parcels[[#This Row],[Village]]=M53,A63+1,1) -> #VALUE!
A65: =IF(tbl_Parcels[[#This Row],[Village]]=M54,A64+1,1) -> #VALUE!
A66: 47
A67: 48

Sheet iV1
C4: 1 | F4: Parcel Land Use & Lot Product | N4: 1 | P4: Development Phasing | Y4: =C4 -> 1 | AA4: Sale Schedule
N5: Village 4 | P5: 1 | Q5: =P5+1 -> 2 | R5: =Q5+1 -> 3 | S5: =R5+1 -> 4 | X5: Lag to Development Completion
J6: Dev | AB6: Front | AC6: Development | AE6: Sale | AF6: Retail | AG6: Subdivision | AH6: Gross Parcel | AI6: Sale | AJ6: =AF6 -> Retail
C7: ID | D7: Parcel# | E7: Use | F7: Acres | G7: DUA | H7: Product | I7: Units | J7: Phase | N7: Start Month | P7: 6 | Q7: 30 | X7: # | Y7: Parcel | Z7: Lots | AA7: Product | AB7: Feet | AC7: Phase | AD7: Compl | AE7: Date | AF7: Price | AG7: Improvement | AH7: Revenue | AI7: Cost | AJ7: NET
C8: 1 | D8: {=_xlfn._xlws.FILTER(tbl_Parcels[Parcel],tbl_Parcels[Village]=C4,0)} -> 1.1 | E8: =IFERROR(_xlfn.XLOOKUP(D8,tbl_Parcels[Parcel],tbl_Parcels[Use]),0) -> MLDR | F8: =IFERROR(_xlfn.XLOOKUP(D8,tbl_Parcels[Parcel],tbl_Parcels[Acres]),0) -> 31.73 | G8: =LOOKUP('iV1'!$H8,Table4[Product],Table4[DUA]) -> 3.4485 | H8: 60x120 | I8: =IFERROR(INT(LOOKUP('iV1'!$H8,lst_LotProducts,lst_ProductDUA)*'iV1'!$F8),0) -> 109 | J8: 1 | N8: Months to Complete | P8: 12 | Q8: 8 | X8: 1 | Y8: {=_xlfn.UNIQUE(_xlfn._xlws.FILTER(D8:D32,D8:D32<>0))} -> 1.1 | Z8: =IFERROR(LOOKUP(Y8,$D$8:$D$32,$I$8:$I$32),0) -> 109 | AA8: =IFERROR(_xlfn.XLOOKUP($Y8,$D$8:$D$32,$H$8:$H$32),0) -> 60x120 | AB8: =IFERROR(Z8*LOOKUP(AA8,Table4[Product],Table4[Width]),0) -> 6540 | AC8: =IFERROR(_xlfn.XLOOKUP($Y8,$D$8:$D$32,$J$8:$J$32),0) -> 1 | AD8: =IFERROR(_xlfn.XLOOKUP(LOOKUP(AC8,$P$5:$S$5,$P$9:$S$9)+1,DATA!$E$11:$E$370,DATA!$F$11:$F$370),"") -> 45078 | AE8: 45108 | AF8: =IFERROR($AB8*(iGeneral!$F$52*LOOKUP($AE8,DATA!$F$11:$F$370,DATA!$L$11:$L$370)),0) -> 13478009 | AG8: =-IFERROR($AB8*(i_Cost.Subd*LOOKUP($AE8,DATA!$F$11:$F$370,DATA!$L$11:$L$370)),0) -> -8760705.7 | AH8: =AF8+AG8 -> 4717303.1
C9: 2 | D9: 1.2 | E9: =IFERROR(_xlfn.XLOOKUP(D9,tbl_Parcels[Parcel],tbl_Parcels[Use]),0) -> MLDR | F9: =IFERROR(_xlfn.XLOOKUP(D9,tbl_Parcels[Parcel],tbl_Parcels[Acres]),0) -> 20.83 | G9: =LOOKUP('iV1'!$H9,Table4[Product],Table4[DUA]) -> 3.31056 | H9: 60x125 | I9: =IFERROR(INT(LOOKUP('iV1'!$H9,lst_LotProducts,lst_ProductDUA)*'iV1'!$F9),0) -> 68 | J9: 1 | N9: Thru Month | P9: =P7+P8-1 -> 17 | Q9: =Q7+Q8-1 -> 37 | X9: =X8+1 -> 2 | Y9: 1.2 | Z9: =IFERROR(LOOKUP(Y9,$D$8:$D$32,$I$8:$I$32),0) -> 147 | AA9: =IFERROR(_xlfn.XLOOKUP($Y9,$D$8:$D$32,$H$8:$H$32),0) -> 60x125 | AB9: =IFERROR(Z9*LOOKUP(AA9,Table4[Product],Table4[Width]),0) -> 8820 | AC9: =IFERROR(_xlfn.XLOOKUP($Y9,$D$8:$D$32,$J$8:$J$32),0) -> 1 | AD9: =IFERROR(_xlfn.XLOOKUP(LOOKUP(AC9,$P$5:$S$5,$P$9:$S$9)+1,DATA!$E$11:$E$370,DATA!$F$11:$F$370),"") -> 45078 | AE9: 45108 | AF9: =IFERROR($AB9*(iGeneral!$F$52*LOOKUP($AE9,DATA!$F$11:$F$370,DATA!$L$11:$L$370)),0) -> 18176764 | AG9: =-IFERROR($AB9*(i_Cost.Subd*LOOKUP($AE9,DATA!$F$11:$F$370,DATA!$L$11:$L$370)),0) -> -11814897 | AH9: =AF9+AG9 -> 6361867.4
C10: 3 | D10: 1.3 | E10: =IFERROR(_xlfn.XLOOKUP(D10,tbl_Parcels[Parcel],tbl_Parcels[Use]),0) -> MDR | F10: =IFERROR(_xlfn.XLOOKUP(D10,tbl_Parcels[Parcel],tbl_Parcels[Acres]),0) -> 18.85 | G10: =LOOKUP('iV1'!$H10,Table4[Product],Table4[DUA]) -> 5.016 | H10: 45x110 | I10: =IFERROR(INT(LOOKUP('iV1'!$H10,lst_LotProducts,lst_ProductDUA)*'iV1'!$F10),0) -> 94 | J10: 1 | T10: Total | X10: =X9+1 -> 3 | Y10: 1.3 | Z10: =IFERROR(LOOKUP(Y10,$D$8:$D$32,$I$8:$I$32),0) -> 147 | AA10: =IFERROR(_xlfn.XLOOKUP($Y10,$D$8:$D$32,$H$8:$H$32),0) -> 45x110 | AB10: =IFERROR(Z10*LOOKUP(AA10,Table4[Product],Table4[Width]),0) -> 6615 | AC10: =IFERROR(_xlfn.XLOOKUP($Y10,$D$8:$D$32,$J$8:$J$32),0) -> 1 | AD10: =IFERROR(_xlfn.XLOOKUP(LOOKUP(AC10,$P$5:$S$5,$P$9:$S$9)+1,DATA!$E$11:$E$370,DATA!$F$11:$F$370),"") -> 45078 | AE10: 45108 | AF10: =IFERROR($AB10*(iGeneral!$F$52*LOOKUP($AE10,DATA!$F$11:$F$370,DATA!$L$11:$L$370)),0) -> 13632573 | AG10: =-IFERROR($AB10*(i_Cost.Subd*LOOKUP($AE10,DATA!$F$11:$F$370,DATA!$L$11:$L$370)),0) -> -8861172.5 | AH10: =AF10+AG10 -> 4771400.6
C11: 4 | D11: 1.4 | E11: =IFERROR(_xlfn.XLOOKUP(D11,tbl_Parcels[Parcel],tbl_Parcels[Use]),0) -> MDR | F11: =IFERROR(_xlfn.XLOOKUP(D11,tbl_Parcels[Parcel],tbl_Parcels[Acres]),0) -> 27.82 | G11: =LOOKUP('iV1'!$H11,Table4[Product],Table4[DUA]) -> 5.016 | H11: 45x110 | I11: =IFERROR(INT(LOOKUP('iV1'!$H11,lst_LotProducts,lst_ProductDUA)*'iV1'!$F11),0) -> 139 | J11: 1 | N11: Acqusition | O11: a | P11: 0 | Q11: 0 | T11: =P11+Q11+R11+S11 -> 0 | V11: insert summary | X11: =X10+1 -> 4 | Y11: 1.4 | Z11: =IFERROR(LOOKUP(Y11,$D$8:$D$32,$I$8:$I$32),0) -> 147 | AA11: =IFERROR(_xlfn.XLOOKUP($Y11,$D$8:$D$32,$H$8:$H$32),0) -> 45x110 | AB11: =IFERROR(Z11*LOOKUP(AA11,Table4[Product],Table4[Width]),0) -> 6615 | AC11: =IFERROR(_xlfn.XLOOKUP($Y11,$D$8:$D$32,$J$8:$J$32),0) -> 1 | AD11: =IFERROR(_xlfn.XLOOKUP(LOOKUP(AC11,$P$5:$S$5,$P$9:$S$9)+1,DATA!$E$11:$E$370,DATA!$F$11:$F$370),"") -> 45078 | AE11: 45231 | AF11: =IFERROR($AB11*(iGeneral!$F$52*LOOKUP($AE11,DATA!$F$11:$F$370,DATA!$L$11:$L$370)),0) -> 13723684 | AG11: =-IFERROR($AB11*(i_Cost.Subd*LOOKUP($AE11,DATA!$F$11:$F$370,DATA!$L$11:$L$370)),0) -> -8920394.8 | AH11: =AF11+AG11 -> 4803289.5
C12: 5 | D12: 1.5 | E12: =IFERROR(_xlfn.XLOOKUP(D12,tbl_Parcels[Parcel],tbl_Parcels[Use]),0) -> MLDR | F12: =IFERROR(_xlfn.XLOOKUP(D12,tbl_Parcels[Parcel],tbl_Parcels[Acres]),0) -> 27.77 | G12: =LOOKUP('iV1'!$H12,Table4[Product],Table4[DUA]) -> 3.31056 | H12: 60x125 | I12: =IFERROR(INT(LOOKUP('iV1'!$H12,lst_LotProducts,lst_ProductDUA)*'iV1'!$F12),0) -> 91 | J12: 1 | L12: insert summary | N12: Entitlements | P12: 500000 | Q12: 100000 | T12: =P12+Q12+R12+S12 -> 600000 | V12: or charts here | X12: =X11+1 -> 5 | Y12: 1.5 | Z12: =IFERROR(LOOKUP(Y12,$D$8:$D$32,$I$8:$I$32),0) -> 147 | AA12: =IFERROR(_xlfn.XLOOKUP($Y12,$D$8:$D$32,$H$8:$H$32),0) -> 60x125 | AB12: =IFERROR(Z12*LOOKUP(AA12,Table4[Product],Table4[Width]),0) -> 8820 | AC12: =IFERROR(_xlfn.XLOOKUP($Y12,$D$8:$D$32,$J$8:$J$32),0) -> 1 | AD12: =IFERROR(_xlfn.XLOOKUP(LOOKUP(AC12,$P$5:$S$5,$P$9:$S$9)+1,DATA!$E$11:$E$370,DATA!$F$11:$F$370),"") -> 45078 | AE12: 45231 | AF12: =IFERROR($AB12*(iGeneral!$F$52*LOOKUP($AE12,DATA!$F$11:$F$370,DATA!$L$11:$L$370)),0) -> 18298246 | AG12: =-IFERROR($AB12*(i_Cost.Subd*LOOKUP($AE12,DATA!$F$11:$F$370,DATA!$L$11:$L$370)),0) -> -11893860 | AH12: =AF12+AG12 -> 6404386
C13: 6 | D13: 1.6 | E13: =IFERROR(_xlfn.XLOOKUP(D13,tbl_Parcels[Parcel],tbl_Parcels[Use]),0) -> MDR | F13: =IFERROR(_xlfn.XLOOKUP(D13,tbl_Parcels[Parcel],tbl_Parcels[Acres]),0) -> 25.8 | G13: =LOOKUP('iV1'!$H13,Table4[Product],Table4[DUA]) -> 3.972672 | H13: 50x125 | I13: =IFERROR(INT(LOOKUP('iV1'!$H13,lst_LotProducts,lst_ProductDUA)*'iV1'!$F13),0) -> 102 | J13: 1 | L13: or charts here | N13: Engineering | P13: 2500000 | Q13: 500000 | T13: =P13+Q13+R13+S13 -> 3000000 | X13: =X12+1 -> 6 | Y13: 1.6 | Z13: =IFERROR(LOOKUP(Y13,$D$8:$D$32,$I$8:$I$32),0) -> 147 | AA13: =IFERROR(_xlfn.XLOOKUP($Y13,$D$8:$D$32,$H$8:$H$32),0) -> 50x125 | AB13: =IFERROR(Z13*LOOKUP(AA13,Table4[Product],Table4[Width]),0) -> 7350 | AC13: =IFERROR(_xlfn.XLOOKUP($Y13,$D$8:$D$32,$J$8:$J$32),0) -> 1 | AD13: =IFERROR(_xlfn.XLOOKUP(LOOKUP(AC13,$P$5:$S$5,$P$9:$S$9)+1,DATA!$E$11:$E$370,DATA!$F$11:$F$370),"") -> 45078 | AE13: 45231 | AF13: =IFERROR($AB13*(iGeneral!$F$52*LOOKUP($AE13,DATA!$F$11:$F$370,DATA!$L$11:$L$370)),0) -> 15248538 | AG13: =-IFERROR($AB13*(i_Cost.Subd*LOOKUP($AE13,DATA!$F$11:$F$370,DATA!$L$11:$L$370)),0) -> -9911549.8 | AH13: =AF13+AG13 -> 5336988.3
C14: 7 | D14: 1.7 | E14: =IFERROR(_xlfn.XLOOKUP(D14,tbl_Parcels[Parcel],tbl_Parcels[Use]),0) -> MDR | F14: =IFERROR(_xlfn.XLOOKUP(D14,tbl_Parcels[Parcel],tbl_Parcels[Acres]),0) -> 19.53 | G14: =LOOKUP('iV1'!$H14,Table4[Product],Table4[DUA]) -> 4.598 | H14: 45x120 | I14: =IFERROR(INT(LOOKUP('iV1'!$H14,lst_LotProducts,lst_ProductDUA)*'iV1'!$F14),0) -> 89 | J14: 1 | N14: Development > Offsite | P14: 2500000 | Q14: 0 | T14: =P14+Q14+R14+S14 -> 2500000 | X14: =X13+1 -> 7 | Y14: 1.7 | Z14: =IFERROR(LOOKUP(Y14,$D$8:$D$32,$I$8:$I$32),0) -> 147 | AA14: =IFERROR(_xlfn.XLOOKUP($Y14,$D$8:$D$32,$H$8:$H$32),0) -> 45x120 | AB14: =IFERROR(Z14*LOOKUP(AA14,Table4[Product],Table4[Width]),0) -> 6615 | AC14: =IFERROR(_xlfn.XLOOKUP($Y14,$D$8:$D$32,$J$8:$J$32),0) -> 1 | AD14: =IFERROR(_xlfn.XLOOKUP(LOOKUP(AC14,$P$5:$S$5,$P$9:$S$9)+1,DATA!$E$11:$E$370,DATA!$F$11:$F$370),"") -> 45078 | AE14: 45231 | AF14: =IFERROR($AB14*(iGeneral!$F$52*LOOKUP($AE14,DATA!$F$11:$F$370,DATA!$L$11:$L$370)),0) -> 13723684 | AG14: =-IFERROR($AB14*(i_Cost.Subd*LOOKUP($AE14,DATA!$F$11:$F$370,DATA!$L$11:$L$370)),0) -> -8920394.8 | AH14: =AF14+AG14 -> 4803289.5
C15: 8 | D15: 1.8 | E15: =IFERROR(_xlfn.XLOOKUP(D15,tbl_Parcels[Parcel],tbl_Parcels[Use]),0) -> MDR | F15: =IFERROR(_xlfn.XLOOKUP(D15,tbl_Parcels[Parcel],tbl_Parcels[Acres]),0) -> 30.58 | G15: =LOOKUP('iV1'!$H15,Table4[Product],Table4[DUA]) -> 4.797913 | H15: 45x115 | I15: =IFERROR(INT(LOOKUP('iV1'!$H15,lst_LotProducts,lst_ProductDUA)*'iV1'!$F15),0) -> 146 | J15: 1 | N15: Development > OnSite | P15: 5000000 | Q15: 3000000 | T15: =P15+Q15+R15+S15 -> 8000000 | X15: =X14+1 -> 8 | Y15: 1.8 | Z15: =IFERROR(LOOKUP(Y15,$D$8:$D$32,$I$8:$I$32),0) -> 147 | AA15: =IFERROR(_xlfn.XLOOKUP($Y15,$D$8:$D$32,$H$8:$H$32),0) -> 45x115 | AB15: =IFERROR(Z15*LOOKUP(AA15,Table4[Product],Table4[Width]),0) -> 6615 | AC15: =IFERROR(_xlfn.XLOOKUP($Y15,$D$8:$D$32,$J$8:$J$32),0) -> 1 | AD15: =IFERROR(_xlfn.XLOOKUP(LOOKUP(AC15,$P$5:$S$5,$P$9:$S$9)+1,DATA!$E$11:$E$370,DATA!$F$11:$F$370),"") -> 45078 | AE15: 45231 | AF15: =IFERROR($AB15*(iGeneral!$F$52*LOOKUP($AE15,DATA!$F$11:$F$370,DATA!$L$11:$L$370)),0) -> 13723684 | AG15: =-IFERROR($AB15*(i_Cost.Subd*LOOKUP($AE15,DATA!$F$11:$F$370,DATA!$L$11:$L$370)),0) -> -8920394.8 | AH15: =AF15+AG15 -> 4803289.5
C16: 9 | D16: 1.9 | E16: =IFERROR(_xlfn.XLOOKUP(D16,tbl_Parcels[Parcel],tbl_Parcels[Use]),0) -> MDR | F16: =IFERROR(_xlfn.XLOOKUP(D16,tbl_Parcels[Parcel],tbl_Parcels[Acres]),0) -> 21.71 | G16: =LOOKUP('iV1'!$H16,Table4[Product],Table4[DUA]) -> 4.5144 | H16: 50x110 | I16: =IFERROR(INT(LOOKUP('iV1'!$H16,lst_LotProducts,lst_ProductDUA)*'iV1'!$F16),0) -> 98 | J16: 2 | N16: Development > Subdivision | P16: 0 | Q16: 15000000 | T16: =P16+Q16+R16+S16 -> 15000000 | X16: =X15+1 -> 9 | Y16: 1.9 | Z16: =IFERROR(LOOKUP(Y16,$D$8:$D$32,$I$8:$I$32),0) -> 147 | AA16: =IFERROR(_xlfn.XLOOKUP($Y16,$D$8:$D$32,$H$8:$H$32),0) -> 50x110 | AB16: =IFERROR(Z16*LOOKUP(AA16,Table4[Product],Table4[Width]),0) -> 7350 | AC16: =IFERROR(_xlfn.XLOOKUP($Y16,$D$8:$D$32,$J$8:$J$32),0) -> 2 | AD16: =IFERROR(_xlfn.XLOOKUP(LOOKUP(AC16,$P$5:$S$5,$P$9:$S$9)+1,DATA!$E$11:$E$370,DATA!$F$11:$F$370),"") -> 45689 | AE16: 45717 | AF16: =IFERROR($AB16*(iGeneral!$F$52*LOOKUP($AE16,DATA!$F$11:$F$370,DATA!$L$11:$L$370)),0) -> 15660288 | AG16: =-IFERROR($AB16*(i_Cost.Subd*LOOKUP($AE16,DATA!$F$11:$F$370,DATA!$L$11:$L$370)),0) -> -10179187 | AH16: =AF16+AG16 -> 5481100.9
C17: 10 | D17: 1.10 | E17: =IFERROR(_xlfn.XLOOKUP(D17,tbl_Parcels[Parcel],tbl_Parcels[Use]),0) -> MDR | F17: =IFERROR(_xlfn.XLOOKUP(D17,tbl_Parcels[Parcel],tbl_Parcels[Acres]),0) -> 22.39 | G17: =LOOKUP('iV1'!$H17,Table4[Product],Table4[DUA]) -> 4.797913 | H17: 45x115 | I17: =IFERROR(INT(LOOKUP('iV1'!$H17,lst_LotProducts,lst_ProductDUA)*'iV1'!$F17),0) -> 107 | J17: 2 | N17: Development > Other | P17: 2500000 | Q17: 1000000 | T17: =P17+Q17+R17+S17 -> 3500000 | X17: =X16+1 -> 10 | Y17: 1.10 | Z17: =IFERROR(LOOKUP(Y17,$D$8:$D$32,$I$8:$I$32),0) -> 109 | AA17: =IFERROR(_xlfn.XLOOKUP($Y17,$D$8:$D$32,$H$8:$H$32),0) -> 45x115 | AB17: =IFERROR(Z17*LOOKUP(AA17,Table4[Product],Table4[Width]),0) -> 4905 | AC17: =IFERROR(_xlfn.XLOOKUP($Y17,$D$8:$D$32,$J$8:$J$32),0) -> 2 | AD17: =IFERROR(_xlfn.XLOOKUP(LOOKUP(AC17,$P$5:$S$5,$P$9:$S$9)+1,DATA!$E$11:$E$370,DATA!$F$11:$F$370),"") -> 45689 | AE17: 45717 | AF17: =IFERROR($AB17*(iGeneral!$F$52*LOOKUP($AE17,DATA!$F$11:$F$370,DATA!$L$11:$L$370)),0) -> 10450846 | AG17: =-IFERROR($AB17*(i_Cost.Subd*LOOKUP($AE17,DATA!$F$11:$F$370,DATA!$L$11:$L$370)),0) -> -6793049.6 | AH17: =AF17+AG17 -> 3657795.9
C18: 11 | D18: 1.11 | E18: =IFERROR(_xlfn.XLOOKUP(D18,tbl_Parcels[Parcel],tbl_Parcels[Use]),0) -> MLDR | F18: =IFERROR(_xlfn.XLOOKUP(D18,tbl_Parcels[Parcel],tbl_Parcels[Acres]),0) -> 29.51 | G18: =LOOKUP('iV1'!$H18,Table4[Product],Table4[DUA]) -> 2.7284835 | H18: 70x130 | I18: =IFERROR(INT(LOOKUP('iV1'!$H18,lst_LotProducts,lst_ProductDUA)*'iV1'!$F18),0) -> 80 | J18: 2 | N18: Other | P18: 0 | Q18: 0 | R18: 0 | S18: 0 | T18: =P18+Q18+R18+S18 -> 0 | X18: =X17+1 -> 11 | Y18: 1.11 | Z18: =IFERROR(LOOKUP(Y18,$D$8:$D$32,$I$8:$I$32),0) -> 109 | AA18: =IFERROR(_xlfn.XLOOKUP($Y18,$D$8:$D$32,$H$8:$H$32),0) -> 70x130 | AB18: =IFERROR(Z18*LOOKUP(AA18,Table4[Product],Table4[Width]),0) -> 7630 | AC18: =IFERROR(_xlfn.XLOOKUP($Y18,$D$8:$D$32,$J$8:$J$32),0) -> 2 | AD18: =IFERROR(_xlfn.XLOOKUP(LOOKUP(AC18,$P$5:$S$5,$P$9:$S$9)+1,DATA!$E$11:$E$370,DATA!$F$11:$F$370),"") -> 45689 | AE18: 45717 | AF18: =IFERROR($AB18*(iGeneral!$F$52*LOOKUP($AE18,DATA!$F$11:$F$370,DATA!$L$11:$L$370)),0) -> 16256871 | AG18: =-IFERROR($AB18*(i_Cost.Subd*LOOKUP($AE18,DATA!$F$11:$F$370,DATA!$L$11:$L$370)),0) -> -10566966 | AH18: =AF18+AG18 -> 5689904.8
C19: 12 | D19: 1.12 | E19: =IFERROR(_xlfn.XLOOKUP(D19,tbl_Parcels[Parcel],tbl_Parcels[Use]),0) -> MLDR | F19: =IFERROR(_xlfn.XLOOKUP(D19,tbl_Parcels[Parcel],tbl_Parcels[Acres]),0) -> 26.9 | G19: =LOOKUP('iV1'!$H19,Table4[Product],Table4[DUA]) -> 3.1832308 | H19: 65x120 | I19: =IFERROR(INT(LOOKUP('iV1'!$H19,lst_LotProducts,lst_ProductDUA)*'iV1'!$F19),0) -> 85 | J19: 2 | P19: 0 | Q19: 0 | R19: 0 | S19: 0 | T19: =P19+Q19+R19+S19 -> 0 | X19: =X18+1 -> 12 | Y19: 1.12 | Z19: =IFERROR(LOOKUP(Y19,$D$8:$D$32,$I$8:$I$32),0) -> 109 | AA19: =IFERROR(_xlfn.XLOOKUP($Y19,$D$8:$D$32,$H$8:$H$32),0) -> 65x120 | AB19: =IFERROR(Z19*LOOKUP(AA19,Table4[Product],Table4[Width]),0) -> 7085 | AC19: =IFERROR(_xlfn.XLOOKUP($Y19,$D$8:$D$32,$J$8:$J$32),0) -> 2 | AD19: =IFERROR(_xlfn.XLOOKUP(LOOKUP(AC19,$P$5:$S$5,$P$9:$S$9)+1,DATA!$E$11:$E$370,DATA!$F$11:$F$370),"") -> 45689 | AE19: 45717 | AF19: =IFERROR($AB19*(iGeneral!$F$52*LOOKUP($AE19,DATA!$F$11:$F$370,DATA!$L$11:$L$370)),0) -> 15095666 | AG19: =-IFERROR($AB19*(i_Cost.Subd*LOOKUP($AE19,DATA!$F$11:$F$370,DATA!$L$11:$L$370)),0) -> -9812182.8 | AH19: =AF19+AG19 -> 5283483
C20: 13 | D20: 1.13 | E20: =IFERROR(_xlfn.XLOOKUP(D20,tbl_Parcels[Parcel],tbl_Parcels[Use]),0) -> MDR | F20: =IFERROR(_xlfn.XLOOKUP(D20,tbl_Parcels[Parcel],tbl_Parcels[Acres]),0) -> 20.29 | G20: =LOOKUP('iV1'!$H20,Table4[Product],Table4[DUA]) -> 4.797913 | H20: 45x115 | I20: =IFERROR(INT(LOOKUP('iV1'!$H20,lst_LotProducts,lst_ProductDUA)*'iV1'!$F20),0) -> 97 | J20: 2 | P20: 0 | Q20: 0 | R20: 0 | S20: 0 | T20: =P20+Q20+R20+S20 -> 0 | X20: =X19+1 -> 13 | Y20: 1.13 | Z20: =IFERROR(LOOKUP(Y20,$D$8:$D$32,$I$8:$I$32),0) -> 97 | AA20: =IFERROR(_xlfn.XLOOKUP($Y20,$D$8:$D$32,$H$8:$H$32),0) -> 45x115 | AB20: =IFERROR(Z20*LOOKUP(AA20,Table4[Product],Table4[Width]),0) -> 4365 | AC20: =IFERROR(_xlfn.XLOOKUP($Y20,$D$8:$D$32,$J$8:$J$32),0) -> 2 | AD20: =IFERROR(_xlfn.XLOOKUP(LOOKUP(AC20,$P$5:$S$5,$P$9:$S$9)+1,DATA!$E$11:$E$370,DATA!$F$11:$F$370),"") -> 45689 | AE20: 45992 | AF20: =IFERROR($AB20*(iGeneral!$F$52*LOOKUP($AE20,DATA!$F$11:$F$370,DATA!$L$11:$L$370)),0) -> 9440731.8 | AG20: =-IFERROR($AB20*(i_Cost.Subd*LOOKUP($AE20,DATA!$F$11:$F$370,DATA!$L$11:$L$370)),0) -> -6136475.7 | AH20: =AF20+AG20 -> 3304256.1
C21: 14 | D21: 1.14 | E21: =IFERROR(_xlfn.XLOOKUP(D21,tbl_Parcels[Parcel],tbl_Parcels[Use]),0) -> MDR | F21: =IFERROR(_xlfn.XLOOKUP(D21,tbl_Parcels[Parcel],tbl_Parcels[Acres]),0) -> 21.53 | G21: =LOOKUP('iV1'!$H21,Table4[Product],Table4[DUA]) -> 5.016 | H21: 45x110 | I21: =IFERROR(INT(LOOKUP('iV1'!$H21,lst_LotProducts,lst_ProductDUA)*'iV1'!$F21),0) -> 107 | J21: 2 | P21: 0 | Q21: 0 | R21: 0 | S21: 0 | T21: =P21+Q21+R21+S21 -> 0 | X21: =X20+1 -> 14 | Y21: 1.14 | Z21: =IFERROR(LOOKUP(Y21,$D$8:$D$32,$I$8:$I$32),0) -> 107 | AA21: =IFERROR(_xlfn.XLOOKUP($Y21,$D$8:$D$32,$H$8:$H$32),0) -> 45x110 | AB21: =IFERROR(Z21*LOOKUP(AA21,Table4[Product],Table4[Width]),0) -> 4815 | AC21: =IFERROR(_xlfn.XLOOKUP($Y21,$D$8:$D$32,$J$8:$J$32),0) -> 2 | AD21: =IFERROR(_xlfn.XLOOKUP(LOOKUP(AC21,$P$5:$S$5,$P$9:$S$9)+1,DATA!$E$11:$E$370,DATA!$F$11:$F$370),"") -> 45689 | AE21: =AE20 -> 45992 | AF21: =IFERROR($AB21*(iGeneral!$F$52*LOOKUP($AE21,DATA!$F$11:$F$370,DATA!$L$11:$L$370)),0) -> 10414003 | AG21: =-IFERROR($AB21*(i_Cost.Subd*LOOKUP($AE21,DATA!$F$11:$F$370,DATA!$L$11:$L$370)),0) -> -6769102 | AH21: =AF21+AG21 -> 3644901.1
C22: 15 | D22: 1.15 | E22: =IFERROR(_xlfn.XLOOKUP(D22,tbl_Parcels[Parcel],tbl_Parcels[Use]),0) -> MDR | F22: =IFERROR(_xlfn.XLOOKUP(D22,tbl_Parcels[Parcel],tbl_Parcels[Acres]),0) -> 34.27 | G22: =IFERROR(LOOKUP('iV1'!$H22,Table4[Product],Table4[DUA]),0) -> 4.3181217 | H22: 50x115 | I22: =IFERROR(INT(LOOKUP('iV1'!$H22,lst_LotProducts,lst_ProductDUA)*'iV1'!$F22),0) -> 147 | J22: 2 | P22: 0 | Q22: 0 | R22: 0 | S22: 0 | T22: =P22+Q22+R22+S22 -> 0 | X22: =X21+1 -> 15 | Y22: 1.15 | Z22: =IFERROR(LOOKUP(Y22,$D$8:$D$32,$I$8:$I$32),0) -> 147 | AA22: =IFERROR(_xlfn.XLOOKUP($Y22,$D$8:$D$32,$H$8:$H$32),0) -> 50x115 | AB22: =IFERROR(Z22*LOOKUP(AA22,Table4[Product],Table4[Width]),0) -> 7350 | AC22: =IFERROR(_xlfn.XLOOKUP($Y22,$D$8:$D$32,$J$8:$J$32),0) -> 2 | AD22: =IFERROR(_xlfn.XLOOKUP(LOOKUP(AC22,$P$5:$S$5,$P$9:$S$9)+1,DATA!$E$11:$E$370,DATA!$F$11:$F$370),"") -> 45689 | AE22: =AE21 -> 45992 | AF22: =IFERROR($AB22*(iGeneral!$F$52*LOOKUP($AE22,DATA!$F$11:$F$370,DATA!$L$11:$L$370)),0) -> 15896765 | AG22: =-IFERROR($AB22*(i_Cost.Subd*LOOKUP($AE22,DATA!$F$11:$F$370,DATA!$L$11:$L$370)),0) -> -10332897 | AH22: =AF22+AG22 -> 5563867.7
C23: 16 | E23: =IFERROR(_xlfn.XLOOKUP(D23,tbl_Parcels[Parcel],tbl_Parcels[Use]),0) -> 0 | F23: =IFERROR(_xlfn.XLOOKUP(D23,tbl_Parcels[Parcel],tbl_Parcels[Acres]),0) -> 0 | G23: =IFERROR(LOOKUP('iV1'!$H23,Table4[Product],Table4[DUA]),0) -> 0 | I23: =IFERROR(INT(LOOKUP('iV1'!$H23,lst_LotProducts,lst_ProductDUA)*'iV1'!$F23),0) -> 0 | P23: 0 | Q23: 0 | R23: 0 | S23: 0 | T23: =P23+Q23+R23+S23 -> 0 | X23: =X22+1 -> 16 | Z23: =IFERROR(LOOKUP(Y23,$D$8:$D$32,$I$8:$I$32),0) -> 0 | AA23: =IFERROR(_xlfn.XLOOKUP($Y23,$D$8:$D$32,$H$8:$H$32),0) -> 0 | AB23: =IFERROR(Z23*LOOKUP(AA23,Table4[Product],Table4[Width]),0) -> 0 | AC23: =IFERROR(_xlfn.XLOOKUP($Y23,$D$8:$D$32,$J$8:$J$32),0) -> 0 | AD23: =IFERROR(_xlfn.XLOOKUP(LOOKUP(AC23,$P$5:$S$5,$P$9:$S$9)+1,DATA!$E$11:$E$370,DATA!$F$11:$F$370),"") | AF23: =IFERROR($AB23*(iGeneral!$F$52*LOOKUP($AE23,DATA!$F$11:$F$370,DATA!$L$11:$L$370)),0) -> 0 | AG23: =-IFERROR($AB23*(i_Cost.Subd*LOOKUP($AE23,DATA!$F$11:$F$370,DATA!$L$11:$L$370)),0) -> 0 | AH23: =AF23+AG23 -> 0
C24: 17 | E24: =IFERROR(_xlfn.XLOOKUP(D24,tbl_Parcels[Parcel],tbl_Parcels[Use]),0) -> 0 | F24: =IFERROR(_xlfn.XLOOKUP(D24,tbl_Parcels[Parcel],tbl_Parcels[Acres]),0) -> 0 | G24: =IFERROR(LOOKUP('iV1'!$H24,Table4[Product],Table4[DUA]),0) -> 0 | I24: =IFERROR(INT(LOOKUP('iV1'!$H24,lst_LotProducts,lst_ProductDUA)*'iV1'!$F24),0) -> 0 | P24: 0 | Q24: 0 | R24: 0 | S24: 0 | T24: =P24+Q24+R24+S24 -> 0 | X24: =X23+1 -> 17 | Z24: =IFERROR(LOOKUP(Y24,$D$8:$D$32,$I$8:$I$32),0) -> 0 | AA24: =IFERROR(_xlfn.XLOOKUP($Y24,$D$8:$D$32,$H$8:$H$32),0) -> 0 | AB24: =IFERROR(Z24*LOOKUP(AA24,Table4[Product],Table4[Width]),0) -> 0 | AC24: =IFERROR(_xlfn.XLOOKUP($Y24,$D$8:$D$32,$J$8:$J$32),0) -> 0 | AD24: =IFERROR(_xlfn.XLOOKUP(LOOKUP(AC24,$P$5:$S$5,$P$9:$S$9)+1,DATA!$E$11:$E$370,DATA!$F$11:$F$370),"") | AF24: =IFERROR($AB24*(iGeneral!$F$52*LOOKUP($AE24,DATA!$F$11:$F$370,DATA!$L$11:$L$370)),0) -> 0 | AG24: =-IFERROR($AB24*(i_Cost.Subd*LOOKUP($AE24,DATA!$F$11:$F$370,DATA!$L$11:$L$370)),0) -> 0 | AH24: =AF24+AG24 -> 0
C25: 18 | E25: =IFERROR(_xlfn.XLOOKUP(D25,tbl_Parcels[Parcel],tbl_Parcels[Use]),0) -> 0 | F25: =IFERROR(_xlfn.XLOOKUP(D25,tbl_Parcels[Parcel],tbl_Parcels[Acres]),0) -> 0 | G25: =IFERROR(LOOKUP('iV1'!$H25,Table4[Product],Table4[DUA]),0) -> 0 | I25: =IFERROR(INT(LOOKUP('iV1'!$H25,lst_LotProducts,lst_ProductDUA)*'iV1'!$F25),0) -> 0 | P25: 0 | Q25: 0 | R25: 0 | S25: 0 | T25: =P25+Q25+R25+S25 -> 0 | X25: =X24+1 -> 18 | Z25: =IFERROR(LOOKUP(Y25,$D$8:$D$32,$I$8:$I$32),0) -> 0 | AA25: =IFERROR(_xlfn.XLOOKUP($Y25,$D$8:$D$32,$H$8:$H$32),0) -> 0 | AB25: =IFERROR(Z25*LOOKUP(AA25,Table4[Product],Table4[Width]),0) -> 0 | AC25: =IFERROR(_xlfn.XLOOKUP($Y25,$D$8:$D$32,$J$8:$J$32),0) -> 0 | AD25: =IFERROR(_xlfn.XLOOKUP(LOOKUP(AC25,$P$5:$S$5,$P$9:$S$9)+1,DATA!$E$11:$E$370,DATA!$F$11:$F$370),"") | AF25: =IFERROR($AB25*(iGeneral!$F$52*LOOKUP($AE25,DATA!$F$11:$F$370,DATA!$L$11:$L$370)),0) -> 0 | AG25: =-IFERROR($AB25*(i_Cost.Subd*LOOKUP($AE25,DATA!$F$11:$F$370,DATA!$L$11:$L$370)),0) -> 0 | AH25: =AF25+AG25 -> 0
C26: 19 | E26: =IFERROR(_xlfn.XLOOKUP(D26,tbl_Parcels[Parcel],tbl_Parcels[Use]),0) -> 0 | F26: =IFERROR(_xlfn.XLOOKUP(D26,tbl_Parcels[Parcel],tbl_Parcels[Acres]),0) -> 0 | G26: =IFERROR(LOOKUP('iV1'!$H26,Table4[Product],Table4[DUA]),0) -> 0 | I26: =IFERROR(INT(LOOKUP('iV1'!$H26,lst_LotProducts,lst_ProductDUA)*'iV1'!$F26),0) -> 0 | P26: 0 | Q26: 0 | R26: 0 | S26: 0 | T26: =P26+Q26+R26+S26 -> 0 | X26: =X25+1 -> 19 | Z26: =IFERROR(LOOKUP(Y26,$D$8:$D$32,$I$8:$I$32),0) -> 0 | AA26: =IFERROR(_xlfn.XLOOKUP($Y26,$D$8:$D$32,$H$8:$H$32),0) -> 0 | AB26: =IFERROR(Z26*LOOKUP(AA26,Table4[Product],Table4[Width]),0) -> 0 | AC26: =IFERROR(_xlfn.XLOOKUP($Y26,$D$8:$D$32,$J$8:$J$32),0) -> 0 | AD26: =IFERROR(_xlfn.XLOOKUP(LOOKUP(AC26,$P$5:$S$5,$P$9:$S$9)+1,DATA!$E$11:$E$370,DATA!$F$11:$F$370),"") | AF26: =IFERROR($AB26*(iGeneral!$F$52*LOOKUP($AE26,DATA!$F$11:$F$370,DATA!$L$11:$L$370)),0) -> 0 | AG26: =-IFERROR($AB26*(i_Cost.Subd*LOOKUP($AE26,DATA!$F$11:$F$370,DATA!$L$11:$L$370)),0) -> 0 | AH26: =AF26+AG26 -> 0
C27: 20 | E27: =IFERROR(_xlfn.XLOOKUP(D27,tbl_Parcels[Parcel],tbl_Parcels[Use]),0) -> 0 | F27: =IFERROR(_xlfn.XLOOKUP(D27,tbl_Parcels[Parcel],tbl_Parcels[Acres]),0) -> 0 | G27: =IFERROR(LOOKUP('iV1'!$H27,Table4[Product],Table4[DUA]),0) -> 0 | I27: =IFERROR(INT(LOOKUP('iV1'!$H27,lst_LotProducts,lst_ProductDUA)*'iV1'!$F27),0) -> 0 | P27: 0 | Q27: 0 | R27: 0 | S27: 0 | T27: =P27+Q27+R27+S27 -> 0 | X27: =X26+1 -> 20 | Z27: =IFERROR(LOOKUP(Y27,$D$8:$D$32,$I$8:$I$32),0) -> 0 | AA27: =IFERROR(_xlfn.XLOOKUP($Y27,$D$8:$D$32,$H$8:$H$32),0) -> 0 | AB27: =IFERROR(Z27*LOOKUP(AA27,Table4[Product],Table4[Width]),0) -> 0 | AC27: =IFERROR(_xlfn.XLOOKUP($Y27,$D$8:$D$32,$J$8:$J$32),0) -> 0 | AD27: =IFERROR(_xlfn.XLOOKUP(LOOKUP(AC27,$P$5:$S$5,$P$9:$S$9)+1,DATA!$E$11:$E$370,DATA!$F$11:$F$370),"") | AF27: =IFERROR($AB27*(iGeneral!$F$52*LOOKUP($AE27,DATA!$F$11:$F$370,DATA!$L$11:$L$370)),0) -> 0 | AG27: =-IFERROR($AB27*(i_Cost.Subd*LOOKUP($AE27,DATA!$F$11:$F$370,DATA!$L$11:$L$370)),0) -> 0 | AH27: =AF27+AG27 -> 0
C28: 21 | E28: =IFERROR(_xlfn.XLOOKUP(D28,tbl_Parcels[Parcel],tbl_Parcels[Use]),0) -> 0 | F28: =IFERROR(_xlfn.XLOOKUP(D28,tbl_Parcels[Parcel],tbl_Parcels[Acres]),0) -> 0 | G28: =IFERROR(LOOKUP('iV1'!$H28,Table4[Product],Table4[DUA]),0) -> 0 | I28: =IFERROR(INT(LOOKUP('iV1'!$H28,lst_LotProducts,lst_ProductDUA)*'iV1'!$F28),0) -> 0 | P28: 0 | Q28: 0 | R28: 0 | S28: 0 | T28: =P28+Q28+R28+S28 -> 0 | X28: =X27+1 -> 21 | Z28: =IFERROR(LOOKUP(Y28,$D$8:$D$32,$I$8:$I$32),0) -> 0 | AA28: =IFERROR(_xlfn.XLOOKUP($Y28,$D$8:$D$32,$H$8:$H$32),0) -> 0 | AB28: =IFERROR(Z28*LOOKUP(AA28,Table4[Product],Table4[Width]),0) -> 0 | AC28: =IFERROR(_xlfn.XLOOKUP($Y28,$D$8:$D$32,$J$8:$J$32),0) -> 0 | AD28: =IFERROR(_xlfn.XLOOKUP(LOOKUP(AC28,$P$5:$S$5,$P$9:$S$9)+1,DATA!$E$11:$E$370,DATA!$F$11:$F$370),"") | AF28: =IFERROR($AB28*(iGeneral!$F$52*LOOKUP($AE28,DATA!$F$11:$F$370,DATA!$L$11:$L$370)),0) -> 0 | AG28: =-IFERROR($AB28*(i_Cost.Subd*LOOKUP($AE28,DATA!$F$11:$F$370,DATA!$L$11:$L$370)),0) -> 0 | AH28: =AF28+AG28 -> 0
C29: 22 | E29: =IFERROR(_xlfn.XLOOKUP(D29,tbl_Parcels[Parcel],tbl_Parcels[Use]),0) -> 0 | F29: =IFERROR(_xlfn.XLOOKUP(D29,tbl_Parcels[Parcel],tbl_Parcels[Acres]),0) -> 0 | G29: =IFERROR(LOOKUP('iV1'!$H29,Table4[Product],Table4[DUA]),0) -> 0 | I29: =IFERROR(INT(LOOKUP('iV1'!$H29,lst_LotProducts,lst_ProductDUA)*'iV1'!$F29),0) -> 0 | P29: 0 | Q29: 0 | R29: 0 | S29: 0 | T29: =P29+Q29+R29+S29 -> 0 | X29: =X28+1 -> 22 | Z29: =IFERROR(LOOKUP(Y29,$D$8:$D$32,$I$8:$I$32),0) -> 0 | AA29: =IFERROR(_xlfn.XLOOKUP($Y29,$D$8:$D$32,$H$8:$H$32),0) -> 0 | AB29: =IFERROR(Z29*LOOKUP(AA29,Table4[Product],Table4[Width]),0) -> 0 | AC29: =IFERROR(_xlfn.XLOOKUP($Y29,$D$8:$D$32,$J$8:$J$32),0) -> 0 | AD29: =IFERROR(_xlfn.XLOOKUP(LOOKUP(AC29,$P$5:$S$5,$P$9:$S$9)+1,DATA!$E$11:$E$370,DATA!$F$11:$F$370),"") | AF29: =IFERROR($AB29*(iGeneral!$F$52*LOOKUP($AE29,DATA!$F$11:$F$370,DATA!$L$11:$L$370)),0) -> 0 | AG29: =-IFERROR($AB29*(i_Cost.Subd*LOOKUP($AE29,DATA!$F$11:$F$370,DATA!$L$11:$L$370)),0) -> 0 | AH29: =AF29+AG29 -> 0
C30: 23 | E30: =IFERROR(_xlfn.XLOOKUP(D30,tbl_Parcels[Parcel],tbl_Parcels[Use]),0) -> 0 | F30: =IFERROR(_xlfn.XLOOKUP(D30,tbl_Parcels[Parcel],tbl_Parcels[Acres]),0) -> 0 | G30: =IFERROR(LOOKUP('iV1'!$H30,Table4[Product],Table4[DUA]),0) -> 0 | I30: =IFERROR(INT(LOOKUP('iV1'!$H30,lst_LotProducts,lst_ProductDUA)*'iV1'!$F30),0) -> 0 | P30: 0 | Q30: 0 | R30: 0 | S30: 0 | T30: =P30+Q30+R30+S30 -> 0 | X30: =X29+1 -> 23 | Z30: =IFERROR(LOOKUP(Y30,$D$8:$D$32,$I$8:$I$32),0) -> 0 | AA30: =IFERROR(_xlfn.XLOOKUP($Y30,$D$8:$D$32,$H$8:$H$32),0) -> 0 | AB30: =IFERROR(Z30*LOOKUP(AA30,Table4[Product],Table4[Width]),0) -> 0 | AC30: =IFERROR(_xlfn.XLOOKUP($Y30,$D$8:$D$32,$J$8:$J$32),0) -> 0 | AD30: =IFERROR(_xlfn.XLOOKUP(LOOKUP(AC30,$P$5:$S$5,$P$9:$S$9)+1,DATA!$E$11:$E$370,DATA!$F$11:$F$370),"") | AF30: =IFERROR($AB30*(iGeneral!$F$52*LOOKUP($AE30,DATA!$F$11:$F$370,DATA!$L$11:$L$370)),0) -> 0 | AG30: =-IFERROR($AB30*(i_Cost.Subd*LOOKUP($AE30,DATA!$F$11:$F$370,DATA!$L$11:$L$370)),0) -> 0 | AH30: =AF30+AG30 -> 0
C31: 24 | E31: =IFERROR(_xlfn.XLOOKUP(D31,tbl_Parcels[Parcel],tbl_Parcels[Use]),0) -> 0 | F31: =IFERROR(_xlfn.XLOOKUP(D31,tbl_Parcels[Parcel],tbl_Parcels[Acres]),0) -> 0 | G31: =IFERROR(LOOKUP('iV1'!$H31,Table4[Product],Table4[DUA]),0) -> 0 | I31: =IFERROR(INT(LOOKUP('iV1'!$H31,lst_LotProducts,lst_ProductDUA)*'iV1'!$F31),0) -> 0 | P31: 0 | Q31: 0 | R31: 0 | S31: 0 | T31: =P31+Q31+R31+S31 -> 0 | X31: =X30+1 -> 24 | Z31: =IFERROR(LOOKUP(Y31,$D$8:$D$32,$I$8:$I$32),0) -> 0 | AA31: =IFERROR(_xlfn.XLOOKUP($Y31,$D$8:$D$32,$H$8:$H$32),0) -> 0 | AB31: =IFERROR(Z31*LOOKUP(AA31,Table4[Product],Table4[Width]),0) -> 0 | AC31: =IFERROR(_xlfn.XLOOKUP($Y31,$D$8:$D$32,$J$8:$J$32),0) -> 0 | AD31: =IFERROR(_xlfn.XLOOKUP(LOOKUP(AC31,$P$5:$S$5,$P$9:$S$9)+1,DATA!$E$11:$E$370,DATA!$F$11:$F$370),"") | AF31: =IFERROR($AB31*(iGeneral!$F$52*LOOKUP($AE31,DATA!$F$11:$F$370,DATA!$L$11:$L$370)),0) -> 0 | AG31: =-IFERROR($AB31*(i_Cost.Subd*LOOKUP($AE31,DATA!$F$11:$F$370,DATA!$L$11:$L$370)),0) -> 0 | AH31: =AF31+AG31 -> 0
C32: 25 | E32: =IFERROR(_xlfn.XLOOKUP(D32,tbl_Parcels[Parcel],tbl_Parcels[Use]),0) -> 0 | F32: =IFERROR(_xlfn.XLOOKUP(D32,tbl_Parcels[Parcel],tbl_Parcels[Acres]),0) -> 0 | G32: =IFERROR(LOOKUP('iV1'!$H32,Table4[Product],Table4[DUA]),0) -> 0 | I32: =IFERROR(INT(LOOKUP('iV1'!$H32,lst_LotProducts,lst_ProductDUA)*'iV1'!$F32),0) -> 0 | P32: 0 | Q32: 0 | R32: 0 | S32: 0 | T32: =P32+Q32+R32+S32 -> 0 | X32: =X31+1 -> 25 | Z32: =IFERROR(LOOKUP(Y32,$D$8:$D$32,$I$8:$I$32),0) -> 0 | AA32: =IFERROR(_xlfn.XLOOKUP($Y32,$D$8:$D$32,$H$8:$H$32),0) -> 0 | AB32: =IFERROR(Z32*LOOKUP(AA32,Table4[Product],Table4[Width]),0) -> 0 | AC32: =IFERROR(_xlfn.XLOOKUP($Y32,$D$8:$D$32,$J$8:$J$32),0) -> 0 | AD32: =IFERROR(_xlfn.XLOOKUP(LOOKUP(AC32,$P$5:$S$5,$P$9:$S$9)+1,DATA!$E$11:$E$370,DATA!$F$11:$F$370),"") | AF32: =IFERROR($AB32*(iGeneral!$F$52*LOOKUP($AE32,DATA!$F$11:$F$370,DATA!$L$11:$L$370)),0) -> 0 | AG32: =-IFERROR($AB32*(i_Cost.Subd*LOOKUP($AE32,DATA!$F$11:$F$370,DATA!$L$11:$L$370)),0) -> 0 | AH32: =AF32+AG32 -> 0
N33: Total | P33: =SUM(P11:P32) -> 13000000 | Q33: =SUM(Q11:Q32) -> 19600000 | R33: =SUM(R11:R32) -> 0 | S33: =SUM(S11:S32) -> 0 | T33: =P33+Q33+R33+S33 -> 32600000

Sheet V2
C4: 2 | F4: ='iV1'!F4 -> Parcel Land Use & Lot Product | O4: =C4 -> 2 | Q4: Development Phasing | Z4: =O4 -> 2 | AB4: Sale Schedule
O5: =O4 -> 2 | Q5: 1 | R5: =Q5+1 -> 2 | S5: =R5+1 -> 3 | T5: =S5+1 -> 4 | Y5: Lag to Development Completion | AC5: 1
J6: Phasing | AD6: Sale | AE6: Proceeds | AF6: Sale | AG6: =AE6 -> Proceeds
C7: ID | D7: Parcel# | E7: Use | F7: Acres | G7: DUA | H7: Product | I7: Units | J7: Develop | K7: Sale | O7: Start Month | Q7: 6 | R7: 18 | S7: 36 | T7: 60 | Y7: # | Z7: Parcel | AA7: Lots | AB7: Product | AC7: Acres | AD7: Phase | AE7: GROSS | AF7: Cost | AG7: NET
C8: 1 | D8: {=_xlfn._xlws.FILTER(tbl_Parcels[Parcel],tbl_Parcels[Village]=C4,0)} -> 2.16 | E8: =IFERROR(_xlfn.XLOOKUP(D8,tbl_Parcels[Parcel],tbl_Parcels[Use]),0) -> MHDR | F8: =IFERROR(LOOKUP(D8,tbl_Parcels[Parcel],tbl_Parcels[Acres]),0) -> 31.85 | G8: =IFERROR(LOOKUP('V2'!$H8,Table4[Product],Table4[DUA]),0) -> 3.4485 | H8: 60x120 | I8: =IFERROR(INT(LOOKUP('V2'!$H8,lst_LotProducts,lst_ProductDUA)*'V2'!$F8),0) -> 109 | J8: 1 | O8: Months to Complete | Q8: 12 | R8: 8 | S8: 10 | T8: 6 | Y8: 1 | Z8: {=_xlfn.UNIQUE(_xlfn._xlws.FILTER(D8:D32,D8:D32<>0))} -> 2.16 | AA8: =IFERROR(LOOKUP(Z8,$D$8:$D$32,$I$8:$I$32),0) -> 109 | AB8: =IFERROR(_xlfn.XLOOKUP($Z8,$D$8:$D$32,$H$8:$H$32),0) -> 60x120 | AC8: =IFERROR(_xlfn.XLOOKUP($Z8,$D$6:$D$30,$F$6:$F$30),0) -> 31.85 | AD8: 1
C9: 2 | D9: 2.17 | E9: =IFERROR(_xlfn.XLOOKUP(D9,tbl_Parcels[Parcel],tbl_Parcels[Use]),0) -> MU | F9: =IFERROR(LOOKUP(D9,tbl_Parcels[Parcel],tbl_Parcels[Acres]),0) -> 31.04 | G9: =IFERROR(LOOKUP('V2'!$H9,Table4[Product],Table4[DUA]),0) -> 3.31056 | H9: 60x125 | I9: =IFERROR(INT(LOOKUP('V2'!$H9,lst_LotProducts,lst_ProductDUA)*'V2'!$F9),0) -> 102 | J9: 1 | U9: Total | Y9: =Y8+1 -> 2 | Z9: 2.17 | AA9: =IFERROR(LOOKUP(Z9,$D$8:$D$32,$I$8:$I$32),0) -> 102 | AB9: =IFERROR(_xlfn.XLOOKUP($Z9,$D$8:$D$32,$H$8:$H$32),0) -> 60x125 | AC9: =IFERROR(_xlfn.XLOOKUP($Z9,$D$6:$D$30,$F$6:$F$30),0) -> 31.04 | AD9: 1
C10: 3 | D10: 2.18 | E10: =IFERROR(_xlfn.XLOOKUP(D10,tbl_Parcels[Parcel],tbl_Parcels[Use]),0) -> MHDR | F10: =IFERROR(LOOKUP(D10,tbl_Parcels[Parcel],tbl_Parcels[Acres]),0) -> 27.56 | G10: =IFERROR(LOOKUP('V2'!$H10,Table4[Product],Table4[DUA]),0) -> 5.016 | H10: 45x110 | I10: =IFERROR(INT(LOOKUP('V2'!$H10,lst_LotProducts,lst_ProductDUA)*'V2'!$F10),0) -> 138 | J10: 1 | O10: Acqusition | P10: a | Q10: 0 | R10: 0 | S10: 0 | T10: 0 | U10: =Q10+R10+S10+T10 -> 0 | Y10: =Y9+1 -> 3 | Z10: 2.18 | AA10: =IFERROR(LOOKUP(Z10,$D$8:$D$32,$I$8:$I$32),0) -> 138 | AB10: =IFERROR(_xlfn.XLOOKUP($Z10,$D$8:$D$32,$H$8:$H$32),0) -> 45x110 | AC10: =IFERROR(_xlfn.XLOOKUP($Z10,$D$6:$D$30,$F$6:$F$30),0) -> 27.56 | AD10: 1
C11: 4 | D11: 2.19 | E11: =IFERROR(_xlfn.XLOOKUP(D11,tbl_Parcels[Parcel],tbl_Parcels[Use]),0) -> MU | F11: =IFERROR(LOOKUP(D11,tbl_Parcels[Parcel],tbl_Parcels[Acres]),0) -> 21.86 | G11: =IFERROR(LOOKUP('V2'!$H11,Table4[Product],Table4[DUA]),0) -> 5.016 | H11: 45x110 | I11: =IFERROR(INT(LOOKUP('V2'!$H11,lst_LotProducts,lst_ProductDUA)*'V2'!$F11),0) -> 109 | J11: 1 | M11: insert summary | O11: Entitlements | Q11: 5000000 | R11: 2500000 | S11: 1500000 | T11: 3000000 | U11: =Q11+R11+S11+T11 -> 12000000 | W11: insert summary | Y11: =Y10+1 -> 4 | Z11: 2.19 | AA11: =IFERROR(LOOKUP(Z11,$D$8:$D$32,$I$8:$I$32),0) -> 109 | AB11: =IFERROR(_xlfn.XLOOKUP($Z11,$D$8:$D$32,$H$8:$H$32),0) -> 45x110 | AC11: =IFERROR(_xlfn.XLOOKUP($Z11,$D$6:$D$30,$F$6:$F$30),0) -> 21.86 | AD11: 1
C12: 5 | D12: 2.20 | E12: =IFERROR(_xlfn.XLOOKUP(D12,tbl_Parcels[Parcel],tbl_Parcels[Use]),0) -> MU | F12: =IFERROR(LOOKUP(D12,tbl_Parcels[Parcel],tbl_Parcels[Acres]),0) -> 35.51 | G12: =IFERROR(LOOKUP('V2'!$H12,Table4[Product],Table4[DUA]),0) -> 3.31056 | H12: 60x125 | I12: =IFERROR(INT(LOOKUP('V2'!$H12,lst_LotProducts,lst_ProductDUA)*'V2'!$F12),0) -> 117 | J12: 1 | M12: or charts here | O12: Engineering | Q12: 0 | R12: 0 | S12: 0 | T12: 0 | U12: =Q12+R12+S12+T12 -> 0 | W12: or charts here | Y12: =Y11+1 -> 5 | Z12: 2.20 | AA12: =IFERROR(LOOKUP(Z12,$D$8:$D$32,$I$8:$I$32),0) -> 117 | AB12: =IFERROR(_xlfn.XLOOKUP($Z12,$D$8:$D$32,$H$8:$H$32),0) -> 60x125 | AC12: =IFERROR(_xlfn.XLOOKUP($Z12,$D$6:$D$30,$F$6:$F$30),0) -> 35.51 | AD12: 1
C13: 6 | D13: 2.21 | E13: =IFERROR(_xlfn.XLOOKUP(D13,tbl_Parcels[Parcel],tbl_Parcels[Use]),0) -> MU | F13: =IFERROR(LOOKUP(D13,tbl_Parcels[Parcel],tbl_Parcels[Acres]),0) -> 43.89 | G13: =IFERROR(LOOKUP('V2'!$H13,Table4[Product],Table4[DUA]),0) -> 3.972672 | H13: 50x125 | I13: =IFERROR(INT(LOOKUP('V2'!$H13,lst_LotProducts,lst_ProductDUA)*'V2'!$F13),0) -> 174 | J13: 1 | O13: Development > Offsite | Q13: 0 | R13: 0 | S13: 0 | T13: 0 | U13: =Q13+R13+S13+T13 -> 0 | Y13: =Y12+1 -> 6 | Z13: 2.21 | AA13: =IFERROR(LOOKUP(Z13,$D$8:$D$32,$I$8:$I$32),0) -> 174 | AB13: =IFERROR(_xlfn.XLOOKUP($Z13,$D$8:$D$32,$H$8:$H$32),0) -> 50x125 | AC13: =IFERROR(_xlfn.XLOOKUP($Z13,$D$6:$D$30,$F$6:$F$30),0) -> 43.89 | AD13: 1
C14: 7 | D14: 2.22 | E14: =IFERROR(_xlfn.XLOOKUP(D14,tbl_Parcels[Parcel],tbl_Parcels[Use]),0) -> MU | F14: =IFERROR(LOOKUP(D14,tbl_Parcels[Parcel],tbl_Parcels[Acres]),0) -> 31.59 | G14: =IFERROR(LOOKUP('V2'!$H14,Table4[Product],Table4[DUA]),0) -> 4.598 | H14: 45x120 | I14: =IFERROR(INT(LOOKUP('V2'!$H14,lst_LotProducts,lst_ProductDUA)*'V2'!$F14),0) -> 145 | J14: 1 | O14: Development > OnSite | Q14: 0 | R14: 0 | S14: 0 | T14: 0 | U14: =Q14+R14+S14+T14 -> 0 | Y14: =Y13+1 -> 7 | Z14: 2.22 | AA14: =IFERROR(LOOKUP(Z14,$D$8:$D$32,$I$8:$I$32),0) -> 145 | AB14: =IFERROR(_xlfn.XLOOKUP($Z14,$D$8:$D$32,$H$8:$H$32),0) -> 45x120 | AC14: =IFERROR(_xlfn.XLOOKUP($Z14,$D$6:$D$30,$F$6:$F$30),0) -> 31.59 | AD14: 1
C15: 8 | E15: =IFERROR(_xlfn.XLOOKUP(D15,tbl_Parcels[Parcel],tbl_Parcels[Use]),0) -> 0 | F15: =IFERROR(LOOKUP(D15,tbl_Parcels[Parcel],tbl_Parcels[Acres]),0) -> 0 | G15: =IFERROR(LOOKUP('V2'!$H15,Table4[Product],Table4[DUA]),0) -> 0 | I15: =IFERROR(INT(LOOKUP('V2'!$H15,lst_LotProducts,lst_ProductDUA)*'V2'!$F15),0) -> 0 | J15: 1 | O15: Development > Subdivision | Q15: 0 | R15: 0 | S15: 0 | T15: 0 | U15: =Q15+R15+S15+T15 -> 0 | Y15: =Y14+1 -> 8 | AA15: =IFERROR(LOOKUP(Z15,$D$8:$D$32,$I$8:$I$32),0) -> 0 | AB15: =IFERROR(_xlfn.XLOOKUP($Z15,$D$8:$D$32,$H$8:$H$32),0) -> 0 | AC15: =IFERROR(_xlfn.XLOOKUP($Z15,$D$6:$D$30,$F$6:$F$30),0) -> 0 | AD15: 2
C16: 9 | E16: =IFERROR(_xlfn.XLOOKUP(D16,tbl_Parcels[Parcel],tbl_Parcels[Use]),0) -> 0 | F16: =IFERROR(LOOKUP(D16,tbl_Parcels[Parcel],tbl_Parcels[Acres]),0) -> 0 | G16: =IFERROR(LOOKUP('V2'!$H16,Table4[Product],Table4[DUA]),0) -> 0 | I16: =IFERROR(INT(LOOKUP('V2'!$H16,lst_LotProducts,lst_ProductDUA)*'V2'!$F16),0) -> 0 | J16: 2 | O16: Development > Other | Q16: 0 | R16: 0 | S16: 0 | T16: 0 | U16: =Q16+R16+S16+T16 -> 0 | Y16: =Y15+1 -> 9 | AA16: =IFERROR(LOOKUP(Z16,$D$8:$D$32,$I$8:$I$32),0) -> 0 | AB16: =IFERROR(_xlfn.XLOOKUP($Z16,$D$8:$D$32,$H$8:$H$32),0) -> 0 | AC16: =IFERROR(_xlfn.XLOOKUP($Z16,$D$6:$D$30,$F$6:$F$30),0) -> 0 | AD16: 2
C17: 10 | E17: =IFERROR(_xlfn.XLOOKUP(D17,tbl_Parcels[Parcel],tbl_Parcels[Use]),0) -> 0 | F17: =IFERROR(LOOKUP(D17,tbl_Parcels[Parcel],tbl_Parcels[Acres]),0) -> 0 | G17: =IFERROR(LOOKUP('V2'!$H17,Table4[Product],Table4[DUA]),0) -> 0 | I17: =IFERROR(INT(LOOKUP('V2'!$H17,lst_LotProducts,lst_ProductDUA)*'V2'!$F17),0) -> 0 | J17: 2 | O17: Other | Q17: 0 | R17: 0 | S17: 0 | T17: 0 | U17: =Q17+R17+S17+T17 -> 0 | Y17: =Y16+1 -> 10 | AA17: =IFERROR(LOOKUP(Z17,$D$8:$D$32,$I$8:$I$32),0) -> 0 | AB17: =IFERROR(_xlfn.XLOOKUP($Z17,$D$8:$D$32,$H$8:$H$32),0) -> 0 | AC17: =IFERROR(_xlfn.XLOOKUP($Z17,$D$6:$D$30,$F$6:$F$30),0) -> 0 | AD17: 2
C18: 11 | E18: =IFERROR(_xlfn.XLOOKUP(D18,tbl_Parcels[Parcel],tbl_Parcels[Use]),0) -> 0 | F18: =IFERROR(LOOKUP(D18,tbl_Parcels[Parcel],tbl_Parcels[Acres]),0) -> 0 | G18: =IFERROR(LOOKUP('V2'!$H18,Table4[Product],Table4[DUA]),0) -> 0 | I18: =IFERROR(INT(LOOKUP('V2'!$H18,lst_LotProducts,lst_ProductDUA)*'V2'!$F18),0) -> 0 | J18: 2 | Q18: 0 | R18: 0 | S18: 0 | T18: 0 | U18: =Q18+R18+S18+T18 -> 0 | Y18: =Y17+1 -> 11 | AA18: =IFERROR(LOOKUP(Z18,$D$8:$D$32,$I$8:$I$32),0) -> 0 | AB18: =IFERROR(_xlfn.XLOOKUP($Z18,$D$8:$D$32,$H$8:$H$32),0) -> 0 | AC18: =IFERROR(_xlfn.XLOOKUP($Z18,$D$6:$D$30,$F$6:$F$30),0) -> 0 | AD18: 2
C19: 12 | E19: =IFERROR(_xlfn.XLOOKUP(D19,tbl_Parcels[Parcel],tbl_Parcels[Use]),0) -> 0 | F19: =IFERROR(LOOKUP(D19,tbl_Parcels[Parcel],tbl_Parcels[Acres]),0) -> 0 | G19: =IFERROR(LOOKUP('V2'!$H19,Table4[Product],Table4[DUA]),0) -> 0 | I19: =IFERROR(INT(LOOKUP('V2'!$H19,lst_LotProducts,lst_ProductDUA)*'V2'!$F19),0) -> 0 | J19: 2 | Q19: 0 | R19: 0 | S19: 0 | T19: 0 | U19: =Q19+R19+S19+T19 -> 0 | Y19: =Y18+1 -> 12 | AA19: =IFERROR(LOOKUP(Z19,$D$8:$D$32,$I$8:$I$32),0) -> 0 | AB19: =IFERROR(_xlfn.XLOOKUP($Z19,$D$8:$D$32,$H$8:$H$32),0) -> 0 | AC19: =IFERROR(_xlfn.XLOOKUP($Z19,$D$6:$D$30,$F$6:$F$30),0) -> 0 | AD19: 2
C20: 13 | E20: =IFERROR(_xlfn.XLOOKUP(D20,tbl_Parcels[Parcel],tbl_Parcels[Use]),0) -> 0 | F20: =IFERROR(LOOKUP(D20,tbl_Parcels[Parcel],tbl_Parcels[Acres]),0) -> 0 | G20: =IFERROR(LOOKUP('V2'!$H20,Table4[Product],Table4[DUA]),0) -> 0 | I20: =IFERROR(INT(LOOKUP('V2'!$H20,lst_LotProducts,lst_ProductDUA)*'V2'!$F20),0) -> 0 | J20: 2 | Q20: 0 | R20: 0 | S20: 0 | T20: 0 | U20: =Q20+R20+S20+T20 -> 0 | Y20: =Y19+1 -> 13 | AA20: =IFERROR(LOOKUP(Z20,$D$8:$D$32,$I$8:$I$32),0) -> 0 | AB20: =IFERROR(_xlfn.XLOOKUP($Z20,$D$8:$D$32,$H$8:$H$32),0) -> 0 | AC20: =IFERROR(_xlfn.XLOOKUP($Z20,$D$6:$D$30,$F$6:$F$30),0) -> 0 | AD20: 2
C21: 14 | E21: =IFERROR(_xlfn.XLOOKUP(D21,tbl_Parcels[Parcel],tbl_Parcels[Use]),0) -> 0 | F21: =IFERROR(LOOKUP(D21,tbl_Parcels[Parcel],tbl_Parcels[Acres]),0) -> 0 | G21: =IFERROR(LOOKUP('V2'!$H21,Table4[Product],Table4[DUA]),0) -> 0 | I21: =IFERROR(INT(LOOKUP('V2'!$H21,lst_LotProducts,lst_ProductDUA)*'V2'!$F21),0) -> 0 | J21: 2 | Q21: 0 | R21: 0 | S21: 0 | T21: 0 | U21: =Q21+R21+S21+T21 -> 0 | Y21: =Y20+1 -> 14 | AA21: =IFERROR(LOOKUP(Z21,$D$8:$D$32,$I$8:$I$32),0) -> 0 | AB21: =IFERROR(_xlfn.XLOOKUP($Z21,$D$8:$D$32,$H$8:$H$32),0) -> 0 | AC21: =IFERROR(_xlfn.XLOOKUP($Z21,$D$6:$D$30,$F$6:$F$30),0) -> 0 | AD21: 2
C22: 15 | E22: =IFERROR(_xlfn.XLOOKUP(D22,tbl_Parcels[Parcel],tbl_Parcels[Use]),0) -> 0 | F22: =IFERROR(LOOKUP(D22,tbl_Parcels[Parcel],tbl_Parcels[Acres]),0) -> 0 | G22: =IFERROR(LOOKUP('V2'!$H22,Table4[Product],Table4[DUA]),0) -> 0 | I22: =IFERROR(INT(LOOKUP('V2'!$H22,lst_LotProducts,lst_ProductDUA)*'V2'!$F22),0) -> 0 | Q22: 0 | R22: 0 | S22: 0 | T22: 0 | U22: =Q22+R22+S22+T22 -> 0 | Y22: =Y21+1 -> 15 | AA22: =IFERROR(LOOKUP(Z22,$D$8:$D$32,$I$8:$I$32),0) -> 0 | AB22: =IFERROR(_xlfn.XLOOKUP($Z22,$D$8:$D$32,$H$8:$H$32),0) -> 0 | AC22: =IFERROR(_xlfn.XLOOKUP($Z22,$D$6:$D$30,$F$6:$F$30),0) -> 0 | AD22: 2
C23: 16 | E23: =IFERROR(_xlfn.XLOOKUP(D23,tbl_Parcels[Parcel],tbl_Parcels[Use]),0) -> 0 | F23: =IFERROR(LOOKUP(D23,tbl_Parcels[Parcel],tbl_Parcels[Acres]),0) -> 0 | G23: =IFERROR(LOOKUP('V2'!$H23,Table4[Product],Table4[DUA]),0) -> 0 | I23: =IFERROR(INT(LOOKUP('V2'!$H23,lst_LotProducts,lst_ProductDUA)*'V2'!$F23),0) -> 0 | Q23: 0 | R23: 0 | S23: 0 | T23: 0 | U23: =Q23+R23+S23+T23 -> 0 | Y23: =Y22+1 -> 16 | AA23: =IFERROR(LOOKUP(Z23,$D$8:$D$32,$I$8:$I$32),0) -> 0 | AB23: =IFERROR(_xlfn.XLOOKUP($Z23,$D$8:$D$32,$H$8:$H$32),0) -> 0 | AC23: =IFERROR(_xlfn.XLOOKUP($Z23,$D$6:$D$30,$F$6:$F$30),0) -> 0
C24: 17 | E24: =IFERROR(_xlfn.XLOOKUP(D24,tbl_Parcels[Parcel],tbl_Parcels[Use]),0) -> 0 | F24: =IFERROR(LOOKUP(D24,tbl_Parcels[Parcel],tbl_Parcels[Acres]),0) -> 0 | G24: =IFERROR(LOOKUP('V2'!$H24,Table4[Product],Table4[DUA]),0) -> 0 | I24: =IFERROR(INT(LOOKUP('V2'!$H24,lst_LotProducts,lst_ProductDUA)*'V2'!$F24),0) -> 0 | Q24: 0 | R24: 0 | S24: 0 | T24: 0 | U24: =Q24+R24+S24+T24 -> 0 | Y24: =Y23+1 -> 17 | AA24: =IFERROR(LOOKUP(Z24,$D$8:$D$32,$I$8:$I$32),0) -> 0 | AB24: =IFERROR(_xlfn.XLOOKUP($Z24,$D$8:$D$32,$H$8:$H$32),0) -> 0 | AC24: =IFERROR(_xlfn.XLOOKUP($Z24,$D$6:$D$30,$F$6:$F$30),0) -> 0
C25: 18 | E25: =IFERROR(_xlfn.XLOOKUP(D25,tbl_Parcels[Parcel],tbl_Parcels[Use]),0) -> 0 | F25: =IFERROR(LOOKUP(D25,tbl_Parcels[Parcel],tbl_Parcels[Acres]),0) -> 0 | G25: =IFERROR(LOOKUP('V2'!$H25,Table4[Product],Table4[DUA]),0) -> 0 | I25: =IFERROR(INT(LOOKUP('V2'!$H25,lst_LotProducts,lst_ProductDUA)*'V2'!$F25),0) -> 0 | Q25: 0 | R25: 0 | S25: 0 | T25: 0 | U25: =Q25+R25+S25+T25 -> 0 | Y25: =Y24+1 -> 18 | AA25: =IFERROR(LOOKUP(Z25,$D$8:$D$32,$I$8:$I$32),0) -> 0 | AB25: =IFERROR(_xlfn.XLOOKUP($Z25,$D$8:$D$32,$H$8:$H$32),0) -> 0 | AC25: =IFERROR(_xlfn.XLOOKUP($Z25,$D$6:$D$30,$F$6:$F$30),0) -> 0
