Workbook
Name Address: Summary!$G$8
Name City: Summary!$G$9
Name Debt_Amount: Inputs!$M$14
Name Debt_Balloon: 'Investment Returns'!$N$8
Name Debt_Payment: 'Investment Returns'!$N$7
Name Discount_Rate_Credit: Inputs!$M$22
Name Discount_Rate_Residual: Inputs!$G$26
Name Discount_Rate_Spec: Inputs!$M$23
Name Equity_Share_LP: 'Investment Returns'!#REF!
Name Equity_Share_Sponsor: 'Investment Returns'!#REF!
Name Interest: Summary!$C$4
Name Land_Acres: Summary!$G$14
Name List_Property_Type: OFFSET(Data!$B$7,0,0,COUNTA(Data!$B$7:$B$14),1)
Name List_Sub1: OFFSET(Data!$D$9,0,0,COUNTA(Data!$D$9:$D$23),1)
Name List_Sub2: OFFSET(Data!$E$9,0,0,COUNTA(Data!$E$9:$E$23),1)
Name List_Sub3: OFFSET(Data!$F$9,0,0,COUNTA(Data!$F$9:$F$23),1)
Name List_Sub4: OFFSET(Data!$G$9,0,0,COUNTA(Data!$G$9:$G$23),1)
Name List_Sub5: OFFSET(Data!$H$9,0,0,COUNTA(Data!$H$9:$H$23),1)
Name List_Sub6: OFFSET(Data!$I$9,0,0,COUNTA(Data!$I$9:$I$23),1)
Name List_Sub7: OFFSET(Data!$J$9,0,0,COUNTA(Data!$J$9:$J$23),1)
Name List_Sub8: OFFSET(Data!$K$9,0,0,COUNTA(Data!$K$9:$K$23),1)
Name List_SubProperty_Type: OFFSET(Data!$M$9,0,0,Data!$M$24,1)
Name Preferred_Return: 'Investment Returns'!#REF!
Name Project_TotalCost: Inputs!$M$11
Name Promote_Structure: 'Investment Returns'!#REF!
Name Property_Name: Summary!$G$7
Name Property_Type: Summary!$G$11
Name Range_Credit: OFFSET(Valuation!$D$34,0,0,1,Inputs!$F$9)
Name Range_Month: OFFSET(Valuation!$D$14,0,0,1,Inputs!$F$9)
Name Range_Residual: OFFSET(Valuation!$D$36,0,0,1,Inputs!$F$9)
Name Range_Spec: OFFSET(Valuation!$D$35,0,0,1,Inputs!$F$9)
Name Rating: Inputs!$M$21
Name Rating_Type: Inputs!$L$21
Name Rent_Base: Inputs!$M$31
Name Rent_Inc_Type: Inputs!$M$30
Name Residual_Month: Inputs!$F$9
Name Residual_NetValue: Inputs!$G$43
Name SF_GBA: Summary!$G$15
Name SF_NRA: SF_GBA
Name State: Summary!$G$10
Name SubProperty_Type: Summary!$G$12
Name Vacancy: Inputs!$G$10
Name Version: Version!$L$3

Sheet Version
B2: SINGLE TENANT NET LEASE VALUATION MODEL
B3: Model Resources | L3: v2.4
B4: Author: Spencer Burton | H4: Important Links:
B5: https://www.adventuresincre.com/ | H5: Visit this Model's Webpage
H6: Guides and Tutorials for Using the Model
B7: Compatibility
B8: Excel 2013 | H8: Browse our entire Library of Real Estate Models
B9: Excel 2016
B10: Excel 365
B12: AdventuresinCRE.com and its affiliates do not provide tax, legal, investment, or accounting advice. This material has been prepared for informational purposes only, and is not intended to provide, and should not be relied on for, tax, legal or accounting advice. You should consult your own tax, legal and accounting advisors before engaging in any transaction.
B13: LEARN TO BUILD INSTITUTIONAL-QUALITY REAL ESTATE MODELS FROM SCRATCH - CLICK HERE TO LEARN MORE -
B14: Changelog
B15: v2.4
B16: Removed CapEx from NOI calculation on Valuation tab
B17: Added 'Lease Summary' section to Summary tab
B18: Added 'Pricing/Valuation' section to Summary tab
B19: Added 'Year 1 Net Operating Income' output to Inputs tab (cell G24)
B20: Revised Summary page layout
B21: Update retail, office, and industrial sub-property type categories to match CREXI
... B90: Initial release of the Value-Add Apartment Acquisition Model

Sheet Summary
B2: STNL VALUTION MODEL | INVESTMENT SUMMARY | U2: =Property_Name -> Wal-Aid Fairview
B4: Interest: | C4: Fee Simple | U4: =Version -> v2.4
B6: PROPERTY DESCRIPTION | I6: LEASE SUMMARY | P6: Property Photo
B7: Name | G7: Wal-Aid Fairview | I7: Lease Commencement | N7: =Inputs!M26 -> 42005
B8: Address | G8: 9999 Tennessee Ave. | I8: Lease Expiration | N8: =Inputs!M28 -> 47483
B9: City | G9: Anytown | I9: Options to Renew | N9: =IF(Inputs!M38="Yes","2+",IF(Inputs!M33="Yes",1,"None")) -> 2+
B10: State | G10: GA | I10: Lease Term | N10: =(N8-N7)/365.25 -> 14.997947
B11: Property Type | G11: Retail | I11: Remaining Term | N11: =(N8-Inputs!G7)/365.25 -> 8.5831622
B12: Sub-Property Type | G12: Pharmacy | I12: Lease Type | N12: NNN
B13: Measurement Type | G13: SF
B14: =IF(G13="M2","Land Size (M2)","Land Size (SF)") -> Land Size (SF) | G14: =1.2*43560 -> 52272 | I14: PRICING/VALUATION | L14: Cap Rate | M14: Amount | N14: Amount
B15: =IF(G12="M2","Net Rentable Area (M2)","Net Rentable Area (SF)") -> Net Rentable Area (SF) | G15: 13500 | I15: Asking Price | L15: ='Investment Returns'!$D$23/N15 -> 0.059438571 | M15: =N15/SF_GBA -> 259.25926 | N15: 3500000
B16: FAR | G16: =SF_GBA/Land_Acres -> 0.25826446 | I16: Acquisition Price | L16: ='Investment Returns'!$D$23/N16 -> 0.06 | M16: =N16/SF_GBA -> 256.83333 | N16: =Inputs!M7 -> 3467250
B17: Parking | E17: # Structured | F17: 0 | G17: 100 | I17: Direct Cap Value | L17: 0.06 | M17: =N17/SF_GBA -> 256.83333 | N17: ='Investment Returns'!D23/L17 -> 3467250
B18: Year Built | E18: Year Renovated | G18: 1999 | I18: DCF Value | L18: ='Investment Returns'!$D$23/N18 -> 0.060017812 | M18: =N18/SF_GBA -> 256.75711 | N18: =Valuation!C8 -> 3466221
I19: Replacement Cost | L19: ='Investment Returns'!$D$23/N19 -> 0.051366667 | M19: =N19/SF_GBA -> 300 | N19: =300*SF_GBA -> 4050000
P20: Location Map
B21: Strengths | I21: Weaknesses
B22: Affluent area (avg. HH income: 1-mile radius = $112,000) | I22: Less than nine years left on lease
B23: 55,000 traffic count | I23: $100,000+ deferred maintenance
B24: Hard corner | I24: New CVG coming across street
B25: Neighboring retailers: Albertsons, Walmart, Pep Boys

Sheet Inputs
B2: STNL VALUTION MODEL | INPUTS | M2: =Property_Name -> Wal-Aid Fairview
B4: Interest: | C4: =Interest -> Fee Simple | M4: =Version -> v2.4
B6: ANALYSIS DETAILS | I6: PROJECT INVESTMENT | J6: Going-in cap | K6: % | L6: =+G27 -> /SF | M6: Amount
B7: Analysis Start | E7: Month | F7: 1 | G7: 44348 | I7: Purchase Price | J7: =Valuation!$C$7/M7 -> 0.06 | L7: =+M7/SF_NRA -> 256.83333 | M7: ='Investment Returns'!D23/0.06 -> 3467250
B8: Analysis Period | G8: =F9 -> 225 | I8: Acquisition Fees | K8: 0.01 | L8: =+M8/SF_NRA -> 2.5683333 | M8: =M7*K8 -> 34672.5
B9: Analysis End | E9: Residual Month | F9: =IF(AND(M33="Yes",M38="Yes"),L40,IF(M33="Yes",L35,L28)) -> 225 | G9: =EOMONTH(G7,G8-1) -> 51195 | I9: Due Diligence Costs | K9: 0.005 | L9: =+M9/SF_NRA -> 1.2841667 | M9: =M7*K9 -> 17336.25
B10: General Vacancy | G10: 0 | I10: Construction Costs | J10: YOC | L10: =+M10/SF_NRA -> 0 | M10: 0
I11: Total Project Costs | J11: =Valuation!$C$7/Project_TotalCost -> 0.0591133 | L11: =SUM(L7:L10) -> 260.68583 | M11: =SUM(M7:M10) -> 3519258.8
B12: OTHER INCOME ASSUMPTIONS
B13: [Other Income] | G13: 0 | I13: DEBT | K13: % of Price | L13: =+L6 -> /SF | M13: Amount
B14: Total Other Income (per Year) | G14: =SUM(G13) -> 0 | I14: Loan Amount | K14: 0.7 | L14: =+M14/SF_NRA -> 179.78333 | M14: =M7*K14 -> 2427075
B15: Income Growth (% /Yr.) | G15: 0 | I15: Fixed Interest Rate | M15: 0.03
I16: Amortization | M16: 360
B17: EXPENSE ASSUMPTIONS | E17: Type | F17: PSF
B18: Tenant Expense Recovery % | E18: NNN | G18: 1 | I18: TENANT DETAILS | NO18: Unhide
B19: Tenant CapEx Recovery % | G19: 0 | I19: Tenant Name | K19: Type | L19: Public | M19: Wal-Aid, Inc.
B20: Year 1 Operating Expenses | F20: =G20/SF_NRA -> 6.5 | G20: =SF_NRA*6.5 -> 87750 | I20: Year Established | M20: 1941
B21: Year 1 Capital Expenditures | F21: =G21/SF_NRA -> 0.5 | G21: =SF_GBA*0.5 -> 6750 | I21: Credit Rating | K21: Type | L21: S&P | M21: BBB
B22: Expense Growth (% /Yr.) | G22: 0 | I22: Credit Income Discount Rate | M22: =Data!B37 -> 0.032
I23: Spec Income Discount Rate | M23: =+Discount_Rate_Residual -> 0.08
B24: Year 1 Net Operating Income | G24: ='Investment Returns'!D23 -> 208035
B25: RESIDUAL ASSUMPTIONS | I25: LEASE RENT DETAILS
B26: Residual Discount Rate | G26: =E39+0.02 -> 0.08 | I26: Lease Start | K26: Month | L26: =IFERROR(DATEDIF(G7,M26,"m"),0) -> 0 | M26: 42005 | O26: Month # | P26: =MONTH(P28) -> 6 | Q26: =MATCH(Inputs!$L$30,Data!$B$55:$B$66,0) -> 1
B27: Residual Pro Forma | F27: Total | G27: =IF(Summary!G13="M2","/M2","/SF") -> /SF | I27: Lease Length | M27: 180 | O27: Month | P27: 1 | Q27: =INDEX($R$52:$NM$52,1,MATCH(Q28,$R$53:$NM$53,0)) -> 8 | R27: =Q27+12 -> 20 | S27: =R27+12 -> 32 | T27: =S27+12 -> 44 | U27: =T27+12 -> 56 | V27: =U27+12 -> 68 | W27: =V27+12 -> 80 | X27: =W27+12 -> 92 | Y27: =X27+12 -> 104 | ... AU27: =AT27+12 -> 368
B28: Gross Rent | F28: =G28*SF_NRA -> 208035 | G28: =Rent_Base*(1+G15)^(F9/12) -> 15.41 | I28: Lease End | K28: End Month | L28: =MATCH(M28,$R$53:$NM$53) -> 103 | M28: =EOMONTH(M26,M27-1) -> 47483 | O28: As of | P28: =EOMONTH($G$7,Q52-1)+1 -> 44348 | Q28: =IF(Q26>P26,DATE(YEAR(P28),Q26,1),DATE(YEAR(P28)+1,Q26,1)) -> 44562 | R28: =EDATE(Q28,12) -> 44927 | S28: =EDATE(R28,12) -> 45292 | T28: =EDATE(S28,12) -> 45658 | U28: =EDATE(T28,12) -> 46023 | V28: =EDATE(U28,12) -> 46388 | W28: =EDATE(V28,12) -> 46753 | X28: =EDATE(W28,12) -> 47119 | Y28: =EDATE(X28,12) -> 47484 | ... AU28: =EDATE(AT28,12) -> 55519
B29: Expense Recovery Income | F29: =G29*SF_NRA -> 87750 | G29: =(G34*G18)+(G36*G19) -> 6.5 | I29: INITIAL LEASE INCOME | M29: =IF(Rent_Inc_Type="Custom","Detail--->","") | O29: Custom Rent | P29: =$M$31 -> 15.41 | Q29: =$M$31 -> 15.41 | R29: =P29 -> 15.41 | S29: =R29 -> 15.41 | T29: 17.5 | U29: =T29 -> 17.5 | V29: =U29 -> 17.5 | W29: =V29 -> 17.5 | X29: =W29 -> 17.5 | Y29: =X29 -> 17.5 | Z29: =Y29 -> 17.5 | AA29: =Z29 -> 17.5 | AB29: =AA29 -> 17.5 | ... AU29: =AT29 -> 17.5
B30: Other Income | F30: =G30*SF_NRA -> 0 | G30: =G15/SF_NRA*(1+G16)^(F10/12) -> 0 | I30: Rent Increase Type | K30: Inc. Month | L30: Jan | M30: None | P30: =IF($M$30<>"Custom","No",IF(P27<=$L$28,"Yes","No")) -> No | Q30: =IF($M$30<>"Custom","No",IF(Q27<=$L$28,"Yes","No")) -> No | R30: =IF($M$30<>"Custom","No",IF(R27<=$L$28,"Yes","No")) -> No | S30: =IF($M$30<>"Custom","No",IF(S27<=$L$28,"Yes","No")) -> No | T30: =IF($M$30<>"Custom","No",IF(T27<=$L$28,"Yes","No")) -> No | U30: =IF($M$30<>"Custom","No",IF(U27<=$L$28,"Yes","No")) -> No | V30: =IF($M$30<>"Custom","No",IF(V27<=$L$28,"Yes","No")) -> No | W30: =IF($M$30<>"Custom","No",IF(W27<=$L$28,"Yes","No")) -> No | ... AU30: =IF($M$30<>"Custom","No",IF(AU27<=$L$28,"Yes","No")) -> No
B31: Total Gross Income | F31: =G31*SF_NRA -> 295785 | G31: =SUM(G28:G30) -> 21.91 | I31: ="Base Rent "&G27&"/Yr (as of Month 1)" -> Base Rent /SF/Yr (as of Month 1) | K31: Annual | L31: =M31*SF_NRA -> 208035 | M31: 15.41
B32: - Vacancy % Credit Loss | F32: =G32*F31 -> 0 | G32: 0 | I32: Rent Increase | M32: 0.02
B33: Effective Gross Revenue | F33: =F31-F32 -> 295785 | G33: =G31*(1-G32) -> 21.91 | I33: OPTION #1 - RENEWAL INCOME | M33: Yes
B34: - Operating Expenses | F34: =G34*SF_NRA -> 87750 | G34: =(G20/SF_NRA)*(1+G22)^(F9/12) -> 6.5 | I34: Exercise Probability | K34: Start Month | L34: =L28+1 -> 104 | M34: 0.75
B35: Net Operating Income | F35: =F33-F34 -> 208035 | G35: =G33-G34 -> 15.41 | I35: Length | K35: End Month | L35: =L34+M35 -> 164 | M35: 60
B36: - CapEx | F36: =G36*SF_NRA -> 6750 | G36: =(G21/SF_NRA)*(1+G22)^(F9/12) -> 0.5 | I36: ="Option Rent "&G27&"/Yr (as of Month "&L34&")" -> Option Rent /SF/Yr (as of Month 104) | M36: =INDEX($R$59:$NM$59,1,$L$28)*(1+M37)*12 -> 15.41
B37: Cash Flow from Operations | F37: =F35-F36 -> 201285 | G37: =G35-G36 -> 14.91 | I37: Option Rent Increase (% /Yr.) | M37: 0
B38: Net Residual Value | E38: Input | F38: Probability | G38: Amount | I38: OPTION #2 - RENEWAL INCOME | M38: Yes
B39: Gross Residual Value | D39: Cap Rate | E39: =Summary!L17 -> 0.06 | G39: =F35/E39 -> 3467250 | I39: Exercise Probability | K39: Start Month | L39: =L35+1 -> 165 | M39: 0.75
B40: - Retenanting Cost | D40: PSF | E40: 0 | F40: 0.5 | G40: =E40*SF_NRA*F40 -> 0 | I40: Length | K40: End Month | L40: =L39+M40 -> 225 | M40: 60
B41: - Downtime | D41: Months | E41: 0 | F41: 0.5 | G41: =(E41/12)*F31*F41 -> 0 | I41: ="Option Rent "&G27&"/Yr (as of Month "&L39&")" -> Option Rent /SF/Yr (as of Month 165) | M41: =M36*(1+M37)^((M35/12)+1) -> 15.41
B42: - Selling Costs | D42: % | E42: 0 | G42: =E42*(G39-G40-G41) -> 0 | I42: Option Rent Increase (% /Yr.) | M42: 0
B43: Net Residual Value | D43: =G27 -> /SF | E43: =G43/SF_NRA -> 256.83333 | G43: =G39-G40-G41-G42 -> 3467250
...

Sheet Investment Returns
B2: STNL VALUTION MODEL | INVESTMENT RETURNS | N2: =Property_Name -> Wal-Aid Fairview
B4: Interest: | C4: =Interest -> Fee Simple | M4: =Version -> v2.4
B6: Unlevered Returns | K6: Debt
B7: IRR | E7: =C61 -> 0.058211604 | K7: Payment (Monthly) | N7: =PMT(Inputs!M15/12,Inputs!M16,-Inputs!M14) -> 10232.646
B8: Equity Multiple | E8: =C62 -> 2.0576332 | K8: Balloon Balance | M8: =Debt_Balloon/Residual_NetValue -> 0.33779455 | N8: =PV(Inputs!M15/12,Inputs!M16-'Investment Returns'!N9,-Debt_Payment) -> 1171218.2
B9: Avg. Free and Clear | E9: =+C60 -> 0.057195283 | K9: Term | N9: =Residual_Month -> 225
B11: Levered Returns
B12: IRR | E12: =C66 -> 0.097666687
B13: Equity Multiple | E13: =C67 -> 3.4497677
B14: Avg. Cash-on-Cash | E14: =C65 -> 0.071868169
B16: ANNUAL CASH FLOW | C16: 0 | D16: =IFERROR(IF(C16+1>MAX($C$37:$MY$37),"",C16+1),"") -> 1 | E16: =IFERROR(IF(D16+1>MAX($C$37:$MY$37),"",D16+1),"") -> 2 | F16: =IFERROR(IF(E16+1>MAX($C$37:$MY$37),"",E16+1),"") -> 3 | G16: =IFERROR(IF(F16+1>MAX($C$37:$MY$37),"",F16+1),"") -> 4 | H16: =IFERROR(IF(G16+1>MAX($C$37:$MY$37),"",G16+1),"") -> 5 | I16: =IFERROR(IF(H16+1>MAX($C$37:$MY$37),"",H16+1),"") -> 6 | J16: =IFERROR(IF(I16+1>MAX($C$37:$MY$37),"",I16+1),"") -> 7 | K16: =IFERROR(IF(J16+1>MAX($C$37:$MY$37),"",J16+1),"") -> 8 | ... AG16: =IFERROR(IF(AF16+1>MAX($C$37:$MY$37),"",AF16+1),"")
B17: Gross Rents | C17: =IF(C$16="","",SUMIF($C$37:$MY$37,C$16,$C40:$MY40)) -> 0 | D17: =IF(D$16="","",SUMIF($C$37:$MY$37,D$16,$C40:$MY40)) -> 208035 | E17: =IF(E$16="","",SUMIF($C$37:$MY$37,E$16,$C40:$MY40)) -> 208035 | F17: =IF(F$16="","",SUMIF($C$37:$MY$37,F$16,$C40:$MY40)) -> 208035 | G17: =IF(G$16="","",SUMIF($C$37:$MY$37,G$16,$C40:$MY40)) -> 208035 | H17: =IF(H$16="","",SUMIF($C$37:$MY$37,H$16,$C40:$MY40)) -> 208035 | I17: =IF(I$16="","",SUMIF($C$37:$MY$37,I$16,$C40:$MY40)) -> 208035 | J17: =IF(J$16="","",SUMIF($C$37:$MY$37,J$16,$C40:$MY40)) -> 208035 | ... AG17: =IF(AG$16="","",SUMIF($C$37:$MY$37,AG$16,$C40:$MY40))
B18: Expense Recovery | C18: =IF(C$16="","",SUMIF($C$37:$MY$37,C$16,$C41:$MY41)) -> 0 | D18: =IF(D$16="","",SUMIF($C$37:$MY$37,D$16,$C41:$MY41)) -> 87750 | E18: =IF(E$16="","",SUMIF($C$37:$MY$37,E$16,$C41:$MY41)) -> 87750 | F18: =IF(F$16="","",SUMIF($C$37:$MY$37,F$16,$C41:$MY41)) -> 87750 | G18: =IF(G$16="","",SUMIF($C$37:$MY$37,G$16,$C41:$MY41)) -> 87750 | H18: =IF(H$16="","",SUMIF($C$37:$MY$37,H$16,$C41:$MY41)) -> 87750 | I18: =IF(I$16="","",SUMIF($C$37:$MY$37,I$16,$C41:$MY41)) -> 87750 | J18: =IF(J$16="","",SUMIF($C$37:$MY$37,J$16,$C41:$MY41)) -> 87750 | ... AG18: =IF(AG$16="","",SUMIF($C$37:$MY$37,AG$16,$C41:$MY41))
B19: Other Income | C19: =IF(C$16="","",SUMIF($C$37:$MY$37,C$16,$C42:$MY42)) -> 0 | D19: =IF(D$16="","",SUMIF($C$37:$MY$37,D$16,$C42:$MY42)) -> 0 | E19: =IF(E$16="","",SUMIF($C$37:$MY$37,E$16,$C42:$MY42)) -> 0 | F19: =IF(F$16="","",SUMIF($C$37:$MY$37,F$16,$C42:$MY42)) -> 0 | G19: =IF(G$16="","",SUMIF($C$37:$MY$37,G$16,$C42:$MY42)) -> 0 | H19: =IF(H$16="","",SUMIF($C$37:$MY$37,H$16,$C42:$MY42)) -> 0 | I19: =IF(I$16="","",SUMIF($C$37:$MY$37,I$16,$C42:$MY42)) -> 0 | J19: =IF(J$16="","",SUMIF($C$37:$MY$37,J$16,$C42:$MY42)) -> 0 | ... AG19: =IF(AG$16="","",SUMIF($C$37:$MY$37,AG$16,$C42:$MY42))
B20: General Vacancy | C20: =IF(C$16="","",SUMIF($C$37:$MY$37,C$16,$C43:$MY43)) -> 0 | D20: =IF(D$16="","",SUMIF($C$37:$MY$37,D$16,$C43:$MY43)) -> 0 | E20: =IF(E$16="","",SUMIF($C$37:$MY$37,E$16,$C43:$MY43)) -> 0 | F20: =IF(F$16="","",SUMIF($C$37:$MY$37,F$16,$C43:$MY43)) -> 0 | G20: =IF(G$16="","",SUMIF($C$37:$MY$37,G$16,$C43:$MY43)) -> 0 | H20: =IF(H$16="","",SUMIF($C$37:$MY$37,H$16,$C43:$MY43)) -> 0 | I20: =IF(I$16="","",SUMIF($C$37:$MY$37,I$16,$C43:$MY43)) -> 0 | J20: =IF(J$16="","",SUMIF($C$37:$MY$37,J$16,$C43:$MY43)) -> 0 | ... AG20: =IF(AG$16="","",SUMIF($C$37:$MY$37,AG$16,$C43:$MY43))
B21: Effective Gross Revenue | C21: =IF(C$16="","",SUMIF($C$37:$MY$37,C$16,$C44:$MY44)) -> 0 | D21: =IF(D$16="","",SUMIF($C$37:$MY$37,D$16,$C44:$MY44)) -> 295785 | E21: =IF(E$16="","",SUMIF($C$37:$MY$37,E$16,$C44:$MY44)) -> 295785 | F21: =IF(F$16="","",SUMIF($C$37:$MY$37,F$16,$C44:$MY44)) -> 295785 | G21: =IF(G$16="","",SUMIF($C$37:$MY$37,G$16,$C44:$MY44)) -> 295785 | H21: =IF(H$16="","",SUMIF($C$37:$MY$37,H$16,$C44:$MY44)) -> 295785 | I21: =IF(I$16="","",SUMIF($C$37:$MY$37,I$16,$C44:$MY44)) -> 295785 | J21: =IF(J$16="","",SUMIF($C$37:$MY$37,J$16,$C44:$MY44)) -> 295785 | ... AG21: =IF(AG$16="","",SUMIF($C$37:$MY$37,AG$16,$C44:$MY44))
B22: Operating Expenses | C22: =IF(C$16="","",SUMIF($C$37:$MY$37,C$16,$C45:$MY45)) -> 0 | D22: =IF(D$16="","",SUMIF($C$37:$MY$37,D$16,$C45:$MY45)) -> 87750 | E22: =IF(E$16="","",SUMIF($C$37:$MY$37,E$16,$C45:$MY45)) -> 87750 | F22: =IF(F$16="","",SUMIF($C$37:$MY$37,F$16,$C45:$MY45)) -> 87750 | G22: =IF(G$16="","",SUMIF($C$37:$MY$37,G$16,$C45:$MY45)) -> 87750 | H22: =IF(H$16="","",SUMIF($C$37:$MY$37,H$16,$C45:$MY45)) -> 87750 | I22: =IF(I$16="","",SUMIF($C$37:$MY$37,I$16,$C45:$MY45)) -> 87750 | J22: =IF(J$16="","",SUMIF($C$37:$MY$37,J$16,$C45:$MY45)) -> 87750 | ... AG22: =IF(AG$16="","",SUMIF($C$37:$MY$37,AG$16,$C45:$MY45))
B23: Net Operating Income | C23: =IF(C$16="","",SUMIF($C$37:$MY$37,C$16,$C46:$MY46)) -> 0 | D23: =IF(D$16="","",SUMIF($C$37:$MY$37,D$16,$C46:$MY46)) -> 208035 | E23: =IF(E$16="","",SUMIF($C$37:$MY$37,E$16,$C46:$MY46)) -> 208035 | F23: =IF(F$16="","",SUMIF($C$37:$MY$37,F$16,$C46:$MY46)) -> 208035 | G23: =IF(G$16="","",SUMIF($C$37:$MY$37,G$16,$C46:$MY46)) -> 208035 | H23: =IF(H$16="","",SUMIF($C$37:$MY$37,H$16,$C46:$MY46)) -> 208035 | I23: =IF(I$16="","",SUMIF($C$37:$MY$37,I$16,$C46:$MY46)) -> 208035 | J23: =IF(J$16="","",SUMIF($C$37:$MY$37,J$16,$C46:$MY46)) -> 208035 | ... AG23: =IF(AG$16="","",SUMIF($C$37:$MY$37,AG$16,$C46:$MY46))
B24: Capital Expenditures | C24: =IF(C$16="","",SUMIF($C$37:$MY$37,C$16,$C47:$MY47)) -> 0 | D24: =IF(D$16="","",SUMIF($C$37:$MY$37,D$16,$C47:$MY47)) -> 6750 | E24: =IF(E$16="","",SUMIF($C$37:$MY$37,E$16,$C47:$MY47)) -> 6750 | F24: =IF(F$16="","",SUMIF($C$37:$MY$37,F$16,$C47:$MY47)) -> 6750 | G24: =IF(G$16="","",SUMIF($C$37:$MY$37,G$16,$C47:$MY47)) -> 6750 | H24: =IF(H$16="","",SUMIF($C$37:$MY$37,H$16,$C47:$MY47)) -> 6750 | I24: =IF(I$16="","",SUMIF($C$37:$MY$37,I$16,$C47:$MY47)) -> 6750 | J24: =IF(J$16="","",SUMIF($C$37:$MY$37,J$16,$C47:$MY47)) -> 6750 | ... AG24: =IF(AG$16="","",SUMIF($C$37:$MY$37,AG$16,$C47:$MY47))
B25: Cash Flow from Operations | C25: =IF(C$16="","",SUMIF($C$37:$MY$37,C$16,$C48:$MY48)) -> 0 | D25: =IF(D$16="","",SUMIF($C$37:$MY$37,D$16,$C48:$MY48)) -> 201285 | E25: =IF(E$16="","",SUMIF($C$37:$MY$37,E$16,$C48:$MY48)) -> 201285 | F25: =IF(F$16="","",SUMIF($C$37:$MY$37,F$16,$C48:$MY48)) -> 201285 | G25: =IF(G$16="","",SUMIF($C$37:$MY$37,G$16,$C48:$MY48)) -> 201285 | H25: =IF(H$16="","",SUMIF($C$37:$MY$37,H$16,$C48:$MY48)) -> 201285 | I25: =IF(I$16="","",SUMIF($C$37:$MY$37,I$16,$C48:$MY48)) -> 201285 | J25: =IF(J$16="","",SUMIF($C$37:$MY$37,J$16,$C48:$MY48)) -> 201285 | ... AG25: =IF(AG$16="","",SUMIF($C$37:$MY$37,AG$16,$C48:$MY48))
B26: Debt Service | C26: =IF(C$16="","",SUMIF($C$37:$MY$37,C$16,$C49:$MY49)) -> 0 | D26: =IF(D$16="","",SUMIF($C$37:$MY$37,D$16,$C49:$MY49)) -> 122791.75 | E26: =IF(E$16="","",SUMIF($C$37:$MY$37,E$16,$C49:$MY49)) -> 122791.75 | F26: =IF(F$16="","",SUMIF($C$37:$MY$37,F$16,$C49:$MY49)) -> 122791.75 | G26: =IF(G$16="","",SUMIF($C$37:$MY$37,G$16,$C49:$MY49)) -> 122791.75 | H26: =IF(H$16="","",SUMIF($C$37:$MY$37,H$16,$C49:$MY49)) -> 122791.75 | I26: =IF(I$16="","",SUMIF($C$37:$MY$37,I$16,$C49:$MY49)) -> 122791.75 | J26: =IF(J$16="","",SUMIF($C$37:$MY$37,J$16,$C49:$MY49)) -> 122791.75 | ... AG26: =IF(AG$16="","",SUMIF($C$37:$MY$37,AG$16,$C49:$MY49))
B27: Cash Flow after Financing | C27: =IF(C$16="","",SUMIF($C$37:$MY$37,C$16,$C50:$MY50)) -> 0 | D27: =IF(D$16="","",SUMIF($C$37:$MY$37,D$16,$C50:$MY50)) -> 78493.247 | E27: =IF(E$16="","",SUMIF($C$37:$MY$37,E$16,$C50:$MY50)) -> 78493.247 | F27: =IF(F$16="","",SUMIF($C$37:$MY$37,F$16,$C50:$MY50)) -> 78493.247 | G27: =IF(G$16="","",SUMIF($C$37:$MY$37,G$16,$C50:$MY50)) -> 78493.247 | H27: =IF(H$16="","",SUMIF($C$37:$MY$37,H$16,$C50:$MY50)) -> 78493.247 | I27: =IF(I$16="","",SUMIF($C$37:$MY$37,I$16,$C50:$MY50)) -> 78493.247 | J27: =IF(J$16="","",SUMIF($C$37:$MY$37,J$16,$C50:$MY50)) -> 78493.247 | ... AG27: =IF(AG$16="","",SUMIF($C$37:$MY$37,AG$16,$C50:$MY50))
B28: Initial Investment | C28: =IF(C$16="","",SUMIF($C$37:$MY$37,C$16,$C51:$MY51)) -> 3519258.8 | D28: =IF(D$16="","",SUMIF($C$37:$MY$37,D$16,$C51:$MY51)) -> 0 | E28: =IF(E$16="","",SUMIF($C$37:$MY$37,E$16,$C51:$MY51)) -> 0 | F28: =IF(F$16="","",SUMIF($C$37:$MY$37,F$16,$C51:$MY51)) -> 0 | G28: =IF(G$16="","",SUMIF($C$37:$MY$37,G$16,$C51:$MY51)) -> 0 | H28: =IF(H$16="","",SUMIF($C$37:$MY$37,H$16,$C51:$MY51)) -> 0 | I28: =IF(I$16="","",SUMIF($C$37:$MY$37,I$16,$C51:$MY51)) -> 0 | J28: =IF(J$16="","",SUMIF($C$37:$MY$37,J$16,$C51:$MY51)) -> 0 | ... AG28: =IF(AG$16="","",SUMIF($C$37:$MY$37,AG$16,$C51:$MY51))
... B34: Levered Cash Flow | C34: =IF(C$16="","",SUMIF($C$37:$MY$37,C$16,$C57:$MY57)) -> -1092183.8 | D34: =IF(D$16="","",SUMIF($C$37:$MY$37,D$16,$C57:$MY57)) -> 78493.247 | E34: =IF(E$16="","",SUMIF($C$37:$MY$37,E$16,$C57:$MY57)) -> 78493.247 | F34: =IF(F$16="","",SUMIF($C$37:$MY$37,F$16,$C57:$MY57)) -> 78493.247 | G34: =IF(G$16="","",SUMIF($C$37:$MY$37,G$16,$C57:$MY57)) -> 78493.247 | H34: =IF(H$16="","",SUMIF($C$37:$MY$37,H$16,$C57:$MY57)) -> 78493.247 | I34: =IF(I$16="","",SUMIF($C$37:$MY$37,I$16,$C57:$MY57)) -> 78493.247 | J34: =IF(J$16="","",SUMIF($C$37:$MY$37,J$16,$C57:$MY57)) -> 78493.247 | ... AG34: =IF(AG$16="","",SUMIF($C$37:$MY$37,AG$16,$C57:$MY57))
B36: MONTHY CASH FLOW
B37: Year | C37: 0 | D37: =Valuation!D13 -> 1 | E37: =Valuation!E13 -> 1 | F37: =Valuation!F13 -> 1 | G37: =Valuation!G13 -> 1 | H37: =Valuation!H13 -> 1 | I37: =Valuation!I13 -> 1 | J37: =Valuation!J13 -> 1 | K37: =Valuation!K13 -> 1 | ... MY37: =Valuation!MY13
B38: Month | C38: 0 | D38: =Valuation!D14 -> 1 | E38: =Valuation!E14 -> 2 | F38: =Valuation!F14 -> 3 | G38: =Valuation!G14 -> 4 | H38: =Valuation!H14 -> 5 | I38: =Valuation!I14 -> 6 | J38: =Valuation!J14 -> 7 | K38: =Valuation!K14 -> 8 | ... MY38: =Valuation!MY14
B39: Month Ending | C39: =EOMONTH(D39,-1) -> 44347 | D39: =EOMONTH(Inputs!G7,0) -> 44377 | E39: =IF(E37="","",EOMONTH(D39,1)) -> 44408 | F39: =IF(F37="","",EOMONTH(E39,1)) -> 44439 | G39: =IF(G37="","",EOMONTH(F39,1)) -> 44469 | H39: =IF(H37="","",EOMONTH(G39,1)) -> 44500 | I39: =IF(I37="","",EOMONTH(H39,1)) -> 44530 | J39: =IF(J37="","",EOMONTH(I39,1)) -> 44561 | K39: =IF(K37="","",EOMONTH(J39,1)) -> 44592 | L39: =IF(L37="","",EOMONTH(K39,1)) -> 44620 | ... MY39: =IF(MY37="","",EOMONTH(MX39,1))
B40: Gross Rents | C40: =IF(C37="","",SUM(Inputs!Q81:Q85)) -> 0 | D40: =IF(D37="","",SUM(Inputs!R81:R85)) -> 17336.25 | E40: =IF(E37="","",SUM(Inputs!S81:S85)) -> 17336.25 | F40: =IF(F37="","",SUM(Inputs!T81:T85)) -> 17336.25 | G40: =IF(G37="","",SUM(Inputs!U81:U85)) -> 17336.25 | H40: =IF(H37="","",SUM(Inputs!V81:V85)) -> 17336.25 | I40: =IF(I37="","",SUM(Inputs!W81:W85)) -> 17336.25 | J40: =IF(J37="","",SUM(Inputs!X81:X85)) -> 17336.25 | ... MY40: =IF(MY37="","",SUM(Inputs!NM81:NM85))
B41: Expense Recovery | C41: =IF(C37="","",SUM(Inputs!Q91)) -> 0 | D41: =IF(D37="","",SUM(Inputs!R91)) -> 7312.5 | E41: =IF(E37="","",SUM(Inputs!S91)) -> 7312.5 | F41: =IF(F37="","",SUM(Inputs!T91)) -> 7312.5 | G41: =IF(G37="","",SUM(Inputs!U91)) -> 7312.5 | H41: =IF(H37="","",SUM(Inputs!V91)) -> 7312.5 | I41: =IF(I37="","",SUM(Inputs!W91)) -> 7312.5 | J41: =IF(J37="","",SUM(Inputs!X91)) -> 7312.5 | ... MY41: =IF(MY37="","",SUM(Inputs!NM91))
B42: Other Income | C42: =IF(C37="","",SUM(Inputs!Q96:Q97)) -> 0 | D42: =IF(D37="","",SUM(Inputs!R96:R97)) -> 0 | E42: =IF(E37="","",SUM(Inputs!S96:S97)) -> 0 | F42: =IF(F37="","",SUM(Inputs!T96:T97)) -> 0 | G42: =IF(G37="","",SUM(Inputs!U96:U97)) -> 0 | H42: =IF(H37="","",SUM(Inputs!V96:V97)) -> 0 | I42: =IF(I37="","",SUM(Inputs!W96:W97)) -> 0 | J42: =IF(J37="","",SUM(Inputs!X96:X97)) -> 0 | ... MY42: =IF(MY37="","",SUM(Inputs!NM96:NM97))
B43: General Vacancy | C43: =IF(C37="","",SUM(C40:C42)*Vacancy) -> 0 | D43: =IF(D37="","",SUM(D40:D42)*Vacancy) -> 0 | E43: =IF(E37="","",SUM(E40:E42)*Vacancy) -> 0 | F43: =IF(F37="","",SUM(F40:F42)*Vacancy) -> 0 | G43: =IF(G37="","",SUM(G40:G42)*Vacancy) -> 0 | H43: =IF(H37="","",SUM(H40:H42)*Vacancy) -> 0 | I43: =IF(I37="","",SUM(I40:I42)*Vacancy) -> 0 | J43: =IF(J37="","",SUM(J40:J42)*Vacancy) -> 0 | ... MY43: =IF(MY37="","",SUM(MY40:MY42)*Vacancy)
B44: Effective Gross Revenue | C44: =IF(C37="","",SUM(C40:C43)) -> 0 | D44: =IF(D37="","",SUM(D40:D43)) -> 24648.75 | E44: =IF(E37="","",SUM(E40:E43)) -> 24648.75 | F44: =IF(F37="","",SUM(F40:F43)) -> 24648.75 | G44: =IF(G37="","",SUM(G40:G43)) -> 24648.75 | H44: =IF(H37="","",SUM(H40:H43)) -> 24648.75 | I44: =IF(I37="","",SUM(I40:I43)) -> 24648.75 | J44: =IF(J37="","",SUM(J40:J43)) -> 24648.75 | ... MY44: =IF(MY37="","",SUM(MY40:MY43))
B45: Operating Expenses | C45: =IF(C37="","",SUM(Inputs!Q102)) -> 0 | D45: =IF(D37="","",SUM(Inputs!R102)) -> 7312.5 | E45: =IF(E37="","",SUM(Inputs!S102)) -> 7312.5 | F45: =IF(F37="","",SUM(Inputs!T102)) -> 7312.5 | G45: =IF(G37="","",SUM(Inputs!U102)) -> 7312.5 | H45: =IF(H37="","",SUM(Inputs!V102)) -> 7312.5 | I45: =IF(I37="","",SUM(Inputs!W102)) -> 7312.5 | J45: =IF(J37="","",SUM(Inputs!X102)) -> 7312.5 | ... MY45: =IF(MY37="","",SUM(Inputs!NM102))
B46: Net Operating Income | C46: =IF(C37="","",C44-C45) -> 0 | D46: =IF(D37="","",D44-D45) -> 17336.25 | E46: =IF(E37="","",E44-E45) -> 17336.25 | F46: =IF(F37="","",F44-F45) -> 17336.25 | G46: =IF(G37="","",G44-G45) -> 17336.25 | H46: =IF(H37="","",H44-H45) -> 17336.25 | I46: =IF(I37="","",I44-I45) -> 17336.25 | J46: =IF(J37="","",J44-J45) -> 17336.25 | ... MY46: =IF(MY37="","",MY44-MY45)
B47: Capital Expenditures | C47: =IF(C37="","",Inputs!Q107) -> 0 | D47: =IF(D37="","",Inputs!R107) -> 562.5 | E47: =IF(E37="","",Inputs!S107) -> 562.5 | F47: =IF(F37="","",Inputs!T107) -> 562.5 | G47: =IF(G37="","",Inputs!U107) -> 562.5 | H47: =IF(H37="","",Inputs!V107) -> 562.5 | I47: =IF(I37="","",Inputs!W107) -> 562.5 | J47: =IF(J37="","",Inputs!X107) -> 562.5 | ... MY47: =IF(MY37="","",Inputs!NM107)
B48: Cash Flow from Operations | C48: =IF(C37="","",C46-C47) -> 0 | D48: =IF(D37="","",D46-D47) -> 16773.75 | E48: =IF(E37="","",E46-E47) -> 16773.75 | F48: =IF(F37="","",F46-F47) -> 16773.75 | G48: =IF(G37="","",G46-G47) -> 16773.75 | H48: =IF(H37="","",H46-H47) -> 16773.75 | I48: =IF(I37="","",I46-I47) -> 16773.75 | J48: =IF(J37="","",J46-J47) -> 16773.75 | ... MY48: =IF(MY37="","",MY46-MY47)
B49: Debt Service | C49: 0 | D49: =IF(D37="","",Debt_Payment) -> 10232.646 | E49: =IF(E37="","",Debt_Payment) -> 10232.646 | F49: =IF(F37="","",Debt_Payment) -> 10232.646 | G49: =IF(G37="","",Debt_Payment) -> 10232.646 | H49: =IF(H37="","",Debt_Payment) -> 10232.646 | I49: =IF(I37="","",Debt_Payment) -> 10232.646 | J49: =IF(J37="","",Debt_Payment) -> 10232.646 | K49: =IF(K37="","",Debt_Payment) -> 10232.646 | ... MY49: =IF(MY37="","",Debt_Payment)
B50: Cash Flow after Financing | C50: =IF(C37="","",C48-C49) -> 0 | D50: =IF(D37="","",D48-D49) -> 6541.1039 | E50: =IF(E37="","",E48-E49) -> 6541.1039 | F50: =IF(F37="","",F48-F49) -> 6541.1039 | G50: =IF(G37="","",G48-G49) -> 6541.1039 | H50: =IF(H37="","",H48-H49) -> 6541.1039 | I50: =IF(I37="","",I48-I49) -> 6541.1039 | J50: =IF(J37="","",J48-J49) -> 6541.1039 | ... MY50: =IF(MY37="","",MY48-MY49)
B51: Initial Investment | C51: =IF(C38>Residual_Month,"",IF(C38>0,0,Project_TotalCost)) -> 3519258.8 | D51: =IF(D38>Residual_Month,"",IF(D38>0,0,Project_TotalCost)) -> 0 | E51: =IF(E38>Residual_Month,"",IF(E38>0,0,Project_TotalCost)) -> 0 | F51: =IF(F38>Residual_Month,"",IF(F38>0,0,Project_TotalCost)) -> 0 | G51: =IF(G38>Residual_Month,"",IF(G38>0,0,Project_TotalCost)) -> 0 | H51: =IF(H38>Residual_Month,"",IF(H38>0,0,Project_TotalCost)) -> 0 | I51: =IF(I38>Residual_Month,"",IF(I38>0,0,Project_TotalCost)) -> 0 | J51: =IF(J38>Residual_Month,"",IF(J38>0,0,Project_TotalCost)) -> 0 | ... MY51: =IF(MY38>Residual_Month,"",IF(MY38>0,0,Project_TotalCost))
...

Sheet Valuation
B2: STNL VALUTION MODEL | VALUATION | M2: =Property_Name -> Wal-Aid Fairview
B4: Interest: | C4: =Interest -> Fee Simple | M4: =Version -> v2.4
B6: VALUATION SUMMARY | J6: Actual | K6: PV | M6: Discount Rate
B7: Year 1 NOI | C7: =SUM(D16:O17)+SUM(D19:O20)+SUM(D22:O23)-SUM(D25:O26)-SUM(D28:O29) -> 208035 | G7: Credit Cash Flows | J7: =SUM(D34:MY34) -> 3070644.6 | K7: =C39 -> 2403422.4 | L7: @ | M7: =C34 -> 0.032
B8: PV of Project Cash Flows | C8: =C42 -> 3466221 | G8: Speculative Cash Flows | J8: =SUM(D35:MY35) -> 703449.14 | K8: =C40 -> 239328.71 | L8: @ | M8: =C35 -> 0.08
B9: Yield-on PV | C9: =C7/C8 -> 0.060017812 | G9: Residual Cash Flows | J9: =SUM(D36:MY36) -> 3467250 | K9: =C41 -> 823469.88 | L9: @ | M9: =C36 -> 0.08
G10: Project Cash Flows | J10: =SUM(J7:J9) -> 7241343.8 | K10: =SUM(K7:K9) -> 3466221 | L10: @ | M10: =SUMPRODUCT(M7:M9,K7:K9)/SUM(K7:K9) -> 0.046717565
B12: MONTHY CASH FLOW
B13: Year | D13: =IF(D14="","",ROUNDUP(D14/12,0)) -> 1 | E13: =IF(E14="","",ROUNDUP(E14/12,0)) -> 1 | F13: =IF(F14="","",ROUNDUP(F14/12,0)) -> 1 | G13: =IF(G14="","",ROUNDUP(G14/12,0)) -> 1 | H13: =IF(H14="","",ROUNDUP(H14/12,0)) -> 1 | I13: =IF(I14="","",ROUNDUP(I14/12,0)) -> 1 | J13: =IF(J14="","",ROUNDUP(J14/12,0)) -> 1 | K13: =IF(K14="","",ROUNDUP(K14/12,0)) -> 1 | ... MY13: =IF(MY14="","",ROUNDUP(MY14/12,0))
B14: Month | D14: =IFERROR(IF(C14+1>Residual_Month,"",C14+1),"") -> 1 | E14: =IFERROR(IF(D14+1>Residual_Month,"",D14+1),"") -> 2 | F14: =IFERROR(IF(E14+1>Residual_Month,"",E14+1),"") -> 3 | G14: =IFERROR(IF(F14+1>Residual_Month,"",F14+1),"") -> 4 | H14: =IFERROR(IF(G14+1>Residual_Month,"",G14+1),"") -> 5 | I14: =IFERROR(IF(H14+1>Residual_Month,"",H14+1),"") -> 6 | J14: =IFERROR(IF(I14+1>Residual_Month,"",I14+1),"") -> 7 | K14: =IFERROR(IF(J14+1>Residual_Month,"",J14+1),"") -> 8 | ... MY14: =IFERROR(IF(MX14+1>Residual_Month,"",MX14+1),"")
B15: Month Ending | D15: =IF(D14="","",'Investment Returns'!D39) -> 44377 | E15: =IF(E14="","",'Investment Returns'!E39) -> 44408 | F15: =IF(F14="","",'Investment Returns'!F39) -> 44439 | G15: =IF(G14="","",'Investment Returns'!G39) -> 44469 | H15: =IF(H14="","",'Investment Returns'!H39) -> 44500 | I15: =IF(I14="","",'Investment Returns'!I39) -> 44530 | J15: =IF(J14="","",'Investment Returns'!J39) -> 44561 | K15: =IF(K14="","",'Investment Returns'!K39) -> 44592 | ... MY15: =IF(MY14="","",'Investment Returns'!MY39)
B16: Credit Rents | D16: =IF(D13="","",Inputs!R81+Inputs!R82+Inputs!R84) -> 17336.25 | E16: =IF(E13="","",Inputs!S81+Inputs!S82+Inputs!S84) -> 17336.25 | F16: =IF(F13="","",Inputs!T81+Inputs!T82+Inputs!T84) -> 17336.25 | G16: =IF(G13="","",Inputs!U81+Inputs!U82+Inputs!U84) -> 17336.25 | H16: =IF(H13="","",Inputs!V81+Inputs!V82+Inputs!V84) -> 17336.25 | I16: =IF(I13="","",Inputs!W81+Inputs!W82+Inputs!W84) -> 17336.25 | J16: =IF(J13="","",Inputs!X81+Inputs!X82+Inputs!X84) -> 17336.25 | K16: =IF(K13="","",Inputs!Y81+Inputs!Y82+Inputs!Y84) -> 17336.25 | ... MY16: =IF(MY13="","",Inputs!NM81+Inputs!NM82+Inputs!NM84)
B17: Spec Rents | D17: =IF(D13="","",Inputs!R83+Inputs!R85) -> 0 | E17: =IF(E13="","",Inputs!S83+Inputs!S85) -> 0 | F17: =IF(F13="","",Inputs!T83+Inputs!T85) -> 0 | G17: =IF(G13="","",Inputs!U83+Inputs!U85) -> 0 | H17: =IF(H13="","",Inputs!V83+Inputs!V85) -> 0 | I17: =IF(I13="","",Inputs!W83+Inputs!W85) -> 0 | J17: =IF(J13="","",Inputs!X83+Inputs!X85) -> 0 | K17: =IF(K13="","",Inputs!Y83+Inputs!Y85) -> 0 | ... MY17: =IF(MY13="","",Inputs!NM83+Inputs!NM85)
B19: Credit Expense Recovery | D19: =IF(D13="","",(D16/SUM(D$16:D$17))*Inputs!R91) -> 7312.5 | E19: =IF(E13="","",(E16/SUM(E$16:E$17))*Inputs!S91) -> 7312.5 | F19: =IF(F13="","",(F16/SUM(F$16:F$17))*Inputs!T91) -> 7312.5 | G19: =IF(G13="","",(G16/SUM(G$16:G$17))*Inputs!U91) -> 7312.5 | H19: =IF(H13="","",(H16/SUM(H$16:H$17))*Inputs!V91) -> 7312.5 | I19: =IF(I13="","",(I16/SUM(I$16:I$17))*Inputs!W91) -> 7312.5 | J19: =IF(J13="","",(J16/SUM(J$16:J$17))*Inputs!X91) -> 7312.5 | K19: =IF(K13="","",(K16/SUM(K$16:K$17))*Inputs!Y91) -> 7312.5 | ... MY19: =IF(MY13="","",(MY16/SUM(MY$16:MY$17))*Inputs!NM91)
B20: Spec Expense Recovery | D20: =IF(D13="","",(D17/SUM(D$16:D$17))*Inputs!R91) -> 0 | E20: =IF(E13="","",(E17/SUM(E$16:E$17))*Inputs!S91) -> 0 | F20: =IF(F13="","",(F17/SUM(F$16:F$17))*Inputs!T91) -> 0 | G20: =IF(G13="","",(G17/SUM(G$16:G$17))*Inputs!U91) -> 0 | H20: =IF(H13="","",(H17/SUM(H$16:H$17))*Inputs!V91) -> 0 | I20: =IF(I13="","",(I17/SUM(I$16:I$17))*Inputs!W91) -> 0 | J20: =IF(J13="","",(J17/SUM(J$16:J$17))*Inputs!X91) -> 0 | K20: =IF(K13="","",(K17/SUM(K$16:K$17))*Inputs!Y91) -> 0 | ... MY20: =IF(MY13="","",(MY17/SUM(MY$16:MY$17))*Inputs!NM91)
B22: Credit Other Income | D22: =IF(D13="","",D16/(SUM(D$16:D$17))*Inputs!R96) -> 0 | E22: =IF(E13="","",E16/(SUM(E$16:E$17))*Inputs!S96) -> 0 | F22: =IF(F13="","",F16/(SUM(F$16:F$17))*Inputs!T96) -> 0 | G22: =IF(G13="","",G16/(SUM(G$16:G$17))*Inputs!U96) -> 0 | H22: =IF(H13="","",H16/(SUM(H$16:H$17))*Inputs!V96) -> 0 | I22: =IF(I13="","",I16/(SUM(I$16:I$17))*Inputs!W96) -> 0 | J22: =IF(J13="","",J16/(SUM(J$16:J$17))*Inputs!X96) -> 0 | K22: =IF(K13="","",K16/(SUM(K$16:K$17))*Inputs!Y96) -> 0 | ... MY22: =IF(MY13="","",MY16/(SUM(MY$16:MY$17))*Inputs!NM96)
B23: Spec Other Income | D23: =IF(D13="","",D17/(SUM(D$16:D$17))*Inputs!R96) -> 0 | E23: =IF(E13="","",E17/(SUM(E$16:E$17))*Inputs!S96) -> 0 | F23: =IF(F13="","",F17/(SUM(F$16:F$17))*Inputs!T96) -> 0 | G23: =IF(G13="","",G17/(SUM(G$16:G$17))*Inputs!U96) -> 0 | H23: =IF(H13="","",H17/(SUM(H$16:H$17))*Inputs!V96) -> 0 | I23: =IF(I13="","",I17/(SUM(I$16:I$17))*Inputs!W96) -> 0 | J23: =IF(J13="","",J17/(SUM(J$16:J$17))*Inputs!X96) -> 0 | K23: =IF(K13="","",K17/(SUM(K$16:K$17))*Inputs!Y96) -> 0 | ... MY23: =IF(MY13="","",MY17/(SUM(MY$16:MY$17))*Inputs!NM96)
B25: Credit Vacancy | D25: =IF(D$13="","",(D16-D19-D22)*Vacancy) -> 0 | E25: =IF(E$13="","",(E16-E19-E22)*Vacancy) -> 0 | F25: =IF(F$13="","",(F16-F19-F22)*Vacancy) -> 0 | G25: =IF(G$13="","",(G16-G19-G22)*Vacancy) -> 0 | H25: =IF(H$13="","",(H16-H19-H22)*Vacancy) -> 0 | I25: =IF(I$13="","",(I16-I19-I22)*Vacancy) -> 0 | J25: =IF(J$13="","",(J16-J19-J22)*Vacancy) -> 0 | K25: =IF(K$13="","",(K16-K19-K22)*Vacancy) -> 0 | ... MY25: =IF(MY$13="","",(MY16-MY19-MY22)*Vacancy)
B26: Spec Vacancy | D26: =IF(D$13="","",(D17-D20-D23)*Vacancy) -> 0 | E26: =IF(E$13="","",(E17-E20-E23)*Vacancy) -> 0 | F26: =IF(F$13="","",(F17-F20-F23)*Vacancy) -> 0 | G26: =IF(G$13="","",(G17-G20-G23)*Vacancy) -> 0 | H26: =IF(H$13="","",(H17-H20-H23)*Vacancy) -> 0 | I26: =IF(I$13="","",(I17-I20-I23)*Vacancy) -> 0 | J26: =IF(J$13="","",(J17-J20-J23)*Vacancy) -> 0 | K26: =IF(K$13="","",(K17-K20-K23)*Vacancy) -> 0 | ... MY26: =IF(MY$13="","",(MY17-MY20-MY23)*Vacancy)
B28: Credit Expenses | D28: =IF(D13="","",(D16/(SUM(D$16:D$17))*Inputs!R$102)) -> 7312.5 | E28: =IF(E13="","",(E16/(SUM(E$16:E$17))*Inputs!S$102)) -> 7312.5 | F28: =IF(F13="","",(F16/(SUM(F$16:F$17))*Inputs!T$102)) -> 7312.5 | G28: =IF(G13="","",(G16/(SUM(G$16:G$17))*Inputs!U$102)) -> 7312.5 | H28: =IF(H13="","",(H16/(SUM(H$16:H$17))*Inputs!V$102)) -> 7312.5 | I28: =IF(I13="","",(I16/(SUM(I$16:I$17))*Inputs!W$102)) -> 7312.5 | J28: =IF(J13="","",(J16/(SUM(J$16:J$17))*Inputs!X$102)) -> 7312.5 | K28: =IF(K13="","",(K16/(SUM(K$16:K$17))*Inputs!Y$102)) -> 7312.5 | ... MY28: =IF(MY13="","",(MY16/(SUM(MY$16:MY$17))*Inputs!NM$102))
B29: Spec Expenses | D29: =IF(D14="","",(D17/(SUM(D$16:D$17))*Inputs!R$102)) -> 0 | E29: =IF(E14="","",(E17/(SUM(E$16:E$17))*Inputs!S$102)) -> 0 | F29: =IF(F14="","",(F17/(SUM(F$16:F$17))*Inputs!T$102)) -> 0 | G29: =IF(G14="","",(G17/(SUM(G$16:G$17))*Inputs!U$102)) -> 0 | H29: =IF(H14="","",(H17/(SUM(H$16:H$17))*Inputs!V$102)) -> 0 | I29: =IF(I14="","",(I17/(SUM(I$16:I$17))*Inputs!W$102)) -> 0 | J29: =IF(J14="","",(J17/(SUM(J$16:J$17))*Inputs!X$102)) -> 0 | K29: =IF(K14="","",(K17/(SUM(K$16:K$17))*Inputs!Y$102)) -> 0 | ... MY29: =IF(MY14="","",(MY17/(SUM(MY$16:MY$17))*Inputs!NM$102))
B31: Credit CapEx | D31: =IF(D$13="","",(D16/(SUM(D$16:D$17))*Inputs!R$107)) -> 562.5 | E31: =IF(E$13="","",(E16/(SUM(E$16:E$17))*Inputs!S$107)) -> 562.5 | F31: =IF(F$13="","",(F16/(SUM(F$16:F$17))*Inputs!T$107)) -> 562.5 | G31: =IF(G$13="","",(G16/(SUM(G$16:G$17))*Inputs!U$107)) -> 562.5 | H31: =IF(H$13="","",(H16/(SUM(H$16:H$17))*Inputs!V$107)) -> 562.5 | I31: =IF(I$13="","",(I16/(SUM(I$16:I$17))*Inputs!W$107)) -> 562.5 | J31: =IF(J$13="","",(J16/(SUM(J$16:J$17))*Inputs!X$107)) -> 562.5 | K31: =IF(K$13="","",(K16/(SUM(K$16:K$17))*Inputs!Y$107)) -> 562.5 | ... MY31: =IF(MY$13="","",(MY16/(SUM(MY$16:MY$17))*Inputs!NM$107))
B32: Spec CapEx | D32: =IF(D$13="","",(D17/(SUM(D$16:D$17))*Inputs!R$107)) -> 0 | E32: =IF(E$13="","",(E17/(SUM(E$16:E$17))*Inputs!S$107)) -> 0 | F32: =IF(F$13="","",(F17/(SUM(F$16:F$17))*Inputs!T$107)) -> 0 | G32: =IF(G$13="","",(G17/(SUM(G$16:G$17))*Inputs!U$107)) -> 0 | H32: =IF(H$13="","",(H17/(SUM(H$16:H$17))*Inputs!V$107)) -> 0 | I32: =IF(I$13="","",(I17/(SUM(I$16:I$17))*Inputs!W$107)) -> 0 | J32: =IF(J$13="","",(J17/(SUM(J$16:J$17))*Inputs!X$107)) -> 0 | K32: =IF(K$13="","",(K17/(SUM(K$16:K$17))*Inputs!Y$107)) -> 0 | ... MY32: =IF(MY$13="","",(MY17/(SUM(MY$16:MY$17))*Inputs!NM$107))
C33: Discount Rate
B34: Credit Cash Flow | C34: =Discount_Rate_Credit -> 0.032 | D34: =IF(D13="","",D16+D19+D22-D25-D28-D31) -> 16773.75 | E34: =IF(E13="","",E16+E19+E22-E25-E28-E31) -> 16773.75 | F34: =IF(F13="","",F16+F19+F22-F25-F28-F31) -> 16773.75 | G34: =IF(G13="","",G16+G19+G22-G25-G28-G31) -> 16773.75 | H34: =IF(H13="","",H16+H19+H22-H25-H28-H31) -> 16773.75 | I34: =IF(I13="","",I16+I19+I22-I25-I28-I31) -> 16773.75 | J34: =IF(J13="","",J16+J19+J22-J25-J28-J31) -> 16773.75 | K34: =IF(K13="","",K16+K19+K22-K25-K28-K31) -> 16773.75 | ... MY34: =IF(MY13="","",MY16+MY19+MY22-MY25-MY28-MY31)
B35: Spec Cash Flow | C35: =Discount_Rate_Spec -> 0.08 | D35: =IF(D14="","",D17+D20+D23-D26-D29-D32) -> 0 | E35: =IF(E14="","",E17+E20+E23-E26-E29-E32) -> 0 | F35: =IF(F14="","",F17+F20+F23-F26-F29-F32) -> 0 | G35: =IF(G14="","",G17+G20+G23-G26-G29-G32) -> 0 | H35: =IF(H14="","",H17+H20+H23-H26-H29-H32) -> 0 | I35: =IF(I14="","",I17+I20+I23-I26-I29-I32) -> 0 | J35: =IF(J14="","",J17+J20+J23-J26-J29-J32) -> 0 | K35: =IF(K14="","",K17+K20+K23-K26-K29-K32) -> 0 | ... MY35: =IF(MY14="","",MY17+MY20+MY23-MY26-MY29-MY32)
B36: Residual Cash Flow | C36: =Discount_Rate_Residual -> 0.08 | D36: =IF(D13="","",(D14=Residual_Month)*Residual_NetValue) -> 0 | E36: =IF(E13="","",(E14=Residual_Month)*Residual_NetValue) -> 0 | F36: =IF(F13="","",(F14=Residual_Month)*Residual_NetValue) -> 0 | G36: =IF(G13="","",(G14=Residual_Month)*Residual_NetValue) -> 0 | H36: =IF(H13="","",(H14=Residual_Month)*Residual_NetValue) -> 0 | I36: =IF(I13="","",(I14=Residual_Month)*Residual_NetValue) -> 0 | J36: =IF(J13="","",(J14=Residual_Month)*Residual_NetValue) -> 0 | K36: =IF(K13="","",(K14=Residual_Month)*Residual_NetValue) -> 0 | ... MY36: =IF(MY13="","",(MY14=Residual_Month)*Residual_NetValue)
C38: PV of CF | D38: Partition
B39: Credit Cash Flow | C39: =XNPV(C34,OFFSET(D34,0,0,1,Residual_Month),OFFSET($D$15,0,0,1,Residual_Month)) -> 2403422.4 | D39: =+C39/$C$42 -> 0.69338407
B40: Spec Cash Flow | C40: =XNPV(C35,OFFSET(D35,0,0,1,Residual_Month),OFFSET($D$15,0,0,1,Residual_Month)) -> 239328.71 | D40: =+C40/$C$42 -> 0.069046003
B41: Residual Cash Flow | C41: =XNPV(C36,OFFSET(D36,0,0,1,Residual_Month),OFFSET($D$15,0,0,1,Residual_Month)) -> 823469.88 | D41: =+C41/$C$42 -> 0.23756993
B42: Present Value | C42: =SUM(C39:C41) -> 3466221 | D42: =+C42/$C$42 -> 1

Sheet Data
B2: STNL VALUTION MODEL | DATA VALIDATION | M2: =Property_Name -> Wal-Aid Fairview
B4: Interest: | C4: =Interest -> Fee Simple | M4: =Version -> v2.4
B6: PROPERTY TYPE | D6: SUB-PROPERTY TYPE | M6: Sub-Property Type
B7: Retail | D7: 1 | E7: 2 | F7: 3 | G7: 4 | H7: 5 | I7: 6 | J7: 7 | K7: 8 | M7: =MATCH(Property_Type,$D$8:$K$8,0) -> 1
B8: Office | D8: =B7 -> Retail | E8: =B8 -> Office | F8: =B9 -> Industrial | G8: =IF(B10="","N/A",B10) -> Farm | H8: =IF(B11="","N/A",B11) -> Special Purpose | I8: =IF(B12="","N/A",B12) -> N/A | J8: =IF(B13="","N/A",B13) -> N/A | K8: =IF(B14="","N/A",B14) -> N/A | M8: =Property_Type -> Retail
B9: Industrial | D9: Bank | E9: Executive Office | F9: Flex | G9: Crop | H9: Marina | M9: =IF(INDEX(D9:K9,1,$M$7)="","",INDEX(D9:K9,1,$M$7)) -> Bank
B10: Farm | D10: Convenience | E10: Medical Office | F10: Warehouse | G10: Pasture | H10: Religious | M10: =IF(INDEX(D10:K10,1,$M$7)="","",INDEX(D10:K10,1,$M$7)) -> Convenience
B11: Special Purpose | D11: Day Care | E11: Creative Office | F11: Distribution | G11: Timber | H11: School | M11: =IF(INDEX(D11:K11,1,$M$7)="","",INDEX(D11:K11,1,$M$7)) -> Day Care
D12: QSR/Fast Food | F12: R&D | G12: Other | H12: Sports | M12: =IF(INDEX(D12:K12,1,$M$7)="","",INDEX(D12:K12,1,$M$7)) -> QSR/Fast Food
D13: Gas Station | F13: Manufacturing | H13: Other | M13: =IF(INDEX(D13:K13,1,$M$7)="","",INDEX(D13:K13,1,$M$7)) -> Gas Station
D14: Grocery | F14: Self Storage | M14: =IF(INDEX(D14:K14,1,$M$7)="","",INDEX(D14:K14,1,$M$7)) -> Grocery
D15: Pharmacy | F15: Cold Storage | M15: =IF(INDEX(D15:K15,1,$M$7)="","",INDEX(D15:K15,1,$M$7)) -> Pharmacy
B16: Current Property Type: | D16: Restaurant | M16: =IF(INDEX(D16:K16,1,$M$7)="","",INDEX(D16:K16,1,$M$7)) -> Restaurant
B17: =Property_Type -> Retail | D17: Bar | M17: =IF(INDEX(D17:K17,1,$M$7)="","",INDEX(D17:K17,1,$M$7)) -> Bar
B18: See Inputs Tab | D18: Storefront | M18: =IF(INDEX(D18:K18,1,$M$7)="","",INDEX(D18:K18,1,$M$7)) -> Storefront
D19: Shopping Center | M19: =IF(INDEX(D19:K19,1,$M$7)="","",INDEX(D19:K19,1,$M$7)) -> Shopping Center
D20: Auto Shop | M20: =IF(INDEX(D20:K20,1,$M$7)="","",INDEX(D20:K20,1,$M$7)) -> Auto Shop
M21: =IF(INDEX(D21:K21,1,$M$7)="","",INDEX(D21:K21,1,$M$7))
M22: =IF(INDEX(D22:K22,1,$M$7)="","",INDEX(D22:K22,1,$M$7))
M23: =IF(INDEX(D23:K23,1,$M$7)="","",INDEX(D23:K23,1,$M$7))
D24: =COUNTA(D9:D23) -> 12 | E24: =COUNTA(E9:E23) -> 3 | F24: =COUNTA(F9:F23) -> 7 | G24: =COUNTA(G9:G23) -> 4 | H24: =COUNTA(H9:H23) -> 5 | I24: =COUNTA(I9:I23) -> 0 | J24: =COUNTA(J9:J23) -> 0 | K24: =COUNTA(K9:K23) -> 0 | M24: =INDEX($D$24:$K$24,1,$M$7) -> 12
B26: CREDIT RATING TYPE | D26: CREDIT RATING BY AGENCY | I26: DISCOUNT RATES
B27: S&P | D27: 1 | E27: 2 | F27: 3 | G27: 4 | J27: 10-Yr UST | K27: 0.007
B28: MOODY'S | C28: Investment Grade | D28: =B27 -> S&P | E28: =B28 -> MOODY'S | F28: =B29 -> FITCH | G28: =B30 -> CUSTOM | I28: =Rating_Type -> S&P | J28: ="Spread over "&J27 -> Spread over 10-Yr UST
B29: FITCH | D29: AAA | E29: Aaa | F29: AAA | G29: AAA | I29: =INDEX(D29:G29,1,MATCH($I$28,$D$28:$G$28,0)) -> AAA | J29: 50 | K29: =(J29/10000)+$K$27 -> 0.012
B30: CUSTOM | D30: AA+ | E30: Aa1 | F30: AA+ | G30: AA+ | I30: =INDEX(D30:G30,1,MATCH($I$28,$D$28:$G$28,0)) -> AA+ | J30: =J29+25 -> 75 | K30: =(J30/10000)+$K$27 -> 0.0145
B31: Long-term Credit Ratings | D31: AA | E31: Aa2 | F31: AA | G31: AA | I31: =INDEX(D31:G31,1,MATCH($I$28,$D$28:$G$28,0)) -> AA | J31: =J30+25 -> 100 | K31: =(J31/10000)+$K$27 -> 0.017
D32: AA− | E32: Aa3 | F32: AA− | G32: AA− | I32: =INDEX(D32:G32,1,MATCH($I$28,$D$28:$G$28,0)) -> AA− | J32: =J31+25 -> 125 | K32: =(J32/10000)+$K$27 -> 0.0195
B33: Credit Rating | D33: A+ | E33: A1 | F33: A+ | G33: A+ | I33: =INDEX(D33:G33,1,MATCH($I$28,$D$28:$G$28,0)) -> A+ | J33: =J32+25 -> 150 | K33: =(J33/10000)+$K$27 -> 0.022
B34: =Rating -> BBB | D34: A | E34: A2 | F34: A | G34: A | I34: =INDEX(D34:G34,1,MATCH($I$28,$D$28:$G$28,0)) -> A | J34: =J33+25 -> 175 | K34: =(J34/10000)+$K$27 -> 0.0245
B35: See Inputs Tab | D35: A− | E35: A3 | F35: A− | G35: A− | I35: =INDEX(D35:G35,1,MATCH($I$28,$D$28:$G$28,0)) -> A− | J35: =J34+25 -> 200 | K35: =(J35/10000)+$K$27 -> 0.027
B36: Discount Rate | D36: BBB+ | E36: Baa1 | F36: BBB+ | G36: BBB+ | I36: =INDEX(D36:G36,1,MATCH($I$28,$D$28:$G$28,0)) -> BBB+ | J36: =J35+25 -> 225 | K36: =(J36/10000)+$K$27 -> 0.0295
B37: =INDEX($K$29:$K$52,MATCH(Rating,$I$29:$I$52,0)) -> 0.032 | D37: BBB | E37: Baa2 | F37: BBB | G37: BBB | I37: =INDEX(D37:G37,1,MATCH($I$28,$D$28:$G$28,0)) -> BBB | J37: =J36+25 -> 250 | K37: =(J37/10000)+$K$27 -> 0.032
C38: Non-Investment Grade | D38: BBB− | E38: Baa3 | F38: BBB− | G38: BBB− | I38: =INDEX(D38:G38,1,MATCH($I$28,$D$28:$G$28,0)) -> BBB− | J38: =J37+25 -> 275 | K38: =(J38/10000)+$K$27 -> 0.0345
D39: BB+ | E39: Ba1 | F39: BB+ | G39: BB+ | I39: =INDEX(D39:G39,1,MATCH($I$28,$D$28:$G$28,0)) -> BB+ | J39: =J38+35 -> 310 | K39: =(J39/10000)+$K$27 -> 0.038
D40: BB | E40: Ba2 | F40: BB | G40: BB | I40: =INDEX(D40:G40,1,MATCH($I$28,$D$28:$G$28,0)) -> BB | J40: =J39+35 -> 345 | K40: =(J40/10000)+$K$27 -> 0.0415
D41: BB− | E41: Ba3 | F41: BB− | G41: BB− | I41: =INDEX(D41:G41,1,MATCH($I$28,$D$28:$G$28,0)) -> BB− | J41: =J40+35 -> 380 | K41: =(J41/10000)+$K$27 -> 0.045
D42: B+ | E42: B1 | F42: B+ | G42: B+ | I42: =INDEX(D42:G42,1,MATCH($I$28,$D$28:$G$28,0)) -> B+ | J42: =J41+35 -> 415 | K42: =(J42/10000)+$K$27 -> 0.0485
D43: B | E43: B2 | F43: B | G43: B | I43: =INDEX(D43:G43,1,MATCH($I$28,$D$28:$G$28,0)) -> B | J43: =J42+35 -> 450 | K43: =(J43/10000)+$K$27 -> 0.052
D44: B− | E44: B3 | F44: B− | G44: B− | I44: =INDEX(D44:G44,1,MATCH($I$28,$D$28:$G$28,0)) -> B− | J44: =J43+35 -> 485 | K44: =(J44/10000)+$K$27 -> 0.0555
...
